Workbook

Sheet 요약
A2: (주)에이팜건강 자금계획 기초 현황
A3: 기준일 2026-09-21 | 농협·우리은행·국민은행 계좌 거래내역 통합 (자동 갱신)
A5: 항목 | B5: 금액 | D5: 계좌 | E5: 최종 거래일 | F5: 잔액
A6: 현재 계좌잔액 | B6: 140020847 | D6: 국민 154577 | E6: 46285 | F6: 20184954
A7: 6개월 외부입금 | B7: 2667659335 | D7: 국민 169124 | E7: 46280 | F7: 100687200
A8: 6개월 외부출금 | B8: 3070029191 | D8: 농협 569003 | E8: 46283 | F8: 1834429
A9: 온라인매출 입금 | B9: 1976158603 | D9: 우리 220351 | E9: 46286 | F9: 17314264
A10: 최근 12주 주평균 온라인입금 | B10: 70815416
A12: 계획 설정 | B12: 값 | D12: 사용 방법
A13: 입금 예측 반영률 | B13: 0.8 | D13: 1. 새 계좌파일을 올리면 RAW 통합표에 이어 붙입니다.
A14: 4주 예상 기말잔액 | B14: ='4주일별계획'!J33 | D14: 2. 노란색 칸에 확정 입금·지출계획을 입력합니다.
A15: 4주 최저 예상잔액 | B15: =MIN('4주일별계획'!J6:J33) | D15: ="3. 온라인 입금은 최근 12주 요일별 평균의 "&TEXT($B$13,"0%")&"로 예측합니다."
A16: 13주 예상 기말잔액 | B16: ='13주주별계획'!J18 | D16: 4. 계좌 간 이체는 내부이체로 표시해 입출금 합계에서 제외합니다.
D17: 5. 정기지출분석의 '확인필요' 항목은 성격을 확인 후 확정합니다.

Sheet 업데이트운영
A2: 계좌 거래내역 업데이트 운영 방법
A3: 6개월 자료는 최초 1회만 필요합니다. 이후에는 매주 은행 원본파일을 그대로 업로드하면 됩니다.
A5: 항목 | B5: 권장 운영 기준 | D5: 처리단계 | E5: 자동 처리 내용 | F5: 중복 판정 기준 | G5: 결과 | H5: 사용자 작업
A6: 업로드 주기 | B6: 주 1회. 월요일 오전에 전주 월요일~일요일 거래내역을 내려받습니다. | D6: 1. 파일 인식 | E6: 은행별 머리글과 데이터 시작행 판별 | F6: 은행·계좌 | G6: 은행 형식 통일 | H6: 파일 첨부
A7: 권장 조회기간 | B7: 누락 방지를 위해 최근 14일을 조회해도 됩니다. 중복 거래는 자동으로 제외합니다. | D7: 2. 거래 표준화 | E7: 거래일시·입금·출금·잔액·적요 변환 | F7: 거래일시·입출금액·잔액·적요 | G7: RAW 한 표로 통합 | H7: 없음
A8: 업로드 장소 | B8: 이 대화창에 농협·우리은행·국민은행 원본파일을 첨부합니다. | D8: 3. 중복 제거 | E8: 기존 거래와 신규 거래 비교 | F8: 계좌+일시+금액+잔액+적요 | G8: 겹친 조회기간 제거 | H8: 없음
A9: 권장 파일형식 | B9: 은행에서 내려받은 XLS, XLSX, CSV 원본을 권장합니다. | D9: 4. 자동 분류 | E9: 매출·내부이체·세금·보험·카드 등 분류 | F9: 적요 키워드 | G9: 분류 및 정기지출 표시 | H9: 확인필요만 검토
A10: 지양할 형식 | B10: PDF, 사진, 화면 캡처는 열 구조가 일정하지 않아 자동처리에 불리합니다. | D10: 5. 잔액 갱신 | E10: 계좌별 최종 거래 잔액 반영 | F10: 가장 최근 거래일시 | G10: 전체 가용잔액 갱신 | H10: 없음
A11: 파일명 | B11: 은행이 만들어 준 원래 파일명을 그대로 사용해도 됩니다. | D11: 6. 계획 갱신 | E11: 최근 12주 패턴 및 선택 반영률 적용 | F11: 드롭다운 반영률 | G11: 4주·13주 전망 변경 | H11: 예정 지출만 보완
A12: 업데이트 요청문 | B12: '이번 주 계좌내역 반영해서 자금계획 업데이트해줘'라고 입력합니다.
A13: 직접 입력 | B13: 거래내역은 복사·붙여넣지 않습니다. 향후 확정 입금·지출계획만 노란색 칸에 입력합니다.
A16: 은행 | B16: 현재 기준 원본파일 | C16: 조회 시작 | D16: 조회 종료 | E16: 반영 거래건수 | F16: 상태
A17: 농협 | B17: 농협계좌_6개월(20260913).xls | C17: 46094 | D17: 46278 | E17: 234 | F17: 반영완료
A18: 우리은행 | B18: 우리은행 거래내역조회 20260913.xlsx | C18: 46095 | D18: 46278 | E18: 862 | F18: 반영완료
A19: 국민은행 | B19: 국민은행_계좌 조회 6개월(20260913).xls | C19: 46095 | D19: 46278 | E19: 995 | F19: 반영완료

Sheet 4주일별계획
A2: 향후 4주 일별 자금계획
A3: ="온라인 예상입금은 최근 12주 요일별 평균 × "&TEXT('요약'!$B$13,"0%")&"로 계산됩니다. 노란색 칸만 입력하세요."
A5: 일자 | B5: 요일 | C5: 온라인 예상입금 | D5: 확정·기타입금 | E5: 송금예정 | F5: 카드결제 | G5: 조정·추정 지출 | H5: 순현금흐름 | I5: 기초잔액 | J5: 기말잔액 | K5: 비고
A6: 46286 | B6: 월 | C6: =INDEX('설정및분류'!$C$6:$C$12,WEEKDAY(A6,2))*'요약'!$B$13 | E6: 5494000 | G6: 5120000 | H6: =C6+D6-E6-F6-G6 | I6: 134654720 | J6: =I6+H6 | K6: 메트라이프 4,900,000, 네이버SA&GFA 3,498,000, 트라이앵글하모니 1,996,000, SK브로드밴드 220,000
A7: 46287 | B7: 화 | C7: =INDEX('설정및분류'!$C$6:$C$12,WEEKDAY(A7,2))*'요약'!$B$13 | E7: 21523110 | H7: =C7+D7-E7-F7-G7 | I7: =J6 | J7: =I7+H7 | K7: 엠에스바이오텍 20,000,000, 와이투홀딩스 1,023,110, 네이버 500,000
A8: 46288 | B8: 수 | C8: =INDEX('설정및분류'!$C$6:$C$12,WEEKDAY(A8,2))*'요약'!$B$13 | E8: 13642786 | G8: 32174232 | H8: =C8+D8-E8-F8-G8 | I8: =J7 | J8: =I8+H8 | K8: 우리카드 25,346,349, 네이버SA&GFA 8,305,000, 농협카드 6,827,883, 인포크비즈니스 3,300,000, 써치엠 1,487,786, ADN 550,000
A9: 46289 | B9: 목 | C9: 0 | H9: =C9+D9-E9-F9-G9 | I9: =J8 | J9: =I9+H9
A10: 46290 | B10: 금 | C10: 0 | G10: 2606450 | H10: =C10+D10-E10-F10-G10 | I10: =J9 | J10: =I10+H10 | K10: 메트라이프 2,497,000, KT 109,450
A11: 46291 | B11: 토 | C11: 0 | H11: =C11+D11-E11-F11-G11 | I11: =J10 | J11: =I11+H11
A12: 46292 | B12: 일 | C12: =INDEX('설정및분류'!$C$6:$C$12,WEEKDAY(A12,2))*'요약'!$B$13 | H12: =C12+D12-E12-F12-G12 | I12: =J11 | J12: =I12+H12
A13: 46293 | B13: 월 | C13: =INDEX('설정및분류'!$C$6:$C$12,WEEKDAY(A13,2))*'요약'!$B$13 | E13: 1650000 | H13: =C13+D13-E13-F13-G13 | I13: =J12 | J13: =I13+H13 | K13: 엘앤에이치컴퍼니 1,650,000
A14: 46294 | B14: 화 | C14: =INDEX('설정및분류'!$C$6:$C$12,WEEKDAY(A14,2))*'요약'!$B$13 | H14: =C14+D14-E14-F14-G14 | I14: =J13 | J14: =I14+H14
A15: 46295 | B15: 수 | C15: =INDEX('설정및분류'!$C$6:$C$12,WEEKDAY(A15,2))*'요약'!$B$13 | D15: 10021867 | H15: =C15+D15-E15-F15-G15 | I15: =J14 | J15: =I15+H15 | K15: 관계사 외상대 입금 추정(주식회사에이팜, 말일)
A16: 46296 | B16: 목 | C16: =INDEX('설정및분류'!$C$6:$C$12,WEEKDAY(A16,2))*'요약'!$B$13 | H16: =C16+D16-E16-F16-G16 | I16: =J15 | J16: =I16+H16
A17: 46297 | B17: 금 | C17: =INDEX('설정및분류'!$C$6:$C$12,WEEKDAY(A17,2))*'요약'!$B$13 | H17: =C17+D17-E17-F17-G17 | I17: =J16 | J17: =I17+H17
A18: 46298 | B18: 토 | C18: 0 | H18: =C18+D18-E18-F18-G18 | I18: =J17 | J18: =I18+H18
A19: 46299 | B19: 일 | C19: =INDEX('설정및분류'!$C$6:$C$12,WEEKDAY(A19,2))*'요약'!$B$13 | H19: =C19+D19-E19-F19-G19 | I19: =J18 | J19: =I19+H19
A20: 46300 | B20: 월 | C20: 0 | H20: =C20+D20-E20-F20-G20 | I20: =J19 | J20: =I20+H20
A21: 46301 | B21: 화 | C21: =INDEX('설정및분류'!$C$6:$C$12,WEEKDAY(A21,2))*'요약'!$B$13 | H21: =C21+D21-E21-F21-G21 | I21: =J20 | J21: =I21+H21
A22: 46302 | B22: 수 | C22: =INDEX('설정및분류'!$C$6:$C$12,WEEKDAY(A22,2))*'요약'!$B$13 | H22: =C22+D22-E22-F22-G22 | I22: =J21 | J22: =I22+H22
A23: 46303 | B23: 목 | C23: =INDEX('설정및분류'!$C$6:$C$12,WEEKDAY(A23,2))*'요약'!$B$13 | H23: =C23+D23-E23-F23-G23 | I23: =J22 | J23: =I23+H23
A24: 46304 | B24: 금 | C24: 0 | H24: =C24+D24-E24-F24-G24 | I24: =J23 | J24: =I24+H24
A25: 46305 | B25: 토 | C25: =INDEX('설정및분류'!$C$6:$C$12,WEEKDAY(A25,2))*'요약'!$B$13 | H25: =C25+D25-E25-F25-G25 | I25: =J24 | J25: =I25+H25
A26: 46306 | B26: 일 | C26: =INDEX('설정및분류'!$C$6:$C$12,WEEKDAY(A26,2))*'요약'!$B$13 | H26: =C26+D26-E26-F26-G26 | I26: =J25 | J26: =I26+H26
A27: 46307 | B27: 월 | C27: =INDEX('설정및분류'!$C$6:$C$12,WEEKDAY(A27,2))*'요약'!$B$13 | H27: =C27+D27-E27-F27-G27 | I27: =J26 | J27: =I27+H27
A28: 46308 | B28: 화 | C28: =INDEX('설정및분류'!$C$6:$C$12,WEEKDAY(A28,2))*'요약'!$B$13 | H28: =C28+D28-E28-F28-G28 | I28: =J27 | J28: =I28+H28
A29: 46309 | B29: 수 | C29: =INDEX('설정및분류'!$C$6:$C$12,WEEKDAY(A29,2))*'요약'!$B$13 | H29: =C29+D29-E29-F29-G29 | I29: =J28 | J29: =I29+H29
A30: 46310 | B30: 목 | C30: =INDEX('설정및분류'!$C$6:$C$12,WEEKDAY(A30,2))*'요약'!$B$13 | H30: =C30+D30-E30-F30-G30 | I30: =J29 | J30: =I30+H30
A31: 46311 | B31: 금 | C31: =INDEX('설정및분류'!$C$6:$C$12,WEEKDAY(A31,2))*'요약'!$B$13 | H31: =C31+D31-E31-F31-G31 | I31: =J30 | J31: =I31+H31
A32: 46312 | B32: 토 | C32: =INDEX('설정및분류'!$C$6:$C$12,WEEKDAY(A32,2))*'요약'!$B$13 | H32: =C32+D32-E32-F32-G32 | I32: =J31 | J32: =I32+H32
A33: 46313 | B33: 일 | C33: =INDEX('설정및분류'!$C$6:$C$12,WEEKDAY(A33,2))*'요약'!$B$13 | H33: =C33+D33-E33-F33-G33 | I33: =J32 | J33: =I33+H33

Sheet 계좌별시나리오
A2: 계좌별 일별 잔액 시나리오 (자동 반영)
A3: 읽는 법: 오늘 총잔액 = 전날 총잔액 + ② 입금 합계 − ③ 지출. 지출은 전액 우리은행에서 집행하고, 모자라면 ④처럼 농협 → 국민 순으로 우리은행에 이체해 채웁니다. '요약' 시트의 입금 반영률(B13)을 바꾸면 이 표도 즉시 다시 계산됩니다. 지난 실적 일자 행은 숨김(마지막 실적일 잔액에서 출발), 실수 방지를 위해 시트 보호(암호 없음). ② 배분 비중(최근 입금 실적): 우리 220351 50% · 농협 569003 3% · 국민 169124 19% · 국민 154577 28%
A4: 일자 | B4: 요일 | C4: ① 잔액 (총잔액 · 계좌별) | H4: ② 오늘 들어오는 돈 — 예상입금 배분 | M4: ③ 지출 | N4: ④ 부족분 이체 | P4: 비고
C5: 총잔액 | D5: 우리 220351 | E5: 농협 569003 | F5: 국민 169124 | G5: 국민 154577 | H5: 합계 | I5: 우리 220351 | J5: 농협 569003 | K5: 국민 169124 | L5: 국민 154577 | M5: 우리은행 집행 | N5: 농협→우리 | O5: 국민→우리
A6: 46286 | B6: 월 | C6: =SUM(D6:G6) | D6: =11948137.00+I6-M6+Q6+R6+S6 | E6: =1834429.00+J6-Q6 | F6: =100687200.00+K6-R6 | G6: =20184954.00+L6-S6 | H6: ='4주일별계획'!C6+'4주일별계획'!D6 | I6: =H6*0.503194 | J6: =H6*0.025182 | K6: =H6*0.191179 | L6: =H6*0.280445 | M6: ='4주일별계획'!E6+'4주일별계획'!F6+'4주일별계획'!G6 | N6: =Q6 | O6: =R6+S6 | P6: =IF(D6<-0.5,"전 계좌 소진 — 부족 "&TEXT(-D6,"#,##0")&"원","") | Q6: =MIN(MAX(0,1834429.00+J6),MAX(0,M6-11948137.00-I6)) | R6: =MIN(MAX(0,100687200.00+K6),MAX(0,M6-11948137.00-I6)-Q6) | S6: =MIN(MAX(0,20184954.00+L6),MAX(0,M6-11948137.00-I6)-Q6-R6)
A7: 46287 | B7: 화 | C7: =SUM(D7:G7) | D7: =D6+I7-M7+Q7+R7+S7 | E7: =E6+J7-Q7 | F7: =F6+K7-R7 | G7: =G6+L7-S7 | H7: ='4주일별계획'!C7+'4주일별계획'!D7 | I7: =H7*0.503194 | J7: =H7*0.025182 | K7: =H7*0.191179 | L7: =H7*0.280445 | M7: ='4주일별계획'!E7+'4주일별계획'!F7+'4주일별계획'!G7 | N7: =Q7 | O7: =R7+S7 | P7: =IF(D7<-0.5,"전 계좌 소진 — 부족 "&TEXT(-D7,"#,##0")&"원","") | Q7: =MIN(MAX(0,E6+J7),MAX(0,M7-D6-I7)) | R7: =MIN(MAX(0,F6+K7),MAX(0,M7-D6-I7)-Q7) | S7: =MIN(MAX(0,G6+L7),MAX(0,M7-D6-I7)-Q7-R7)
A8: 46288 | B8: 수 | C8: =SUM(D8:G8) | D8: =D7+I8-M8+Q8+R8+S8 | E8: =E7+J8-Q8 | F8: =F7+K8-R8 | G8: =G7+L8-S8 | H8: ='4주일별계획'!C8+'4주일별계획'!D8 | I8: =H8*0.503194 | J8: =H8*0.025182 | K8: =H8*0.191179 | L8: =H8*0.280445 | M8: ='4주일별계획'!E8+'4주일별계획'!F8+'4주일별계획'!G8 | N8: =Q8 | O8: =R8+S8 | P8: =IF(D8<-0.5,"전 계좌 소진 — 부족 "&TEXT(-D8,"#,##0")&"원","") | Q8: =MIN(MAX(0,E7+J8),MAX(0,M8-D7-I8)) | R8: =MIN(MAX(0,F7+K8),MAX(0,M8-D7-I8)-Q8) | S8: =MIN(MAX(0,G7+L8),MAX(0,M8-D7-I8)-Q8-R8)
A9: 46289 | B9: 목 | C9: =SUM(D9:G9) | D9: =D8+I9-M9+Q9+R9+S9 | E9: =E8+J9-Q9 | F9: =F8+K9-R9 | G9: =G8+L9-S9 | H9: ='4주일별계획'!C9+'4주일별계획'!D9 | I9: =H9*0.503194 | J9: =H9*0.025182 | K9: =H9*0.191179 | L9: =H9*0.280445 | M9: ='4주일별계획'!E9+'4주일별계획'!F9+'4주일별계획'!G9 | N9: =Q9 | O9: =R9+S9 | P9: =IF(D9<-0.5,"전 계좌 소진 — 부족 "&TEXT(-D9,"#,##0")&"원","") | Q9: =MIN(MAX(0,E8+J9),MAX(0,M9-D8-I9)) | R9: =MIN(MAX(0,F8+K9),MAX(0,M9-D8-I9)-Q9) | S9: =MIN(MAX(0,G8+L9),MAX(0,M9-D8-I9)-Q9-R9)
A10: 46290 | B10: 금 | C10: =SUM(D10:G10) | D10: =D9+I10-M10+Q10+R10+S10 | E10: =E9+J10-Q10 | F10: =F9+K10-R10 | G10: =G9+L10-S10 | H10: ='4주일별계획'!C10+'4주일별계획'!D10 | I10: =H10*0.503194 | J10: =H10*0.025182 | K10: =H10*0.191179 | L10: =H10*0.280445 | M10: ='4주일별계획'!E10+'4주일별계획'!F10+'4주일별계획'!G10 | N10: =Q10 | O10: =R10+S10 | P10: =IF(D10<-0.5,"전 계좌 소진 — 부족 "&TEXT(-D10,"#,##0")&"원","") | Q10: =MIN(MAX(0,E9+J10),MAX(0,M10-D9-I10)) | R10: =MIN(MAX(0,F9+K10),MAX(0,M10-D9-I10)-Q10) | S10: =MIN(MAX(0,G9+L10),MAX(0,M10-D9-I10)-Q10-R10)
A11: 46291 | B11: 토 | C11: =SUM(D11:G11) | D11: =D10+I11-M11+Q11+R11+S11 | E11: =E10+J11-Q11 | F11: =F10+K11-R11 | G11: =G10+L11-S11 | H11: ='4주일별계획'!C11+'4주일별계획'!D11 | I11: =H11*0.503194 | J11: =H11*0.025182 | K11: =H11*0.191179 | L11: =H11*0.280445 | M11: ='4주일별계획'!E11+'4주일별계획'!F11+'4주일별계획'!G11 | N11: =Q11 | O11: =R11+S11 | P11: =IF(D11<-0.5,"전 계좌 소진 — 부족 "&TEXT(-D11,"#,##0")&"원","") | Q11: =MIN(MAX(0,E10+J11),MAX(0,M11-D10-I11)) | R11: =MIN(MAX(0,F10+K11),MAX(0,M11-D10-I11)-Q11) | S11: =MIN(MAX(0,G10+L11),MAX(0,M11-D10-I11)-Q11-R11)
A12: 46292 | B12: 일 | C12: =SUM(D12:G12) | D12: =D11+I12-M12+Q12+R12+S12 | E12: =E11+J12-Q12 | F12: =F11+K12-R12 | G12: =G11+L12-S12 | H12: ='4주일별계획'!C12+'4주일별계획'!D12 | I12: =H12*0.503194 | J12: =H12*0.025182 | K12: =H12*0.191179 | L12: =H12*0.280445 | M12: ='4주일별계획'!E12+'4주일별계획'!F12+'4주일별계획'!G12 | N12: =Q12 | O12: =R12+S12 | P12: =IF(D12<-0.5,"전 계좌 소진 — 부족 "&TEXT(-D12,"#,##0")&"원","") | Q12: =MIN(MAX(0,E11+J12),MAX(0,M12-D11-I12)) | R12: =MIN(MAX(0,F11+K12),MAX(0,M12-D11-I12)-Q12) | S12: =MIN(MAX(0,G11+L12),MAX(0,M12-D11-I12)-Q12-R12)
A13: 46293 | B13: 월 | C13: =SUM(D13:G13) | D13: =D12+I13-M13+Q13+R13+S13 | E13: =E12+J13-Q13 | F13: =F12+K13-R13 | G13: =G12+L13-S13 | H13: ='4주일별계획'!C13+'4주일별계획'!D13 | I13: =H13*0.503194 | J13: =H13*0.025182 | K13: =H13*0.191179 | L13: =H13*0.280445 | M13: ='4주일별계획'!E13+'4주일별계획'!F13+'4주일별계획'!G13 | N13: =Q13 | O13: =R13+S13 | P13: =IF(D13<-0.5,"전 계좌 소진 — 부족 "&TEXT(-D13,"#,##0")&"원","") | Q13: =MIN(MAX(0,E12+J13),MAX(0,M13-D12-I13)) | R13: =MIN(MAX(0,F12+K13),MAX(0,M13-D12-I13)-Q13) | S13: =MIN(MAX(0,G12+L13),MAX(0,M13-D12-I13)-Q13-R13)
A14: 46294 | B14: 화 | C14: =SUM(D14:G14) | D14: =D13+I14-M14+Q14+R14+S14 | E14: =E13+J14-Q14 | F14: =F13+K14-R14 | G14: =G13+L14-S14 | H14: ='4주일별계획'!C14+'4주일별계획'!D14 | I14: =H14*0.503194 | J14: =H14*0.025182 | K14: =H14*0.191179 | L14: =H14*0.280445 | M14: ='4주일별계획'!E14+'4주일별계획'!F14+'4주일별계획'!G14 | N14: =Q14 | O14: =R14+S14 | P14: =IF(D14<-0.5,"전 계좌 소진 — 부족 "&TEXT(-D14,"#,##0")&"원","") | Q14: =MIN(MAX(0,E13+J14),MAX(0,M14-D13-I14)) | R14: =MIN(MAX(0,F13+K14),MAX(0,M14-D13-I14)-Q14) | S14: =MIN(MAX(0,G13+L14),MAX(0,M14-D13-I14)-Q14-R14)
A15: 46295 | B15: 수 | C15: =SUM(D15:G15) | D15: =D14+I15-M15+Q15+R15+S15 | E15: =E14+J15-Q15 | F15: =F14+K15-R15 | G15: =G14+L15-S15 | H15: ='4주일별계획'!C15+'4주일별계획'!D15 | I15: =H15*0.503194 | J15: =H15*0.025182 | K15: =H15*0.191179 | L15: =H15*0.280445 | M15: ='4주일별계획'!E15+'4주일별계획'!F15+'4주일별계획'!G15 | N15: =Q15 | O15: =R15+S15 | P15: =IF(D15<-0.5,"전 계좌 소진 — 부족 "&TEXT(-D15,"#,##0")&"원","") | Q15: =MIN(MAX(0,E14+J15),MAX(0,M15-D14-I15)) | R15: =MIN(MAX(0,F14+K15),MAX(0,M15-D14-I15)-Q15) | S15: =MIN(MAX(0,G14+L15),MAX(0,M15-D14-I15)-Q15-R15)
A16: 46296 | B16: 목 | C16: =SUM(D16:G16) | D16: =D15+I16-M16+Q16+R16+S16 | E16: =E15+J16-Q16 | F16: =F15+K16-R16 | G16: =G15+L16-S16 | H16: ='4주일별계획'!C16+'4주일별계획'!D16 | I16: =H16*0.503194 | J16: =H16*0.025182 | K16: =H16*0.191179 | L16: =H16*0.280445 | M16: ='4주일별계획'!E16+'4주일별계획'!F16+'4주일별계획'!G16 | N16: =Q16 | O16: =R16+S16 | P16: =IF(D16<-0.5,"전 계좌 소진 — 부족 "&TEXT(-D16,"#,##0")&"원","") | Q16: =MIN(MAX(0,E15+J16),MAX(0,M16-D15-I16)) | R16: =MIN(MAX(0,F15+K16),MAX(0,M16-D15-I16)-Q16) | S16: =MIN(MAX(0,G15+L16),MAX(0,M16-D15-I16)-Q16-R16)
A17: 46297 | B17: 금 | C17: =SUM(D17:G17) | D17: =D16+I17-M17+Q17+R17+S17 | E17: =E16+J17-Q17 | F17: =F16+K17-R17 | G17: =G16+L17-S17 | H17: ='4주일별계획'!C17+'4주일별계획'!D17 | I17: =H17*0.503194 | J17: =H17*0.025182 | K17: =H17*0.191179 | L17: =H17*0.280445 | M17: ='4주일별계획'!E17+'4주일별계획'!F17+'4주일별계획'!G17 | N17: =Q17 | O17: =R17+S17 | P17: =IF(D17<-0.5,"전 계좌 소진 — 부족 "&TEXT(-D17,"#,##0")&"원","") | Q17: =MIN(MAX(0,E16+J17),MAX(0,M17-D16-I17)) | R17: =MIN(MAX(0,F16+K17),MAX(0,M17-D16-I17)-Q17) | S17: =MIN(MAX(0,G16+L17),MAX(0,M17-D16-I17)-Q17-R17)
A18: 46298 | B18: 토 | C18: =SUM(D18:G18) | D18: =D17+I18-M18+Q18+R18+S18 | E18: =E17+J18-Q18 | F18: =F17+K18-R18 | G18: =G17+L18-S18 | H18: ='4주일별계획'!C18+'4주일별계획'!D18 | I18: =H18*0.503194 | J18: =H18*0.025182 | K18: =H18*0.191179 | L18: =H18*0.280445 | M18: ='4주일별계획'!E18+'4주일별계획'!F18+'4주일별계획'!G18 | N18: =Q18 | O18: =R18+S18 | P18: =IF(D18<-0.5,"전 계좌 소진 — 부족 "&TEXT(-D18,"#,##0")&"원","") | Q18: =MIN(MAX(0,E17+J18),MAX(0,M18-D17-I18)) | R18: =MIN(MAX(0,F17+K18),MAX(0,M18-D17-I18)-Q18) | S18: =MIN(MAX(0,G17+L18),MAX(0,M18-D17-I18)-Q18-R18)
... A33: 46313 | B33: 일 | C33: =SUM(D33:G33) | D33: =D32+I33-M33+Q33+R33+S33 | E33: =E32+J33-Q33 | F33: =F32+K33-R33 | G33: =G32+L33-S33 | H33: ='4주일별계획'!C33+'4주일별계획'!D33 | I33: =H33*0.503194 | J33: =H33*0.025182 | K33: =H33*0.191179 | L33: =H33*0.280445 | M33: ='4주일별계획'!E33+'4주일별계획'!F33+'4주일별계획'!G33 | N33: =Q33 | O33: =R33+S33 | P33: =IF(D33<-0.5,"전 계좌 소진 — 부족 "&TEXT(-D33,"#,##0")&"원","") | Q33: =MIN(MAX(0,E32+J33),MAX(0,M33-D32-I33)) | R33: =MIN(MAX(0,F32+K33),MAX(0,M33-D32-I33)-Q33) | S33: =MIN(MAX(0,G32+L33),MAX(0,M33-D32-I33)-Q33-R33)

Sheet 13주주별계획
A2: 향후 13주 주별 자금계획
A3: ="온라인 예상입금 반영률 "&TEXT('요약'!$B$13,"0%")&" 적용. 1~4주는 일별 계획 합계, 5~13주는 자동 예상입금과 입력한 주간 계획을 반영합니다."
A5: 주차 | B5: 기간 | C5: 온라인 예상입금 | D5: 확정·기타입금 | E5: 송금예정 | F5: 카드결제 | G5: 조정·추정 지출 | H5: 추가 주간조정 | I5: 순현금흐름 | J5: 기말잔액 | K5: 상태
A6: 1주차 | B6: 2026-09-21 ~ 2026-09-27 | C6: =SUMIFS('4주일별계획'!$C$6:$C$33,'4주일별계획'!$A$6:$A$33,">="&DATE(2026,9,21),'4주일별계획'!$A$6:$A$33,"<="&DATE(2026,9,27)) | D6: =SUMIFS('4주일별계획'!$D$6:$D$33,'4주일별계획'!$A$6:$A$33,">="&DATE(2026,9,21),'4주일별계획'!$A$6:$A$33,"<="&DATE(2026,9,27)) | E6: =SUMIFS('4주일별계획'!$E$6:$E$33,'4주일별계획'!$A$6:$A$33,">="&DATE(2026,9,21),'4주일별계획'!$A$6:$A$33,"<="&DATE(2026,9,27)) | F6: =SUMIFS('4주일별계획'!$F$6:$F$33,'4주일별계획'!$A$6:$A$33,">="&DATE(2026,9,21),'4주일별계획'!$A$6:$A$33,"<="&DATE(2026,9,27)) | G6: =SUMIFS('4주일별계획'!$G$6:$G$33,'4주일별계획'!$A$6:$A$33,">="&DATE(2026,9,21),'4주일별계획'!$A$6:$A$33,"<="&DATE(2026,9,27)) | I6: =C6+D6-E6-F6-G6+H6 | J6: ='요약'!$B$6+I6 | K6: =IF(J6<0,"자금부족",IF(J6<'요약'!$B$6*0.2,"주의","정상"))
A7: 2주차 | B7: 2026-09-28 ~ 2026-10-04 | C7: =SUMIFS('4주일별계획'!$C$6:$C$33,'4주일별계획'!$A$6:$A$33,">="&DATE(2026,9,28),'4주일별계획'!$A$6:$A$33,"<="&DATE(2026,10,4)) | D7: =SUMIFS('4주일별계획'!$D$6:$D$33,'4주일별계획'!$A$6:$A$33,">="&DATE(2026,9,28),'4주일별계획'!$A$6:$A$33,"<="&DATE(2026,10,4)) | E7: =SUMIFS('4주일별계획'!$E$6:$E$33,'4주일별계획'!$A$6:$A$33,">="&DATE(2026,9,28),'4주일별계획'!$A$6:$A$33,"<="&DATE(2026,10,4)) | F7: =SUMIFS('4주일별계획'!$F$6:$F$33,'4주일별계획'!$A$6:$A$33,">="&DATE(2026,9,28),'4주일별계획'!$A$6:$A$33,"<="&DATE(2026,10,4)) | G7: =SUMIFS('4주일별계획'!$G$6:$G$33,'4주일별계획'!$A$6:$A$33,">="&DATE(2026,9,28),'4주일별계획'!$A$6:$A$33,"<="&DATE(2026,10,4)) | I7: =C7+D7-E7-F7-G7+H7 | J7: =J6+I7 | K7: =IF(J7<0,"자금부족",IF(J7<'요약'!$B$6*0.2,"주의","정상"))
A8: 3주차 | B8: 2026-10-05 ~ 2026-10-11 | C8: =SUMIFS('4주일별계획'!$C$6:$C$33,'4주일별계획'!$A$6:$A$33,">="&DATE(2026,10,5),'4주일별계획'!$A$6:$A$33,"<="&DATE(2026,10,11)) | D8: =SUMIFS('4주일별계획'!$D$6:$D$33,'4주일별계획'!$A$6:$A$33,">="&DATE(2026,10,5),'4주일별계획'!$A$6:$A$33,"<="&DATE(2026,10,11)) | E8: =SUMIFS('4주일별계획'!$E$6:$E$33,'4주일별계획'!$A$6:$A$33,">="&DATE(2026,10,5),'4주일별계획'!$A$6:$A$33,"<="&DATE(2026,10,11)) | F8: =SUMIFS('4주일별계획'!$F$6:$F$33,'4주일별계획'!$A$6:$A$33,">="&DATE(2026,10,5),'4주일별계획'!$A$6:$A$33,"<="&DATE(2026,10,11)) | G8: =SUMIFS('4주일별계획'!$G$6:$G$33,'4주일별계획'!$A$6:$A$33,">="&DATE(2026,10,5),'4주일별계획'!$A$6:$A$33,"<="&DATE(2026,10,11)) | I8: =C8+D8-E8-F8-G8+H8 | J8: =J7+I8 | K8: =IF(J8<0,"자금부족",IF(J8<'요약'!$B$6*0.2,"주의","정상"))
A9: 4주차 | B9: 2026-10-12 ~ 2026-10-18 | C9: =SUMIFS('4주일별계획'!$C$6:$C$33,'4주일별계획'!$A$6:$A$33,">="&DATE(2026,10,12),'4주일별계획'!$A$6:$A$33,"<="&DATE(2026,10,18)) | D9: =SUMIFS('4주일별계획'!$D$6:$D$33,'4주일별계획'!$A$6:$A$33,">="&DATE(2026,10,12),'4주일별계획'!$A$6:$A$33,"<="&DATE(2026,10,18)) | E9: =SUMIFS('4주일별계획'!$E$6:$E$33,'4주일별계획'!$A$6:$A$33,">="&DATE(2026,10,12),'4주일별계획'!$A$6:$A$33,"<="&DATE(2026,10,18)) | F9: =SUMIFS('4주일별계획'!$F$6:$F$33,'4주일별계획'!$A$6:$A$33,">="&DATE(2026,10,12),'4주일별계획'!$A$6:$A$33,"<="&DATE(2026,10,18)) | G9: =SUMIFS('4주일별계획'!$G$6:$G$33,'4주일별계획'!$A$6:$A$33,">="&DATE(2026,10,12),'4주일별계획'!$A$6:$A$33,"<="&DATE(2026,10,18)) | I9: =C9+D9-E9-F9-G9+H9 | J9: =J8+I9 | K9: =IF(J9<0,"자금부족",IF(J9<'요약'!$B$6*0.2,"주의","정상"))
A10: 5주차 | B10: 2026-10-19 ~ 2026-10-25 | C10: =SUM('설정및분류'!$C$6:$C$12)*'요약'!$B$13 | F10: 6066502 | G10: 7864831 | I10: =C10+D10-E10-F10-G10+H10 | J10: =J9+I10 | K10: =IF(J10<0,"자금부족",IF(J10<'요약'!$B$6*0.2,"주의","정상"))
A11: 6주차 | B11: 2026-10-26 ~ 2026-11-01 | C11: =SUM('설정및분류'!$C$6:$C$12)*'요약'!$B$13 | D11: 10021867 | F11: 25712983 | G11: 73310994 | I11: =C11+D11-E11-F11-G11+H11 | J11: =J10+I11 | K11: =IF(J11<0,"자금부족",IF(J11<'요약'!$B$6*0.2,"주의","정상"))
A12: 7주차 | B12: 2026-11-02 ~ 2026-11-08 | C12: =SUM('설정및분류'!$C$6:$C$12)*'요약'!$B$13 | G12: 34494000 | I12: =C12+D12-E12-F12-G12+H12 | J12: =J11+I12 | K12: =IF(J12<0,"자금부족",IF(J12<'요약'!$B$6*0.2,"주의","정상"))
A13: 8주차 | B13: 2026-11-09 ~ 2026-11-15 | C13: =SUM('설정및분류'!$C$6:$C$12)*'요약'!$B$13 | G13: 84413290 | I13: =C13+D13-E13-F13-G13+H13 | J13: =J12+I13 | K13: =IF(J13<0,"자금부족",IF(J13<'요약'!$B$6*0.2,"주의","정상"))
A14: 9주차 | B14: 2026-11-16 ~ 2026-11-22 | C14: =SUM('설정및분류'!$C$6:$C$12)*'요약'!$B$13 | F14: 155361 | G14: 5046740 | I14: =C14+D14-E14-F14-G14+H14 | J14: =J13+I14 | K14: =IF(J14<0,"자금부족",IF(J14<'요약'!$B$6*0.2,"주의","정상"))
A15: 10주차 | B15: 2026-11-23 ~ 2026-11-29 | C15: =SUM('설정및분류'!$C$6:$C$12)*'요약'!$B$13 | F15: 31779485 | G15: 7978464 | I15: =C15+D15-E15-F15-G15+H15 | J15: =J14+I15 | K15: =IF(J15<0,"자금부족",IF(J15<'요약'!$B$6*0.2,"주의","정상"))
A16: 11주차 | B16: 2026-11-30 ~ 2026-12-06 | C16: =SUM('설정및분류'!$C$6:$C$12)*'요약'!$B$13 | D16: 10021867 | G16: 103197361 | I16: =C16+D16-E16-F16-G16+H16 | J16: =J15+I16 | K16: =IF(J16<0,"자금부족",IF(J16<'요약'!$B$6*0.2,"주의","정상"))
A17: 12주차 | B17: 2026-12-07 ~ 2026-12-13 | C17: =SUM('설정및분류'!$C$6:$C$12)*'요약'!$B$13 | G17: 88907290 | I17: =C17+D17-E17-F17-G17+H17 | J17: =J16+I17 | K17: =IF(J17<0,"자금부족",IF(J17<'요약'!$B$6*0.2,"주의","정상"))
A18: 13주차 | B18: 2026-12-14 ~ 2026-12-20 | C18: =SUM('설정및분류'!$C$6:$C$12)*'요약'!$B$13 | F18: 155361 | G18: 5046740 | I18: =C18+D18-E18-F18-G18+H18 | J18: =J17+I18 | K18: =IF(J18<0,"자금부족",IF(J18<'요약'!$B$6*0.2,"주의","정상"))

Sheet 지출계획_취합
A2: 팀 지출계획 취합 (자동 반영)
A3: 매 실행마다 팀 제출 파일에서 자동 갱신됩니다. 대외비는 분류·총액만 표시됩니다. 경영보고와 같은 실행일~차주 금요일 기간만 표시합니다 (그 밖의 반영일 행은 숨김 — 행 숨기기 해제로 전체 확인).
A5: 요청ID | B5: 팀명 | C5: 신청자 | D5: 품의승인 | E5: 지급예정일 | F5: 자금계획 반영일 | G5: 거래처 | H5: 지출내용 | I5: 예상금액 | J5: 지급방법 | K5: 카드구분 | L5: 확정여부 | M5: 진행상태 | N5: 최종수정일 | O5: 원본파일 | P5: 반영상태 | Q5: 확인사항
A6: 경영-20260918-011 | B6: 경영지원팀 | C6: 송채은 | E6: 46283 | F6: 46283 | G6: 이앤씨이노비즈타워 | H6: 본사관리비 | I6: 1553720 | J6: 계좌송금 | L6: 확정 | M6: 신규 | N6: 46283 | O6: 지출계획_2026-09-21.xlsx | P6: 에이팜 별도관리
A7: 건강-20260918-001 | B7: 건강사업팀 | C7: 양혜원 | E7: 46286 | F7: 46286 | G7: 트라이앵글하모니 | H7: 카카오톡선물하기 베리시톨 리뷰작업 | I7: 1996000 | J7: 계좌송금 | L7: 확정 | M7: 신규 | N7: 46283 | O7: 지출계획_2026-09-21.xlsx | P7: 정상반영
A8: 건강-20260918-003 | B8: 건강사업팀 | C8: 전은신 | E8: 46286 | F8: 46286 | G8: 네이버SA&GFA | H8: 네이버 SA&GFA 광고비 충전 | I8: 3498000 | J8: 계좌송금 | L8: 확정 | M8: 변경 | N8: 46283 | O8: 지출계획_2026-09-21.xlsx | P8: 정상반영
A9: 경영-20260918-005 | B9: 경영지원팀 | C9: 김수희 | E9: 46286 | F9: 46286 | G9: 메트라이프 | H9: 달러경영인정기보험_63회차/55회차 | I9: 4900000 | J9: 자동이체 | L9: 확정 | M9: 변경 | N9: 46283 | O9: 지출계획_2026-09-21.xlsx | P9: 정상반영
A10: 경영-20260918-006 | B10: 경영지원팀 | C10: 김수희 | E10: 46286 | F10: 46286 | G10: SK브로드밴드 | H10: 사내전화 | I10: 220000 | J10: 자동이체 | L10: 확정 | M10: 신규 | N10: 46283 | O10: 지출계획_2026-09-21.xlsx | P10: 정상반영
A11: 건강-20260918-002 | B11: 건강사업팀 | C11: 양혜원 | E11: 46287 | F11: 46287 | G11: 네이버 | H11: 네이버 톡톡 발송 | I11: 500000 | J11: 계좌송금 | L11: 확정 | M11: 신규 | N11: 46283 | O11: 지출계획_2026-09-21.xlsx | P11: 정상반영
A12: 경영-20260918-007 | B12: 경영지원팀 | C12: 송채은 | E12: 46287 | F12: 46287 | G12: 와이투홀딩스 | H12: 직원 추석 선물세트 구입 | I12: 1023110 | J12: 계좌송금 | L12: 확정 | M12: 변경 | N12: 46283 | O12: 지출계획_2026-09-21.xlsx | P12: 정상반영
A13: 경영-20260918-015 | B13: 경영지원팀 | C13: 김정원 | E13: 46287 | F13: 46287 | G13: 엠에스바이오텍 | H13: 외상매입금 | I13: 20000000 | J13: 계좌송금 | L13: 확정 | M13: 변경 | N13: 46284 | O13: 지출계획_2026-09-21.xlsx | P13: 정상반영
A14: 건강-20260918-004 | B14: 건강사업팀 | C14: 전은신 | E14: 46288 | F14: 46288 | G14: 인포크비즈니스 | H14: 베리시톨 인플루언서 비용 | I14: 3300000 | J14: 계좌송금 | L14: 확정 | M14: 변경 | N14: 46286 | O14: 지출계획_2026-09-21.xlsx | P14: 정상반영
A15: 건강-20260918-005 | B15: 건강사업팀 | C15: 전은신 | E15: 46288 | F15: 46288 | G15: 써치엠 | H15: 메타 광고 대행 수수 | I15: 1487786 | J15: 계좌송금 | L15: 확정 | M15: 신규 | N15: 46283 | O15: 지출계획_2026-09-21.xlsx | P15: 정상반영
A16: 건강-20260918-006 | B16: 건강사업팀 | C16: 전은신 | E16: 46288 | F16: 46288 | G16: 네이버SA&GFA | H16: 네이버SA&GFA 광고 비용 충전 | I16: 8305000 | J16: 계좌송금 | L16: 확정 | M16: 신규 | N16: 46283 | O16: 지출계획_2026-09-21.xlsx | P16: 정상반영
A17: 건강-20260918-007 | B17: 건강사업팀 | C17: 전은신 | E17: 46288 | F17: 46288 | G17: ADN | H17: ADN 광고-추석 유입 | I17: 550000 | J17: 계좌송금 | L17: 확정 | M17: 신규 | N17: 46283 | O17: 지출계획_2026-09-21.xlsx | P17: 정상반영
... A26: 경영-20260918-014 | B26: 경영지원팀 | C26: 송채은 | E26: 46295 | F26: 46295 | G26: 대구상공회의소 | H26: 하반기연회비 | I26: 250000 | J26: 계좌송금 | L26: 확정 | M26: 신규 | N26: 46283 | O26: 지출계획_2026-09-21.xlsx | P26: 에이팜 별도관리

Sheet 에이팜 지출계획
A2: 에이팜 지출계획 (자동 반영)
A3: 지출계획 비고에 '에이팜'으로 표시한 건은 자금계획(4주·13주)에 반영하지 않고 여기서만 관리합니다. '반영' 표시 건은 자금계획에 포함된 에이팜 관련 참고 항목입니다.
A5: 일자 | B5: 요일 | C5: 출처 | D5: 자금계획 반영 | E5: 팀명 | F5: 거래처 | G5: 지출내용 | H5: 예상금액 | I5: 지급방법 | J5: 비고
A6: 46283 | B6: 금 | C6: 팀 지출계획 | D6: 미반영(별도 관리) | E6: 경영지원팀 | F6: 이앤씨이노비즈타워 | G6: 본사관리비 | H6: 1553720 | I6: 계좌송금 | J6: 에이팜
A7: 46288 | B7: 수 | C7: 팀 지출계획 | D7: 미반영(별도 관리) | E7: 경영지원팀 | F7: 비씨카드 | G7: 8월카드대금 | H7: 269810 | I7: 계좌송금 | J7: 에이팜
A8: 46295 | B8: 수 | C8: 팀 지출계획 | D8: 미반영(별도 관리) | E8: 경영지원팀 | F8: 서원회계법인 | G8: 기장료 | H8: 330000 | I8: 계좌송금 | J8: 에이팜
A9: 46295 | B9: 수 | C9: 팀 지출계획 | D9: 미반영(별도 관리) | E9: 경영지원팀 | F9: 가가사무기 | G9: 복합기 9월 임대비용 | H9: 280000 | I9: 계좌송금 | J9: 에이팜
A10: 46295 | B10: 수 | C10: 팀 지출계획 | D10: 미반영(별도 관리) | E10: 경영지원팀 | F10: 대구상공회의소 | G10: 하반기연회비 | H10: 250000 | I10: 계좌송금 | J10: 에이팜
G11: 합계(자금계획 미반영) | H11: 2683530

Sheet 계좌내역통합_RAW
A1: 거래일시 | B1: 거래일 | C1: 은행 | D1: 계좌 | E1: 출금액 | F1: 입금액 | G1: 거래후잔액 | H1: 적요 | I1: 기재내용·상대방 | J1: 취급점 | K1: 자동분류 | L1: 내부이체 | M1: 정기지출후보 | N1: 현금유출입 | O1: 원본파일 | P1: 반영상태
A2: 46106.435 | B2: 46106 | C2: 국민은행 | D2: 국민 169124 | E2: 0 | F2: 2497000 | G2: 3871400 | H2: 기일입금 | I2: (주)에이팜건강 | J2: 진천역 | K2: 계좌간이체 | L2: Y | M2: N | N2: 0 | O2: 농협계좌_6개월(20260913).xls | P2: 기존내역
A3: 46106.665 | B3: 46106 | C3: 국민은행 | D3: 국민 169124 | E3: 0 | F3: 110000000 | G3: 113871400 | H3: FBS입금 | I3: 한화생중도인출 | J3: ERP사 | K3: 보험 중도인출·보험금 입금 | L3: N | M3: N | N3: 110000000 | O3: 농협계좌_6개월(20260913).xls | P3: 기존내역
A4: 46106.833 | B4: 46106 | C4: 국민은행 | D4: 국민 169124 | E4: 2497000 | F4: 0 | G4: 111374400 | H4: CMS 공동 | I4: METLIFE03036 | J4: ERP사 | K4: 기타지출 | L4: N | M4: Y | N4: -2497000 | O4: 농협계좌_6개월(20260913).xls | P4: 기존내역
A5: 46106.839 | B5: 46106 | C5: 국민은행 | D5: 국민 169124 | E5: 110000000 | F5: 0 | G5: 1374400 | H5: FBS출금 | I5: 푸본현02-002 | J5: ERP사 | K5: 보험료 | L5: N | M5: N | N5: -110000000 | O5: 농협계좌_6개월(20260913).xls | P5: 기존내역
A6: 46107.488 | B6: 46107 | C6: 국민은행 | D6: 국민 169124 | E6: 1374400 | F6: 0 | G6: 0 | H6: 스마트출금 | I6: (주)에이팜건강 | J6: 진천역 | K6: 계좌간이체 | L6: Y | M6: N | N6: 0 | O6: 농협계좌_6개월(20260913).xls | P6: 기존내역
A7: 46115.726 | B7: 46115 | C7: 국민은행 | D7: 국민 169124 | E7: 0 | F7: 3003000 | G7: 3003000 | H7: 전자금융 | I7: 주식회사에이팜건강 | J7: 우리은행 | K7: 계좌간이체 | L7: Y | M7: N | N7: 0 | O7: 국민은행_계좌 조회 6개월(20260913).xls | P7: 기존내역
A8: 46118.429 | B8: 46118 | C8: 국민은행 | D8: 국민 169124 | E8: 0 | F8: 5240400 | G8: 48764600 | H8: 기일입금 | I8: (주)에이팜건강 | J8: 진천역 | K8: 계좌간이체 | L8: Y | M8: N | N8: 0 | O8: 국민은행_계좌 조회 6개월(20260913).xls | P8: 기존내역
A9: 46118.429 | B9: 46118 | C9: 국민은행 | D9: 국민 169124 | E9: 0 | F9: 500000 | G9: 43524200 | H9: 기일입금 | I9: (주)에이팜건강 | J9: 진천역 | K9: 계좌간이체 | L9: Y | M9: N | N9: 0 | O9: 국민은행_계좌 조회 6개월(20260913).xls | P9: 기존내역
A10: 46118.429 | B10: 46118 | C10: 국민은행 | D10: 국민 169124 | E10: 0 | F10: 30000000 | G10: 43024200 | H10: 기일입금 | I10: (주)에이팜건강 | J10: 진천역 | K10: 계좌간이체 | L10: Y | M10: N | N10: 0 | O10: 국민은행_계좌 조회 6개월(20260913).xls | P10: 기존내역
A11: 46118.429 | B11: 46118 | C11: 국민은행 | D11: 국민 169124 | E11: 0 | F11: 10021200 | G11: 13024200 | H11: 기일입금 | I11: (주)에이팜건강 | J11: 진천역 | K11: 계좌간이체 | L11: Y | M11: N | N11: 0 | O11: 우리은행 거래내역조회 20260913.xlsx | P11: 기존내역
A12: 46118.796 | B12: 46118 | C12: 국민은행 | D12: 국민 169124 | E12: 40521200 | F12: 0 | G12: 8243400 | H12: FBS출금 | I12: 한화생04-03 | J12: ERP사 | K12: 보험료 | L12: N | M12: Y | N12: -40521200 | O12: 우리은행 거래내역조회 20260913.xlsx | P12: 기존내역
A13: 46118.809 | B13: 46118 | C13: 국민은행 | D13: 국민 169124 | E13: 8243400 | F13: 0 | G13: 0 | H13: FBS출금 | I13: 삼성04002건 | J13: ERP사 | K13: 보험료 | L13: N | M13: Y | N13: -8243400 | O13: 우리은행 거래내역조회 20260913.xlsx | P13: 기존내역
... A146: 46286.219 | B146: 46286 | C146: 우리은행 | D146: 우리 220351 | E146: 0 | F146: 5694170 | G146: 17314264 | H146: 펌뱅킹 | I146: 스마트스토어정산 | J146: 두산타워기업영업지원팀 | K146: 온라인매출입금 | L146: N | M146: N | N146: 5694170 | O146: 우리은행 거래내역조회 20260913.xlsx | P146: 기존내역
O147: 우리은행 거래내역조회 20260913.xlsx | P147: 기존내역
O148: 우리은행 거래내역조회 20260913.xlsx | P148: 기존내역
O149: 우리은행 거래내역조회 20260913.xlsx | P149: 기존내역
O150: 우리은행 거래내역조회 20260913.xlsx | P150: 기존내역
O151: 우리은행 거래내역조회 20260913.xlsx | P151: 기존내역
O152: 국민은행_계좌 조회 6개월(20260913).xls | P152: 기존내역
O153: 국민은행_계좌 조회 6개월(20260913).xls | P153: 기존내역
O154: 국민은행_계좌 조회 6개월(20260913).xls | P154: 기존내역
O155: 국민은행_계좌 조회 6개월(20260913).xls | P155: 기존내역
O156: 국민은행_계좌 조회 6개월(20260913).xls | P156: 기존내역
O157: 국민은행_계좌 조회 6개월(20260913).xls | P157: 기존내역
O158: 농협계좌_6개월(20260913).xls | P158: 기존내역
... O2092: 국민은행_계좌 조회 6개월(20260913).xls | P2092: 기존내역
O2093: =IF($A2093="","","주간붙여넣기_농협") | P2093: =IF($A2093="","",IF(COUNTIFS($C$2:$C$2092,$C2093,$B$2:$B$2092,$B2093,$E$2:$E$2092,$E2093,$F$2:$F$2092,$F2093,$G$2:$G$2092,$G2093)>0,"중복제외","신규반영"))
O2094: =IF($A2094="","","주간붙여넣기_농협") | P2094: =IF($A2094="","",IF(COUNTIFS($C$2:$C$2093,$C2094,$B$2:$B$2093,$B2094,$E$2:$E$2093,$E2094,$F$2:$F$2093,$F2094,$G$2:$G$2093,$G2094)>0,"중복제외","신규반영"))
O2095: =IF($A2095="","","주간붙여넣기_농협") | P2095: =IF($A2095="","",IF(COUNTIFS($C$2:$C$2094,$C2095,$B$2:$B$2094,$B2095,$E$2:$E$2094,$E2095,$F$2:$F$2094,$F2095,$G$2:$G$2094,$G2095)>0,"중복제외","신규반영"))
O2096: =IF($A2096="","","주간붙여넣기_농협") | P2096: =IF($A2096="","",IF(COUNTIFS($C$2:$C$2095,$C2096,$B$2:$B$2095,$B2096,$E$2:$E$2095,$E2096,$F$2:$F$2095,$F2096,$G$2:$G$2095,$G2096)>0,"중복제외","신규반영"))
O2097: =IF($A2097="","","주간붙여넣기_농협") | P2097: =IF($A2097="","",IF(COUNTIFS($C$2:$C$2096,$C2097,$B$2:$B$2096,$B2097,$E$2:$E$2096,$E2097,$F$2:$F$2096,$F2097,$G$2:$G$2096,$G2097)>0,"중복제외","신규반영"))
O2098: =IF($A2098="","","주간붙여넣기_농협") | P2098: =IF($A2098="","",IF(COUNTIFS($C$2:$C$2097,$C2098,$B$2:$B$2097,$B2098,$E$2:$E$2097,$E2098,$F$2:$F$2097,$F2098,$G$2:$G$2097,$G2098)>0,"중복제외","신규반영"))
O2099: =IF($A2099="","","주간붙여넣기_농협") | P2099: =IF($A2099="","",IF(COUNTIFS($C$2:$C$2098,$C2099,$B$2:$B$2098,$B2099,$E$2:$E$2098,$E2099,$F$2:$F$2098,$F2099,$G$2:$G$2098,$G2099)>0,"중복제외","신규반영"))
O2100: =IF($A2100="","","주간붙여넣기_농협") | P2100: =IF($A2100="","",IF(COUNTIFS($C$2:$C$2099,$C2100,$B$2:$B$2099,$B2100,$E$2:$E$2099,$E2100,$F$2:$F$2099,$F2100,$G$2:$G$2099,$G2100)>0,"중복제외","신규반영"))
O2101: =IF($A2101="","","주간붙여넣기_농협") | P2101: =IF($A2101="","",IF(COUNTIFS($C$2:$C$2100,$C2101,$B$2:$B$2100,$B2101,$E$2:$E$2100,$E2101,$F$2:$F$2100,$F2101,$G$2:$G$2100,$G2101)>0,"중복제외","신규반영"))
O2102: =IF($A2102="","","주간붙여넣기_농협") | P2102: =IF($A2102="","",IF(COUNTIFS($C$2:$C$2101,$C2102,$B$2:$B$2101,$B2102,$E$2:$E$2101,$E2102,$F$2:$F$2101,$F2102,$G$2:$G$2101,$G2102)>0,"중복제외","신규반영"))
O2103: =IF($A2103="","","주간붙여넣기_농협") | P2103: =IF($A2103="","",IF(COUNTIFS($C$2:$C$2102,$C2103,$B$2:$B$2102,$B2103,$E$2:$E$2102,$E2103,$F$2:$F$2102,$F2103,$G$2:$G$2102,$G2103)>0,"중복제외","신규반영"))
O2104: =IF($A2104="","","주간붙여넣기_농협") | P2104: =IF($A2104="","",IF(COUNTIFS($C$2:$C$2103,$C2104,$B$2:$B$2103,$B2104,$E$2:$E$2103,$E2104,$F$2:$F$2103,$F2104,$G$2:$G$2103,$G2104)>0,"중복제외","신규반영"))
O2105: =IF($A2105="","","주간붙여넣기_농협") | P2105: =IF($A2105="","",IF(COUNTIFS($C$2:$C$2104,$C2105,$B$2:$B$2104,$B2105,$E$2:$E$2104,$E2105,$F$2:$F$2104,$F2105,$G$2:$G$2104,$G2105)>0,"중복제외","신규반영"))
...

Sheet 설정및분류
A2: 예측 설정 및 자동분류 기준
A5: 요일번호 | B5: 요일 | C5: 최근 12주 온라인입금 일평균 | E5: 분류 | F5: 대표 키워드 | H5: 반영률 선택값
A6: 1 | B6: 월 | C6: 10677756 | E6: 온라인매출입금 | F6: 스마트스토어, KG이니시스, Npay, NHN페이, 카드가맹점 | H6: 0.6
A7: 2 | B7: 화 | C7: 22255001 | E7: 계좌간이체 | F7: 에이팜건강 표시(광고·네이버 제외) | H7: 0.7
A8: 3 | B8: 수 | C8: 14296943 | E8: 4대보험 | F8: 우리은행의 사회보험·건강보험 | H8: 0.8
A9: 4 | B9: 목 | C9: 13264811 | E9: 원천세·국세 | F9: 우리은행의 국고·원천세 | H9: 0.9
A10: 5 | B10: 금 | C10: 10320905 | E10: 법인카드결제 | F10: 우리카드결제대금, KB카드출금 | H10: 1
A11: 6 | B11: 토 | C11: 0 | E11: 보험료(기타) | F11: 한화생명, 메트라이프, ABL생명, 미래에셋
A12: 7 | B12: 일 | C12: 0 | E12: 광고선전비 | F12: 네이버, 광고, 비즈월렛, 캐시워크
E13: 급여·인건비(대외비) | F13: 급여, 상여, 퇴직, 국민은행 월말 TOP출금
E14: 대출·이자 | F14: 대출, 이자
E15: 기타입출금 | F15: 위 기준에 해당하지 않는 거래
