Workbook

Sheet 요약
A2: (주)에이팜건강 자금계획 기초 현황
A3: 기준일 2026-09-14 | 농협·우리은행·국민은행 계좌 거래내역 통합 (자동 갱신)
A5: 항목 | B5: 금액 | D5: 계좌 | E5: 최종 거래일 | F5: 잔액
A6: 현재 계좌잔액 | B6: 134614868 | D6: 국민 154577 | E6: 46283 | F6: 20147954
A7: 6개월 외부입금 | B7: 2661925313 | D7: 국민 169124 | E7: 46280 | F7: 100687200
A8: 6개월 외부출금 | B8: 3069701148 | D8: 농협 569003 | E8: 46283 | F8: 1834429
A9: 온라인매출 입금 | B9: 1970464433 | D9: 우리 220351 | E9: 46283 | F9: 11945285
A10: 최근 12주 주평균 온라인입금 | B10: 73729639
A12: 계획 설정 | B12: 값 | D12: 사용 방법
A13: 입금 예측 반영률 | B13: 0.8 | D13: 1. 새 계좌파일을 올리면 RAW 통합표에 이어 붙입니다.
A14: 4주 예상 기말잔액 | B14: ='4주일별계획'!J33 -> -89860063 | D14: 2. 노란색 칸에 확정 입금·지출계획을 입력합니다.
A15: 4주 최저 예상잔액 | B15: =MIN('4주일별계획'!J6:J33) -> -89860063 | D15: ="3. 온라인 입금은 최근 12주 요일별 평균의 "&TEXT($B$13,"0%")&"로 예측합니다." -> 3. 온라인 입금은 최근 12주 요일별 평균의 80%로 예측합니다.
A16: 13주 예상 기말잔액 | B16: ='13주주별계획'!J18 -> -3.5171847e+08 | D16: 4. 계좌 간 이체는 내부이체로 표시해 입출금 합계에서 제외합니다.
D17: 5. 정기지출분석의 '확인필요' 항목은 성격을 확인 후 확정합니다.

Sheet 업데이트운영
A2: 계좌 거래내역 업데이트 운영 방법
A3: 6개월 자료는 최초 1회만 필요합니다. 이후에는 매주 은행 원본파일을 그대로 업로드하면 됩니다.
A5: 항목 | B5: 권장 운영 기준 | D5: 처리단계 | E5: 자동 처리 내용 | F5: 중복 판정 기준 | G5: 결과 | H5: 사용자 작업
A6: 업로드 주기 | B6: 주 1회. 월요일 오전에 전주 월요일~일요일 거래내역을 내려받습니다. | D6: 1. 파일 인식 | E6: 은행별 머리글과 데이터 시작행 판별 | F6: 은행·계좌 | G6: 은행 형식 통일 | H6: 파일 첨부
A7: 권장 조회기간 | B7: 누락 방지를 위해 최근 14일을 조회해도 됩니다. 중복 거래는 자동으로 제외합니다. | D7: 2. 거래 표준화 | E7: 거래일시·입금·출금·잔액·적요 변환 | F7: 거래일시·입출금액·잔액·적요 | G7: RAW 한 표로 통합 | H7: 없음
A8: 업로드 장소 | B8: 이 대화창에 농협·우리은행·국민은행 원본파일을 첨부합니다. | D8: 3. 중복 제거 | E8: 기존 거래와 신규 거래 비교 | F8: 계좌+일시+금액+잔액+적요 | G8: 겹친 조회기간 제거 | H8: 없음
A9: 권장 파일형식 | B9: 은행에서 내려받은 XLS, XLSX, CSV 원본을 권장합니다. | D9: 4. 자동 분류 | E9: 매출·내부이체·세금·보험·카드 등 분류 | F9: 적요 키워드 | G9: 분류 및 정기지출 표시 | H9: 확인필요만 검토
A10: 지양할 형식 | B10: PDF, 사진, 화면 캡처는 열 구조가 일정하지 않아 자동처리에 불리합니다. | D10: 5. 잔액 갱신 | E10: 계좌별 최종 거래 잔액 반영 | F10: 가장 최근 거래일시 | G10: 전체 가용잔액 갱신 | H10: 없음
A11: 파일명 | B11: 은행이 만들어 준 원래 파일명을 그대로 사용해도 됩니다. | D11: 6. 계획 갱신 | E11: 최근 12주 패턴 및 선택 반영률 적용 | F11: 드롭다운 반영률 | G11: 4주·13주 전망 변경 | H11: 예정 지출만 보완
A12: 업데이트 요청문 | B12: '이번 주 계좌내역 반영해서 자금계획 업데이트해줘'라고 입력합니다.
A13: 직접 입력 | B13: 거래내역은 복사·붙여넣지 않습니다. 향후 확정 입금·지출계획만 노란색 칸에 입력합니다.
A16: 은행 | B16: 현재 기준 원본파일 | C16: 조회 시작 | D16: 조회 종료 | E16: 반영 거래건수 | F16: 상태
A17: 농협 | B17: 농협계좌_6개월(20260913).xls | C17: 46094 | D17: 46278 | E17: 234 | F17: 반영완료
A18: 우리은행 | B18: 우리은행 거래내역조회 20260913.xlsx | C18: 46095 | D18: 46278 | E18: 862 | F18: 반영완료
A19: 국민은행 | B19: 국민은행_계좌 조회 6개월(20260913).xls | C19: 46095 | D19: 46278 | E19: 995 | F19: 반영완료

Sheet 4주일별계획
A2: 향후 4주 일별 자금계획
A3: ="온라인 예상입금은 최근 12주 요일별 평균 × "&TEXT(요약!$B$13,"0%")&"로 계산됩니다. 노란색 칸만 입력하세요." -> 온라인 예상입금은 최근 12주 요일별 평균 × 80%로 계산됩니다. 노란색 칸만 입력하세요.
A5: 일자 | B5: 요일 | C5: 온라인 예상입금 | D5: 확정·기타입금 | E5: 송금예정 | F5: 카드결제 | G5: 기타지출 | H5: 순현금흐름 | I5: 기초잔액 | J5: 기말잔액 | K5: 비고
A6: 46279 | B6: 월 | C6: 7726405 | D6: 41610 | G6: 2312400 | H6: =C6+D6-E6-F6-G6 -> 5455615 | I6: 106349419 | J6: =I6+H6 -> 111805034 | K6: 실적 | 지출: 국민(주)트레이드파 1,000,000, 국민(주)트레이드파 800,000, 농협사단법인한국경영 200,000 외 2건 | 기타입금: KB103013814 25,610, 조성윤 16,000
A7: 46280 | B7: 화 | C7: 20539071 | D7: 278510 | G7: 20370602 | H7: =C7+D7-E7-F7-G7 -> 446979 | I7: =J6 -> 111805034 | J7: =I7+H7 -> 112252013 | K7: 실적 | 지출: 신한고은미(이룸파트 11,953,700, ABL생명09010 5,001,750, (주)카카오 1,500,000 외 15건 | 기타입금: 에스케이엠앤서비스 78,710, KB103013814 68,600 외 3건
A8: 46281 | B8: 수 | C8: 7657774 | D8: 1580236 | G8: 40000 | H8: =C8+D8-E8-F8-G8 -> 9198010 | I8: =J7 -> 112252013 | J8: =I8+H8 -> 121450023 | K8: 실적 | 지출: (사)한국 40,000 | 기타입금: 726168386BC 1,333,398, 도정은 105,760 외 2건
A9: 46282 | B9: 목 | C9: 7449431 | D9: 80720 | G9: 1378509 | H9: =C9+D9-E9-F9-G9 -> 6151642 | I9: =J8 -> 121450023 | J9: =I9+H9 -> 127601665 | K9: 실적 | 지출: 농협(주)레인보우8 550,000, 국민비즈월렛_쁘띠앤 498,509, 국민네이버 ddi5 330,000 | 기타입금: 정유림 80,720
A10: 46283 | B10: 금 | C10: 7902370 | D10: 200833 | G10: 1090000 | H10: =C10+D10-E10-F10-G10 -> 7013203 | I10: =J9 -> 127601665 | J10: =I10+H10 -> 134614868 | K10: 실적 | 지출: 국민네이버 ddi5 990,000, 카카이찬민 100,000 | 기타입금: 김수희 141,000, GS리테일 30,400 외 1건
A11: 46284 | B11: 토 | C11: =INDEX(설정및분류!$C$6:$C$12,WEEKDAY(A11,2))*요약!$B$13 -> 0 | G11: 2290345 | H11: =C11+D11-E11-F11-G11 -> -2290345 | I11: =J10 -> 134614868 | J11: =I11+H11 -> 132324523 | K11: 자동추정: 국민비즈월렛_쁘띠앤
A12: 46285 | B12: 일 | C12: =INDEX(설정및분류!$C$6:$C$12,WEEKDAY(A12,2))*요약!$B$13 -> 0 | H12: =C12+D12-E12-F12-G12 -> 0 | I12: =J11 -> 132324523 | J12: =I12+H12 -> 132324523
A13: 46286 | B13: 월 | C13: =INDEX(설정및분류!$C$6:$C$12,WEEKDAY(A13,2))*요약!$B$13 -> 8369888 | E13: 8794000 | G13: 5120000 | H13: =C13+D13-E13-F13-G13 -> -5544112 | I13: =J12 -> 132324523 | J13: =I13+H13 -> 126780411 | K13: 트라이앵글하모니 1,996,000, 네이버SA&GFA 3,498,000, 인포크비즈니스 3,300,000 외 2건
A14: 46287 | B14: 화 | C14: =INDEX(설정및분류!$C$6:$C$12,WEEKDAY(A14,2))*요약!$B$13 -> 19255995 | E14: 1523110 | H14: =C14+D14-E14-F14-G14 -> 17732885 | I14: =J13 -> 126780411 | J14: =I14+H14 -> 1.445133e+08 | K14: 네이버 500,000, 기타 대외비 지출 1,023,110
A15: 46288 | B15: 수 | C15: =INDEX(설정및분류!$C$6:$C$12,WEEKDAY(A15,2))*요약!$B$13 -> 12121911 | E15: 10612596 | G15: 46055796 | H15: =C15+D15-E15-F15-G15 -> -44546481 | I15: =J14 -> 1.445133e+08 | J15: =I15+H15 -> 99966815 | K15: 써치엠 1,487,786, 네이버SA&GFA 8,305,000, ADN 550,000 외 2건; 자동추정: METLIFE, NH기업카드, 아이현종찬
A16: 46289 | B16: 목 | C16: =INDEX(설정및분류!$C$6:$C$12,WEEKDAY(A16,2))*요약!$B$13 -> 10263043 | G16: 2000000 | H16: =C16+D16-E16-F16-G16 -> 8263043.2 | I16: =J15 -> 99966815 | J16: =I16+H16 -> 1.0822986e+08 | K16: 자동추정: 세이브더칠드런
A17: 46290 | B17: 금 | C17: =INDEX(설정및분류!$C$6:$C$12,WEEKDAY(A17,2))*요약!$B$13 -> 8972873.6 | G17: 2606450 | H17: =C17+D17-E17-F17-G17 -> 6366423.6 | I17: =J16 -> 1.0822986e+08 | J17: =I17+H17 -> 1.1459628e+08 | K17: 세금·보험(대외비) 2,497,000, 기타 대외비 지출 109,450
A18: 46291 | B18: 토 | C18: =INDEX(설정및분류!$C$6:$C$12,WEEKDAY(A18,2))*요약!$B$13 -> 0 | H18: =C18+D18-E18-F18-G18 -> 0 | I18: =J17 -> 1.1459628e+08 | J18: =I18+H18 -> 1.1459628e+08
A19: 46292 | B19: 일 | C19: =INDEX(설정및분류!$C$6:$C$12,WEEKDAY(A19,2))*요약!$B$13 -> 0 | G19: 2099429 | H19: =C19+D19-E19-F19-G19 -> -2099429 | I19: =J18 -> 1.1459628e+08 | J19: =I19+H19 -> 1.1249685e+08 | K19: 자동추정: 농협한혜선, 하나남경 노무법인
A20: 46293 | B20: 월 | C20: =INDEX(설정및분류!$C$6:$C$12,WEEKDAY(A20,2))*요약!$B$13 -> 8369888 | G20: 45969026 | H20: =C20+D20-E20-F20-G20 -> -37599138 | I20: =J19 -> 1.1249685e+08 | J20: =I20+H20 -> 74897715 | K20: 자동추정: 기업콜마비앤에이치, 국민주식회사 에이팜
A21: 46294 | B21: 화 | C21: =INDEX(설정및분류!$C$6:$C$12,WEEKDAY(A21,2))*요약!$B$13 -> 19255995 | G21: 2979792 | H21: =C21+D21-E21-F21-G21 -> 16276203 | I21: =J20 -> 74897715 | J21: =I21+H21 -> 91173918 | K21: 자동추정: 아이서원회계법인 대, 국민주식회사 오애드, 하나흥덕IT밸리관리
A22: 46295 | B22: 수 | C22: =INDEX(설정및분류!$C$6:$C$12,WEEKDAY(A22,2))*요약!$B$13 -> 12121911 | D22: 10021867 | E22: 860000 | G22: 84202207 | H22: =C22+D22-E22-F22-G22 -> -62918429 | I22: =J21 -> 91173918 | J22: =I22+H22 -> 28255490 | K22: 기타 대외비 지출 860,000; 자동추정: TOP출금, 한진주식회사, 퇴직예약출금, 국민엠제이테크노파크; 관계사 외상대 입금 추정(주식회사에이팜, 말일)
A23: 46296 | B23: 목 | C23: =INDEX(설정및분류!$C$6:$C$12,WEEKDAY(A23,2))*요약!$B$13 -> 10263043 | G23: 2952747 | H23: =C23+D23-E23-F23-G23 -> 7310296.2 | I23: =J22 -> 28255490 | J23: =I23+H23 -> 35565786 | K23: 자동추정: KB
A24: 46297 | B24: 금 | C24: =INDEX(설정및분류!$C$6:$C$12,WEEKDAY(A24,2))*요약!$B$13 -> 8972873.6 | H24: =C24+D24-E24-F24-G24 -> 8972873.6 | I24: =J23 -> 35565786 | J24: =I24+H24 -> 44538659
A25: 46298 | B25: 토 | C25: =INDEX(설정및분류!$C$6:$C$12,WEEKDAY(A25,2))*요약!$B$13 -> 0 | G25: 100000 | H25: =C25+D25-E25-F25-G25 -> -100000 | I25: =J24 -> 44538659 | J25: =I25+H25 -> 44438659 | K25: 자동추정: 대한사회복지회
A26: 46299 | B26: 일 | C26: =INDEX(설정및분류!$C$6:$C$12,WEEKDAY(A26,2))*요약!$B$13 -> 0 | G26: 30000000 | H26: =C26+D26-E26-F26-G26 -> -30000000 | I26: =J25 -> 44438659 | J26: =I26+H26 -> 14438659 | K26: 자동추정: 한화스마트
A27: 46300 | B27: 월 | C27: =INDEX(설정및분류!$C$6:$C$12,WEEKDAY(A27,2))*요약!$B$13 -> 8369888 | H27: =C27+D27-E27-F27-G27 -> 8369888 | I27: =J26 -> 14438659 | J27: =I27+H27 -> 22808547
A28: 46301 | B28: 화 | C28: =INDEX(설정및분류!$C$6:$C$12,WEEKDAY(A28,2))*요약!$B$13 -> 19255995 | G28: 4494000 | H28: =C28+D28-E28-F28-G28 -> 14761995 | I28: =J27 -> 22808547 | J28: =I28+H28 -> 37570543 | K28: 자동추정: 미래
A29: 46302 | B29: 수 | C29: =INDEX(설정및분류!$C$6:$C$12,WEEKDAY(A29,2))*요약!$B$13 -> 12121911 | G29: 8898225 | H29: =C29+D29-E29-F29-G29 -> 3223686.2 | I29: =J28 -> 37570543 | J29: =I29+H29 -> 40794229 | K29: 자동추정: 삼성건
A30: 46303 | B30: 목 | C30: =INDEX(설정및분류!$C$6:$C$12,WEEKDAY(A30,2))*요약!$B$13 -> 10263043 | G30: 42006200 | H30: =C30+D30-E30-F30-G30 -> -31743157 | I30: =J29 -> 40794229 | J30: =I30+H30 -> 9051072 | K30: 자동추정: 한화생
A31: 46304 | B31: 금 | C31: =INDEX(설정및분류!$C$6:$C$12,WEEKDAY(A31,2))*요약!$B$13 -> 8972873.6 | G31: 14690500 | H31: =C31+D31-E31-F31-G31 -> -5717626.4 | I31: =J30 -> 9051072 | J31: =I31+H31 -> 3333445.6 | K31: 자동추정: 국민주식회사 아이디, 국민SA, 국민GFA, 기업주식회사 채널코
A32: 46305 | B32: 토 | C32: =INDEX(설정및분류!$C$6:$C$12,WEEKDAY(A32,2))*요약!$B$13 -> 0 | G32: 52883549 | H32: =C32+D32-E32-F32-G32 -> -52883549 | I32: =J31 -> 3333445.6 | J32: =I32+H32 -> -49550103 | K32: 자동추정: 국고_주식회사, 신한고은미이룸파트, 사회보험, 신한대구달서구주식 외 1건
A33: 46306 | B33: 일 | C33: =INDEX(설정및분류!$C$6:$C$12,WEEKDAY(A33,2))*요약!$B$13 -> 0 | G33: 40309960 | H33: =C33+D33-E33-F33-G33 -> -40309960 | I33: =J32 -> -49550103 | J33: =I33+H33 -> -89860063 | K33: 자동추정: 허용, 농협주레인보우, 아이로펌더봄엄요한

Sheet 13주주별계획
A2: 향후 13주 주별 자금계획
A3: ="온라인 예상입금 반영률 "&TEXT(요약!$B$13,"0%")&" 적용. 1~4주는 일별 계획 합계, 5~13주는 자동 예상입금과 입력한 주간 계획을 반영합니다." -> 온라인 예상입금 반영률 80% 적용. 1~4주는 일별 계획 합계, 5~13주는 자동 예상입금과 입력한 주간 계획을 반영합니다.
A5: 주차 | B5: 기간 | C5: 온라인 예상입금 | D5: 확정·기타입금 | E5: 송금예정 | F5: 카드결제 | G5: 기타지출 | H5: 추가 주간조정 | I5: 순현금흐름 | J5: 기말잔액 | K5: 상태
A6: 1주차 | B6: 2026-09-14 ~ 2026-09-20 | C6: =SUMIFS('4주일별계획'!$C$6:$C$33,'4주일별계획'!$A$6:$A$33,">="&DATE(2026,9,14),'4주일별계획'!$A$6:$A$33,"<="&DATE(2026,9,20)) -> 51275051 | D6: =SUMIFS('4주일별계획'!$D$6:$D$33,'4주일별계획'!$A$6:$A$33,">="&DATE(2026,9,14),'4주일별계획'!$A$6:$A$33,"<="&DATE(2026,9,20)) -> 2181909 | E6: =SUMIFS('4주일별계획'!$E$6:$E$33,'4주일별계획'!$A$6:$A$33,">="&DATE(2026,9,14),'4주일별계획'!$A$6:$A$33,"<="&DATE(2026,9,20)) -> 0 | F6: =SUMIFS('4주일별계획'!$F$6:$F$33,'4주일별계획'!$A$6:$A$33,">="&DATE(2026,9,14),'4주일별계획'!$A$6:$A$33,"<="&DATE(2026,9,20)) -> 0 | G6: =SUMIFS('4주일별계획'!$G$6:$G$33,'4주일별계획'!$A$6:$A$33,">="&DATE(2026,9,14),'4주일별계획'!$A$6:$A$33,"<="&DATE(2026,9,20)) -> 27481856 | I6: =C6+D6-E6-F6-G6+H6 -> 25975104 | J6: =요약!$B$6+I6 -> 160589972 | K6: =IF(J6<0,"자금부족",IF(J6<요약!$B$6*0.2,"주의","정상")) -> 정상
A7: 2주차 | B7: 2026-09-21 ~ 2026-09-27 | C7: =SUMIFS('4주일별계획'!$C$6:$C$33,'4주일별계획'!$A$6:$A$33,">="&DATE(2026,9,21),'4주일별계획'!$A$6:$A$33,"<="&DATE(2026,9,27)) -> 58983711 | D7: =SUMIFS('4주일별계획'!$D$6:$D$33,'4주일별계획'!$A$6:$A$33,">="&DATE(2026,9,21),'4주일별계획'!$A$6:$A$33,"<="&DATE(2026,9,27)) -> 0 | E7: =SUMIFS('4주일별계획'!$E$6:$E$33,'4주일별계획'!$A$6:$A$33,">="&DATE(2026,9,21),'4주일별계획'!$A$6:$A$33,"<="&DATE(2026,9,27)) -> 20929706 | F7: =SUMIFS('4주일별계획'!$F$6:$F$33,'4주일별계획'!$A$6:$A$33,">="&DATE(2026,9,21),'4주일별계획'!$A$6:$A$33,"<="&DATE(2026,9,27)) -> 0 | G7: =SUMIFS('4주일별계획'!$G$6:$G$33,'4주일별계획'!$A$6:$A$33,">="&DATE(2026,9,21),'4주일별계획'!$A$6:$A$33,"<="&DATE(2026,9,27)) -> 57881675 | I7: =C7+D7-E7-F7-G7+H7 -> -19827670 | J7: =J6+I7 -> 1.407623e+08 | K7: =IF(J7<0,"자금부족",IF(J7<요약!$B$6*0.2,"주의","정상")) -> 정상
A8: 3주차 | B8: 2026-09-28 ~ 2026-10-04 | C8: =SUMIFS('4주일별계획'!$C$6:$C$33,'4주일별계획'!$A$6:$A$33,">="&DATE(2026,9,28),'4주일별계획'!$A$6:$A$33,"<="&DATE(2026,10,4)) -> 58983711 | D8: =SUMIFS('4주일별계획'!$D$6:$D$33,'4주일별계획'!$A$6:$A$33,">="&DATE(2026,9,28),'4주일별계획'!$A$6:$A$33,"<="&DATE(2026,10,4)) -> 10021867 | E8: =SUMIFS('4주일별계획'!$E$6:$E$33,'4주일별계획'!$A$6:$A$33,">="&DATE(2026,9,28),'4주일별계획'!$A$6:$A$33,"<="&DATE(2026,10,4)) -> 860000 | F8: =SUMIFS('4주일별계획'!$F$6:$F$33,'4주일별계획'!$A$6:$A$33,">="&DATE(2026,9,28),'4주일별계획'!$A$6:$A$33,"<="&DATE(2026,10,4)) -> 0 | G8: =SUMIFS('4주일별계획'!$G$6:$G$33,'4주일별계획'!$A$6:$A$33,">="&DATE(2026,9,28),'4주일별계획'!$A$6:$A$33,"<="&DATE(2026,10,4)) -> 166203772 | I8: =C8+D8-E8-F8-G8+H8 -> -98058194 | J8: =J7+I8 -> 42704108 | K8: =IF(J8<0,"자금부족",IF(J8<요약!$B$6*0.2,"주의","정상")) -> 정상
A9: 4주차 | B9: 2026-10-05 ~ 2026-10-11 | C9: =SUMIFS('4주일별계획'!$C$6:$C$33,'4주일별계획'!$A$6:$A$33,">="&DATE(2026,10,5),'4주일별계획'!$A$6:$A$33,"<="&DATE(2026,10,11)) -> 58983711 | D9: =SUMIFS('4주일별계획'!$D$6:$D$33,'4주일별계획'!$A$6:$A$33,">="&DATE(2026,10,5),'4주일별계획'!$A$6:$A$33,"<="&DATE(2026,10,11)) -> 0 | E9: =SUMIFS('4주일별계획'!$E$6:$E$33,'4주일별계획'!$A$6:$A$33,">="&DATE(2026,10,5),'4주일별계획'!$A$6:$A$33,"<="&DATE(2026,10,11)) -> 0 | F9: =SUMIFS('4주일별계획'!$F$6:$F$33,'4주일별계획'!$A$6:$A$33,">="&DATE(2026,10,5),'4주일별계획'!$A$6:$A$33,"<="&DATE(2026,10,11)) -> 0 | G9: =SUMIFS('4주일별계획'!$G$6:$G$33,'4주일별계획'!$A$6:$A$33,">="&DATE(2026,10,5),'4주일별계획'!$A$6:$A$33,"<="&DATE(2026,10,11)) -> 163282434 | I9: =C9+D9-E9-F9-G9+H9 -> -1.0429872e+08 | J9: =J8+I9 -> -61594614 | K9: =IF(J9<0,"자금부족",IF(J9<요약!$B$6*0.2,"주의","정상")) -> 자금부족
A10: 5주차 | B10: 2026-10-12 ~ 2026-10-18 | C10: =SUM(설정및분류!$C$6:$C$12)*요약!$B$13 -> 58983711 | F10: 139091 | G10: 41543949 | I10: =C10+D10-E10-F10-G10+H10 -> 17300671 | J10: =J9+I10 -> -44293943 | K10: =IF(J10<0,"자금부족",IF(J10<요약!$B$6*0.2,"주의","정상")) -> 자금부족
A11: 6주차 | B11: 2026-10-19 ~ 2026-10-25 | C11: =SUM(설정및분류!$C$6:$C$12)*요약!$B$13 -> 58983711 | F11: 26105540 | G11: 20273781 | I11: =C11+D11-E11-F11-G11+H11 -> 12604390 | J11: =J10+I11 -> -31689553 | K11: =IF(J11<0,"자금부족",IF(J11<요약!$B$6*0.2,"주의","정상")) -> 자금부족
A12: 7주차 | B12: 2026-10-26 ~ 2026-11-01 | C12: =SUM(설정및분류!$C$6:$C$12)*요약!$B$13 -> 58983711 | D12: 10021867 | G12: 138203201 | I12: =C12+D12-E12-F12-G12+H12 -> -69197623 | J12: =J11+I12 -> -1.0088718e+08 | K12: =IF(J12<0,"자금부족",IF(J12<요약!$B$6*0.2,"주의","정상")) -> 자금부족
A13: 8주차 | B13: 2026-11-02 ~ 2026-11-08 | C13: =SUM(설정및분류!$C$6:$C$12)*요약!$B$13 -> 58983711 | G13: 85498425 | I13: =C13+D13-E13-F13-G13+H13 -> -26514714 | J13: =J12+I13 -> -1.2740189e+08 | K13: =IF(J13<0,"자금부족",IF(J13<요약!$B$6*0.2,"주의","정상")) -> 자금부족
A14: 9주차 | B14: 2026-11-09 ~ 2026-11-15 | C14: =SUM(설정및분류!$C$6:$C$12)*요약!$B$13 -> 58983711 | F14: 139091 | G14: 144070815 | I14: =C14+D14-E14-F14-G14+H14 -> -85226195 | J14: =J13+I14 -> -2.1262808e+08 | K14: =IF(J14<0,"자금부족",IF(J14<요약!$B$6*0.2,"주의","정상")) -> 자금부족
A15: 10주차 | B15: 2026-11-16 ~ 2026-11-22 | C15: =SUM(설정및분류!$C$6:$C$12)*요약!$B$13 -> 58983711 | G15: 9635728 | I15: =C15+D15-E15-F15-G15+H15 -> 49347983 | J15: =J14+I15 -> -1.632801e+08 | K15: =IF(J15<0,"자금부족",IF(J15<요약!$B$6*0.2,"주의","정상")) -> 자금부족
A16: 11주차 | B16: 2026-11-23 ~ 2026-11-29 | C16: =SUM(설정및분류!$C$6:$C$12)*요약!$B$13 -> 58983711 | F16: 26105540 | G16: 67043444 | I16: =C16+D16-E16-F16-G16+H16 -> -34165273 | J16: =J15+I16 -> -197445374 | K16: =IF(J16<0,"자금부족",IF(J16<요약!$B$6*0.2,"주의","정상")) -> 자금부족
A17: 12주차 | B17: 2026-11-30 ~ 2026-12-06 | C17: =SUM(설정및분류!$C$6:$C$12)*요약!$B$13 -> 58983711 | D17: 10021867 | G17: 121748953 | I17: =C17+D17-E17-F17-G17+H17 -> -52743375 | J17: =J16+I17 -> -2.5018875e+08 | K17: =IF(J17<0,"자금부족",IF(J17<요약!$B$6*0.2,"주의","정상")) -> 자금부족
A18: 13주차 | B18: 2026-12-07 ~ 2026-12-13 | C18: =SUM(설정및분류!$C$6:$C$12)*요약!$B$13 -> 58983711 | G18: 160513434 | I18: =C18+D18-E18-F18-G18+H18 -> -1.0152972e+08 | J18: =J17+I18 -> -3.5171847e+08 | K18: =IF(J18<0,"자금부족",IF(J18<요약!$B$6*0.2,"주의","정상")) -> 자금부족

Sheet 지출계획_취합
A2: 팀 지출계획 취합 (자동 반영)
A3: 매 실행마다 팀 제출 파일에서 자동 갱신됩니다. 대외비는 분류·총액만 표시됩니다.
A5: 요청ID | B5: 팀명 | C5: 신청자 | D5: 품의승인 | E5: 지급예정일 | F5: 자금계획 반영일 | G5: 거래처 | H5: 지출내용 | I5: 예상금액 | J5: 지급방법 | K5: 카드구분 | L5: 확정여부 | M5: 진행상태 | N5: 최종수정일 | O5: 원본파일 | P5: 반영상태 | Q5: 확인사항
A6: 대외비-집계 | B6: 경영지원팀 | E6: 46283 | F6: 46283 | G6: 대외비 | H6: 기타 대외비 지출 | I6: 1553720 | J6: 계좌송금 | L6: 확정 | O6: 지출계획_2026-09-18.xlsx | P6: 정상반영
A7: 건강-20260918-001 | B7: 건강사업팀 | C7: 양혜원 | E7: 46286 | F7: 46286 | G7: 트라이앵글하모니 | H7: 카카오톡선물하기 베리시톨 리뷰작업 | I7: 1996000 | J7: 계좌송금 | L7: 확정 | M7: 신규 | N7: 46283 | O7: 지출계획_2026-09-18.xlsx | P7: 정상반영
A8: 건강-20260918-003 | B8: 건강사업팀 | C8: 전은신 | E8: 46286 | F8: 46286 | G8: 네이버SA&GFA | H8: 네이버 SA&GFA 광고비 충전 | I8: 3498000 | J8: 계좌송금 | L8: 확정 | M8: 변경 | N8: 46283 | O8: 지출계획_2026-09-18.xlsx | P8: 정상반영
A9: 건강-20260918-004 | B9: 건강사업팀 | C9: 전은신 | E9: 46286 | F9: 46286 | G9: 인포크비즈니스 | H9: 베리시톨 인플루언서 비용 | I9: 3300000 | J9: 계좌송금 | L9: 확정 | M9: 신규 | N9: 46283 | O9: 지출계획_2026-09-18.xlsx | P9: 정상반영
A10: 대외비-집계 | B10: 경영지원팀 | E10: 46286 | F10: 46286 | G10: 대외비 | H10: 세금·보험(대외비) | I10: 4900000 | J10: 자동이체 | L10: 확정 | O10: 지출계획_2026-09-18.xlsx | P10: 정상반영
A11: 대외비-집계 | B11: 경영지원팀 | E11: 46286 | F11: 46286 | G11: 대외비 | H11: 기타 대외비 지출 | I11: 220000 | J11: 자동이체 | L11: 확정 | O11: 지출계획_2026-09-18.xlsx | P11: 정상반영
A12: 건강-20260918-002 | B12: 건강사업팀 | C12: 양혜원 | E12: 46287 | F12: 46287 | G12: 네이버 | H12: 네이버 톡톡 발송 | I12: 500000 | J12: 계좌송금 | L12: 확정 | M12: 신규 | N12: 46283 | O12: 지출계획_2026-09-18.xlsx | P12: 정상반영
A13: 대외비-집계 | B13: 경영지원팀 | E13: 46287 | F13: 46287 | G13: 대외비 | H13: 기타 대외비 지출 | I13: 1023110 | J13: 계좌송금 | L13: 확정 | O13: 지출계획_2026-09-18.xlsx | P13: 정상반영
A14: 건강-20260918-005 | B14: 건강사업팀 | C14: 전은신 | E14: 46288 | F14: 46288 | G14: 써치엠 | H14: 메타 광고 대행 수수 | I14: 1487786 | J14: 계좌송금 | L14: 확정 | M14: 신규 | N14: 46283 | O14: 지출계획_2026-09-18.xlsx | P14: 정상반영
A15: 건강-20260918-006 | B15: 건강사업팀 | C15: 전은신 | E15: 46288 | F15: 46288 | G15: 네이버SA&GFA | H15: 네이버SA&GFA 광고 비용 충전 | I15: 8305000 | J15: 계좌송금 | L15: 확정 | M15: 신규 | N15: 46283 | O15: 지출계획_2026-09-18.xlsx | P15: 정상반영
A16: 건강-20260918-007 | B16: 건강사업팀 | C16: 전은신 | E16: 46288 | F16: 46288 | G16: ADN | H16: ADN 광고-추석 유입 | I16: 550000 | J16: 계좌송금 | L16: 확정 | M16: 신규 | N16: 46283 | O16: 지출계획_2026-09-18.xlsx | P16: 정상반영
A17: 대외비-집계 | B17: 경영지원팀 | E17: 46288 | F17: 46288 | G17: 대외비 | H17: 기타 대외비 지출 | I17: 32174232 | J17: 자동이체 | L17: 확정 | O17: 지출계획_2026-09-18.xlsx | P17: 정상반영
A18: 대외비-집계 | B18: 경영지원팀 | E18: 46288 | F18: 46288 | G18: 대외비 | H18: 기타 대외비 지출 | I18: 269810 | J18: 계좌송금 | L18: 확정 | O18: 지출계획_2026-09-18.xlsx | P18: 정상반영
A19: 대외비-집계 | B19: 경영지원팀 | E19: 46290 | F19: 46290 | G19: 대외비 | H19: 세금·보험(대외비) | I19: 2497000 | J19: 자동이체 | L19: 확정 | O19: 지출계획_2026-09-18.xlsx | P19: 정상반영
A20: 대외비-집계 | B20: 경영지원팀 | E20: 46290 | F20: 46290 | G20: 대외비 | H20: 기타 대외비 지출 | I20: 109450 | J20: 자동이체 | L20: 확정 | O20: 지출계획_2026-09-18.xlsx | P20: 정상반영
A21: 대외비-집계 | B21: 경영지원팀 | E21: 46295 | F21: 46295 | G21: 대외비 | H21: 기타 대외비 지출 | I21: 860000 | J21: 계좌송금 | L21: 확정 | O21: 지출계획_2026-09-18.xlsx | P21: 정상반영

Sheet 계좌내역통합_RAW
A1: 거래일시 | B1: 거래일 | C1: 은행 | D1: 계좌 | E1: 출금액 | F1: 입금액 | G1: 거래후잔액 | H1: 적요 | I1: 기재내용·상대방 | J1: 취급점 | K1: 자동분류 | L1: 내부이체 | M1: 정기지출후보 | N1: 현금유출입 | O1: 원본파일 | P1: 반영상태
A2: 46106.435 | B2: 46106 | C2: 국민은행 | D2: 국민 169124 | E2: 0 | F2: 2497000 | G2: 3871400 | H2: 기일입금 | I2: (주)에이팜건강 | J2: 진천역 | K2: 계좌간이체 | L2: Y | M2: N | N2: 0 | O2: 농협계좌_6개월(20260913).xls | P2: 기존내역
A3: 46106.665 | B3: 46106 | C3: 국민은행 | D3: 국민 169124 | E3: 0 | F3: 110000000 | G3: 113871400 | H3: FBS입금 | I3: 한화생중도인출 | J3: ERP사 | K3: 보험 중도인출·보험금 입금 | L3: N | M3: N | N3: 110000000 | O3: 농협계좌_6개월(20260913).xls | P3: 기존내역
A4: 46106.833 | B4: 46106 | C4: 국민은행 | D4: 국민 169124 | E4: 2497000 | F4: 0 | G4: 111374400 | H4: CMS 공동 | I4: METLIFE03036 | J4: ERP사 | K4: 기타지출 | L4: N | M4: Y | N4: -2497000 | O4: 농협계좌_6개월(20260913).xls | P4: 기존내역
A5: 46106.839 | B5: 46106 | C5: 국민은행 | D5: 국민 169124 | E5: 110000000 | F5: 0 | G5: 1374400 | H5: FBS출금 | I5: 푸본현02-002 | J5: ERP사 | K5: 보험료 | L5: N | M5: N | N5: -110000000 | O5: 농협계좌_6개월(20260913).xls | P5: 기존내역
A6: 46107.488 | B6: 46107 | C6: 국민은행 | D6: 국민 169124 | E6: 1374400 | F6: 0 | G6: 0 | H6: 스마트출금 | I6: (주)에이팜건강 | J6: 진천역 | K6: 계좌간이체 | L6: Y | M6: N | N6: 0 | O6: 농협계좌_6개월(20260913).xls | P6: 기존내역
A7: 46115.726 | B7: 46115 | C7: 국민은행 | D7: 국민 169124 | E7: 0 | F7: 3003000 | G7: 3003000 | H7: 전자금융 | I7: 주식회사에이팜건강 | J7: 우리은행 | K7: 계좌간이체 | L7: Y | M7: N | N7: 0 | O7: 국민은행_계좌 조회 6개월(20260913).xls | P7: 기존내역
A8: 46118.429 | B8: 46118 | C8: 국민은행 | D8: 국민 169124 | E8: 0 | F8: 5240400 | G8: 48764600 | H8: 기일입금 | I8: (주)에이팜건강 | J8: 진천역 | K8: 계좌간이체 | L8: Y | M8: N | N8: 0 | O8: 국민은행_계좌 조회 6개월(20260913).xls | P8: 기존내역
A9: 46118.429 | B9: 46118 | C9: 국민은행 | D9: 국민 169124 | E9: 0 | F9: 500000 | G9: 43524200 | H9: 기일입금 | I9: (주)에이팜건강 | J9: 진천역 | K9: 계좌간이체 | L9: Y | M9: N | N9: 0 | O9: 국민은행_계좌 조회 6개월(20260913).xls | P9: 기존내역
A10: 46118.429 | B10: 46118 | C10: 국민은행 | D10: 국민 169124 | E10: 0 | F10: 30000000 | G10: 43024200 | H10: 기일입금 | I10: (주)에이팜건강 | J10: 진천역 | K10: 계좌간이체 | L10: Y | M10: N | N10: 0 | O10: 국민은행_계좌 조회 6개월(20260913).xls | P10: 기존내역
A11: 46118.429 | B11: 46118 | C11: 국민은행 | D11: 국민 169124 | E11: 0 | F11: 10021200 | G11: 13024200 | H11: 기일입금 | I11: (주)에이팜건강 | J11: 진천역 | K11: 계좌간이체 | L11: Y | M11: N | N11: 0 | O11: 우리은행 거래내역조회 20260913.xlsx | P11: 기존내역
A12: 46118.796 | B12: 46118 | C12: 국민은행 | D12: 국민 169124 | E12: 40521200 | F12: 0 | G12: 8243400 | H12: FBS출금 | I12: 한화생04-03 | J12: ERP사 | K12: 보험료 | L12: N | M12: Y | N12: -40521200 | O12: 우리은행 거래내역조회 20260913.xlsx | P12: 기존내역
A13: 46118.809 | B13: 46118 | C13: 국민은행 | D13: 국민 169124 | E13: 8243400 | F13: 0 | G13: 0 | H13: FBS출금 | I13: 삼성04002건 | J13: ERP사 | K13: 보험료 | L13: N | M13: Y | N13: -8243400 | O13: 우리은행 거래내역조회 20260913.xlsx | P13: 기존내역
... A152: 46283.701 | B152: 46283 | C152: 우리은행 | D152: 우리 220351 | E152: 990000 | F152: 0 | G152: 11945285 | H152: 인터넷 | I152: 국민네이버 ddi5 | J152: 성서공단금융센터 | K152: 기타지출 | L152: N | M152: N | N152: -990000 | O152: 국민은행_계좌 조회 6개월(20260913).xls | P152: 기존내역
O153: 국민은행_계좌 조회 6개월(20260913).xls | P153: 기존내역
O154: 국민은행_계좌 조회 6개월(20260913).xls | P154: 기존내역
O155: 국민은행_계좌 조회 6개월(20260913).xls | P155: 기존내역
O156: 국민은행_계좌 조회 6개월(20260913).xls | P156: 기존내역
O157: 국민은행_계좌 조회 6개월(20260913).xls | P157: 기존내역
O158: 농협계좌_6개월(20260913).xls | P158: 기존내역
O159: 국민은행_계좌 조회 6개월(20260913).xls | P159: 기존내역
O160: 국민은행_계좌 조회 6개월(20260913).xls | P160: 기존내역
O161: 우리은행 거래내역조회 20260913.xlsx | P161: 기존내역
O162: 국민은행_계좌 조회 6개월(20260913).xls | P162: 기존내역
O163: 국민은행_계좌 조회 6개월(20260913).xls | P163: 기존내역
O164: 국민은행_계좌 조회 6개월(20260913).xls | P164: 기존내역
... O2092: 국민은행_계좌 조회 6개월(20260913).xls | P2092: 기존내역
O2093: =IF($A2093="","","주간붙여넣기_농협") | P2093: =IF($A2093="","",IF(COUNTIFS($C$2:$C$2092,$C2093,$B$2:$B$2092,$B2093,$E$2:$E$2092,$E2093,$F$2:$F$2092,$F2093,$G$2:$G$2092,$G2093)>0,"중복제외","신규반영"))
O2094: =IF($A2094="","","주간붙여넣기_농협") | P2094: =IF($A2094="","",IF(COUNTIFS($C$2:$C$2093,$C2094,$B$2:$B$2093,$B2094,$E$2:$E$2093,$E2094,$F$2:$F$2093,$F2094,$G$2:$G$2093,$G2094)>0,"중복제외","신규반영"))
O2095: =IF($A2095="","","주간붙여넣기_농협") | P2095: =IF($A2095="","",IF(COUNTIFS($C$2:$C$2094,$C2095,$B$2:$B$2094,$B2095,$E$2:$E$2094,$E2095,$F$2:$F$2094,$F2095,$G$2:$G$2094,$G2095)>0,"중복제외","신규반영"))
O2096: =IF($A2096="","","주간붙여넣기_농협") | P2096: =IF($A2096="","",IF(COUNTIFS($C$2:$C$2095,$C2096,$B$2:$B$2095,$B2096,$E$2:$E$2095,$E2096,$F$2:$F$2095,$F2096,$G$2:$G$2095,$G2096)>0,"중복제외","신규반영"))
O2097: =IF($A2097="","","주간붙여넣기_농협") | P2097: =IF($A2097="","",IF(COUNTIFS($C$2:$C$2096,$C2097,$B$2:$B$2096,$B2097,$E$2:$E$2096,$E2097,$F$2:$F$2096,$F2097,$G$2:$G$2096,$G2097)>0,"중복제외","신규반영"))
O2098: =IF($A2098="","","주간붙여넣기_농협") | P2098: =IF($A2098="","",IF(COUNTIFS($C$2:$C$2097,$C2098,$B$2:$B$2097,$B2098,$E$2:$E$2097,$E2098,$F$2:$F$2097,$F2098,$G$2:$G$2097,$G2098)>0,"중복제외","신규반영"))
O2099: =IF($A2099="","","주간붙여넣기_농협") | P2099: =IF($A2099="","",IF(COUNTIFS($C$2:$C$2098,$C2099,$B$2:$B$2098,$B2099,$E$2:$E$2098,$E2099,$F$2:$F$2098,$F2099,$G$2:$G$2098,$G2099)>0,"중복제외","신규반영"))
O2100: =IF($A2100="","","주간붙여넣기_농협") | P2100: =IF($A2100="","",IF(COUNTIFS($C$2:$C$2099,$C2100,$B$2:$B$2099,$B2100,$E$2:$E$2099,$E2100,$F$2:$F$2099,$F2100,$G$2:$G$2099,$G2100)>0,"중복제외","신규반영"))
O2101: =IF($A2101="","","주간붙여넣기_농협") | P2101: =IF($A2101="","",IF(COUNTIFS($C$2:$C$2100,$C2101,$B$2:$B$2100,$B2101,$E$2:$E$2100,$E2101,$F$2:$F$2100,$F2101,$G$2:$G$2100,$G2101)>0,"중복제외","신규반영"))
O2102: =IF($A2102="","","주간붙여넣기_농협") | P2102: =IF($A2102="","",IF(COUNTIFS($C$2:$C$2101,$C2102,$B$2:$B$2101,$B2102,$E$2:$E$2101,$E2102,$F$2:$F$2101,$F2102,$G$2:$G$2101,$G2102)>0,"중복제외","신규반영"))
O2103: =IF($A2103="","","주간붙여넣기_농협") | P2103: =IF($A2103="","",IF(COUNTIFS($C$2:$C$2102,$C2103,$B$2:$B$2102,$B2103,$E$2:$E$2102,$E2103,$F$2:$F$2102,$F2103,$G$2:$G$2102,$G2103)>0,"중복제외","신규반영"))
O2104: =IF($A2104="","","주간붙여넣기_농협") | P2104: =IF($A2104="","",IF(COUNTIFS($C$2:$C$2103,$C2104,$B$2:$B$2103,$B2104,$E$2:$E$2103,$E2104,$F$2:$F$2103,$F2104,$G$2:$G$2103,$G2104)>0,"중복제외","신규반영"))
O2105: =IF($A2105="","","주간붙여넣기_농협") | P2105: =IF($A2105="","",IF(COUNTIFS($C$2:$C$2104,$C2105,$B$2:$B$2104,$B2105,$E$2:$E$2104,$E2105,$F$2:$F$2104,$F2105,$G$2:$G$2104,$G2105)>0,"중복제외","신규반영"))
...

Sheet 설정및분류
A2: 예측 설정 및 자동분류 기준
A5: 요일번호 | B5: 요일 | C5: 최근 12주 온라인입금 일평균 | E5: 분류 | F5: 대표 키워드 | H5: 반영률 선택값
A6: 1 | B6: 월 | C6: 10462360 | E6: 온라인매출입금 | F6: 스마트스토어, KG이니시스, Npay, NHN페이, 카드가맹점 | H6: 0.6
A7: 2 | B7: 화 | C7: 24069994 | E7: 계좌간이체 | F7: 에이팜건강 표시(광고·네이버 제외) | H7: 0.7
A8: 3 | B8: 수 | C8: 15152389 | E8: 4대보험 | F8: 우리은행의 사회보험·건강보험 | H8: 0.8
A9: 4 | B9: 목 | C9: 12828804 | E9: 원천세·국세 | F9: 우리은행의 국고·원천세 | H9: 0.9
A10: 5 | B10: 금 | C10: 11216092 | E10: 법인카드결제 | F10: 우리카드결제대금, KB카드출금 | H10: 1
A11: 6 | B11: 토 | C11: 0 | E11: 보험료(기타) | F11: 한화생명, 메트라이프, ABL생명, 미래에셋
A12: 7 | B12: 일 | C12: 0 | E12: 광고선전비 | F12: 네이버, 광고, 비즈월렛, 캐시워크
E13: 급여·인건비(대외비) | F13: 급여, 상여, 퇴직, 국민은행 월말 TOP출금
E14: 대출·이자 | F14: 대출, 이자
E15: 기타입출금 | F15: 위 기준에 해당하지 않는 거래

Sheet 정기지출분석
A2: 월 정기지출 분석
A3: 최근 6개월 중 4개월 이상 반복된 지출입니다. '확인필요' 건은 경영지원팀에서 실제 성격을 확인한 뒤 자금계획 고정비로 등록하세요.
A5: 은행 | B5: 정기지출명 | C5: 분류 | D5: 발생개월수 | E5: 거래건수 | F5: 평균 월지출 | G5: 최소 월지출 | H5: 최대 월지출 | I5: 대표 지급일 | J5: 신뢰도 | K5: 성격
A6: 국민은행 | B6: TOP출금 | C6: 급여·인건비(대외비) | D6: 7 | E6: 7 | F6: 65040941 | G6: 1227818 | H6: 81931610 | I6: 매월 30일 전후 | J6: 낮음 | K6: 정기
A7: 우리은행 | B7: 기업콜마비앤에이치 | C7: 외상매입금 | D7: 4 | E7: 6 | F7: 44600001 | G7: 15119315 | H7: 107542010 | I7: 매월 28일 전후 | J7: 중간 | K7: 정기
A8: 국민은행 | B8: 한화생 | C8: 보험료 | D8: 6 | E8: 12 | F8: 42006200 | G8: 42006200 | H8: 42006200 | I8: 매월 8일 전후 | J8: 중간 | K8: 정기
A9: 국민은행 | B9: 허용 | C9: 대표 가지급금 | D9: 4 | E9: 6 | F9: 39250000 | G9: 20000000 | H9: 55000000 | I9: 매월 11일 전후 | J9: 낮음 | K9: 정기
A10: 국민은행 | B10: 한화스마트 | C10: 보험료 | D10: 6 | E10: 6 | F10: 30000000 | G10: 30000000 | H10: 30000000 | I10: 매월 4일 전후 | J10: 높음 | K10: 정기
A11: 우리은행 | B11: 신한주노바렉스 | C11: 외상매입금 | D11: 4 | E11: 5 | F11: 26655210 | G11: 19409038 | H11: 40000000 | I11: 매월 14일 전후 | J11: 낮음 | K11: 정기
A12: 우리은행 | B12: 우리카드결제대금 | C12: 우리카드 결제 | D12: 6 | E12: 9 | F12: 26105540 | G12: 19820525 | H12: 29671488 | I12: 매월 23일 전후 | J12: 중간 | K12: 정기
A13: 우리은행 | B13: 국고_주식회사 | C13: 원천세·국세 | D13: 6 | E13: 15 | F13: 16964733 | G13: 4267600 | H13: 38595390 | I13: 매월 10일 전후 | J13: 낮음 | K13: 정기
A14: 우리은행 | B14: 신한고은미이룸파트 | C14: 광고비 | D14: 5 | E14: 5 | F14: 16732980 | G14: 12282600 | H14: 22391600 | I14: 매월 10일 전후 | J14: 중간 | K14: 정기
A15: 우리은행 | B15: 사회보험 | C15: 4대보험 | D15: 6 | E15: 6 | F15: 16413167 | G15: 13186330 | H15: 21278390 | I15: 매월 10일 전후 | J15: 높음 | K15: 정기
A16: 우리은행 | B16: 한진주식회사 | C16: 운반비 | D16: 6 | E16: 6 | F16: 10790260 | G16: 10060810 | H16: 11946900 | I16: 매월 30일 전후 | J16: 높음 | K16: 정기
A17: 우리은행 | B17: 국민주식회사 아이디 | C17: 광고비 | D17: 4 | E17: 6 | F17: 9157500 | G17: 3630000 | H17: 11000000 | I17: 매월 9일 전후 | J17: 낮음 | K17: 정기
... A57: 우리은행 | B57: LGUMM | C57: 통신비 | D57: 6 | E57: 6 | F57: 11000 | G57: 11000 | H57: 11000 | I57: 매월 15일 전후 | J57: 중간 | K57: 정기
