Workbook

Sheet 요약
A2: (주)에이팜건강 자금계획 기초 현황
A3: 기준일 2026-09-28 | 농협·우리은행·국민은행 계좌 거래내역 통합 (자동 갱신)
A5: 항목 | B5: 금액 | D5: 계좌 | E5: 최종 거래일 | F5: 잔액
A6: 현재 계좌잔액 | B6: 72530640 | D6: 국민 154577 | E6: 46297 | F6: 40946401
A7: 6개월 외부입금 | B7: 3408819820 | D7: 국민 169124 | E7: 46294 | F7: 30687200
A8: 6개월 외부출금 | B8: 3656421770 | D8: 농협 569003 | E8: 46297 | F8: 210724
A9: 온라인매출 입금 | B9: 2107057659 | D9: 우리 220351 | E9: 46297 | F9: 686315
A10: 최근 12주 주평균 온라인입금 | B10: 71003532
A12: 계획 설정 | B12: 값 | D12: 사용 방법
A13: 입금 예측 반영률 | B13: ='경영보고'!$F$12 | D13: 1. 입력·수정은 전부 '경영보고' 시트의 노란 칸에서 합니다 — 나머지 시트는 수식으로 자동 재계산됩니다.
A14: 4주 예상 기말잔액 | B14: ='4주일별계획'!R35 | D14: 2. '대표보고' 시트는 그대로 인쇄(A4 한 장), 일별 상세는 '4주일별계획' 시트에서 봅니다.
A15: 4주 최저 예상잔액 | B15: =MIN('4주일별계획'!R8:R35) | D15: ="3. 온라인 입금은 최근 12주 요일별 평균의 "&TEXT($B$13,"0%")&"로 예측합니다."
A16: 13주 예상 기말잔액 | B16: ='13주주별계획'!J18 | D16: 4. 계좌 간 이체는 내부이체로 표시해 입출금 합계에서 제외합니다.
D17: 5. 무엇을 고치면 어디가 바뀌는지는 아래 '경영보고 시트 수정 방법' 표를 보세요.
A19: 경영보고 시트 수정 방법 — 무엇을 고치면 어디가 바뀌나 (전부 수식 자동 반영)
A20: 수정하는 곳 (경영보고 노란 칸) | B20: 이렇게 수정 | D20: 바뀌는 곳 (수정 즉시 자동 재계산)
A21: F12 · 입금 반영률 (총잔액 옆) | B21: 60~100%에서 선택 | D21: 경영보고 ③ 일별 온라인 예상입금·④ 잔액과 판정 → 4주일별계획 온라인 예상입금 열 → 계좌별시나리오·13주 → 요약 B13~B16 → 대표보고 시나리오 표
A22: ② 지출예정 A열(지급일)·E열(금액) | B22: 일자·금액을 바로 고침 (숨은 예비 행을 펴면 새 지출 추가) | D22: 경영보고 ② 합계 E110·④ 그 날짜의 지출·잔액·지출 내역 → 4주일별계획 송금·카드·조정 열과 잔액 → 계좌별시나리오 → 대표보고
A23: ② G열(실지출·은행 확인) | B23: 실제 나간 금액을 입력 | D23: ② H열(차이)만 자동 계산 — 계획 대비 대조 기록용이라 다른 시트 숫자는 바뀌지 않음
A24: ② I열(확인 드롭다운) | B24: 적용 / 보류 선택 (빈칸 = 적용) | D24: '보류' 행은 ② 합계 E110·④ 일별 흐름·4주일별계획·대표보고에서 전부 빠짐 — 이 파일 안에서만 유효
A25: ③ 입금예정 확정입금 행 A(일자)·E(금액) | B25: 확정입금 일자·금액을 고침 | D25: 경영보고 ④ 그 날짜 입금·잔액 → 4주일별계획 확정·기타입금 열 → 계좌별시나리오 → 대표보고
A26: C172 · 목표 최저잔액 | B26: 안정 목표 금액을 입력 | D26: ⑤ 필요 추가 입금(반영률 시나리오별 부족액)만 다시 계산
A27: ※ 이 파일에서 한 수정은 이 파일 안에서만 유효합니다 — 다음 실행 결과는 팀 지출계획·확인 단계 기준으로 새로 계산됩니다. 숨겨진 날짜·예비 행은 행 숨기기 해제로 볼 수 있습니다.

Sheet 업데이트운영
A2: 이 파일 사용·업데이트 안내
A3: 매주 실행 때마다 05_결과 폴더에 새 주간자금계획 파일이 만들어집니다 — 열어 볼 파일은 최신 파일 하나입니다. 이 안내는 실행할 때마다 자동으로 새로 쓰입니다.
A5: ① 매주 운영 순서
A6: 1. 은행 파일 | B6: 월요일 아침 농협·우리은행·국민은행에서 최근 거래내역(엑셀)을 내려받아 03_은행거래내역 폴더에 넣습니다 — 조회기간이 겹쳐도 중복 거래는 자동 제외되고, 지난 파일은 자동 보관됩니다.
A7: 2. 팀 지출계획 | B7: 각 팀 주간 지출계획 파일을 01_지출계획 폴더에 넣습니다 (경영지원 대외비 파일은 02_경영지원_대외비 폴더).
A8: 3. 자동 실행 | B8: 월요일 09:10 자동 실행됩니다 (트레이 아이콘 → '지금 실행'으로 언제든 수동 실행 가능). 먼저 06_확인필요 폴더에 확인 파일이 열립니다.
A9: 4. 확인·저장 | B9: 확인 파일의 시트(확인필요·정기지출누락·정기지출분석)를 검토하고 '안내' 시트 B2를 '예'로 바꿔 저장하면 몇 분 안에 이 결과 파일이 만들어집니다.
A10: 5. 수정·보고 | B10: 이 파일의 '경영보고' 시트 노란 칸에서 일정·금액을 수정하고(전 시트 자동 반영 — 요약 시트의 표 참고), '대표보고' 시트를 그대로 A4 인쇄해 보고합니다.
A11: 6. 금요일 대조 | B11: 금요일 17:00 은행 파일을 새로 받아 넣으면 06_확인필요에 주간대조 파일이 생성됩니다 — 이번 주 계획 vs 실제 입출금 차이를 확인합니다.
A13: ② 이 파일의 시트 구성
A14: 요약 | B14: 잔액·통계 요약 + 경영보고 수정 방법 표
A15: 업데이트운영 | B15: 이 안내 (운영 순서·시트 구성·은행 자료 현황)
A16: 경영보고 | B16: ★ 입력 기준 시트 — ①현황 ②지출예정 ③입금예정 ④일별 흐름 ⑤필요 추가 입금 ⑥메모. 노란 칸을 고치면 전 시트 자동 재계산
A17: 대표보고 | B17: A4 한 장 인쇄용 요약 — 경영보고에 수식으로 연동
A18: 4주일별계획 | B18: 일별 상세(실무용) — 경영보고 수정에 자동 연동
A19: 계좌별시나리오 | B19: 계좌별 잔액·입금 배분·부족분 이체 계획
A20: 지출계획_취합 | B20: 팀 지출계획 취합 (대외비는 분류·총액만)
A21: 에이팜 지출계획 | B21: 에이팜 지출 상세
A22: 계좌내역통합_RAW | B22: 은행 3사 거래내역 통합 원본
A23: 설정및분류 | B23: 요일평균 등 내부 계산용 (수정 불필요)
A24: 13주주별계획 (숨김) | B24: 13주 주별 전망 — 시트 숨기기 해제로 열람
A26: ③ 현재 반영된 은행 자료 (자동 집계)
A27: 은행 | B27: 반영 거래건수 | C27: 자료 시작일 | D27: 최종 거래일
A28: 국민은행 | B28: 145 | C28: 46272 | D28: 46297
A29: 농협 | B29: 36 | C29: 46272 | D29: 46297
A30: 우리은행 | B30: 128 | C30: 46271 | D30: 46297
A32: ※ 은행 파일에서 읽은 거래 기준입니다. 최종 거래일이 오래됐으면 새 은행 파일을 03_은행거래내역 폴더에 넣고 다시 실행하세요.

Sheet 경영보고
A1: 주간 자금 경영보고 — (주)에이팜건강
A2: 기준주 2026-09-28 (월) ~ 2026-10-04 (일) · 작성 2026-10-04 23:19:26 · 실행일~차주 금요일만 표시 (그 밖의 일자 행은 숨김 — 행 숨기기 해제로 열람 가능)
A3: 노란 칸(입금 반영률 F12·② 지출 지급일·금액·③ 확정입금·목표 최저잔액)을 고치면 이 시트의 ④ 일별 흐름과 라이브 시트 전체가 즉시 다시 계산됩니다. ② 지출예정에서 실지출과 차이 나는 행(주황)은 확인(I열) 드롭다운으로 표시하세요.
A5: ① 현재 자금 현황
A6: 국민 154577 | C6: 40946401 | D6: 최종 거래일 2026-10-02
A7: 국민 169124 | C7: 30687200 | D7: 최종 거래일 2026-09-29
A8: 농협 569003 | C8: 210724 | D8: 최종 거래일 2026-10-02
A9: 우리 220351 | C9: 686315 | D9: 최종 거래일 2026-10-02
A12: 총잔액 | C12: =SUM(C6:C11) | E12: 입금 반영률 | F12: 0.8
A14: ② 반영된 지출예정 (실행일~차주 금요일 표시) — 지급일·금액(노란 칸)을 고치면 아래 ④ 일별 흐름과 라이브 시트 전체가 다시 계산됩니다 · 실지출(G)을 적으면 차이(H) 자동 계산 · 확인(I)에서 '보류'를 고른 행은 계획에서 제외
A15: 지급일 | B15: 요일 | C15: 구분 | D15: 내용 | E15: 금액 | F15: 지급방법 | G15: 실지출(은행 확인) | H15: 차이(잔여) | I15: 확인
A16: 46301 | B16: =IF(A16="","",MID("월화수목금토일",WEEKDAY(A16,2),1)) | C16: 건강사업팀 | D16: 네이버 네이버 SA&GFA 광고 비용 | E16: 3366000 | F16: 계좌송금 | H16: =IF(OR(G16="",E16=""),"",E16-G16)
A17: 46301 | B17: =IF(A17="","",MID("월화수목금토일",WEEKDAY(A17,2),1)) | C17: 건강사업팀 | D17: 카카오톡 플러스친구 카카오톡 플러스친구 충전 | E17: 1500000 | F17: 계좌송금 | H17: =IF(OR(G17="",E17=""),"",E17-G17)
A18: 46301 | B18: =IF(A18="","",MID("월화수목금토일",WEEKDAY(A18,2),1)) | C18: 건강사업팀 | D18: 네이버 네이버 톡톡 | E18: 500000 | F18: 계좌송금 | H18: =IF(OR(G18="",E18=""),"",E18-G18)
A19: 46301 | B19: =IF(A19="","",MID("월화수목금토일",WEEKDAY(A19,2),1)) | C19: 건강사업팀 | D19: 비즈콘 정기배송 50회차, 60회차 달성8명, 신세계상품권 5만원권 발송 | E19: 400000 | F19: 계좌송금 | H19: =IF(OR(G19="",E19=""),"",E19-G19)
A20: 46302 | B20: =IF(A20="","",MID("월화수목금토일",WEEKDAY(A20,2),1)) | C20: 건강사업팀 | D20: 인포크비즈니스 베리시톨 인플루언서 비용 | E20: 3300000 | F20: 계좌송금 | H20: =IF(OR(G20="",E20=""),"",E20-G20)
A21: 46302 | B21: =IF(A21="","",MID("월화수목금토일",WEEKDAY(A21,2),1)) | C21: 건강사업팀 | D21: 써치엠 메타 광고 대행 수수 | E21: 1487786 | F21: 계좌송금 | H21: =IF(OR(G21="",E21=""),"",E21-G21)
A22: 46302 | B22: =IF(A22="","",MID("월화수목금토일",WEEKDAY(A22,2),1)) | C22: 건강사업팀 | D22: ADN ADN 광고 송출 비용 | E22: 500000 | F22: 계좌송금 | H22: =IF(OR(G22="",E22=""),"",E22-G22)
A23: 46302 | B23: =IF(A23="","",MID("월화수목금토일",WEEKDAY(A23,2),1)) | C23: 경영지원팀 | D23: 서원회계법인 기장료 | E23: 385000 | F23: 계좌송금 | H23: =IF(OR(G23="",E23=""),"",E23-G23)
A24: 46302 | B24: =IF(A24="","",MID("월화수목금토일",WEEKDAY(A24,2),1)) | C24: 건강사업팀 | D24: 비즈콘 9월 프로모션 사은품 지급 | E24: 300000 | F24: 계좌송금 | H24: =IF(OR(G24="",E24=""),"",E24-G24)
A25: 46303 | B25: =IF(A25="","",MID("월화수목금토일",WEEKDAY(A25,2),1)) | C25: 데이터사이언스팀 | D25: KICTA CES 참가 부스 최종 대금 | E25: 9189417 | F25: 계좌송금 | H25: =IF(OR(G25="",E25=""),"",E25-G25)
A26: 46303 | B26: =IF(A26="","",MID("월화수목금토일",WEEKDAY(A26,2),1)) | C26: 건강사업팀 | D26: 네이버 네이버 SA&GFA 광고 비용 | E26: 6424000 | F26: 계좌송금 | H26: =IF(OR(G26="",E26=""),"",E26-G26)
A27: 46303 | B27: =IF(A27="","",MID("월화수목금토일",WEEKDAY(A27,2),1)) | C27: 건강사업팀 | D27: 네이버 브랜드 검색 광고 | E27: 1980000 | F27: 계좌송금 | H27: =IF(OR(G27="",E27=""),"",E27-G27)
... A29: 46318 | B29: =IF(A29="","",MID("월화수목금토일",WEEKDAY(A29,2),1)) | C29: 경영지원팀 | D29: 위버 워크샵 (1부/2부) 이용료 | E29: 1675000 | F29: 법인카드 | H29: =IF(OR(G29="",E29=""),"",E29-G29)
B30: =IF(A30="","",MID("월화수목금토일",WEEKDAY(A30,2),1)) | H30: =IF(OR(G30="",E30=""),"",E30-G30)
B31: =IF(A31="","",MID("월화수목금토일",WEEKDAY(A31,2),1)) | H31: =IF(OR(G31="",E31=""),"",E31-G31)
B32: =IF(A32="","",MID("월화수목금토일",WEEKDAY(A32,2),1)) | H32: =IF(OR(G32="",E32=""),"",E32-G32)
B33: =IF(A33="","",MID("월화수목금토일",WEEKDAY(A33,2),1)) | H33: =IF(OR(G33="",E33=""),"",E33-G33)
B34: =IF(A34="","",MID("월화수목금토일",WEEKDAY(A34,2),1)) | H34: =IF(OR(G34="",E34=""),"",E34-G34)
B35: =IF(A35="","",MID("월화수목금토일",WEEKDAY(A35,2),1)) | H35: =IF(OR(G35="",E35=""),"",E35-G35)
B36: =IF(A36="","",MID("월화수목금토일",WEEKDAY(A36,2),1)) | H36: =IF(OR(G36="",E36=""),"",E36-G36)
B37: =IF(A37="","",MID("월화수목금토일",WEEKDAY(A37,2),1)) | H37: =IF(OR(G37="",E37=""),"",E37-G37)
B38: =IF(A38="","",MID("월화수목금토일",WEEKDAY(A38,2),1)) | H38: =IF(OR(G38="",E38=""),"",E38-G38)
B39: =IF(A39="","",MID("월화수목금토일",WEEKDAY(A39,2),1)) | H39: =IF(OR(G39="",E39=""),"",E39-G39)
B40: =IF(A40="","",MID("월화수목금토일",WEEKDAY(A40,2),1)) | H40: =IF(OR(G40="",E40=""),"",E40-G40)
B41: =IF(A41="","",MID("월화수목금토일",WEEKDAY(A41,2),1)) | H41: =IF(OR(G41="",E41=""),"",E41-G41)
... B109: =IF(A109="","",MID("월화수목금토일",WEEKDAY(A109,2),1)) | H109: =IF(OR(G109="",E109=""),"",E109-G109)
D110: 합계(숨긴 행 포함 4주 전체 · 보류 제외) | E110: =SUMIFS(E16:E109,I16:I109,"<>보류")
A112: ③ 반영된 입금예정 (실행일~차주 금요일) — 예상은 반영률(F12) 연동 · 실입금은 은행 확인 값
A113: 입금일 | B113: 요일 | C113: 구분 | D113: 내용 | E113: 예상금액 | F113: 실입금(은행 확인) | G113: 차이
...

Sheet 대표보고
A1: (주)에이팜건강 주간 자금계획 보고
A2: ="기준일 2026-09-28 · 작성 2026-10-04 23:19:26 · 입금 반영률 "&TEXT('경영보고'!$F$12,"0%")&" (경영보고 시트와 실시간 연동)"
A4: 핵심 요약
A5: 현재 전체 계좌잔액 | C5: ='경영보고'!C12
A6: 4주 예상 기말잔액 | C6: ='경영보고'!E167
A7: 4주 최저 예상잔액 | C7: ='경영보고'!C168 | D7: =TEXT(INDEX('경영보고'!$A$140:$A$167,MATCH('경영보고'!C168,'경영보고'!$E$140:$E$167,0)),"m/d 예상")
A8: 향후 4주 확정지출 | C8: ='경영보고'!E110
A9: 카드 결제 예정액(4주) | C9: =SUMIFS('경영보고'!$E$16:$E$109,'경영보고'!$F$16:$F$109,"법인카드",'경영보고'!$I$16:$I$109,"<>보류")
A10: 자금부족 예상일 | C10: =IFERROR(TEXT(INDEX('경영보고'!$A$140:$A$167,MATCH(TRUE,INDEX('경영보고'!$E$140:$E$167<0,0),0)),"yyyy-mm-dd"),"없음")
A11: 확인필요 건수 | C11: 64건
A12: 자료 미제출 팀 | C12: 없음
A14: ='경영보고'!A169
A16: 차주 일별 잔액 전망 (월~금) — 반영률·지출 수정과 실시간 연동
A17: 일자 | B17: 요일 | C17: 예상 기말잔액 | D17: 상태
A18: ='경영보고'!A147 | B18: 월 | C18: ='경영보고'!E147 | D18: =IF(C18<0,"부족","")
A19: ='경영보고'!A148 | B19: 화 | C19: ='경영보고'!E148 | D19: =IF(C19<0,"부족","")
A20: ='경영보고'!A149 | B20: 수 | C20: ='경영보고'!E149 | D20: =IF(C20<0,"부족","")
A21: ='경영보고'!A150 | B21: 목 | C21: ='경영보고'!E150 | D21: =IF(C21<0,"부족","")
A22: ='경영보고'!A151 | B22: 금 | C22: ='경영보고'!E151 | D22: =IF(C22<0,"부족","")
A24: 입금 반영률 시나리오 (80·90·100%) — 필요 추가 입금
A25: 반영률 | C25: 4주 기말잔액 | D25: 4주 최저잔액 | E25: 필요 추가 입금
A26: ='경영보고'!A174 | C26: ='경영보고'!C174 | D26: ='경영보고'!D174 | E26: ='경영보고'!F174
A27: ='경영보고'!A175 | C27: ='경영보고'!C175 | D27: ='경영보고'!D175 | E27: ='경영보고'!F175
A28: ='경영보고'!A176 | C28: ='경영보고'!C176 | D28: ='경영보고'!D176 | E28: ='경영보고'!F176
A30: ="· 목표 최저잔액 "&TEXT('경영보고'!$C$172,"#,##0")&"원 기준. 시나리오 값은 실행 시점 계산이며, 반영률·지출 수정은 위 표와 경영보고에 즉시 반영됩니다."
A31: · 대외비 항목은 분류·총액으로만 표시됩니다. 상세 내역은 같은 파일의 경영보고·지출계획_취합 시트를 확인하십시오.

Sheet 4주일별계획
A2: 향후 4주 일별 자금계획
A3: 온라인 예상입금은 최근 12주 요일별 평균 × 입금 반영률('경영보고' F12 연동)로 계산됩니다. 지급일·금액·확정입금은 '경영보고' 시트의 ③·④ 표에서 고치세요 — 이 표는 자동으로 따라옵니다. | 실잔고(은행 최근 확인): 우리 220351 686,315(10-02) · 농협 569003 210,724(10-02) · 국민 154577 40,946,401(10-02) · 국민 169124 30,687,200(09-29) — 실행일 행은 은행 파일 그대로 실적으로 마감(기말 = 오늘 실잔고)하고, 아직 안 나간 예정(보류 제외)은 익일로 이월합니다. 자금 예산은 익일부터 오늘 실잔고에서 출발합니다(반영률 B13 연동)
C4: 계좌별 예상잔고 | H4: 계좌별 입금 배분(예상)
A5: 일자 | B5: 요일 | C5: 우리 220351 | D5: 농협 569003 | E5: 국민 154577 | F5: 국민 169124 | G5: 온라인 예상입금 | H5: 우리 220351 | I5: 농협 569003 | J5: 국민 154577 | K5: 국민 169124 | L5: 확정·기타입금 | M5: 송금예정 | N5: 카드결제 | O5: 조정·추정 지출 | P5: 순현금흐름 | Q5: 기초잔액 | R5: 기말잔액 | S5: 비고
A6: 46298 | B6: 토 | C6: ='계좌별시나리오'!D6 | D6: ='계좌별시나리오'!E6 | E6: ='계좌별시나리오'!F6 | F6: ='계좌별시나리오'!G6 | R6: ='계좌별시나리오'!C6 | S6: 전일 마감 실잔고 — 여기서 계획 시작
A7: 46299 | B7: 일 | C7: ='계좌별시나리오'!D7 | D7: ='계좌별시나리오'!E7 | E7: ='계좌별시나리오'!F7 | F7: ='계좌별시나리오'!G7 | R7: ='요약'!$B$6 | S7: 오늘 실잔고(은행 확인)·실제 입금·출금 — 참고 (이중계산 안 됨)
A8: 46293 | B8: 월 | C8: ='계좌별시나리오'!D8 | D8: ='계좌별시나리오'!E8 | E8: ='계좌별시나리오'!F8 | F8: ='계좌별시나리오'!G8 | G8: 4102481 | H8: ='계좌별시나리오'!I8 | I8: ='계좌별시나리오'!J8 | J8: ='계좌별시나리오'!K8 | K8: ='계좌별시나리오'!L8 | L8: 41000 | O8: 5025353 | P8: =G8+L8-M8-N8-O8 | Q8: 136021881 | R8: =Q8+P8 | S8: 실적 | 지출: METLIFE09042 2,497,000, 우리카드결제대금 2,493,338, NH기업카드 35,000 외 1건 | 기타입금: 허수원 35,000, 정소영 6,000
A9: 46294 | B9: 화 | C9: ='계좌별시나리오'!D9 | D9: ='계좌별시나리오'!E9 | E9: ='계좌별시나리오'!F9 | F9: ='계좌별시나리오'!G9 | G9: 24361884 | H9: ='계좌별시나리오'!I9 | I9: ='계좌별시나리오'!J9 | J9: ='계좌별시나리오'!K9 | K9: ='계좌별시나리오'!L9 | L9: 134000 | O9: 15624012 | P9: =G9+L9-M9-N9-O9 | Q9: =R8 | R9: =Q9+P9 | S9: 실적 | 지출: NH기업카드 4,490,586, 우리카드결제대금 3,438,607, 국민네이버 apha 2,310,000 외 9건 | 기타입금: 양혜원 103,000, 전수민 20,000 외 1건
A10: 46295 | B10: 수 | C10: ='계좌별시나리오'!D10 | D10: ='계좌별시나리오'!E10 | E10: ='계좌별시나리오'!F10 | F10: ='계좌별시나리오'!G10 | G10: 16248020 | H10: ='계좌별시나리오'!I10 | I10: ='계좌별시나리오'!J10 | J10: ='계좌별시나리오'!K10 | K10: ='계좌별시나리오'!L10 | L10: 24570387 | O10: 108772816 | P10: =G10+L10-M10-N10-O10 | Q10: =R9 | R10: =Q10+P10 | S10: 실적 | 지출: TOP출금 70,320,656, 주식회사 서흥헬스케 20,000,000, 한진-주식회사 9,350,870 외 8건 | 기타입금: (주)에이팜건강 20,000,000, 주식회사에이팜 4,040,700 외 3건
A11: 46296 | B11: 목 | C11: ='계좌별시나리오'!D11 | D11: ='계좌별시나리오'!E11 | E11: ='계좌별시나리오'!F11 | F11: ='계좌별시나리오'!G11 | G11: 9290881 | H11: ='계좌별시나리오'!I11 | I11: ='계좌별시나리오'!J11 | J11: ='계좌별시나리오'!K11 | K11: ='계좌별시나리오'!L11 | L11: 26800 | O11: 15378890 | P11: =G11+L11-M11-N11-O11 | Q11: =R10 | R11: =Q11+P11 | S11: 실적 | 지출: 김정원 9,000,000, KB7008 2,797,570, 국민네이버 apha 1,144,000 외 3건 | 기타입금: 신민경 20,800, 강철왕 6,000
A12: 46297 | B12: 금 | C12: ='계좌별시나리오'!D12 | D12: ='계좌별시나리오'!E12 | E12: ='계좌별시나리오'!F12 | F12: ='계좌별시나리오'!G12 | G12: 8662097 | H12: ='계좌별시나리오'!I12 | I12: ='계좌별시나리오'!J12 | J12: ='계좌별시나리오'!K12 | K12: ='계좌별시나리오'!L12 | L12: 105280 | O12: 6233000 | P12: =G12+L12-M12-N12-O12 | Q12: =R11 | R12: =Q12+P12 | S12: 실적 | 지출: 국민네이버 apha 3,718,000, 국민네이버 ddi5 1,320,000, 국민네이버 에이팜건 880,000 외 2건 | 기타입금: 김소희 56,300, 허수원 25,000 외 2건
A13: 46298 | B13: 토 | C13: ='계좌별시나리오'!D13 | D13: ='계좌별시나리오'!E13 | E13: ='계좌별시나리오'!F13 | F13: ='계좌별시나리오'!G13 | G13: 0 | H13: ='계좌별시나리오'!I13 | I13: ='계좌별시나리오'!J13 | J13: ='계좌별시나리오'!K13 | K13: ='계좌별시나리오'!L13 | L13: =SUMIFS('경영보고'!$E$114:$E$135,'경영보고'!$A$114:$A$135,$A13,'경영보고'!$C$114:$C$135,"확정입금") | M13: =SUMIFS('경영보고'!$E$16:$E$109,'경영보고'!$A$16:$A$109,$A13,'경영보고'!$I$16:$I$109,"<>보류",'경영보고'!$F$16:$F$109,"계좌송금") | N13: =SUMIFS('경영보고'!$E$16:$E$109,'경영보고'!$A$16:$A$109,$A13,'경영보고'!$I$16:$I$109,"<>보류",'경영보고'!$F$16:$F$109,"법인카드") | O13: =SUMIFS('경영보고'!$E$16:$E$109,'경영보고'!$A$16:$A$109,$A13,'경영보고'!$I$16:$I$109,"<>보류")-M13-N13 | P13: =G13+L13-M13-N13-O13 | Q13: =R12 | R13: =Q13+P13
A14: 46299 | B14: 일 | C14: ='계좌별시나리오'!D14 | D14: ='계좌별시나리오'!E14 | E14: ='계좌별시나리오'!F14 | F14: ='계좌별시나리오'!G14 | G14: =INDEX('설정및분류'!$C$6:$C$12,WEEKDAY(A14,2))*'요약'!$B$13 | H14: ='계좌별시나리오'!I14 | I14: ='계좌별시나리오'!J14 | J14: ='계좌별시나리오'!K14 | K14: ='계좌별시나리오'!L14 | L14: =SUMIFS('경영보고'!$E$114:$E$135,'경영보고'!$A$114:$A$135,$A14,'경영보고'!$C$114:$C$135,"확정입금") | M14: =SUMIFS('경영보고'!$E$16:$E$109,'경영보고'!$A$16:$A$109,$A14,'경영보고'!$I$16:$I$109,"<>보류",'경영보고'!$F$16:$F$109,"계좌송금") | N14: =SUMIFS('경영보고'!$E$16:$E$109,'경영보고'!$A$16:$A$109,$A14,'경영보고'!$I$16:$I$109,"<>보류",'경영보고'!$F$16:$F$109,"법인카드") | O14: =SUMIFS('경영보고'!$E$16:$E$109,'경영보고'!$A$16:$A$109,$A14,'경영보고'!$I$16:$I$109,"<>보류")-M14-N14 | P14: =G14+L14-M14-N14-O14 | Q14: =R13 | R14: =Q14+P14
A15: 46300 | B15: 월 | C15: ='계좌별시나리오'!D15 | D15: ='계좌별시나리오'!E15 | E15: ='계좌별시나리오'!F15 | F15: ='계좌별시나리오'!G15 | G15: 0 | H15: ='계좌별시나리오'!I15 | I15: ='계좌별시나리오'!J15 | J15: ='계좌별시나리오'!K15 | K15: ='계좌별시나리오'!L15 | L15: =SUMIFS('경영보고'!$E$114:$E$135,'경영보고'!$A$114:$A$135,$A15,'경영보고'!$C$114:$C$135,"확정입금") | M15: =SUMIFS('경영보고'!$E$16:$E$109,'경영보고'!$A$16:$A$109,$A15,'경영보고'!$I$16:$I$109,"<>보류",'경영보고'!$F$16:$F$109,"계좌송금") | N15: =SUMIFS('경영보고'!$E$16:$E$109,'경영보고'!$A$16:$A$109,$A15,'경영보고'!$I$16:$I$109,"<>보류",'경영보고'!$F$16:$F$109,"법인카드") | O15: =SUMIFS('경영보고'!$E$16:$E$109,'경영보고'!$A$16:$A$109,$A15,'경영보고'!$I$16:$I$109,"<>보류")-M15-N15 | P15: =G15+L15-M15-N15-O15 | Q15: =R14 | R15: =Q15+P15
A16: 46301 | B16: 화 | C16: ='계좌별시나리오'!D16 | D16: ='계좌별시나리오'!E16 | E16: ='계좌별시나리오'!F16 | F16: ='계좌별시나리오'!G16 | G16: =INDEX('설정및분류'!$C$6:$C$12,WEEKDAY(A16,2))*'요약'!$B$13 | H16: ='계좌별시나리오'!I16 | I16: ='계좌별시나리오'!J16 | J16: ='계좌별시나리오'!K16 | K16: ='계좌별시나리오'!L16 | L16: =SUMIFS('경영보고'!$E$114:$E$135,'경영보고'!$A$114:$A$135,$A16,'경영보고'!$C$114:$C$135,"확정입금") | M16: =SUMIFS('경영보고'!$E$16:$E$109,'경영보고'!$A$16:$A$109,$A16,'경영보고'!$I$16:$I$109,"<>보류",'경영보고'!$F$16:$F$109,"계좌송금") | N16: =SUMIFS('경영보고'!$E$16:$E$109,'경영보고'!$A$16:$A$109,$A16,'경영보고'!$I$16:$I$109,"<>보류",'경영보고'!$F$16:$F$109,"법인카드") | O16: =SUMIFS('경영보고'!$E$16:$E$109,'경영보고'!$A$16:$A$109,$A16,'경영보고'!$I$16:$I$109,"<>보류")-M16-N16 | P16: =G16+L16-M16-N16-O16 | Q16: =R15 | R16: =Q16+P16 | S16: 네이버 3,366,000, 카카오톡 플러스친구 1,500,000, 네이버 500,000, 비즈콘 400,000
A17: 46302 | B17: 수 | C17: ='계좌별시나리오'!D17 | D17: ='계좌별시나리오'!E17 | E17: ='계좌별시나리오'!F17 | F17: ='계좌별시나리오'!G17 | G17: =INDEX('설정및분류'!$C$6:$C$12,WEEKDAY(A17,2))*'요약'!$B$13 | H17: ='계좌별시나리오'!I17 | I17: ='계좌별시나리오'!J17 | J17: ='계좌별시나리오'!K17 | K17: ='계좌별시나리오'!L17 | L17: =SUMIFS('경영보고'!$E$114:$E$135,'경영보고'!$A$114:$A$135,$A17,'경영보고'!$C$114:$C$135,"확정입금") | M17: =SUMIFS('경영보고'!$E$16:$E$109,'경영보고'!$A$16:$A$109,$A17,'경영보고'!$I$16:$I$109,"<>보류",'경영보고'!$F$16:$F$109,"계좌송금") | N17: =SUMIFS('경영보고'!$E$16:$E$109,'경영보고'!$A$16:$A$109,$A17,'경영보고'!$I$16:$I$109,"<>보류",'경영보고'!$F$16:$F$109,"법인카드") | O17: =SUMIFS('경영보고'!$E$16:$E$109,'경영보고'!$A$16:$A$109,$A17,'경영보고'!$I$16:$I$109,"<>보류")-M17-N17 | P17: =G17+L17-M17-N17-O17 | Q17: =R16 | R17: =Q17+P17 | S17: 인포크비즈니스 3,300,000, 써치엠 1,487,786, ADN 500,000, 서원회계법인 385,000, 비즈콘 300,000
A18: 46303 | B18: 목 | C18: ='계좌별시나리오'!D18 | D18: ='계좌별시나리오'!E18 | E18: ='계좌별시나리오'!F18 | F18: ='계좌별시나리오'!G18 | G18: =INDEX('설정및분류'!$C$6:$C$12,WEEKDAY(A18,2))*'요약'!$B$13 | H18: ='계좌별시나리오'!I18 | I18: ='계좌별시나리오'!J18 | J18: ='계좌별시나리오'!K18 | K18: ='계좌별시나리오'!L18 | L18: =SUMIFS('경영보고'!$E$114:$E$135,'경영보고'!$A$114:$A$135,$A18,'경영보고'!$C$114:$C$135,"확정입금") | M18: =SUMIFS('경영보고'!$E$16:$E$109,'경영보고'!$A$16:$A$109,$A18,'경영보고'!$I$16:$I$109,"<>보류",'경영보고'!$F$16:$F$109,"계좌송금") | N18: =SUMIFS('경영보고'!$E$16:$E$109,'경영보고'!$A$16:$A$109,$A18,'경영보고'!$I$16:$I$109,"<>보류",'경영보고'!$F$16:$F$109,"법인카드") | O18: =SUMIFS('경영보고'!$E$16:$E$109,'경영보고'!$A$16:$A$109,$A18,'경영보고'!$I$16:$I$109,"<>보류")-M18-N18 | P18: =G18+L18-M18-N18-O18 | Q18: =R17 | R18: =Q18+P18 | S18: KICTA 9,189,417, 네이버 6,424,000, 네이버 1,980,000, (주)채널코퍼레이션 198,000
A19: 46304 | B19: 금 | C19: ='계좌별시나리오'!D19 | D19: ='계좌별시나리오'!E19 | E19: ='계좌별시나리오'!F19 | F19: ='계좌별시나리오'!G19 | G19: 0 | H19: ='계좌별시나리오'!I19 | I19: ='계좌별시나리오'!J19 | J19: ='계좌별시나리오'!K19 | K19: ='계좌별시나리오'!L19 | L19: =SUMIFS('경영보고'!$E$114:$E$135,'경영보고'!$A$114:$A$135,$A19,'경영보고'!$C$114:$C$135,"확정입금") | M19: =SUMIFS('경영보고'!$E$16:$E$109,'경영보고'!$A$16:$A$109,$A19,'경영보고'!$I$16:$I$109,"<>보류",'경영보고'!$F$16:$F$109,"계좌송금") | N19: =SUMIFS('경영보고'!$E$16:$E$109,'경영보고'!$A$16:$A$109,$A19,'경영보고'!$I$16:$I$109,"<>보류",'경영보고'!$F$16:$F$109,"법인카드") | O19: =SUMIFS('경영보고'!$E$16:$E$109,'경영보고'!$A$16:$A$109,$A19,'경영보고'!$I$16:$I$109,"<>보류")-M19-N19 | P19: =G19+L19-M19-N19-O19 | Q19: =R18 | R19: =Q19+P19
A20: 46305 | B20: 토 | C20: ='계좌별시나리오'!D20 | D20: ='계좌별시나리오'!E20 | E20: ='계좌별시나리오'!F20 | F20: ='계좌별시나리오'!G20 | G20: =INDEX('설정및분류'!$C$6:$C$12,WEEKDAY(A20,2))*'요약'!$B$13 | H20: ='계좌별시나리오'!I20 | I20: ='계좌별시나리오'!J20 | J20: ='계좌별시나리오'!K20 | K20: ='계좌별시나리오'!L20 | L20: =SUMIFS('경영보고'!$E$114:$E$135,'경영보고'!$A$114:$A$135,$A20,'경영보고'!$C$114:$C$135,"확정입금") | M20: =SUMIFS('경영보고'!$E$16:$E$109,'경영보고'!$A$16:$A$109,$A20,'경영보고'!$I$16:$I$109,"<>보류",'경영보고'!$F$16:$F$109,"계좌송금") | N20: =SUMIFS('경영보고'!$E$16:$E$109,'경영보고'!$A$16:$A$109,$A20,'경영보고'!$I$16:$I$109,"<>보류",'경영보고'!$F$16:$F$109,"법인카드") | O20: =SUMIFS('경영보고'!$E$16:$E$109,'경영보고'!$A$16:$A$109,$A20,'경영보고'!$I$16:$I$109,"<>보류")-M20-N20 | P20: =G20+L20-M20-N20-O20 | Q20: =R19 | R20: =Q20+P20
A21: 46306 | B21: 일 | C21: ='계좌별시나리오'!D21 | D21: ='계좌별시나리오'!E21 | E21: ='계좌별시나리오'!F21 | F21: ='계좌별시나리오'!G21 | G21: =INDEX('설정및분류'!$C$6:$C$12,WEEKDAY(A21,2))*'요약'!$B$13 | H21: ='계좌별시나리오'!I21 | I21: ='계좌별시나리오'!J21 | J21: ='계좌별시나리오'!K21 | K21: ='계좌별시나리오'!L21 | L21: =SUMIFS('경영보고'!$E$114:$E$135,'경영보고'!$A$114:$A$135,$A21,'경영보고'!$C$114:$C$135,"확정입금") | M21: =SUMIFS('경영보고'!$E$16:$E$109,'경영보고'!$A$16:$A$109,$A21,'경영보고'!$I$16:$I$109,"<>보류",'경영보고'!$F$16:$F$109,"계좌송금") | N21: =SUMIFS('경영보고'!$E$16:$E$109,'경영보고'!$A$16:$A$109,$A21,'경영보고'!$I$16:$I$109,"<>보류",'경영보고'!$F$16:$F$109,"법인카드") | O21: =SUMIFS('경영보고'!$E$16:$E$109,'경영보고'!$A$16:$A$109,$A21,'경영보고'!$I$16:$I$109,"<>보류")-M21-N21 | P21: =G21+L21-M21-N21-O21 | Q21: =R20 | R21: =Q21+P21
A22: 46307 | B22: 월 | C22: ='계좌별시나리오'!D22 | D22: ='계좌별시나리오'!E22 | E22: ='계좌별시나리오'!F22 | F22: ='계좌별시나리오'!G22 | G22: =INDEX('설정및분류'!$C$6:$C$12,WEEKDAY(A22,2))*'요약'!$B$13 | H22: ='계좌별시나리오'!I22 | I22: ='계좌별시나리오'!J22 | J22: ='계좌별시나리오'!K22 | K22: ='계좌별시나리오'!L22 | L22: =SUMIFS('경영보고'!$E$114:$E$135,'경영보고'!$A$114:$A$135,$A22,'경영보고'!$C$114:$C$135,"확정입금") | M22: =SUMIFS('경영보고'!$E$16:$E$109,'경영보고'!$A$16:$A$109,$A22,'경영보고'!$I$16:$I$109,"<>보류",'경영보고'!$F$16:$F$109,"계좌송금") | N22: =SUMIFS('경영보고'!$E$16:$E$109,'경영보고'!$A$16:$A$109,$A22,'경영보고'!$I$16:$I$109,"<>보류",'경영보고'!$F$16:$F$109,"법인카드") | O22: =SUMIFS('경영보고'!$E$16:$E$109,'경영보고'!$A$16:$A$109,$A22,'경영보고'!$I$16:$I$109,"<>보류")-M22-N22 | P22: =G22+L22-M22-N22-O22 | Q22: =R21 | R22: =Q22+P22
A23: 46308 | B23: 화 | C23: ='계좌별시나리오'!D23 | D23: ='계좌별시나리오'!E23 | E23: ='계좌별시나리오'!F23 | F23: ='계좌별시나리오'!G23 | G23: =INDEX('설정및분류'!$C$6:$C$12,WEEKDAY(A23,2))*'요약'!$B$13 | H23: ='계좌별시나리오'!I23 | I23: ='계좌별시나리오'!J23 | J23: ='계좌별시나리오'!K23 | K23: ='계좌별시나리오'!L23 | L23: =SUMIFS('경영보고'!$E$114:$E$135,'경영보고'!$A$114:$A$135,$A23,'경영보고'!$C$114:$C$135,"확정입금") | M23: =SUMIFS('경영보고'!$E$16:$E$109,'경영보고'!$A$16:$A$109,$A23,'경영보고'!$I$16:$I$109,"<>보류",'경영보고'!$F$16:$F$109,"계좌송금") | N23: =SUMIFS('경영보고'!$E$16:$E$109,'경영보고'!$A$16:$A$109,$A23,'경영보고'!$I$16:$I$109,"<>보류",'경영보고'!$F$16:$F$109,"법인카드") | O23: =SUMIFS('경영보고'!$E$16:$E$109,'경영보고'!$A$16:$A$109,$A23,'경영보고'!$I$16:$I$109,"<>보류")-M23-N23 | P23: =G23+L23-M23-N23-O23 | Q23: =R22 | R23: =Q23+P23
A24: 46309 | B24: 수 | C24: ='계좌별시나리오'!D24 | D24: ='계좌별시나리오'!E24 | E24: ='계좌별시나리오'!F24 | F24: ='계좌별시나리오'!G24 | G24: =INDEX('설정및분류'!$C$6:$C$12,WEEKDAY(A24,2))*'요약'!$B$13 | H24: ='계좌별시나리오'!I24 | I24: ='계좌별시나리오'!J24 | J24: ='계좌별시나리오'!K24 | K24: ='계좌별시나리오'!L24 | L24: =SUMIFS('경영보고'!$E$114:$E$135,'경영보고'!$A$114:$A$135,$A24,'경영보고'!$C$114:$C$135,"확정입금") | M24: =SUMIFS('경영보고'!$E$16:$E$109,'경영보고'!$A$16:$A$109,$A24,'경영보고'!$I$16:$I$109,"<>보류",'경영보고'!$F$16:$F$109,"계좌송금") | N24: =SUMIFS('경영보고'!$E$16:$E$109,'경영보고'!$A$16:$A$109,$A24,'경영보고'!$I$16:$I$109,"<>보류",'경영보고'!$F$16:$F$109,"법인카드") | O24: =SUMIFS('경영보고'!$E$16:$E$109,'경영보고'!$A$16:$A$109,$A24,'경영보고'!$I$16:$I$109,"<>보류")-M24-N24 | P24: =G24+L24-M24-N24-O24 | Q24: =R23 | R24: =Q24+P24
A25: 46310 | B25: 목 | C25: ='계좌별시나리오'!D25 | D25: ='계좌별시나리오'!E25 | E25: ='계좌별시나리오'!F25 | F25: ='계좌별시나리오'!G25 | G25: =INDEX('설정및분류'!$C$6:$C$12,WEEKDAY(A25,2))*'요약'!$B$13 | H25: ='계좌별시나리오'!I25 | I25: ='계좌별시나리오'!J25 | J25: ='계좌별시나리오'!K25 | K25: ='계좌별시나리오'!L25 | L25: =SUMIFS('경영보고'!$E$114:$E$135,'경영보고'!$A$114:$A$135,$A25,'경영보고'!$C$114:$C$135,"확정입금") | M25: =SUMIFS('경영보고'!$E$16:$E$109,'경영보고'!$A$16:$A$109,$A25,'경영보고'!$I$16:$I$109,"<>보류",'경영보고'!$F$16:$F$109,"계좌송금") | N25: =SUMIFS('경영보고'!$E$16:$E$109,'경영보고'!$A$16:$A$109,$A25,'경영보고'!$I$16:$I$109,"<>보류",'경영보고'!$F$16:$F$109,"법인카드") | O25: =SUMIFS('경영보고'!$E$16:$E$109,'경영보고'!$A$16:$A$109,$A25,'경영보고'!$I$16:$I$109,"<>보류")-M25-N25 | P25: =G25+L25-M25-N25-O25 | Q25: =R24 | R25: =Q25+P25
A26: 46311 | B26: 금 | C26: ='계좌별시나리오'!D26 | D26: ='계좌별시나리오'!E26 | E26: ='계좌별시나리오'!F26 | F26: ='계좌별시나리오'!G26 | G26: =INDEX('설정및분류'!$C$6:$C$12,WEEKDAY(A26,2))*'요약'!$B$13 | H26: ='계좌별시나리오'!I26 | I26: ='계좌별시나리오'!J26 | J26: ='계좌별시나리오'!K26 | K26: ='계좌별시나리오'!L26 | L26: =SUMIFS('경영보고'!$E$114:$E$135,'경영보고'!$A$114:$A$135,$A26,'경영보고'!$C$114:$C$135,"확정입금") | M26: =SUMIFS('경영보고'!$E$16:$E$109,'경영보고'!$A$16:$A$109,$A26,'경영보고'!$I$16:$I$109,"<>보류",'경영보고'!$F$16:$F$109,"계좌송금") | N26: =SUMIFS('경영보고'!$E$16:$E$109,'경영보고'!$A$16:$A$109,$A26,'경영보고'!$I$16:$I$109,"<>보류",'경영보고'!$F$16:$F$109,"법인카드") | O26: =SUMIFS('경영보고'!$E$16:$E$109,'경영보고'!$A$16:$A$109,$A26,'경영보고'!$I$16:$I$109,"<>보류")-M26-N26 | P26: =G26+L26-M26-N26-O26 | Q26: =R25 | R26: =Q26+P26
A27: 46312 | B27: 토 | C27: ='계좌별시나리오'!D27 | D27: ='계좌별시나리오'!E27 | E27: ='계좌별시나리오'!F27 | F27: ='계좌별시나리오'!G27 | G27: =INDEX('설정및분류'!$C$6:$C$12,WEEKDAY(A27,2))*'요약'!$B$13 | H27: ='계좌별시나리오'!I27 | I27: ='계좌별시나리오'!J27 | J27: ='계좌별시나리오'!K27 | K27: ='계좌별시나리오'!L27 | L27: =SUMIFS('경영보고'!$E$114:$E$135,'경영보고'!$A$114:$A$135,$A27,'경영보고'!$C$114:$C$135,"확정입금") | M27: =SUMIFS('경영보고'!$E$16:$E$109,'경영보고'!$A$16:$A$109,$A27,'경영보고'!$I$16:$I$109,"<>보류",'경영보고'!$F$16:$F$109,"계좌송금") | N27: =SUMIFS('경영보고'!$E$16:$E$109,'경영보고'!$A$16:$A$109,$A27,'경영보고'!$I$16:$I$109,"<>보류",'경영보고'!$F$16:$F$109,"법인카드") | O27: =SUMIFS('경영보고'!$E$16:$E$109,'경영보고'!$A$16:$A$109,$A27,'경영보고'!$I$16:$I$109,"<>보류")-M27-N27 | P27: =G27+L27-M27-N27-O27 | Q27: =R26 | R27: =Q27+P27
A28: 46313 | B28: 일 | C28: ='계좌별시나리오'!D28 | D28: ='계좌별시나리오'!E28 | E28: ='계좌별시나리오'!F28 | F28: ='계좌별시나리오'!G28 | G28: =INDEX('설정및분류'!$C$6:$C$12,WEEKDAY(A28,2))*'요약'!$B$13 | H28: ='계좌별시나리오'!I28 | I28: ='계좌별시나리오'!J28 | J28: ='계좌별시나리오'!K28 | K28: ='계좌별시나리오'!L28 | L28: =SUMIFS('경영보고'!$E$114:$E$135,'경영보고'!$A$114:$A$135,$A28,'경영보고'!$C$114:$C$135,"확정입금") | M28: =SUMIFS('경영보고'!$E$16:$E$109,'경영보고'!$A$16:$A$109,$A28,'경영보고'!$I$16:$I$109,"<>보류",'경영보고'!$F$16:$F$109,"계좌송금") | N28: =SUMIFS('경영보고'!$E$16:$E$109,'경영보고'!$A$16:$A$109,$A28,'경영보고'!$I$16:$I$109,"<>보류",'경영보고'!$F$16:$F$109,"법인카드") | O28: =SUMIFS('경영보고'!$E$16:$E$109,'경영보고'!$A$16:$A$109,$A28,'경영보고'!$I$16:$I$109,"<>보류")-M28-N28 | P28: =G28+L28-M28-N28-O28 | Q28: =R27 | R28: =Q28+P28
A29: 46314 | B29: 월 | C29: ='계좌별시나리오'!D29 | D29: ='계좌별시나리오'!E29 | E29: ='계좌별시나리오'!F29 | F29: ='계좌별시나리오'!G29 | G29: =INDEX('설정및분류'!$C$6:$C$12,WEEKDAY(A29,2))*'요약'!$B$13 | H29: ='계좌별시나리오'!I29 | I29: ='계좌별시나리오'!J29 | J29: ='계좌별시나리오'!K29 | K29: ='계좌별시나리오'!L29 | L29: =SUMIFS('경영보고'!$E$114:$E$135,'경영보고'!$A$114:$A$135,$A29,'경영보고'!$C$114:$C$135,"확정입금") | M29: =SUMIFS('경영보고'!$E$16:$E$109,'경영보고'!$A$16:$A$109,$A29,'경영보고'!$I$16:$I$109,"<>보류",'경영보고'!$F$16:$F$109,"계좌송금") | N29: =SUMIFS('경영보고'!$E$16:$E$109,'경영보고'!$A$16:$A$109,$A29,'경영보고'!$I$16:$I$109,"<>보류",'경영보고'!$F$16:$F$109,"법인카드") | O29: =SUMIFS('경영보고'!$E$16:$E$109,'경영보고'!$A$16:$A$109,$A29,'경영보고'!$I$16:$I$109,"<>보류")-M29-N29 | P29: =G29+L29-M29-N29-O29 | Q29: =R28 | R29: =Q29+P29
A30: 46315 | B30: 화 | C30: ='계좌별시나리오'!D30 | D30: ='계좌별시나리오'!E30 | E30: ='계좌별시나리오'!F30 | F30: ='계좌별시나리오'!G30 | G30: =INDEX('설정및분류'!$C$6:$C$12,WEEKDAY(A30,2))*'요약'!$B$13 | H30: ='계좌별시나리오'!I30 | I30: ='계좌별시나리오'!J30 | J30: ='계좌별시나리오'!K30 | K30: ='계좌별시나리오'!L30 | L30: =SUMIFS('경영보고'!$E$114:$E$135,'경영보고'!$A$114:$A$135,$A30,'경영보고'!$C$114:$C$135,"확정입금") | M30: =SUMIFS('경영보고'!$E$16:$E$109,'경영보고'!$A$16:$A$109,$A30,'경영보고'!$I$16:$I$109,"<>보류",'경영보고'!$F$16:$F$109,"계좌송금") | N30: =SUMIFS('경영보고'!$E$16:$E$109,'경영보고'!$A$16:$A$109,$A30,'경영보고'!$I$16:$I$109,"<>보류",'경영보고'!$F$16:$F$109,"법인카드") | O30: =SUMIFS('경영보고'!$E$16:$E$109,'경영보고'!$A$16:$A$109,$A30,'경영보고'!$I$16:$I$109,"<>보류")-M30-N30 | P30: =G30+L30-M30-N30-O30 | Q30: =R29 | R30: =Q30+P30
A31: 46316 | B31: 수 | C31: ='계좌별시나리오'!D31 | D31: ='계좌별시나리오'!E31 | E31: ='계좌별시나리오'!F31 | F31: ='계좌별시나리오'!G31 | G31: =INDEX('설정및분류'!$C$6:$C$12,WEEKDAY(A31,2))*'요약'!$B$13 | H31: ='계좌별시나리오'!I31 | I31: ='계좌별시나리오'!J31 | J31: ='계좌별시나리오'!K31 | K31: ='계좌별시나리오'!L31 | L31: =SUMIFS('경영보고'!$E$114:$E$135,'경영보고'!$A$114:$A$135,$A31,'경영보고'!$C$114:$C$135,"확정입금") | M31: =SUMIFS('경영보고'!$E$16:$E$109,'경영보고'!$A$16:$A$109,$A31,'경영보고'!$I$16:$I$109,"<>보류",'경영보고'!$F$16:$F$109,"계좌송금") | N31: =SUMIFS('경영보고'!$E$16:$E$109,'경영보고'!$A$16:$A$109,$A31,'경영보고'!$I$16:$I$109,"<>보류",'경영보고'!$F$16:$F$109,"법인카드") | O31: =SUMIFS('경영보고'!$E$16:$E$109,'경영보고'!$A$16:$A$109,$A31,'경영보고'!$I$16:$I$109,"<>보류")-M31-N31 | P31: =G31+L31-M31-N31-O31 | Q31: =R30 | R31: =Q31+P31
A32: 46317 | B32: 목 | C32: ='계좌별시나리오'!D32 | D32: ='계좌별시나리오'!E32 | E32: ='계좌별시나리오'!F32 | F32: ='계좌별시나리오'!G32 | G32: =INDEX('설정및분류'!$C$6:$C$12,WEEKDAY(A32,2))*'요약'!$B$13 | H32: ='계좌별시나리오'!I32 | I32: ='계좌별시나리오'!J32 | J32: ='계좌별시나리오'!K32 | K32: ='계좌별시나리오'!L32 | L32: =SUMIFS('경영보고'!$E$114:$E$135,'경영보고'!$A$114:$A$135,$A32,'경영보고'!$C$114:$C$135,"확정입금") | M32: =SUMIFS('경영보고'!$E$16:$E$109,'경영보고'!$A$16:$A$109,$A32,'경영보고'!$I$16:$I$109,"<>보류",'경영보고'!$F$16:$F$109,"계좌송금") | N32: =SUMIFS('경영보고'!$E$16:$E$109,'경영보고'!$A$16:$A$109,$A32,'경영보고'!$I$16:$I$109,"<>보류",'경영보고'!$F$16:$F$109,"법인카드") | O32: =SUMIFS('경영보고'!$E$16:$E$109,'경영보고'!$A$16:$A$109,$A32,'경영보고'!$I$16:$I$109,"<>보류")-M32-N32 | P32: =G32+L32-M32-N32-O32 | Q32: =R31 | R32: =Q32+P32
A33: 46318 | B33: 금 | C33: ='계좌별시나리오'!D33 | D33: ='계좌별시나리오'!E33 | E33: ='계좌별시나리오'!F33 | F33: ='계좌별시나리오'!G33 | G33: =INDEX('설정및분류'!$C$6:$C$12,WEEKDAY(A33,2))*'요약'!$B$13 | H33: ='계좌별시나리오'!I33 | I33: ='계좌별시나리오'!J33 | J33: ='계좌별시나리오'!K33 | K33: ='계좌별시나리오'!L33 | L33: =SUMIFS('경영보고'!$E$114:$E$135,'경영보고'!$A$114:$A$135,$A33,'경영보고'!$C$114:$C$135,"확정입금") | M33: =SUMIFS('경영보고'!$E$16:$E$109,'경영보고'!$A$16:$A$109,$A33,'경영보고'!$I$16:$I$109,"<>보류",'경영보고'!$F$16:$F$109,"계좌송금") | N33: =SUMIFS('경영보고'!$E$16:$E$109,'경영보고'!$A$16:$A$109,$A33,'경영보고'!$I$16:$I$109,"<>보류",'경영보고'!$F$16:$F$109,"법인카드") | O33: =SUMIFS('경영보고'!$E$16:$E$109,'경영보고'!$A$16:$A$109,$A33,'경영보고'!$I$16:$I$109,"<>보류")-M33-N33 | P33: =G33+L33-M33-N33-O33 | Q33: =R32 | R33: =Q33+P33 | S33: 위버 1,675,000
A34: 46319 | B34: 토 | C34: ='계좌별시나리오'!D34 | D34: ='계좌별시나리오'!E34 | E34: ='계좌별시나리오'!F34 | F34: ='계좌별시나리오'!G34 | G34: =INDEX('설정및분류'!$C$6:$C$12,WEEKDAY(A34,2))*'요약'!$B$13 | H34: ='계좌별시나리오'!I34 | I34: ='계좌별시나리오'!J34 | J34: ='계좌별시나리오'!K34 | K34: ='계좌별시나리오'!L34 | L34: =SUMIFS('경영보고'!$E$114:$E$135,'경영보고'!$A$114:$A$135,$A34,'경영보고'!$C$114:$C$135,"확정입금") | M34: =SUMIFS('경영보고'!$E$16:$E$109,'경영보고'!$A$16:$A$109,$A34,'경영보고'!$I$16:$I$109,"<>보류",'경영보고'!$F$16:$F$109,"계좌송금") | N34: =SUMIFS('경영보고'!$E$16:$E$109,'경영보고'!$A$16:$A$109,$A34,'경영보고'!$I$16:$I$109,"<>보류",'경영보고'!$F$16:$F$109,"법인카드") | O34: =SUMIFS('경영보고'!$E$16:$E$109,'경영보고'!$A$16:$A$109,$A34,'경영보고'!$I$16:$I$109,"<>보류")-M34-N34 | P34: =G34+L34-M34-N34-O34 | Q34: =R33 | R34: =Q34+P34
A35: 46320 | B35: 일 | C35: ='계좌별시나리오'!D35 | D35: ='계좌별시나리오'!E35 | E35: ='계좌별시나리오'!F35 | F35: ='계좌별시나리오'!G35 | G35: =INDEX('설정및분류'!$C$6:$C$12,WEEKDAY(A35,2))*'요약'!$B$13 | H35: ='계좌별시나리오'!I35 | I35: ='계좌별시나리오'!J35 | J35: ='계좌별시나리오'!K35 | K35: ='계좌별시나리오'!L35 | L35: =SUMIFS('경영보고'!$E$114:$E$135,'경영보고'!$A$114:$A$135,$A35,'경영보고'!$C$114:$C$135,"확정입금") | M35: =SUMIFS('경영보고'!$E$16:$E$109,'경영보고'!$A$16:$A$109,$A35,'경영보고'!$I$16:$I$109,"<>보류",'경영보고'!$F$16:$F$109,"계좌송금") | N35: =SUMIFS('경영보고'!$E$16:$E$109,'경영보고'!$A$16:$A$109,$A35,'경영보고'!$I$16:$I$109,"<>보류",'경영보고'!$F$16:$F$109,"법인카드") | O35: =SUMIFS('경영보고'!$E$16:$E$109,'경영보고'!$A$16:$A$109,$A35,'경영보고'!$I$16:$I$109,"<>보류")-M35-N35 | P35: =G35+L35-M35-N35-O35 | Q35: =R34 | R35: =Q35+P35

Sheet 계좌별시나리오
A2: 계좌별 일별 잔액 시나리오 (자동 반영)
A3: 읽는 법: 오늘 총잔액 = 전날 총잔액 + ② 입금 합계 − ③ 지출. 지출은 전액 우리은행에서 집행하고, 모자라면 ④처럼 농협 → 국민 순으로 우리은행에 이체해 채웁니다. '요약' 시트의 입금 반영률(B13)을 바꾸면 이 표도 즉시 다시 계산됩니다. 지난 실적 일자 행은 숨김(마지막 실적일 잔액에서 출발), 실수 방지를 위해 시트 보호(암호 없음). ② 배분 비중(최근 입금 실적): 우리 220351 44% · 농협 569003 2% · 국민 154577 34% · 국민 169124 20%
A4: 일자 | B4: 요일 | C4: ① 잔액 (총잔액 · 계좌별) | H4: ② 오늘 들어오는 돈 — 예상입금 배분 | M4: ③ 지출 | N4: ④ 부족분 이체 | P4: 비고
C5: 총잔액 | D5: 우리 220351 | E5: 농협 569003 | F5: 국민 154577 | G5: 국민 169124 | H5: 합계 | I5: 우리 220351 | J5: 농협 569003 | K5: 국민 154577 | L5: 국민 169124 | M5: 우리은행 집행 | N5: 농협→우리 | O5: 국민→우리
A6: 46298 | B6: 토 | C6: =SUM(D6:G6) | D6: 686315 | E6: 210724 | F6: 40946401 | G6: 30687200 | P6: 전일 마감 실잔고 — 여기서 출발
A7: 46299 | B7: 일 | C7: =SUM(D7:G7) | D7: 686315 | E7: 210724 | F7: 40946401 | G7: 30687200 | P7: 오늘 실잔고(은행 확인) — 참고
A8: 46293 | B8: 월 | P8: 실적 구간
A9: 46294 | B9: 화 | P9: 실적 구간
A10: 46295 | B10: 수 | P10: 실적 구간
A11: 46296 | B11: 목 | P11: 실적 구간
A12: 46297 | B12: 금 | C12: 72530640 | D12: 686315 | E12: 210724 | F12: 40946401 | G12: 30687200 | P12: 실적 구간
A13: 46298 | B13: 토 | C13: =SUM(D13:G13) | D13: =D12+I13-M13+Q13+R13+S13 | E13: =E12+J13-Q13 | F13: =F12+K13-R13 | G13: =G12+L13-S13 | H13: ='4주일별계획'!G13+'4주일별계획'!L13 | I13: =H13*0.440226 | J13: =H13*0.019948 | K13: =H13*0.337410 | L13: =H13*0.202416 | M13: ='4주일별계획'!M13+'4주일별계획'!N13+'4주일별계획'!O13 | N13: =Q13 | O13: =R13+S13 | P13: =IF(D13<-0.5,"전 계좌 소진 — 부족 "&TEXT(-D13,"#,##0")&"원","") | Q13: =MIN(MAX(0,E12+J13),MAX(0,M13-D12-I13)) | R13: =MIN(MAX(0,F12+K13),MAX(0,M13-D12-I13)-Q13) | S13: =MIN(MAX(0,G12+L13),MAX(0,M13-D12-I13)-Q13-R13)
A14: 46299 | B14: 일 | C14: =SUM(D14:G14) | D14: =D13+I14-M14+Q14+R14+S14 | E14: =E13+J14-Q14 | F14: =F13+K14-R14 | G14: =G13+L14-S14 | H14: ='4주일별계획'!G14+'4주일별계획'!L14 | I14: =H14*0.440226 | J14: =H14*0.019948 | K14: =H14*0.337410 | L14: =H14*0.202416 | M14: ='4주일별계획'!M14+'4주일별계획'!N14+'4주일별계획'!O14 | N14: =Q14 | O14: =R14+S14 | P14: =IF(D14<-0.5,"전 계좌 소진 — 부족 "&TEXT(-D14,"#,##0")&"원","") | Q14: =MIN(MAX(0,E13+J14),MAX(0,M14-D13-I14)) | R14: =MIN(MAX(0,F13+K14),MAX(0,M14-D13-I14)-Q14) | S14: =MIN(MAX(0,G13+L14),MAX(0,M14-D13-I14)-Q14-R14)
A15: 46300 | B15: 월 | C15: =SUM(D15:G15) | D15: =D14+I15-M15+Q15+R15+S15 | E15: =E14+J15-Q15 | F15: =F14+K15-R15 | G15: =G14+L15-S15 | H15: ='4주일별계획'!G15+'4주일별계획'!L15 | I15: =H15*0.440226 | J15: =H15*0.019948 | K15: =H15*0.337410 | L15: =H15*0.202416 | M15: ='4주일별계획'!M15+'4주일별계획'!N15+'4주일별계획'!O15 | N15: =Q15 | O15: =R15+S15 | P15: =IF(D15<-0.5,"전 계좌 소진 — 부족 "&TEXT(-D15,"#,##0")&"원","") | Q15: =MIN(MAX(0,E14+J15),MAX(0,M15-D14-I15)) | R15: =MIN(MAX(0,F14+K15),MAX(0,M15-D14-I15)-Q15) | S15: =MIN(MAX(0,G14+L15),MAX(0,M15-D14-I15)-Q15-R15)
A16: 46301 | B16: 화 | C16: =SUM(D16:G16) | D16: =D15+I16-M16+Q16+R16+S16 | E16: =E15+J16-Q16 | F16: =F15+K16-R16 | G16: =G15+L16-S16 | H16: ='4주일별계획'!G16+'4주일별계획'!L16 | I16: =H16*0.440226 | J16: =H16*0.019948 | K16: =H16*0.337410 | L16: =H16*0.202416 | M16: ='4주일별계획'!M16+'4주일별계획'!N16+'4주일별계획'!O16 | N16: =Q16 | O16: =R16+S16 | P16: =IF(D16<-0.5,"전 계좌 소진 — 부족 "&TEXT(-D16,"#,##0")&"원","") | Q16: =MIN(MAX(0,E15+J16),MAX(0,M16-D15-I16)) | R16: =MIN(MAX(0,F15+K16),MAX(0,M16-D15-I16)-Q16) | S16: =MIN(MAX(0,G15+L16),MAX(0,M16-D15-I16)-Q16-R16)
A17: 46302 | B17: 수 | C17: =SUM(D17:G17) | D17: =D16+I17-M17+Q17+R17+S17 | E17: =E16+J17-Q17 | F17: =F16+K17-R17 | G17: =G16+L17-S17 | H17: ='4주일별계획'!G17+'4주일별계획'!L17 | I17: =H17*0.440226 | J17: =H17*0.019948 | K17: =H17*0.337410 | L17: =H17*0.202416 | M17: ='4주일별계획'!M17+'4주일별계획'!N17+'4주일별계획'!O17 | N17: =Q17 | O17: =R17+S17 | P17: =IF(D17<-0.5,"전 계좌 소진 — 부족 "&TEXT(-D17,"#,##0")&"원","") | Q17: =MIN(MAX(0,E16+J17),MAX(0,M17-D16-I17)) | R17: =MIN(MAX(0,F16+K17),MAX(0,M17-D16-I17)-Q17) | S17: =MIN(MAX(0,G16+L17),MAX(0,M17-D16-I17)-Q17-R17)
A18: 46303 | B18: 목 | C18: =SUM(D18:G18) | D18: =D17+I18-M18+Q18+R18+S18 | E18: =E17+J18-Q18 | F18: =F17+K18-R18 | G18: =G17+L18-S18 | H18: ='4주일별계획'!G18+'4주일별계획'!L18 | I18: =H18*0.440226 | J18: =H18*0.019948 | K18: =H18*0.337410 | L18: =H18*0.202416 | M18: ='4주일별계획'!M18+'4주일별계획'!N18+'4주일별계획'!O18 | N18: =Q18 | O18: =R18+S18 | P18: =IF(D18<-0.5,"전 계좌 소진 — 부족 "&TEXT(-D18,"#,##0")&"원","") | Q18: =MIN(MAX(0,E17+J18),MAX(0,M18-D17-I18)) | R18: =MIN(MAX(0,F17+K18),MAX(0,M18-D17-I18)-Q18) | S18: =MIN(MAX(0,G17+L18),MAX(0,M18-D17-I18)-Q18-R18)
A19: 46304 | B19: 금 | C19: =SUM(D19:G19) | D19: =D18+I19-M19+Q19+R19+S19 | E19: =E18+J19-Q19 | F19: =F18+K19-R19 | G19: =G18+L19-S19 | H19: ='4주일별계획'!G19+'4주일별계획'!L19 | I19: =H19*0.440226 | J19: =H19*0.019948 | K19: =H19*0.337410 | L19: =H19*0.202416 | M19: ='4주일별계획'!M19+'4주일별계획'!N19+'4주일별계획'!O19 | N19: =Q19 | O19: =R19+S19 | P19: =IF(D19<-0.5,"전 계좌 소진 — 부족 "&TEXT(-D19,"#,##0")&"원","") | Q19: =MIN(MAX(0,E18+J19),MAX(0,M19-D18-I19)) | R19: =MIN(MAX(0,F18+K19),MAX(0,M19-D18-I19)-Q19) | S19: =MIN(MAX(0,G18+L19),MAX(0,M19-D18-I19)-Q19-R19)
A20: 46305 | B20: 토 | C20: =SUM(D20:G20) | D20: =D19+I20-M20+Q20+R20+S20 | E20: =E19+J20-Q20 | F20: =F19+K20-R20 | G20: =G19+L20-S20 | H20: ='4주일별계획'!G20+'4주일별계획'!L20 | I20: =H20*0.440226 | J20: =H20*0.019948 | K20: =H20*0.337410 | L20: =H20*0.202416 | M20: ='4주일별계획'!M20+'4주일별계획'!N20+'4주일별계획'!O20 | N20: =Q20 | O20: =R20+S20 | P20: =IF(D20<-0.5,"전 계좌 소진 — 부족 "&TEXT(-D20,"#,##0")&"원","") | Q20: =MIN(MAX(0,E19+J20),MAX(0,M20-D19-I20)) | R20: =MIN(MAX(0,F19+K20),MAX(0,M20-D19-I20)-Q20) | S20: =MIN(MAX(0,G19+L20),MAX(0,M20-D19-I20)-Q20-R20)
A21: 46306 | B21: 일 | C21: =SUM(D21:G21) | D21: =D20+I21-M21+Q21+R21+S21 | E21: =E20+J21-Q21 | F21: =F20+K21-R21 | G21: =G20+L21-S21 | H21: ='4주일별계획'!G21+'4주일별계획'!L21 | I21: =H21*0.440226 | J21: =H21*0.019948 | K21: =H21*0.337410 | L21: =H21*0.202416 | M21: ='4주일별계획'!M21+'4주일별계획'!N21+'4주일별계획'!O21 | N21: =Q21 | O21: =R21+S21 | P21: =IF(D21<-0.5,"전 계좌 소진 — 부족 "&TEXT(-D21,"#,##0")&"원","") | Q21: =MIN(MAX(0,E20+J21),MAX(0,M21-D20-I21)) | R21: =MIN(MAX(0,F20+K21),MAX(0,M21-D20-I21)-Q21) | S21: =MIN(MAX(0,G20+L21),MAX(0,M21-D20-I21)-Q21-R21)
A22: 46307 | B22: 월 | C22: =SUM(D22:G22) | D22: =D21+I22-M22+Q22+R22+S22 | E22: =E21+J22-Q22 | F22: =F21+K22-R22 | G22: =G21+L22-S22 | H22: ='4주일별계획'!G22+'4주일별계획'!L22 | I22: =H22*0.440226 | J22: =H22*0.019948 | K22: =H22*0.337410 | L22: =H22*0.202416 | M22: ='4주일별계획'!M22+'4주일별계획'!N22+'4주일별계획'!O22 | N22: =Q22 | O22: =R22+S22 | P22: =IF(D22<-0.5,"전 계좌 소진 — 부족 "&TEXT(-D22,"#,##0")&"원","") | Q22: =MIN(MAX(0,E21+J22),MAX(0,M22-D21-I22)) | R22: =MIN(MAX(0,F21+K22),MAX(0,M22-D21-I22)-Q22) | S22: =MIN(MAX(0,G21+L22),MAX(0,M22-D21-I22)-Q22-R22)
A23: 46308 | B23: 화 | C23: =SUM(D23:G23) | D23: =D22+I23-M23+Q23+R23+S23 | E23: =E22+J23-Q23 | F23: =F22+K23-R23 | G23: =G22+L23-S23 | H23: ='4주일별계획'!G23+'4주일별계획'!L23 | I23: =H23*0.440226 | J23: =H23*0.019948 | K23: =H23*0.337410 | L23: =H23*0.202416 | M23: ='4주일별계획'!M23+'4주일별계획'!N23+'4주일별계획'!O23 | N23: =Q23 | O23: =R23+S23 | P23: =IF(D23<-0.5,"전 계좌 소진 — 부족 "&TEXT(-D23,"#,##0")&"원","") | Q23: =MIN(MAX(0,E22+J23),MAX(0,M23-D22-I23)) | R23: =MIN(MAX(0,F22+K23),MAX(0,M23-D22-I23)-Q23) | S23: =MIN(MAX(0,G22+L23),MAX(0,M23-D22-I23)-Q23-R23)
A24: 46309 | B24: 수 | C24: =SUM(D24:G24) | D24: =D23+I24-M24+Q24+R24+S24 | E24: =E23+J24-Q24 | F24: =F23+K24-R24 | G24: =G23+L24-S24 | H24: ='4주일별계획'!G24+'4주일별계획'!L24 | I24: =H24*0.440226 | J24: =H24*0.019948 | K24: =H24*0.337410 | L24: =H24*0.202416 | M24: ='4주일별계획'!M24+'4주일별계획'!N24+'4주일별계획'!O24 | N24: =Q24 | O24: =R24+S24 | P24: =IF(D24<-0.5,"전 계좌 소진 — 부족 "&TEXT(-D24,"#,##0")&"원","") | Q24: =MIN(MAX(0,E23+J24),MAX(0,M24-D23-I24)) | R24: =MIN(MAX(0,F23+K24),MAX(0,M24-D23-I24)-Q24) | S24: =MIN(MAX(0,G23+L24),MAX(0,M24-D23-I24)-Q24-R24)
... A35: 46320 | B35: 일 | C35: =SUM(D35:G35) | D35: =D34+I35-M35+Q35+R35+S35 | E35: =E34+J35-Q35 | F35: =F34+K35-R35 | G35: =G34+L35-S35 | H35: ='4주일별계획'!G35+'4주일별계획'!L35 | I35: =H35*0.440226 | J35: =H35*0.019948 | K35: =H35*0.337410 | L35: =H35*0.202416 | M35: ='4주일별계획'!M35+'4주일별계획'!N35+'4주일별계획'!O35 | N35: =Q35 | O35: =R35+S35 | P35: =IF(D35<-0.5,"전 계좌 소진 — 부족 "&TEXT(-D35,"#,##0")&"원","") | Q35: =MIN(MAX(0,E34+J35),MAX(0,M35-D34-I35)) | R35: =MIN(MAX(0,F34+K35),MAX(0,M35-D34-I35)-Q35) | S35: =MIN(MAX(0,G34+L35),MAX(0,M35-D34-I35)-Q35-R35)

Sheet 13주주별계획
A2: 향후 13주 주별 자금계획
A3: ="온라인 예상입금 반영률 "&TEXT('요약'!$B$13,"0%")&" 적용. 1~4주는 일별 계획 합계, 5~13주는 자동 예상입금과 입력한 주간 계획을 반영합니다."
A5: 주차 | B5: 기간 | C5: 온라인 예상입금 | D5: 확정·기타입금 | E5: 송금예정 | F5: 카드결제 | G5: 조정·추정 지출 | H5: 추가 주간조정 | I5: 순현금흐름 | J5: 기말잔액 | K5: 상태
A6: 1주차 | B6: 2026-09-28 ~ 2026-10-04 | C6: =SUMIFS('4주일별계획'!$G$8:$G$35,'4주일별계획'!$A$8:$A$35,">="&DATE(2026,9,28),'4주일별계획'!$A$8:$A$35,"<="&DATE(2026,10,4)) | D6: =SUMIFS('4주일별계획'!$L$8:$L$35,'4주일별계획'!$A$8:$A$35,">="&DATE(2026,9,28),'4주일별계획'!$A$8:$A$35,"<="&DATE(2026,10,4)) | E6: =SUMIFS('4주일별계획'!$M$8:$M$35,'4주일별계획'!$A$8:$A$35,">="&DATE(2026,9,28),'4주일별계획'!$A$8:$A$35,"<="&DATE(2026,10,4)) | F6: =SUMIFS('4주일별계획'!$N$8:$N$35,'4주일별계획'!$A$8:$A$35,">="&DATE(2026,9,28),'4주일별계획'!$A$8:$A$35,"<="&DATE(2026,10,4)) | G6: =SUMIFS('4주일별계획'!$O$8:$O$35,'4주일별계획'!$A$8:$A$35,">="&DATE(2026,9,28),'4주일별계획'!$A$8:$A$35,"<="&DATE(2026,10,4)) | I6: =C6+D6-E6-F6-G6+H6 | J6: ='요약'!$B$6+I6 | K6: =IF(J6<0,"자금부족",IF(J6<'요약'!$B$6*0.2,"주의","정상"))
A7: 2주차 | B7: 2026-10-05 ~ 2026-10-11 | C7: =SUMIFS('4주일별계획'!$G$8:$G$35,'4주일별계획'!$A$8:$A$35,">="&DATE(2026,10,5),'4주일별계획'!$A$8:$A$35,"<="&DATE(2026,10,11)) | D7: =SUMIFS('4주일별계획'!$L$8:$L$35,'4주일별계획'!$A$8:$A$35,">="&DATE(2026,10,5),'4주일별계획'!$A$8:$A$35,"<="&DATE(2026,10,11)) | E7: =SUMIFS('4주일별계획'!$M$8:$M$35,'4주일별계획'!$A$8:$A$35,">="&DATE(2026,10,5),'4주일별계획'!$A$8:$A$35,"<="&DATE(2026,10,11)) | F7: =SUMIFS('4주일별계획'!$N$8:$N$35,'4주일별계획'!$A$8:$A$35,">="&DATE(2026,10,5),'4주일별계획'!$A$8:$A$35,"<="&DATE(2026,10,11)) | G7: =SUMIFS('4주일별계획'!$O$8:$O$35,'4주일별계획'!$A$8:$A$35,">="&DATE(2026,10,5),'4주일별계획'!$A$8:$A$35,"<="&DATE(2026,10,11)) | I7: =C7+D7-E7-F7-G7+H7 | J7: =J6+I7 | K7: =IF(J7<0,"자금부족",IF(J7<'요약'!$B$6*0.2,"주의","정상"))
A8: 3주차 | B8: 2026-10-12 ~ 2026-10-18 | C8: =SUMIFS('4주일별계획'!$G$8:$G$35,'4주일별계획'!$A$8:$A$35,">="&DATE(2026,10,12),'4주일별계획'!$A$8:$A$35,"<="&DATE(2026,10,18)) | D8: =SUMIFS('4주일별계획'!$L$8:$L$35,'4주일별계획'!$A$8:$A$35,">="&DATE(2026,10,12),'4주일별계획'!$A$8:$A$35,"<="&DATE(2026,10,18)) | E8: =SUMIFS('4주일별계획'!$M$8:$M$35,'4주일별계획'!$A$8:$A$35,">="&DATE(2026,10,12),'4주일별계획'!$A$8:$A$35,"<="&DATE(2026,10,18)) | F8: =SUMIFS('4주일별계획'!$N$8:$N$35,'4주일별계획'!$A$8:$A$35,">="&DATE(2026,10,12),'4주일별계획'!$A$8:$A$35,"<="&DATE(2026,10,18)) | G8: =SUMIFS('4주일별계획'!$O$8:$O$35,'4주일별계획'!$A$8:$A$35,">="&DATE(2026,10,12),'4주일별계획'!$A$8:$A$35,"<="&DATE(2026,10,18)) | I8: =C8+D8-E8-F8-G8+H8 | J8: =J7+I8 | K8: =IF(J8<0,"자금부족",IF(J8<'요약'!$B$6*0.2,"주의","정상"))
A9: 4주차 | B9: 2026-10-19 ~ 2026-10-25 | C9: =SUMIFS('4주일별계획'!$G$8:$G$35,'4주일별계획'!$A$8:$A$35,">="&DATE(2026,10,19),'4주일별계획'!$A$8:$A$35,"<="&DATE(2026,10,25)) | D9: =SUMIFS('4주일별계획'!$L$8:$L$35,'4주일별계획'!$A$8:$A$35,">="&DATE(2026,10,19),'4주일별계획'!$A$8:$A$35,"<="&DATE(2026,10,25)) | E9: =SUMIFS('4주일별계획'!$M$8:$M$35,'4주일별계획'!$A$8:$A$35,">="&DATE(2026,10,19),'4주일별계획'!$A$8:$A$35,"<="&DATE(2026,10,25)) | F9: =SUMIFS('4주일별계획'!$N$8:$N$35,'4주일별계획'!$A$8:$A$35,">="&DATE(2026,10,19),'4주일별계획'!$A$8:$A$35,"<="&DATE(2026,10,25)) | G9: =SUMIFS('4주일별계획'!$O$8:$O$35,'4주일별계획'!$A$8:$A$35,">="&DATE(2026,10,19),'4주일별계획'!$A$8:$A$35,"<="&DATE(2026,10,25)) | I9: =C9+D9-E9-F9-G9+H9 | J9: =J8+I9 | K9: =IF(J9<0,"자금부족",IF(J9<'요약'!$B$6*0.2,"주의","정상"))
A10: 5주차 | B10: 2026-10-26 ~ 2026-11-01 | C10: =SUM('설정및분류'!$C$6:$C$12)*'요약'!$B$13 | D10: 10021867 | I10: =C10+D10-E10-F10-G10+H10 | J10: =J9+I10 | K10: =IF(J10<0,"자금부족",IF(J10<'요약'!$B$6*0.2,"주의","정상"))
A11: 6주차 | B11: 2026-11-02 ~ 2026-11-08 | C11: =SUM('설정및분류'!$C$6:$C$12)*'요약'!$B$13 | I11: =C11+D11-E11-F11-G11+H11 | J11: =J10+I11 | K11: =IF(J11<0,"자금부족",IF(J11<'요약'!$B$6*0.2,"주의","정상"))
A12: 7주차 | B12: 2026-11-09 ~ 2026-11-15 | C12: =SUM('설정및분류'!$C$6:$C$12)*'요약'!$B$13 | I12: =C12+D12-E12-F12-G12+H12 | J12: =J11+I12 | K12: =IF(J12<0,"자금부족",IF(J12<'요약'!$B$6*0.2,"주의","정상"))
A13: 8주차 | B13: 2026-11-16 ~ 2026-11-22 | C13: =SUM('설정및분류'!$C$6:$C$12)*'요약'!$B$13 | I13: =C13+D13-E13-F13-G13+H13 | J13: =J12+I13 | K13: =IF(J13<0,"자금부족",IF(J13<'요약'!$B$6*0.2,"주의","정상"))
A14: 9주차 | B14: 2026-11-23 ~ 2026-11-29 | C14: =SUM('설정및분류'!$C$6:$C$12)*'요약'!$B$13 | I14: =C14+D14-E14-F14-G14+H14 | J14: =J13+I14 | K14: =IF(J14<0,"자금부족",IF(J14<'요약'!$B$6*0.2,"주의","정상"))
A15: 10주차 | B15: 2026-11-30 ~ 2026-12-06 | C15: =SUM('설정및분류'!$C$6:$C$12)*'요약'!$B$13 | D15: 10021867 | I15: =C15+D15-E15-F15-G15+H15 | J15: =J14+I15 | K15: =IF(J15<0,"자금부족",IF(J15<'요약'!$B$6*0.2,"주의","정상"))
A16: 11주차 | B16: 2026-12-07 ~ 2026-12-13 | C16: =SUM('설정및분류'!$C$6:$C$12)*'요약'!$B$13 | I16: =C16+D16-E16-F16-G16+H16 | J16: =J15+I16 | K16: =IF(J16<0,"자금부족",IF(J16<'요약'!$B$6*0.2,"주의","정상"))
A17: 12주차 | B17: 2026-12-14 ~ 2026-12-20 | C17: =SUM('설정및분류'!$C$6:$C$12)*'요약'!$B$13 | I17: =C17+D17-E17-F17-G17+H17 | J17: =J16+I17 | K17: =IF(J17<0,"자금부족",IF(J17<'요약'!$B$6*0.2,"주의","정상"))
A18: 13주차 | B18: 2026-12-21 ~ 2026-12-27 | C18: =SUM('설정및분류'!$C$6:$C$12)*'요약'!$B$13 | I18: =C18+D18-E18-F18-G18+H18 | J18: =J17+I18 | K18: =IF(J18<0,"자금부족",IF(J18<'요약'!$B$6*0.2,"주의","정상"))

Sheet 지출계획_취합
A2: 팀 지출계획 취합 (자동 반영)
A3: 매 실행마다 팀 제출 파일에서 자동 갱신됩니다. 대외비는 분류·총액만 표시됩니다. 경영보고와 같은 실행일~차주 금요일 기간만 표시합니다 (그 밖의 반영일 행은 숨김 — 행 숨기기 해제로 전체 확인).
A5: 요청ID | B5: 팀명 | C5: 신청자 | D5: 품의승인 | E5: 지급예정일 | F5: 자금계획 반영일 | G5: 거래처 | H5: 지출내용 | I5: 예상금액 | J5: 지급방법 | K5: 카드구분 | L5: 확정여부 | M5: 진행상태 | N5: 최종수정일 | O5: 원본파일 | P5: 반영상태 | Q5: 확인사항
A6: 건강-20261002-001 | B6: 건강사업팀 | C6: 김솔이 | E6: 46301 | F6: 46301 | G6: 비즈콘 | H6: 정기배송 50회차, 60회차 달성8명, 신세계상품권 5만원권 발송 | I6: 400000 | J6: 계좌송금 | L6: 확정 | M6: 신규 | N6: 46297 | O6: 지출계획_2026-10-04.xlsx | P6: 정상반영
A7: 건강-20261002-005 | B7: 건강사업팀 | C7: 전은신 | E7: 46301 | F7: 46301 | G7: 네이버 | H7: 네이버 SA&GFA 광고 비용 | I7: 3366000 | J7: 계좌송금 | L7: 확정 | M7: 신규 | N7: 46297 | O7: 지출계획_2026-10-04.xlsx | P7: 정상반영
A8: 건강-20261002-008 | B8: 건강사업팀 | C8: 양혜원 | E8: 46301 | F8: 46301 | G8: 카카오톡 플러스친구 | H8: 카카오톡 플러스친구 충전 | I8: 1500000 | J8: 계좌송금 | L8: 확정 | M8: 신규 | N8: 46297 | O8: 지출계획_2026-10-04.xlsx | P8: 정상반영
A9: 건강-20261002-009 | B9: 건강사업팀 | C9: 양혜원 | E9: 46301 | F9: 46301 | G9: 네이버 | H9: 네이버 톡톡 | I9: 500000 | J9: 계좌송금 | L9: 확정 | M9: 신규 | N9: 46297 | O9: 지출계획_2026-10-04.xlsx | P9: 정상반영
A10: 건강-20260918-004 | B10: 건강사업팀 | C10: 전은신 | E10: 46302 | F10: 46302 | G10: 인포크비즈니스 | H10: 베리시톨 인플루언서 비용 | I10: 3300000 | J10: 계좌송금 | L10: 확정 | M10: 변경 | N10: 46297 | O10: 지출계획_2026-10-04.xlsx | P10: 정상반영
A11: 건강-20260918-005 | B11: 건강사업팀 | C11: 전은신 | E11: 46302 | F11: 46302 | G11: 써치엠 | H11: 메타 광고 대행 수수 | I11: 1487786 | J11: 계좌송금 | L11: 확정 | M11: 변경 | N11: 46297 | O11: 지출계획_2026-10-04.xlsx | P11: 정상반영
A12: 건강-20261002-002 | B12: 건강사업팀 | C12: 전은신 | E12: 46302 | F12: 46302 | G12: ADN | H12: ADN 광고 송출 비용 | I12: 500000 | J12: 계좌송금 | L12: 확정 | M12: 신규 | N12: 46297 | O12: 지출계획_2026-10-04.xlsx | P12: 정상반영
A13: 건강-20261002-010 | B13: 건강사업팀 | C13: 양혜원 | E13: 46302 | F13: 46302 | G13: 비즈콘 | H13: 9월 프로모션 사은품 지급 | I13: 300000 | J13: 계좌송금 | L13: 확정 | M13: 신규 | N13: 46297 | O13: 지출계획_2026-10-04.xlsx | P13: 정상반영
A14: 경영-20260923-004 | B14: 경영지원팀 | C14: 김수희 | E14: 46302 | F14: 46302 | G14: 서원회계법인 | H14: 기장료 | I14: 385000 | J14: 계좌송금 | L14: 확정 | M14: 변경 | N14: 46297 | O14: 지출계획_2026-10-04.xlsx | P14: 정상반영
A15: CS-20261001-001 | B15: CS팀 | C15: 조민경 | E15: 46303 | F15: 46303 | G15: (주)채널코퍼레이션 | H15: 쁘띠앤 채널톡 예치금 충전 | I15: 198000 | J15: 계좌송금 | L15: 확정 | M15: 신규 | N15: 46296 | O15: 지출계획_2026-10-04.xlsx | P15: 정상반영
A16: 건강-20261002-006 | B16: 건강사업팀 | C16: 전은신 | E16: 46303 | F16: 46303 | G16: 네이버 | H16: 네이버 SA&GFA 광고 비용 | I16: 6424000 | J16: 계좌송금 | L16: 확정 | M16: 신규 | N16: 46297 | O16: 지출계획_2026-10-04.xlsx | P16: 정상반영
A17: 건강-20261002-007 | B17: 건강사업팀 | C17: 전은신 | E17: 46303 | F17: 46303 | G17: 네이버 | H17: 브랜드 검색 광고 | I17: 1980000 | J17: 계좌송금 | L17: 확정 | M17: 신규 | N17: 46297 | O17: 지출계획_2026-10-04.xlsx | P17: 정상반영
A18: 데이터-20261002-001 | B18: 데이터사이언스팀 | C18: 조성윤 | E18: 46303 | F18: 46303 | G18: KICTA | H18: CES 참가 부스 최종 대금 | I18: 9189417 | J18: 계좌송금 | L18: 확정 | M18: 신규 | N18: 46297 | O18: 지출계획_2026-10-04.xlsx | P18: 정상반영
A19: 경영-20260922-008 | B19: 경영지원팀 | C19: 장은총 | E19: 46302 | F19: 46318 | G19: 위버 | H19: 워크샵 (1부/2부) 이용료 | I19: 1675000 | J19: 법인카드 | K19: 우리카드 | L19: 확정 | M19: 변경 | N19: 46296 | O19: 지출계획_2026-10-04.xlsx | P19: 정상반영

Sheet 에이팜 지출계획
A2: 에이팜 지출계획 (자동 반영)
A3: 지출계획 비고에 '에이팜'으로 표시한 건은 자금계획(4주·13주)에 반영하지 않고 여기서만 관리합니다. '반영' 표시 건은 자금계획에 포함된 에이팜 관련 참고 항목입니다.
A5: 일자 | B5: 요일 | C5: 출처 | D5: 자금계획 반영 | E5: 팀명 | F5: 거래처 | G5: 지출내용 | H5: 예상금액 | I5: 지급방법 | J5: 비고
A6: 이번 실행에 정리할 에이팜 지출계획이 없습니다.

Sheet 계좌내역통합_RAW
A1: 거래일시 | B1: 거래일 | C1: 은행 | D1: 계좌 | E1: 출금액 | F1: 입금액 | G1: 거래후잔액 | H1: 적요 | I1: 기재내용·상대방 | J1: 취급점 | K1: 자동분류 | L1: 내부이체 | M1: 정기지출후보 | N1: 현금유출입 | O1: 원본파일 | P1: 반영상태
A2: 46271.693 | B2: 46271 | C2: 우리은행 | D2: 우리 220351 | E2: 0 | F2: 25895 | G2: 919723 | H2: 타행건별 | I2: 박신영 | J2: 하나은행(081225) | K2: 기타입금 | L2: N | M2: N | N2: 25895 | O2: 농협계좌_6개월(20260913).xls | P2: 기존내역
A3: 46272.133 | B3: 46272 | C3: 우리은행 | D3: 우리 220351 | E3: 0 | F3: 6637041 | G3: 7556764 | H3: 펌뱅킹 | I3: 스마트스토어정산 | J3: 두산타워기업영업지원팀 | K3: 온라인매출입금 | L3: N | M3: N | N3: 6637041 | O3: 농협계좌_6개월(20260913).xls | P3: 기존내역
A4: 46272.194 | B4: 46272 | C4: 국민은행 | D4: 국민 154577 | E4: 0 | F4: 49863 | G4: 26397326 | H4: 전자금융 | I4: Npay정산 | J4: SC은행 | K4: 온라인매출입금 | L4: N | M4: N | N4: 49863 | O4: 농협계좌_6개월(20260913).xls | P4: 기존내역
A5: 46272.409 | B5: 46272 | C5: 농협 | D5: 농협 569003 | E5: 0 | F5: 159268 | G5: 324618 | H5: PC우리은행 | I5: 현423337508 | J5: 우리 0202905 | K5: 기타입금 | L5: N | M5: N | N5: 159268 | O5: 농협계좌_6개월(20260913).xls | P5: 기존내역
A6: 46272.424 | B6: 46272 | C6: 농협 | D6: 농협 569003 | E6: 0 | F6: 168000 | G6: 492618 | H6: 폰카카오 | I6: 류기련 | J6: 카카오뱅크 0900032 | K6: 기타입금 | L6: N | M6: N | N6: 168000 | O6: 농협계좌_6개월(20260913).xls | P6: 기존내역
A7: 46272.428 | B7: 46272 | C7: 국민은행 | D7: 국민 154577 | E7: 500000 | F7: 0 | G7: 20656926 | H7: 기일출금 | I7: (주)에이팜건강 | J7: 진천역 | K7: 계좌간이체 | L7: Y | M7: N | N7: 0 | O7: 국민은행_계좌 조회 6개월(20260913).xls | P7: 기존내역
A8: 46272.428 | B8: 46272 | C8: 국민은행 | D8: 국민 154577 | E8: 5240400 | F8: 0 | G8: 21156926 | H8: 기일출금 | I8: (주)에이팜건강 | J8: 진천역 | K8: 계좌간이체 | L8: Y | M8: N | N8: 0 | O8: 국민은행_계좌 조회 6개월(20260913).xls | P8: 기존내역
A9: 46272.428 | B9: 46272 | C9: 국민은행 | D9: 국민 169124 | E9: 0 | F9: 500000 | G9: 148764600 | H9: 기일입금 | I9: (주)에이팜건강 | J9: 진천역 | K9: 계좌간이체 | L9: Y | M9: N | N9: 0 | O9: 국민은행_계좌 조회 6개월(20260913).xls | P9: 기존내역
A10: 46272.428 | B10: 46272 | C10: 국민은행 | D10: 국민 169124 | E10: 0 | F10: 5240400 | G10: 148264600 | H10: 기일입금 | I10: (주)에이팜건강 | J10: 진천역 | K10: 계좌간이체 | L10: Y | M10: N | N10: 0 | O10: 국민은행_계좌 조회 6개월(20260913).xls | P10: 기존내역
A11: 46272.46 | B11: 46272 | C11: 국민은행 | D11: 국민 154577 | E11: 0 | F11: 2550320 | G11: 23207246 | H11: 전자금융 | I11: KG이니시스 | J11: 하나은행 | K11: 온라인매출입금 | L11: N | M11: N | N11: 2550320 | O11: 우리은행 거래내역조회 20260913.xlsx | P11: 기존내역
A12: 46272.472 | B12: 46272 | C12: 국민은행 | D12: 국민 154577 | E12: 0 | F12: 51404 | G12: 23258650 | H12: 전자금융 | I12: KG이니시스 | J12: 하나은행 | K12: 온라인매출입금 | L12: N | M12: N | N12: 51404 | O12: 우리은행 거래내역조회 20260913.xlsx | P12: 기존내역
A13: 46272.647 | B13: 46272 | C13: 국민은행 | D13: 국민 154577 | E13: 0 | F13: 128071 | G13: 23386721 | H13: 전자금융 | I13: 엔에이치엔페이 | J13: 신한은행 | K13: 온라인매출입금 | L13: N | M13: N | N13: 128071 | O13: 우리은행 거래내역조회 20260913.xlsx | P13: 기존내역
... A72: 46276.108 | B72: 46276 | C72: 우리은행 | D72: 우리 220351 | E72: 0 | F72: 5937777 | G72: 9358002 | H72: 펌뱅킹 | I72: 스마트스토어정산 | J72: 두산타워기업영업지원팀 | K72: 온라인매출입금 | L72: N | M72: N | N72: 5937777 | O72: 농협계좌_6개월(20260913).xls | P72: 기존내역
A73: 46276.418 | B73: 46276 | C73: 국민은행 | D73: 국민 154577 | E73: 1227818 | F73: 0 | G73: 16718934 | H73: TOP출금 | J73: 진천역 | K73: 확인필요 | L73: N | M73: Y | N73: -1227818 | O73: 우리은행 거래내역조회 20260913.xlsx | P73: 기존내역
A74: 46276.424 | B74: 46276 | C74: 국민은행 | D74: 국민 154577 | E74: 550356 | F74: 0 | G74: 16168578 | H74: 기일출금 | I74: 59601604151338 | J74: 진천역 | K74: 기타지출 | L74: N | M74: N | N74: -550356 | O74: 우리은행 거래내역조회 20260913.xlsx | P74: 기존내역
A75: 46276.426 | B75: 46276 | C75: 농협 | D75: 농협 569003 | E75: 0 | F75: 45310 | G75: 45310 | H75: KB카드 | I75: KB103013814 | J75: 농협 000998 | K75: 기타입금 | L75: N | M75: N | N75: 45310 | O75: 농협계좌_6개월(20260913).xls | P75: 기존내역
A76: 46276.46 | B76: 46276 | C76: 국민은행 | D76: 국민 154577 | E76: 0 | F76: 184067 | G76: 16352645 | H76: 전자금융 | I76: KG이니시스 | J76: 하나은행 | K76: 온라인매출입금 | L76: N | M76: N | N76: 184067 | O76: 국민은행_계좌 조회 6개월(20260913).xls | P76: 기존내역
A77: 46276.466 | B77: 46276 | C77: 국민은행 | D77: 국민 154577 | E77: 0 | F77: 1053497 | G77: 17406142 | H77: 전자금융 | I77: KG이니시스 | J77: 하나은행 | K77: 온라인매출입금 | L77: N | M77: N | N77: 1053497 | O77: 국민은행_계좌 조회 6개월(20260913).xls | P77: 기존내역
A78: 46276.735 | B78: 46276 | C78: 우리은행 | D78: 우리 220351 | E78: 600000 | F78: 0 | G78: 8758002 | H78: 전자결제 | J78: 자금부 | K78: 기타지출 | L78: N | M78: Y | N78: -600000 | O78: 국민은행_계좌 조회 6개월(20260913).xls | P78: 기존내역
A79: 46276.74 | B79: 46276 | C79: 우리은행 | D79: 우리 220351 | E79: 3960000 | F79: 0 | G79: 4248002 | H79: 인터넷 | I79: 국민네이버 apha | J79: 성서공단금융센터 | K79: 기타지출 | L79: N | M79: Y | N79: -3960000 | O79: 우리은행 거래내역조회 20260913.xlsx | P79: 기존내역
A80: 46276.74 | B80: 46276 | C80: 우리은행 | D80: 우리 220351 | E80: 550000 | F80: 0 | G80: 8208002 | H80: 인터넷 | I80: 농협(주)레인보우8 | J80: 성서공단금융센터 | K80: 기타지출 | L80: N | M80: Y | N80: -550000 | O80: 우리은행 거래내역조회 20260913.xlsx | P80: 기존내역
A81: 46276.74 | B81: 46276 | C81: 우리은행 | D81: 우리 220351 | E81: 330000 | F81: 0 | G81: 3918002 | H81: 인터넷 | I81: 국민네이버 에이팜건 | J81: 성서공단금융센터 | K81: 기타지출 | L81: N | M81: Y | N81: -330000 | O81: 농협계좌_6개월(20260913).xls | P81: 기존내역
A82: 46276.74 | B82: 46276 | C82: 우리은행 | D82: 우리 220351 | E82: 990000 | F82: 0 | G82: 2928002 | H82: 인터넷 | I82: 국민네이버 ddi5 | J82: 성서공단금융센터 | K82: 기타지출 | L82: N | M82: N | N82: -990000 | O82: 국민은행_계좌 조회 6개월(20260913).xls | P82: 기존내역
A83: 46276.74 | B83: 46276 | C83: 우리은행 | D83: 우리 220351 | E83: 434000 | F83: 0 | G83: 1209702 | H83: 인터넷 | I83: 국민비즈월렛_쁘띠앤 | J83: 성서공단금융센터 | K83: 기타지출 | L83: N | M83: Y | N83: -434000 | O83: 국민은행_계좌 조회 6개월(20260913).xls | P83: 기존내역
A84: 46276.74 | B84: 46276 | C84: 우리은행 | D84: 우리 220351 | E84: 1236000 | F84: 0 | G84: 1643702 | H84: 인터넷 | I84: SC임정아 | J84: 성서공단금융센터 | K84: 기타지출 | L84: N | M84: N | N84: -1236000 | O84: 국민은행_계좌 조회 6개월(20260913).xls | P84: 기존내역
A85: 46276.74 | B85: 46276 | C85: 우리은행 | D85: 우리 220351 | E85: 48300 | F85: 0 | G85: 2879702 | H85: 인터넷 | I85: 국민김사랑 | J85: 성서공단금융센터 | K85: 기타지출 | L85: N | M85: N | N85: -48300 | O85: 국민은행_계좌 조회 6개월(20260913).xls | P85: 기존내역
A86: 46276.965 | B86: 46276 | C86: 국민은행 | D86: 국민 154577 | E86: 0 | F86: 51500 | G86: 17457642 | H86: 전자금융 | I86: 김금란 | J86: 카뱅 | K86: 기타입금 | L86: N | M86: N | N86: 51500 | O86: 국민은행_계좌 조회 6개월(20260913).xls | P86: 기존내역
A87: 46277.558 | B87: 46277 | C87: 우리은행 | D87: 우리 220351 | E87: 0 | F87: 55335 | G87: 1265037 | H87: 타행건별 | I87: 정지민 | J87: 하나은행(081225) | K87: 기타입금 | L87: N | M87: N | N87: 55335 | O87: 우리은행 거래내역조회 20260913.xlsx | P87: 기존내역
A88: 46278.892 | B88: 46278 | C88: 국민은행 | D88: 국민 154577 | E88: 0 | F88: 77430 | G88: 17535072 | H88: 전자금융 | I88: 양효진 | J88: 토스뱅크 | K88: 기타입금 | L88: N | M88: N | N88: 77430 | O88: 국민은행_계좌 조회 6개월(20260913).xls | P88: 기존내역
A89: 46279.09 | B89: 46279 | C89: 국민은행 | D89: 국민 154577 | E89: 0 | F89: 101554 | G89: 17636626 | H89: 전자금융 | I89: Npay정산 | J89: SC은행 | K89: 온라인매출입금 | L89: N | M89: N | N89: 101554 | O89: 우리은행 거래내역조회 20260913.xlsx | P89: 기존내역
A90: 46279.127 | B90: 46279 | C90: 우리은행 | D90: 우리 220351 | E90: 0 | F90: 6026309 | G90: 7291346 | H90: 펌뱅킹 | I90: 스마트스토어정산 | J90: 두산타워기업영업지원팀 | K90: 온라인매출입금 | L90: N | M90: N | N90: 6026309 | O90: 우리은행 거래내역조회 20260913.xlsx | P90: 기존내역
... A196: 46287.698 | B196: 46287 | C196: 우리은행 | D196: 우리 220351 | E196: 350000 | F196: 0 | G196: 9421750 | H196: 인터넷 | I196: 아이임대규 | J196: 성서공단금융센터 | K196: 기타지출 | L196: N | M196: Y | N196: -350000 | O196: 국민은행_계좌 조회 6개월(20260913).xls | P196: 기존내역
A197: 46287.709 | B197: 46287 | C197: 국민은행 | D197: 국민 154577 | E197: 7800000 | F197: 0 | G197: 36085938 | H197: TOP출금 | J197: 진천역 | K197: 확인필요 | L197: N | M197: Y | N197: -7800000 | O197: 국민은행_계좌 조회 6개월(20260913).xls | P197: 기존내역
A198: 46288.103 | B198: 46288 | C198: 우리은행 | D198: 우리 220351 | E198: 0 | F198: 5580156 | G198: 14506389 | H198: 펌뱅킹 | I198: 스마트스토어정산 | J198: 두산타워기업영업지원팀 | K198: 온라인매출입금 | L198: N | M198: N | N198: 5580156 | O198: 국민은행_계좌 조회 6개월(20260913).xls | P198: 기존내역
A199: 46288.135 | B199: 46288 | C199: 우리은행 | D199: 우리 220351 | E199: 14506389 | F199: 0 | G199: 0 | H199: 우리카드 | I199: 우리카드결제대금 | J199: 리테일영업총괄부(카드) | K199: 우리카드 결제 | L199: N | M199: Y | N199: -14506389 | O199: 우리은행 거래내역조회 20260913.xlsx | P199: 기존내역
A200: 46288.142 | B200: 46288 | C200: 국민은행 | D200: 국민 154577 | E200: 0 | F200: 76239 | G200: 36162177 | H200: 전자금융 | I200: Npay정산 | J200: SC은행 | K200: 온라인매출입금 | L200: N | M200: N | N200: 76239 | O200: 우리은행 거래내역조회 20260913.xlsx | P200: 기존내역
A201: 46288.218 | B201: 46288 | C201: 농협 | D201: 농협 569003 | E201: 0 | F201: 39066 | G201: 2266495 | H201: BC카드 | I201: 726168386BC | J201: 농협 000998 | K201: 기타입금 | L201: N | M201: N | N201: 39066 | O201: 우리은행 거래내역조회 20260913.xlsx | P201: 기존내역
A202: 46288.447 | B202: 46288 | C202: 국민은행 | D202: 국민 154577 | E202: 0 | F202: 228129 | G202: 36390306 | H202: 전자금융 | I202: KG이니시스 | J202: 하나은행 | K202: 온라인매출입금 | L202: N | M202: N | N202: 228129 | O202: 국민은행_계좌 조회 6개월(20260913).xls | P202: 기존내역
A203: 46288.45 | B203: 46288 | C203: 국민은행 | D203: 국민 154577 | E203: 0 | F203: 1533549 | G203: 37923855 | H203: 전자금융 | I203: KG이니시스 | J203: 하나은행 | K203: 온라인매출입금 | L203: N | M203: N | N203: 1533549 | O203: 우리은행 거래내역조회 20260913.xlsx | P203: 기존내역
...

Sheet 설정및분류
A2: 예측 설정 및 자동분류 기준
A5: 요일번호 | B5: 요일 | C5: 최근 12주 온라인입금 일평균 | E5: 분류 | F5: 대표 키워드 | H5: 반영률 선택값
A6: 1 | B6: 월 | C6: 12572607 | E6: 온라인매출입금 | F6: 스마트스토어, KG이니시스, Npay, NHN페이, 카드가맹점 | H6: 0.6
A7: 2 | B7: 화 | C7: 24396851 | E7: 계좌간이체 | F7: 에이팜건강 표시(광고·네이버 제외) | H7: 0.7
A8: 3 | B8: 수 | C8: 14769134 | E8: 4대보험 | F8: 우리은행의 사회보험·건강보험 | H8: 0.8
A9: 4 | B9: 목 | C9: 10899812 | E9: 원천세·국세 | F9: 우리은행의 국고·원천세 | H9: 0.9
A10: 5 | B10: 금 | C10: 8365128 | E10: 법인카드결제 | F10: 우리카드결제대금, KB카드출금 | H10: 1
A11: 6 | B11: 토 | C11: 0 | E11: 보험료(기타) | F11: 한화생명, 메트라이프, ABL생명, 미래에셋
A12: 7 | B12: 일 | C12: 0 | E12: 광고선전비 | F12: 네이버, 광고, 비즈월렛, 캐시워크
E13: 급여·인건비(대외비) | F13: 급여, 상여, 퇴직, 국민은행 월말 TOP출금
E14: 대출·이자 | F14: 대출, 이자
E15: 기타입출금 | F15: 위 기준에 해당하지 않는 거래
