Workbook

Sheet 경영보고
A1: 주간 자금 경영보고 — (주)에이팜건강
A2: 기준주 2026-09-21 (월) ~ 2026-09-27 (일) · 작성 2026-09-23 17:56:01 · 실행일~차주 금요일만 표시 (그 밖의 일자 행은 숨김 — 행 숨기기 해제로 열람 가능)
A3: 노란 칸(입금 반영률·목표 최저잔액·지출 지급일·금액)을 고치면 아래 모든 수치가 즉시 다시 계산됩니다. ④ 지출예정에서 실지출과 차이 나는 행(주황)은 확인(I열) 드롭다운으로 확인 표시하세요.
A5: ① 현재 자금 현황
A6: 국민 154577 | C6: 35256466 | D6: 최종 거래일 2026-09-23
A7: 국민 169124 | C7: 100687200 | D7: 최종 거래일 2026-09-15
A8: 농협 569003 | C8: 2311495 | D8: 최종 거래일 2026-09-23
A9: 우리 220351 | C9: 0 | D9: 최종 거래일 2026-09-23
A10: 총잔액 | C10: =SUM(C6:C9)
A12: ② 향후 4주 일별 자금 흐름 (실행일~차주 금요일만 표시 · 계산은 4주 전체) | E12: 입금 반영률 | F12: 0.8
A13: 일자 | B13: 요일 | C13: 입금 | D13: 지출 | E13: 예상잔액 | F13: 상태 | K13: 96418911
A14: 46286 | B14: 월 | C14: 60967810 | D14: 16528386 | E14: =$K$13+C14-D14 | F14: 실적 | J14: 10677756 | K14: 40220000
A15: 46287 | B15: 화 | C15: 35963982 | D15: 28895517 | E15: =E14+C15-D15 | F15: 실적 | J15: 22255001 | K15: 529613
A16: 46288 | B16: 수 | C16: 17829750 | D16: 27501389 | E16: =E15+C16-D16 | F16: 실적 | J16: 14296943 | K16: 84066
A17: 46289 | B17: 목 | C17: =ROUND(J17*$F$12,0)+K17 | D17: =SUMIFS($E$73:$E$166,$A$73:$A$166,A17) | E17: =E16+C17-D17 | F17: =IF(E17<0,"부족","") | J17: 0 | K17: =SUMIFS($E$47:$E$68,$A$47:$A$68,A17,$C$47:$C$68,"확정입금")
A18: 46290 | B18: 금 | C18: =ROUND(J18*$F$12,0)+K18 | D18: =SUMIFS($E$73:$E$166,$A$73:$A$166,A18) | E18: =E17+C18-D18 | F18: =IF(E18<0,"부족","") | J18: 0 | K18: =SUMIFS($E$47:$E$68,$A$47:$A$68,A18,$C$47:$C$68,"확정입금")
A19: 46291 | B19: 토 | C19: =ROUND(J19*$F$12,0)+K19 | D19: =SUMIFS($E$73:$E$166,$A$73:$A$166,A19) | E19: =E18+C19-D19 | F19: =IF(E19<0,"부족","") | J19: 0 | K19: =SUMIFS($E$47:$E$68,$A$47:$A$68,A19,$C$47:$C$68,"확정입금")
A20: 46292 | B20: 일 | C20: =ROUND(J20*$F$12,0)+K20 | D20: =SUMIFS($E$73:$E$166,$A$73:$A$166,A20) | E20: =E19+C20-D20 | F20: =IF(E20<0,"부족","") | J20: 0 | K20: =SUMIFS($E$47:$E$68,$A$47:$A$68,A20,$C$47:$C$68,"확정입금")
A21: 46293 | B21: 월 | C21: =ROUND(J21*$F$12,0)+K21 | D21: =SUMIFS($E$73:$E$166,$A$73:$A$166,A21)+0 | E21: =E20+C21-D21 | F21: =IF(E21<0,"부족","") | J21: 10677756 | K21: =SUMIFS($E$47:$E$68,$A$47:$A$68,A21,$C$47:$C$68,"확정입금")+0
A22: 46294 | B22: 화 | C22: =ROUND(J22*$F$12,0)+K22 | D22: =SUMIFS($E$73:$E$166,$A$73:$A$166,A22) | E22: =E21+C22-D22 | F22: =IF(E22<0,"부족","") | J22: 22255001 | K22: =SUMIFS($E$47:$E$68,$A$47:$A$68,A22,$C$47:$C$68,"확정입금")
A23: 46295 | B23: 수 | C23: =ROUND(J23*$F$12,0)+K23 | D23: =SUMIFS($E$73:$E$166,$A$73:$A$166,A23) | E23: =E22+C23-D23 | F23: =IF(E23<0,"부족","") | J23: 14296943 | K23: =SUMIFS($E$47:$E$68,$A$47:$A$68,A23,$C$47:$C$68,"확정입금")
A24: 46296 | B24: 목 | C24: =ROUND(J24*$F$12,0)+K24 | D24: =SUMIFS($E$73:$E$166,$A$73:$A$166,A24) | E24: =E23+C24-D24 | F24: =IF(E24<0,"부족","") | J24: 13264811 | K24: =SUMIFS($E$47:$E$68,$A$47:$A$68,A24,$C$47:$C$68,"확정입금")
A25: 46297 | B25: 금 | C25: =ROUND(J25*$F$12,0)+K25 | D25: =SUMIFS($E$73:$E$166,$A$73:$A$166,A25) | E25: =E24+C25-D25 | F25: =IF(E25<0,"부족","") | J25: 10320905 | K25: =SUMIFS($E$47:$E$68,$A$47:$A$68,A25,$C$47:$C$68,"확정입금")
A26: 46298 | B26: 토 | C26: =ROUND(J26*$F$12,0)+K26 | D26: =SUMIFS($E$73:$E$166,$A$73:$A$166,A26) | E26: =E25+C26-D26 | F26: =IF(E26<0,"부족","") | J26: 0 | K26: =SUMIFS($E$47:$E$68,$A$47:$A$68,A26,$C$47:$C$68,"확정입금")
A27: 46299 | B27: 일 | C27: =ROUND(J27*$F$12,0)+K27 | D27: =SUMIFS($E$73:$E$166,$A$73:$A$166,A27) | E27: =E26+C27-D27 | F27: =IF(E27<0,"부족","") | J27: 0 | K27: =SUMIFS($E$47:$E$68,$A$47:$A$68,A27,$C$47:$C$68,"확정입금")
A28: 46300 | B28: 월 | C28: =ROUND(J28*$F$12,0)+K28 | D28: =SUMIFS($E$73:$E$166,$A$73:$A$166,A28) | E28: =E27+C28-D28 | F28: =IF(E28<0,"부족","") | J28: 0 | K28: =SUMIFS($E$47:$E$68,$A$47:$A$68,A28,$C$47:$C$68,"확정입금")
A29: 46301 | B29: 화 | C29: =ROUND(J29*$F$12,0)+K29 | D29: =SUMIFS($E$73:$E$166,$A$73:$A$166,A29) | E29: =E28+C29-D29 | F29: =IF(E29<0,"부족","") | J29: 22255001 | K29: =SUMIFS($E$47:$E$68,$A$47:$A$68,A29,$C$47:$C$68,"확정입금")
A30: 46302 | B30: 수 | C30: =ROUND(J30*$F$12,0)+K30 | D30: =SUMIFS($E$73:$E$166,$A$73:$A$166,A30) | E30: =E29+C30-D30 | F30: =IF(E30<0,"부족","") | J30: 14296943 | K30: =SUMIFS($E$47:$E$68,$A$47:$A$68,A30,$C$47:$C$68,"확정입금")
A31: 46303 | B31: 목 | C31: =ROUND(J31*$F$12,0)+K31 | D31: =SUMIFS($E$73:$E$166,$A$73:$A$166,A31) | E31: =E30+C31-D31 | F31: =IF(E31<0,"부족","") | J31: 13264811 | K31: =SUMIFS($E$47:$E$68,$A$47:$A$68,A31,$C$47:$C$68,"확정입금")
A32: 46304 | B32: 금 | C32: =ROUND(J32*$F$12,0)+K32 | D32: =SUMIFS($E$73:$E$166,$A$73:$A$166,A32) | E32: =E31+C32-D32 | F32: =IF(E32<0,"부족","") | J32: 0 | K32: =SUMIFS($E$47:$E$68,$A$47:$A$68,A32,$C$47:$C$68,"확정입금")
A33: 46305 | B33: 토 | C33: =ROUND(J33*$F$12,0)+K33 | D33: =SUMIFS($E$73:$E$166,$A$73:$A$166,A33) | E33: =E32+C33-D33 | F33: =IF(E33<0,"부족","") | J33: 0 | K33: =SUMIFS($E$47:$E$68,$A$47:$A$68,A33,$C$47:$C$68,"확정입금")
... A41: 46313 | B41: 일 | C41: =ROUND(J41*$F$12,0)+K41 | D41: =SUMIFS($E$73:$E$166,$A$73:$A$166,A41) | E41: =E40+C41-D41 | F41: =IF(E41<0,"부족","") | J41: 0 | K41: =SUMIFS($E$47:$E$68,$A$47:$A$68,A41,$C$47:$C$68,"확정입금")
A42: 4주 최저 잔액 | C42: =MIN(E14:E41) | D42: 4주 예상 기말잔액 | E42: =E41
A43: =IF(C42>=0,"향후 4주 부족분 없음 — 계획대로 집행 가능합니다.","향후 4주 최대 부족 "&TEXT(-C42,"#,##0")&"원 — 지출 일정 조정 또는 자금 조치가 필요합니다.")
A45: ③ 반영된 입금예정 (실행일~차주 금요일) — 예상은 반영률(F12) 연동 · 실입금은 은행 확인 값
A46: 입금일 | B46: 요일 | C46: 구분 | D46: 내용 | E46: 예상금액 | F46: 실입금(은행 확인) | G46: 차이
A47: 46288 | B47: 수 | C47: 온라인 예상 | D47: 12주 요일평균 × 반영률 | E47: =ROUND(J16*$F$12,0) | F47: 17745684 | G47: =IF(OR(F47="",E47=""),"",F47-E47)
A48: 46288 | B48: 수 | C48: 기타 실입금 | D48: 계획 외 입금(은행 확인) | F48: 84066 | G48: =IF(OR(F48="",E48=""),"",F48-E48)
A49: 46289 | B49: 목 | C49: 온라인 예상 | D49: 12주 요일평균 × 반영률 | E49: =ROUND(J17*$F$12,0) | G49: =IF(OR(F49="",E49=""),"",F49-E49)
A50: 46290 | B50: 금 | C50: 온라인 예상 | D50: 12주 요일평균 × 반영률 | E50: =ROUND(J18*$F$12,0) | G50: =IF(OR(F50="",E50=""),"",F50-E50)
...

Sheet 대표보고
A1: (주)에이팜건강 주간 자금계획 보고
A2: ="기준일 2026-09-21 · 작성 2026-09-23 17:56:01 · 입금 반영률 "&TEXT('경영보고'!$F$12,"0%")&" (경영보고 시트와 실시간 연동)"
A4: 핵심 요약
A5: 현재 전체 계좌잔액 | C5: ='경영보고'!C10
A6: 4주 예상 기말잔액 | C6: ='경영보고'!E41
A7: 4주 최저 예상잔액 | C7: ='경영보고'!C42 | D7: =TEXT(INDEX('경영보고'!$A$14:$A$41,MATCH('경영보고'!C42,'경영보고'!$E$14:$E$41,0)),"m/d 예상")
A8: 향후 4주 확정지출 | C8: ='경영보고'!E167
A9: 카드 결제 예정액(4주) | C9: =SUMIFS('경영보고'!$E$73:$E$166,'경영보고'!$F$73:$F$166,"법인카드")
A10: 자금부족 예상일 | C10: =IFERROR(TEXT(INDEX('경영보고'!$A$14:$A$41,MATCH(TRUE,INDEX('경영보고'!$E$14:$E$41<0,0),0)),"yyyy-mm-dd"),"없음")
A11: 확인필요 건수 | C11: 47건
A12: 자료 미제출 팀 | C12: 없음
A14: ='경영보고'!A43
A16: 금주 일별 잔액 전망 (월~금) — 반영률·지출 수정과 실시간 연동
A17: 일자 | B17: 요일 | C17: 예상 기말잔액 | D17: 상태
A18: ='경영보고'!A14 | B18: 월 | C18: ='경영보고'!E14 | D18: =IF(C18<0,"부족","")
A19: ='경영보고'!A15 | B19: 화 | C19: ='경영보고'!E15 | D19: =IF(C19<0,"부족","")
A20: ='경영보고'!A16 | B20: 수 | C20: ='경영보고'!E16 | D20: =IF(C20<0,"부족","")
A21: ='경영보고'!A17 | B21: 목 | C21: ='경영보고'!E17 | D21: =IF(C21<0,"부족","")
A22: ='경영보고'!A18 | B22: 금 | C22: ='경영보고'!E18 | D22: =IF(C22<0,"부족","")
A24: 입금 반영률 시나리오 (80·90·100%) — 필요 추가 입금
A25: 반영률 | C25: 4주 기말잔액 | D25: 4주 최저잔액 | E25: 필요 추가 입금
A26: ='경영보고'!A172 | C26: ='경영보고'!C172 | D26: ='경영보고'!D172 | E26: ='경영보고'!F172
A27: ='경영보고'!A173 | C27: ='경영보고'!C173 | D27: ='경영보고'!D173 | E27: ='경영보고'!F173
A28: ='경영보고'!A174 | C28: ='경영보고'!C174 | D28: ='경영보고'!D174 | E28: ='경영보고'!F174
A30: ="· 목표 최저잔액 "&TEXT('경영보고'!$C$170,"#,##0")&"원 기준. 시나리오 값은 실행 시점 계산이며, 반영률·지출 수정은 위 표와 경영보고에 즉시 반영됩니다."
A31: · 대외비 항목은 분류·총액으로만 표시됩니다. 상세 내역은 같은 파일의 경영보고·지출계획_취합 시트를 확인하십시오.

Sheet 요약
A2: (주)에이팜건강 자금계획 기초 현황
A3: 기준일 2026-09-21 | 농협·우리은행·국민은행 계좌 거래내역 통합 (자동 갱신)
A5: 항목 | B5: 금액 | D5: 계좌 | E5: 최종 거래일 | F5: 잔액
A6: 현재 계좌잔액 | B6: 138255161 | D6: 국민 154577 | E6: 46288 | F6: 35256466
A7: 6개월 외부입금 | B7: 3336213775 | D7: 국민 169124 | E7: 46280 | F7: 100687200
A8: 6개월 외부출금 | B8: 3518091204 | D8: 농협 569003 | E8: 46288 | F8: 2311495
A9: 온라인매출 입금 | B9: 2044392296 | D9: 우리 220351 | E9: 46288 | F9: 0
A10: 최근 12주 주평균 온라인입금 | B10: 70815416
A12: 계획 설정 | B12: 값 | D12: 사용 방법
A13: 입금 예측 반영률 | B13: ='경영보고'!$F$12 | D13: 1. 새 계좌파일을 올리면 RAW 통합표에 이어 붙입니다.
A14: 4주 예상 기말잔액 | B14: ='4주일별계획'!R35 | D14: 2. 노란색 칸에 확정 입금·지출계획을 입력합니다.
A15: 4주 최저 예상잔액 | B15: =MIN('4주일별계획'!R8:R35) | D15: ="3. 온라인 입금은 최근 12주 요일별 평균의 "&TEXT($B$13,"0%")&"로 예측합니다."
A16: 13주 예상 기말잔액 | B16: ='13주주별계획'!J18 | D16: 4. 계좌 간 이체는 내부이체로 표시해 입출금 합계에서 제외합니다.
D17: 5. 정기지출분석의 '확인필요' 항목은 성격을 확인 후 확정합니다.

Sheet 업데이트운영
A2: 계좌 거래내역 업데이트 운영 방법
A3: 6개월 자료는 최초 1회만 필요합니다. 이후에는 매주 은행 원본파일을 그대로 업로드하면 됩니다.
A5: 항목 | B5: 권장 운영 기준 | D5: 처리단계 | E5: 자동 처리 내용 | F5: 중복 판정 기준 | G5: 결과 | H5: 사용자 작업
A6: 업로드 주기 | B6: 주 1회. 월요일 오전에 전주 월요일~일요일 거래내역을 내려받습니다. | D6: 1. 파일 인식 | E6: 은행별 머리글과 데이터 시작행 판별 | F6: 은행·계좌 | G6: 은행 형식 통일 | H6: 파일 첨부
A7: 권장 조회기간 | B7: 누락 방지를 위해 최근 14일을 조회해도 됩니다. 중복 거래는 자동으로 제외합니다. | D7: 2. 거래 표준화 | E7: 거래일시·입금·출금·잔액·적요 변환 | F7: 거래일시·입출금액·잔액·적요 | G7: RAW 한 표로 통합 | H7: 없음
A8: 업로드 장소 | B8: 이 대화창에 농협·우리은행·국민은행 원본파일을 첨부합니다. | D8: 3. 중복 제거 | E8: 기존 거래와 신규 거래 비교 | F8: 계좌+일시+금액+잔액+적요 | G8: 겹친 조회기간 제거 | H8: 없음
A9: 권장 파일형식 | B9: 은행에서 내려받은 XLS, XLSX, CSV 원본을 권장합니다. | D9: 4. 자동 분류 | E9: 매출·내부이체·세금·보험·카드 등 분류 | F9: 적요 키워드 | G9: 분류 및 정기지출 표시 | H9: 확인필요만 검토
A10: 지양할 형식 | B10: PDF, 사진, 화면 캡처는 열 구조가 일정하지 않아 자동처리에 불리합니다. | D10: 5. 잔액 갱신 | E10: 계좌별 최종 거래 잔액 반영 | F10: 가장 최근 거래일시 | G10: 전체 가용잔액 갱신 | H10: 없음
A11: 파일명 | B11: 은행이 만들어 준 원래 파일명을 그대로 사용해도 됩니다. | D11: 6. 계획 갱신 | E11: 최근 12주 패턴 및 선택 반영률 적용 | F11: 드롭다운 반영률 | G11: 4주·13주 전망 변경 | H11: 예정 지출만 보완
A12: 업데이트 요청문 | B12: '이번 주 계좌내역 반영해서 자금계획 업데이트해줘'라고 입력합니다.
A13: 직접 입력 | B13: 거래내역은 복사·붙여넣지 않습니다. 향후 확정 입금·지출계획만 노란색 칸에 입력합니다.
A16: 은행 | B16: 현재 기준 원본파일 | C16: 조회 시작 | D16: 조회 종료 | E16: 반영 거래건수 | F16: 상태
A17: 농협 | B17: 농협계좌_6개월(20260913).xls | C17: 46094 | D17: 46278 | E17: 234 | F17: 반영완료
A18: 우리은행 | B18: 우리은행 거래내역조회 20260913.xlsx | C18: 46095 | D18: 46278 | E18: 862 | F18: 반영완료
A19: 국민은행 | B19: 국민은행_계좌 조회 6개월(20260913).xls | C19: 46095 | D19: 46278 | E19: 995 | F19: 반영완료

Sheet 4주일별계획
A2: 향후 4주 일별 자금계획
A3: 온라인 예상입금은 최근 12주 요일별 평균 × 입금 반영률('경영보고' F12 연동)로 계산됩니다. 지급일·금액·확정입금은 '경영보고' 시트의 ③·④ 표에서 고치세요 — 이 표는 자동으로 따라옵니다. | 실잔고(은행 최근 확인): 우리 220351 0(09-23) · 농협 569003 2,311,495(09-23) · 국민 169124 100,687,200(09-15) · 국민 154577 35,256,466(09-23) — 실행일 행은 은행 파일 그대로 실적으로 마감(기말 = 오늘 실잔고)하고, 아직 안 나간 예정(보류 제외)은 익일로 이월합니다. 자금 예산은 익일부터 오늘 실잔고에서 출발합니다(반영률 B13 연동)
C4: 계좌별 예상잔고 | H4: 계좌별 입금 배분(예상)
A5: 일자 | B5: 요일 | C5: 우리 220351 | D5: 농협 569003 | E5: 국민 169124 | F5: 국민 154577 | G5: 온라인 예상입금 | H5: 우리 220351 | I5: 농협 569003 | J5: 국민 169124 | K5: 국민 154577 | L5: 확정·기타입금 | M5: 송금예정 | N5: 카드결제 | O5: 조정·추정 지출 | P5: 순현금흐름 | Q5: 기초잔액 | R5: 기말잔액 | S5: 비고
A6: 46287 | B6: 화 | C6: ='계좌별시나리오'!D6 | D6: ='계좌별시나리오'!E6 | E6: ='계좌별시나리오'!F6 | F6: ='계좌별시나리오'!G6 | R6: ='계좌별시나리오'!C6 | S6: 전일 마감 실잔고 — 여기서 계획 시작
A7: 46288 | B7: 수 | C7: ='계좌별시나리오'!D7 | D7: ='계좌별시나리오'!E7 | E7: ='계좌별시나리오'!F7 | F7: ='계좌별시나리오'!G7 | G7: 17745684 | L7: 84066 | O7: 27501389 | P7: -9671639 | R7: ='요약'!$B$6 | S7: 오늘 실잔고(은행 확인)·실제 입금·출금 — 참고 (이중계산 안 됨)
A8: 46286 | B8: 월 | C8: ='계좌별시나리오'!D8 | D8: ='계좌별시나리오'!E8 | E8: ='계좌별시나리오'!F8 | F8: ='계좌별시나리오'!G8 | G8: 20747810 | H8: ='계좌별시나리오'!I8 | I8: ='계좌별시나리오'!J8 | J8: ='계좌별시나리오'!K8 | K8: ='계좌별시나리오'!L8 | L8: 40220000 | O8: 16528386 | P8: =G8+L8-M8-N8-O8 | Q8: 96418911 | R8: =Q8+P8 | S8: 실적 | 지출: METLIFE09002 4,795,900, METLIFE09002 4,795,900, 국민네이버 ａｐｈａ 2,178,000 외 11건 | 기타입금: 허용 20,000,000, 허용 20,000,000 외 2건
A9: 46287 | B9: 화 | C9: ='계좌별시나리오'!D9 | D9: ='계좌별시나리오'!E9 | E9: ='계좌별시나리오'!F9 | F9: ='계좌별시나리오'!G9 | G9: 35434369 | H9: ='계좌별시나리오'!I9 | I9: ='계좌별시나리오'!J9 | J9: ='계좌별시나리오'!K9 | K9: ='계좌별시나리오'!L9 | L9: 529613 | O9: 28895517 | P9: =G9+L9-M9-N9-O9 | Q9: =R8 | R9: =Q9+P9 | S9: 실적 | 지출: 기업엠에스바이오텍( 20,000,000, TOP출금 7,800,000, 국민비즈월렛_쁘띠앤 495,517 외 2건 | 기타입금: 석계아이엔디(주)( 280,000, 화물택배물 246,613 외 2건
A10: 46288 | B10: 수 | C10: ='계좌별시나리오'!D10 | D10: ='계좌별시나리오'!E10 | E10: ='계좌별시나리오'!F10 | F10: ='계좌별시나리오'!G10 | G10: 17745684 | H10: ='계좌별시나리오'!I10 | I10: ='계좌별시나리오'!J10 | J10: ='계좌별시나리오'!K10 | K10: ='계좌별시나리오'!L10 | L10: 84066 | M10: 5995000 | O10: 21506389 | P10: =G10+L10-M10-N10-O10 | Q10: =R9 | R10: =Q10+P10 | S10: 우리카드 14,506,389, 네이버SA&GFA 8,305,000, 인포크비즈니스 3,300,000, 농협카드 2,266,495, 써치엠 1,487,786, 와이투홀딩스 1,023,110 외 1건; 실적(은행 확인): 입금 17,829,750·출금 27,501,389 / 보류 제외: 인포크비즈니스 3,300,000, 써치엠 1,487,786, 네이버SA&GFA 2,310,000
A11: 46289 | B11: 목 | C11: ='계좌별시나리오'!D11 | D11: ='계좌별시나리오'!E11 | E11: ='계좌별시나리오'!F11 | F11: ='계좌별시나리오'!G11 | G11: 0 | H11: ='계좌별시나리오'!I11 | I11: ='계좌별시나리오'!J11 | J11: ='계좌별시나리오'!K11 | K11: ='계좌별시나리오'!L11 | L11: =SUMIFS('경영보고'!$E$47:$E$68,'경영보고'!$A$47:$A$68,$A11,'경영보고'!$C$47:$C$68,"확정입금") | M11: =SUMIFS('경영보고'!$E$73:$E$166,'경영보고'!$A$73:$A$166,$A11,'경영보고'!$F$73:$F$166,"계좌송금") | N11: =SUMIFS('경영보고'!$E$73:$E$166,'경영보고'!$A$73:$A$166,$A11,'경영보고'!$F$73:$F$166,"법인카드") | O11: =SUMIFS('경영보고'!$E$73:$E$166,'경영보고'!$A$73:$A$166,$A11)-M11-N11 | P11: =G11+L11-M11-N11-O11 | Q11: =R10 | R11: =Q11+P11
A12: 46290 | B12: 금 | C12: ='계좌별시나리오'!D12 | D12: ='계좌별시나리오'!E12 | E12: ='계좌별시나리오'!F12 | F12: ='계좌별시나리오'!G12 | G12: 0 | H12: ='계좌별시나리오'!I12 | I12: ='계좌별시나리오'!J12 | J12: ='계좌별시나리오'!K12 | K12: ='계좌별시나리오'!L12 | L12: =SUMIFS('경영보고'!$E$47:$E$68,'경영보고'!$A$47:$A$68,$A12,'경영보고'!$C$47:$C$68,"확정입금") | M12: =SUMIFS('경영보고'!$E$73:$E$166,'경영보고'!$A$73:$A$166,$A12,'경영보고'!$F$73:$F$166,"계좌송금") | N12: =SUMIFS('경영보고'!$E$73:$E$166,'경영보고'!$A$73:$A$166,$A12,'경영보고'!$F$73:$F$166,"법인카드") | O12: =SUMIFS('경영보고'!$E$73:$E$166,'경영보고'!$A$73:$A$166,$A12)-M12-N12 | P12: =G12+L12-M12-N12-O12 | Q12: =R11 | R12: =Q12+P12
A13: 46291 | B13: 토 | C13: ='계좌별시나리오'!D13 | D13: ='계좌별시나리오'!E13 | E13: ='계좌별시나리오'!F13 | F13: ='계좌별시나리오'!G13 | G13: 0 | H13: ='계좌별시나리오'!I13 | I13: ='계좌별시나리오'!J13 | J13: ='계좌별시나리오'!K13 | K13: ='계좌별시나리오'!L13 | L13: =SUMIFS('경영보고'!$E$47:$E$68,'경영보고'!$A$47:$A$68,$A13,'경영보고'!$C$47:$C$68,"확정입금") | M13: =SUMIFS('경영보고'!$E$73:$E$166,'경영보고'!$A$73:$A$166,$A13,'경영보고'!$F$73:$F$166,"계좌송금") | N13: =SUMIFS('경영보고'!$E$73:$E$166,'경영보고'!$A$73:$A$166,$A13,'경영보고'!$F$73:$F$166,"법인카드") | O13: =SUMIFS('경영보고'!$E$73:$E$166,'경영보고'!$A$73:$A$166,$A13)-M13-N13 | P13: =G13+L13-M13-N13-O13 | Q13: =R12 | R13: =Q13+P13
A14: 46292 | B14: 일 | C14: ='계좌별시나리오'!D14 | D14: ='계좌별시나리오'!E14 | E14: ='계좌별시나리오'!F14 | F14: ='계좌별시나리오'!G14 | G14: =INDEX('설정및분류'!$C$6:$C$12,WEEKDAY(A14,2))*'요약'!$B$13 | H14: ='계좌별시나리오'!I14 | I14: ='계좌별시나리오'!J14 | J14: ='계좌별시나리오'!K14 | K14: ='계좌별시나리오'!L14 | L14: =SUMIFS('경영보고'!$E$47:$E$68,'경영보고'!$A$47:$A$68,$A14,'경영보고'!$C$47:$C$68,"확정입금") | M14: =SUMIFS('경영보고'!$E$73:$E$166,'경영보고'!$A$73:$A$166,$A14,'경영보고'!$F$73:$F$166,"계좌송금") | N14: =SUMIFS('경영보고'!$E$73:$E$166,'경영보고'!$A$73:$A$166,$A14,'경영보고'!$F$73:$F$166,"법인카드") | O14: =SUMIFS('경영보고'!$E$73:$E$166,'경영보고'!$A$73:$A$166,$A14)-M14-N14 | P14: =G14+L14-M14-N14-O14 | Q14: =R13 | R14: =Q14+P14
A15: 46293 | B15: 월 | C15: ='계좌별시나리오'!D15 | D15: ='계좌별시나리오'!E15 | E15: ='계좌별시나리오'!F15 | F15: ='계좌별시나리오'!G15 | G15: =INDEX('설정및분류'!$C$6:$C$12,WEEKDAY(A15,2))*'요약'!$B$13 | H15: ='계좌별시나리오'!I15 | I15: ='계좌별시나리오'!J15 | J15: ='계좌별시나리오'!K15 | K15: ='계좌별시나리오'!L15 | L15: =SUMIFS('경영보고'!$E$47:$E$68,'경영보고'!$A$47:$A$68,$A15,'경영보고'!$C$47:$C$68,"확정입금") | M15: =SUMIFS('경영보고'!$E$73:$E$166,'경영보고'!$A$73:$A$166,$A15,'경영보고'!$F$73:$F$166,"계좌송금") | N15: =SUMIFS('경영보고'!$E$73:$E$166,'경영보고'!$A$73:$A$166,$A15,'경영보고'!$F$73:$F$166,"법인카드") | O15: =SUMIFS('경영보고'!$E$73:$E$166,'경영보고'!$A$73:$A$166,$A15)-M15-N15 | P15: =G15+L15-M15-N15-O15 | Q15: =R14 | R15: =Q15+P15 | S15: 우리카드 10,839,960, 농협카드 4,610,000, 농협카드 4,561,388, 메트라이프 2,497,000, 엘앤에이치컴퍼니 1,650,000, 남경노무법인 275,000 외 1건
A16: 46294 | B16: 화 | C16: ='계좌별시나리오'!D16 | D16: ='계좌별시나리오'!E16 | E16: ='계좌별시나리오'!F16 | F16: ='계좌별시나리오'!G16 | G16: =INDEX('설정및분류'!$C$6:$C$12,WEEKDAY(A16,2))*'요약'!$B$13 | H16: ='계좌별시나리오'!I16 | I16: ='계좌별시나리오'!J16 | J16: ='계좌별시나리오'!K16 | K16: ='계좌별시나리오'!L16 | L16: =SUMIFS('경영보고'!$E$47:$E$68,'경영보고'!$A$47:$A$68,$A16,'경영보고'!$C$47:$C$68,"확정입금") | M16: =SUMIFS('경영보고'!$E$73:$E$166,'경영보고'!$A$73:$A$166,$A16,'경영보고'!$F$73:$F$166,"계좌송금") | N16: =SUMIFS('경영보고'!$E$73:$E$166,'경영보고'!$A$73:$A$166,$A16,'경영보고'!$F$73:$F$166,"법인카드") | O16: =SUMIFS('경영보고'!$E$73:$E$166,'경영보고'!$A$73:$A$166,$A16)-M16-N16 | P16: =G16+L16-M16-N16-O16 | Q16: =R15 | R16: =Q16+P16 | S16: 네이버 500,000, 정상은(이준이서맘) 500,000, 마고성인권연구소 40,000
A17: 46295 | B17: 수 | C17: ='계좌별시나리오'!D17 | D17: ='계좌별시나리오'!E17 | E17: ='계좌별시나리오'!F17 | F17: ='계좌별시나리오'!G17 | G17: =INDEX('설정및분류'!$C$6:$C$12,WEEKDAY(A17,2))*'요약'!$B$13 | H17: ='계좌별시나리오'!I17 | I17: ='계좌별시나리오'!J17 | J17: ='계좌별시나리오'!K17 | K17: ='계좌별시나리오'!L17 | L17: =SUMIFS('경영보고'!$E$47:$E$68,'경영보고'!$A$47:$A$68,$A17,'경영보고'!$C$47:$C$68,"확정입금") | M17: =SUMIFS('경영보고'!$E$73:$E$166,'경영보고'!$A$73:$A$166,$A17,'경영보고'!$F$73:$F$166,"계좌송금") | N17: =SUMIFS('경영보고'!$E$73:$E$166,'경영보고'!$A$73:$A$166,$A17,'경영보고'!$F$73:$F$166,"법인카드") | O17: =SUMIFS('경영보고'!$E$73:$E$166,'경영보고'!$A$73:$A$166,$A17)-M17-N17 | P17: =G17+L17-M17-N17-O17 | Q17: =R16 | R17: =Q17+P17 | S17: 흥덕IT밸리 관리위원회 903,320, (주) 오애드 880,000, 서원회계법인 385,000, 카카오톡 비즈니스 200,000, 특허법인다옴 91,730; 관계사 외상대 입금 추정(주식회사에이팜, 말일)
A18: 46296 | B18: 목 | C18: ='계좌별시나리오'!D18 | D18: ='계좌별시나리오'!E18 | E18: ='계좌별시나리오'!F18 | F18: ='계좌별시나리오'!G18 | G18: =INDEX('설정및분류'!$C$6:$C$12,WEEKDAY(A18,2))*'요약'!$B$13 | H18: ='계좌별시나리오'!I18 | I18: ='계좌별시나리오'!J18 | J18: ='계좌별시나리오'!K18 | K18: ='계좌별시나리오'!L18 | L18: =SUMIFS('경영보고'!$E$47:$E$68,'경영보고'!$A$47:$A$68,$A18,'경영보고'!$C$47:$C$68,"확정입금") | M18: =SUMIFS('경영보고'!$E$73:$E$166,'경영보고'!$A$73:$A$166,$A18,'경영보고'!$F$73:$F$166,"계좌송금") | N18: =SUMIFS('경영보고'!$E$73:$E$166,'경영보고'!$A$73:$A$166,$A18,'경영보고'!$F$73:$F$166,"법인카드") | O18: =SUMIFS('경영보고'!$E$73:$E$166,'경영보고'!$A$73:$A$166,$A18)-M18-N18 | P18: =G18+L18-M18-N18-O18 | Q18: =R17 | R18: =Q18+P18
A19: 46297 | B19: 금 | C19: ='계좌별시나리오'!D19 | D19: ='계좌별시나리오'!E19 | E19: ='계좌별시나리오'!F19 | F19: ='계좌별시나리오'!G19 | G19: =INDEX('설정및분류'!$C$6:$C$12,WEEKDAY(A19,2))*'요약'!$B$13 | H19: ='계좌별시나리오'!I19 | I19: ='계좌별시나리오'!J19 | J19: ='계좌별시나리오'!K19 | K19: ='계좌별시나리오'!L19 | L19: =SUMIFS('경영보고'!$E$47:$E$68,'경영보고'!$A$47:$A$68,$A19,'경영보고'!$C$47:$C$68,"확정입금") | M19: =SUMIFS('경영보고'!$E$73:$E$166,'경영보고'!$A$73:$A$166,$A19,'경영보고'!$F$73:$F$166,"계좌송금") | N19: =SUMIFS('경영보고'!$E$73:$E$166,'경영보고'!$A$73:$A$166,$A19,'경영보고'!$F$73:$F$166,"법인카드") | O19: =SUMIFS('경영보고'!$E$73:$E$166,'경영보고'!$A$73:$A$166,$A19)-M19-N19 | P19: =G19+L19-M19-N19-O19 | Q19: =R18 | R19: =Q19+P19
A20: 46298 | B20: 토 | C20: ='계좌별시나리오'!D20 | D20: ='계좌별시나리오'!E20 | E20: ='계좌별시나리오'!F20 | F20: ='계좌별시나리오'!G20 | G20: 0 | H20: ='계좌별시나리오'!I20 | I20: ='계좌별시나리오'!J20 | J20: ='계좌별시나리오'!K20 | K20: ='계좌별시나리오'!L20 | L20: =SUMIFS('경영보고'!$E$47:$E$68,'경영보고'!$A$47:$A$68,$A20,'경영보고'!$C$47:$C$68,"확정입금") | M20: =SUMIFS('경영보고'!$E$73:$E$166,'경영보고'!$A$73:$A$166,$A20,'경영보고'!$F$73:$F$166,"계좌송금") | N20: =SUMIFS('경영보고'!$E$73:$E$166,'경영보고'!$A$73:$A$166,$A20,'경영보고'!$F$73:$F$166,"법인카드") | O20: =SUMIFS('경영보고'!$E$73:$E$166,'경영보고'!$A$73:$A$166,$A20)-M20-N20 | P20: =G20+L20-M20-N20-O20 | Q20: =R19 | R20: =Q20+P20
A21: 46299 | B21: 일 | C21: ='계좌별시나리오'!D21 | D21: ='계좌별시나리오'!E21 | E21: ='계좌별시나리오'!F21 | F21: ='계좌별시나리오'!G21 | G21: =INDEX('설정및분류'!$C$6:$C$12,WEEKDAY(A21,2))*'요약'!$B$13 | H21: ='계좌별시나리오'!I21 | I21: ='계좌별시나리오'!J21 | J21: ='계좌별시나리오'!K21 | K21: ='계좌별시나리오'!L21 | L21: =SUMIFS('경영보고'!$E$47:$E$68,'경영보고'!$A$47:$A$68,$A21,'경영보고'!$C$47:$C$68,"확정입금") | M21: =SUMIFS('경영보고'!$E$73:$E$166,'경영보고'!$A$73:$A$166,$A21,'경영보고'!$F$73:$F$166,"계좌송금") | N21: =SUMIFS('경영보고'!$E$73:$E$166,'경영보고'!$A$73:$A$166,$A21,'경영보고'!$F$73:$F$166,"법인카드") | O21: =SUMIFS('경영보고'!$E$73:$E$166,'경영보고'!$A$73:$A$166,$A21)-M21-N21 | P21: =G21+L21-M21-N21-O21 | Q21: =R20 | R21: =Q21+P21
A22: 46300 | B22: 월 | C22: ='계좌별시나리오'!D22 | D22: ='계좌별시나리오'!E22 | E22: ='계좌별시나리오'!F22 | F22: ='계좌별시나리오'!G22 | G22: 0 | H22: ='계좌별시나리오'!I22 | I22: ='계좌별시나리오'!J22 | J22: ='계좌별시나리오'!K22 | K22: ='계좌별시나리오'!L22 | L22: =SUMIFS('경영보고'!$E$47:$E$68,'경영보고'!$A$47:$A$68,$A22,'경영보고'!$C$47:$C$68,"확정입금") | M22: =SUMIFS('경영보고'!$E$73:$E$166,'경영보고'!$A$73:$A$166,$A22,'경영보고'!$F$73:$F$166,"계좌송금") | N22: =SUMIFS('경영보고'!$E$73:$E$166,'경영보고'!$A$73:$A$166,$A22,'경영보고'!$F$73:$F$166,"법인카드") | O22: =SUMIFS('경영보고'!$E$73:$E$166,'경영보고'!$A$73:$A$166,$A22)-M22-N22 | P22: =G22+L22-M22-N22-O22 | Q22: =R21 | R22: =Q22+P22
A23: 46301 | B23: 화 | C23: ='계좌별시나리오'!D23 | D23: ='계좌별시나리오'!E23 | E23: ='계좌별시나리오'!F23 | F23: ='계좌별시나리오'!G23 | G23: =INDEX('설정및분류'!$C$6:$C$12,WEEKDAY(A23,2))*'요약'!$B$13 | H23: ='계좌별시나리오'!I23 | I23: ='계좌별시나리오'!J23 | J23: ='계좌별시나리오'!K23 | K23: ='계좌별시나리오'!L23 | L23: =SUMIFS('경영보고'!$E$47:$E$68,'경영보고'!$A$47:$A$68,$A23,'경영보고'!$C$47:$C$68,"확정입금") | M23: =SUMIFS('경영보고'!$E$73:$E$166,'경영보고'!$A$73:$A$166,$A23,'경영보고'!$F$73:$F$166,"계좌송금") | N23: =SUMIFS('경영보고'!$E$73:$E$166,'경영보고'!$A$73:$A$166,$A23,'경영보고'!$F$73:$F$166,"법인카드") | O23: =SUMIFS('경영보고'!$E$73:$E$166,'경영보고'!$A$73:$A$166,$A23)-M23-N23 | P23: =G23+L23-M23-N23-O23 | Q23: =R22 | R23: =Q23+P23
A24: 46302 | B24: 수 | C24: ='계좌별시나리오'!D24 | D24: ='계좌별시나리오'!E24 | E24: ='계좌별시나리오'!F24 | F24: ='계좌별시나리오'!G24 | G24: =INDEX('설정및분류'!$C$6:$C$12,WEEKDAY(A24,2))*'요약'!$B$13 | H24: ='계좌별시나리오'!I24 | I24: ='계좌별시나리오'!J24 | J24: ='계좌별시나리오'!K24 | K24: ='계좌별시나리오'!L24 | L24: =SUMIFS('경영보고'!$E$47:$E$68,'경영보고'!$A$47:$A$68,$A24,'경영보고'!$C$47:$C$68,"확정입금") | M24: =SUMIFS('경영보고'!$E$73:$E$166,'경영보고'!$A$73:$A$166,$A24,'경영보고'!$F$73:$F$166,"계좌송금") | N24: =SUMIFS('경영보고'!$E$73:$E$166,'경영보고'!$A$73:$A$166,$A24,'경영보고'!$F$73:$F$166,"법인카드") | O24: =SUMIFS('경영보고'!$E$73:$E$166,'경영보고'!$A$73:$A$166,$A24)-M24-N24 | P24: =G24+L24-M24-N24-O24 | Q24: =R23 | R24: =Q24+P24
A25: 46303 | B25: 목 | C25: ='계좌별시나리오'!D25 | D25: ='계좌별시나리오'!E25 | E25: ='계좌별시나리오'!F25 | F25: ='계좌별시나리오'!G25 | G25: =INDEX('설정및분류'!$C$6:$C$12,WEEKDAY(A25,2))*'요약'!$B$13 | H25: ='계좌별시나리오'!I25 | I25: ='계좌별시나리오'!J25 | J25: ='계좌별시나리오'!K25 | K25: ='계좌별시나리오'!L25 | L25: =SUMIFS('경영보고'!$E$47:$E$68,'경영보고'!$A$47:$A$68,$A25,'경영보고'!$C$47:$C$68,"확정입금") | M25: =SUMIFS('경영보고'!$E$73:$E$166,'경영보고'!$A$73:$A$166,$A25,'경영보고'!$F$73:$F$166,"계좌송금") | N25: =SUMIFS('경영보고'!$E$73:$E$166,'경영보고'!$A$73:$A$166,$A25,'경영보고'!$F$73:$F$166,"법인카드") | O25: =SUMIFS('경영보고'!$E$73:$E$166,'경영보고'!$A$73:$A$166,$A25)-M25-N25 | P25: =G25+L25-M25-N25-O25 | Q25: =R24 | R25: =Q25+P25
A26: 46304 | B26: 금 | C26: ='계좌별시나리오'!D26 | D26: ='계좌별시나리오'!E26 | E26: ='계좌별시나리오'!F26 | F26: ='계좌별시나리오'!G26 | G26: 0 | H26: ='계좌별시나리오'!I26 | I26: ='계좌별시나리오'!J26 | J26: ='계좌별시나리오'!K26 | K26: ='계좌별시나리오'!L26 | L26: =SUMIFS('경영보고'!$E$47:$E$68,'경영보고'!$A$47:$A$68,$A26,'경영보고'!$C$47:$C$68,"확정입금") | M26: =SUMIFS('경영보고'!$E$73:$E$166,'경영보고'!$A$73:$A$166,$A26,'경영보고'!$F$73:$F$166,"계좌송금") | N26: =SUMIFS('경영보고'!$E$73:$E$166,'경영보고'!$A$73:$A$166,$A26,'경영보고'!$F$73:$F$166,"법인카드") | O26: =SUMIFS('경영보고'!$E$73:$E$166,'경영보고'!$A$73:$A$166,$A26)-M26-N26 | P26: =G26+L26-M26-N26-O26 | Q26: =R25 | R26: =Q26+P26
A27: 46305 | B27: 토 | C27: ='계좌별시나리오'!D27 | D27: ='계좌별시나리오'!E27 | E27: ='계좌별시나리오'!F27 | F27: ='계좌별시나리오'!G27 | G27: =INDEX('설정및분류'!$C$6:$C$12,WEEKDAY(A27,2))*'요약'!$B$13 | H27: ='계좌별시나리오'!I27 | I27: ='계좌별시나리오'!J27 | J27: ='계좌별시나리오'!K27 | K27: ='계좌별시나리오'!L27 | L27: =SUMIFS('경영보고'!$E$47:$E$68,'경영보고'!$A$47:$A$68,$A27,'경영보고'!$C$47:$C$68,"확정입금") | M27: =SUMIFS('경영보고'!$E$73:$E$166,'경영보고'!$A$73:$A$166,$A27,'경영보고'!$F$73:$F$166,"계좌송금") | N27: =SUMIFS('경영보고'!$E$73:$E$166,'경영보고'!$A$73:$A$166,$A27,'경영보고'!$F$73:$F$166,"법인카드") | O27: =SUMIFS('경영보고'!$E$73:$E$166,'경영보고'!$A$73:$A$166,$A27)-M27-N27 | P27: =G27+L27-M27-N27-O27 | Q27: =R26 | R27: =Q27+P27
A28: 46306 | B28: 일 | C28: ='계좌별시나리오'!D28 | D28: ='계좌별시나리오'!E28 | E28: ='계좌별시나리오'!F28 | F28: ='계좌별시나리오'!G28 | G28: =INDEX('설정및분류'!$C$6:$C$12,WEEKDAY(A28,2))*'요약'!$B$13 | H28: ='계좌별시나리오'!I28 | I28: ='계좌별시나리오'!J28 | J28: ='계좌별시나리오'!K28 | K28: ='계좌별시나리오'!L28 | L28: =SUMIFS('경영보고'!$E$47:$E$68,'경영보고'!$A$47:$A$68,$A28,'경영보고'!$C$47:$C$68,"확정입금") | M28: =SUMIFS('경영보고'!$E$73:$E$166,'경영보고'!$A$73:$A$166,$A28,'경영보고'!$F$73:$F$166,"계좌송금") | N28: =SUMIFS('경영보고'!$E$73:$E$166,'경영보고'!$A$73:$A$166,$A28,'경영보고'!$F$73:$F$166,"법인카드") | O28: =SUMIFS('경영보고'!$E$73:$E$166,'경영보고'!$A$73:$A$166,$A28)-M28-N28 | P28: =G28+L28-M28-N28-O28 | Q28: =R27 | R28: =Q28+P28
A29: 46307 | B29: 월 | C29: ='계좌별시나리오'!D29 | D29: ='계좌별시나리오'!E29 | E29: ='계좌별시나리오'!F29 | F29: ='계좌별시나리오'!G29 | G29: =INDEX('설정및분류'!$C$6:$C$12,WEEKDAY(A29,2))*'요약'!$B$13 | H29: ='계좌별시나리오'!I29 | I29: ='계좌별시나리오'!J29 | J29: ='계좌별시나리오'!K29 | K29: ='계좌별시나리오'!L29 | L29: =SUMIFS('경영보고'!$E$47:$E$68,'경영보고'!$A$47:$A$68,$A29,'경영보고'!$C$47:$C$68,"확정입금") | M29: =SUMIFS('경영보고'!$E$73:$E$166,'경영보고'!$A$73:$A$166,$A29,'경영보고'!$F$73:$F$166,"계좌송금") | N29: =SUMIFS('경영보고'!$E$73:$E$166,'경영보고'!$A$73:$A$166,$A29,'경영보고'!$F$73:$F$166,"법인카드") | O29: =SUMIFS('경영보고'!$E$73:$E$166,'경영보고'!$A$73:$A$166,$A29)-M29-N29 | P29: =G29+L29-M29-N29-O29 | Q29: =R28 | R29: =Q29+P29
A30: 46308 | B30: 화 | C30: ='계좌별시나리오'!D30 | D30: ='계좌별시나리오'!E30 | E30: ='계좌별시나리오'!F30 | F30: ='계좌별시나리오'!G30 | G30: =INDEX('설정및분류'!$C$6:$C$12,WEEKDAY(A30,2))*'요약'!$B$13 | H30: ='계좌별시나리오'!I30 | I30: ='계좌별시나리오'!J30 | J30: ='계좌별시나리오'!K30 | K30: ='계좌별시나리오'!L30 | L30: =SUMIFS('경영보고'!$E$47:$E$68,'경영보고'!$A$47:$A$68,$A30,'경영보고'!$C$47:$C$68,"확정입금") | M30: =SUMIFS('경영보고'!$E$73:$E$166,'경영보고'!$A$73:$A$166,$A30,'경영보고'!$F$73:$F$166,"계좌송금") | N30: =SUMIFS('경영보고'!$E$73:$E$166,'경영보고'!$A$73:$A$166,$A30,'경영보고'!$F$73:$F$166,"법인카드") | O30: =SUMIFS('경영보고'!$E$73:$E$166,'경영보고'!$A$73:$A$166,$A30)-M30-N30 | P30: =G30+L30-M30-N30-O30 | Q30: =R29 | R30: =Q30+P30
A31: 46309 | B31: 수 | C31: ='계좌별시나리오'!D31 | D31: ='계좌별시나리오'!E31 | E31: ='계좌별시나리오'!F31 | F31: ='계좌별시나리오'!G31 | G31: =INDEX('설정및분류'!$C$6:$C$12,WEEKDAY(A31,2))*'요약'!$B$13 | H31: ='계좌별시나리오'!I31 | I31: ='계좌별시나리오'!J31 | J31: ='계좌별시나리오'!K31 | K31: ='계좌별시나리오'!L31 | L31: =SUMIFS('경영보고'!$E$47:$E$68,'경영보고'!$A$47:$A$68,$A31,'경영보고'!$C$47:$C$68,"확정입금") | M31: =SUMIFS('경영보고'!$E$73:$E$166,'경영보고'!$A$73:$A$166,$A31,'경영보고'!$F$73:$F$166,"계좌송금") | N31: =SUMIFS('경영보고'!$E$73:$E$166,'경영보고'!$A$73:$A$166,$A31,'경영보고'!$F$73:$F$166,"법인카드") | O31: =SUMIFS('경영보고'!$E$73:$E$166,'경영보고'!$A$73:$A$166,$A31)-M31-N31 | P31: =G31+L31-M31-N31-O31 | Q31: =R30 | R31: =Q31+P31
A32: 46310 | B32: 목 | C32: ='계좌별시나리오'!D32 | D32: ='계좌별시나리오'!E32 | E32: ='계좌별시나리오'!F32 | F32: ='계좌별시나리오'!G32 | G32: =INDEX('설정및분류'!$C$6:$C$12,WEEKDAY(A32,2))*'요약'!$B$13 | H32: ='계좌별시나리오'!I32 | I32: ='계좌별시나리오'!J32 | J32: ='계좌별시나리오'!K32 | K32: ='계좌별시나리오'!L32 | L32: =SUMIFS('경영보고'!$E$47:$E$68,'경영보고'!$A$47:$A$68,$A32,'경영보고'!$C$47:$C$68,"확정입금") | M32: =SUMIFS('경영보고'!$E$73:$E$166,'경영보고'!$A$73:$A$166,$A32,'경영보고'!$F$73:$F$166,"계좌송금") | N32: =SUMIFS('경영보고'!$E$73:$E$166,'경영보고'!$A$73:$A$166,$A32,'경영보고'!$F$73:$F$166,"법인카드") | O32: =SUMIFS('경영보고'!$E$73:$E$166,'경영보고'!$A$73:$A$166,$A32)-M32-N32 | P32: =G32+L32-M32-N32-O32 | Q32: =R31 | R32: =Q32+P32
A33: 46311 | B33: 금 | C33: ='계좌별시나리오'!D33 | D33: ='계좌별시나리오'!E33 | E33: ='계좌별시나리오'!F33 | F33: ='계좌별시나리오'!G33 | G33: =INDEX('설정및분류'!$C$6:$C$12,WEEKDAY(A33,2))*'요약'!$B$13 | H33: ='계좌별시나리오'!I33 | I33: ='계좌별시나리오'!J33 | J33: ='계좌별시나리오'!K33 | K33: ='계좌별시나리오'!L33 | L33: =SUMIFS('경영보고'!$E$47:$E$68,'경영보고'!$A$47:$A$68,$A33,'경영보고'!$C$47:$C$68,"확정입금") | M33: =SUMIFS('경영보고'!$E$73:$E$166,'경영보고'!$A$73:$A$166,$A33,'경영보고'!$F$73:$F$166,"계좌송금") | N33: =SUMIFS('경영보고'!$E$73:$E$166,'경영보고'!$A$73:$A$166,$A33,'경영보고'!$F$73:$F$166,"법인카드") | O33: =SUMIFS('경영보고'!$E$73:$E$166,'경영보고'!$A$73:$A$166,$A33)-M33-N33 | P33: =G33+L33-M33-N33-O33 | Q33: =R32 | R33: =Q33+P33
A34: 46312 | B34: 토 | C34: ='계좌별시나리오'!D34 | D34: ='계좌별시나리오'!E34 | E34: ='계좌별시나리오'!F34 | F34: ='계좌별시나리오'!G34 | G34: =INDEX('설정및분류'!$C$6:$C$12,WEEKDAY(A34,2))*'요약'!$B$13 | H34: ='계좌별시나리오'!I34 | I34: ='계좌별시나리오'!J34 | J34: ='계좌별시나리오'!K34 | K34: ='계좌별시나리오'!L34 | L34: =SUMIFS('경영보고'!$E$47:$E$68,'경영보고'!$A$47:$A$68,$A34,'경영보고'!$C$47:$C$68,"확정입금") | M34: =SUMIFS('경영보고'!$E$73:$E$166,'경영보고'!$A$73:$A$166,$A34,'경영보고'!$F$73:$F$166,"계좌송금") | N34: =SUMIFS('경영보고'!$E$73:$E$166,'경영보고'!$A$73:$A$166,$A34,'경영보고'!$F$73:$F$166,"법인카드") | O34: =SUMIFS('경영보고'!$E$73:$E$166,'경영보고'!$A$73:$A$166,$A34)-M34-N34 | P34: =G34+L34-M34-N34-O34 | Q34: =R33 | R34: =Q34+P34
A35: 46313 | B35: 일 | C35: ='계좌별시나리오'!D35 | D35: ='계좌별시나리오'!E35 | E35: ='계좌별시나리오'!F35 | F35: ='계좌별시나리오'!G35 | G35: =INDEX('설정및분류'!$C$6:$C$12,WEEKDAY(A35,2))*'요약'!$B$13 | H35: ='계좌별시나리오'!I35 | I35: ='계좌별시나리오'!J35 | J35: ='계좌별시나리오'!K35 | K35: ='계좌별시나리오'!L35 | L35: =SUMIFS('경영보고'!$E$47:$E$68,'경영보고'!$A$47:$A$68,$A35,'경영보고'!$C$47:$C$68,"확정입금") | M35: =SUMIFS('경영보고'!$E$73:$E$166,'경영보고'!$A$73:$A$166,$A35,'경영보고'!$F$73:$F$166,"계좌송금") | N35: =SUMIFS('경영보고'!$E$73:$E$166,'경영보고'!$A$73:$A$166,$A35,'경영보고'!$F$73:$F$166,"법인카드") | O35: =SUMIFS('경영보고'!$E$73:$E$166,'경영보고'!$A$73:$A$166,$A35)-M35-N35 | P35: =G35+L35-M35-N35-O35 | Q35: =R34 | R35: =Q35+P35

Sheet 계좌별시나리오
A2: 계좌별 일별 잔액 시나리오 (자동 반영)
A3: 읽는 법: 오늘 총잔액 = 전날 총잔액 + ② 입금 합계 − ③ 지출. 지출은 전액 우리은행에서 집행하고, 모자라면 ④처럼 농협 → 국민 순으로 우리은행에 이체해 채웁니다. '요약' 시트의 입금 반영률(B13)을 바꾸면 이 표도 즉시 다시 계산됩니다. 지난 실적 일자 행은 숨김(마지막 실적일 잔액에서 출발), 실수 방지를 위해 시트 보호(암호 없음). ② 배분 비중(최근 입금 실적): 우리 220351 44% · 농협 569003 2% · 국민 169124 21% · 국민 154577 33%
A4: 일자 | B4: 요일 | C4: ① 잔액 (총잔액 · 계좌별) | H4: ② 오늘 들어오는 돈 — 예상입금 배분 | M4: ③ 지출 | N4: ④ 부족분 이체 | P4: 비고
C5: 총잔액 | D5: 우리 220351 | E5: 농협 569003 | F5: 국민 169124 | G5: 국민 154577 | H5: 합계 | I5: 우리 220351 | J5: 농협 569003 | K5: 국민 169124 | L5: 국민 154577 | M5: 우리은행 집행 | N5: 농협→우리 | O5: 국민→우리
A6: 46287 | B6: 화 | C6: =SUM(D6:G6) | D6: 8926233 | E6: 2227429 | F6: 100687200 | G6: 36085938 | P6: 전일 마감 실잔고 — 여기서 출발
A7: 46288 | B7: 수 | C7: =SUM(D7:G7) | D7: 0 | E7: 2311495 | F7: 100687200 | G7: 35256466 | P7: 오늘 실잔고(은행 확인) — 참고
A8: 46286 | B8: 월 | P8: 실적 구간
A9: 46287 | B9: 화 | C9: 147926800 | D9: 8926233 | E9: 2227429 | F9: 100687200 | G9: 36085938 | P9: 실적 구간
A10: 46288 | B10: 수 | C10: 138255161 | D10: 0 | E10: 2311495 | F10: 100687200 | G10: 35256466 | P10: 실적(은행 확인) — 여기서 예산 출발
A11: 46289 | B11: 목 | C11: =SUM(D11:G11) | D11: =D10+I11-M11+Q11+R11+S11 | E11: =E10+J11-Q11 | F11: =F10+K11-R11 | G11: =G10+L11-S11 | H11: ='4주일별계획'!G11+'4주일별계획'!L11 | I11: =H11*0.437547 | J11: =H11*0.020312 | K11: =H11*0.211322 | L11: =H11*0.330819 | M11: ='4주일별계획'!M11+'4주일별계획'!N11+'4주일별계획'!O11 | N11: =Q11 | O11: =R11+S11 | P11: =IF(D11<-0.5,"전 계좌 소진 — 부족 "&TEXT(-D11,"#,##0")&"원","") | Q11: =MIN(MAX(0,E10+J11),MAX(0,M11-D10-I11)) | R11: =MIN(MAX(0,F10+K11),MAX(0,M11-D10-I11)-Q11) | S11: =MIN(MAX(0,G10+L11),MAX(0,M11-D10-I11)-Q11-R11)
A12: 46290 | B12: 금 | C12: =SUM(D12:G12) | D12: =D11+I12-M12+Q12+R12+S12 | E12: =E11+J12-Q12 | F12: =F11+K12-R12 | G12: =G11+L12-S12 | H12: ='4주일별계획'!G12+'4주일별계획'!L12 | I12: =H12*0.437547 | J12: =H12*0.020312 | K12: =H12*0.211322 | L12: =H12*0.330819 | M12: ='4주일별계획'!M12+'4주일별계획'!N12+'4주일별계획'!O12 | N12: =Q12 | O12: =R12+S12 | P12: =IF(D12<-0.5,"전 계좌 소진 — 부족 "&TEXT(-D12,"#,##0")&"원","") | Q12: =MIN(MAX(0,E11+J12),MAX(0,M12-D11-I12)) | R12: =MIN(MAX(0,F11+K12),MAX(0,M12-D11-I12)-Q12) | S12: =MIN(MAX(0,G11+L12),MAX(0,M12-D11-I12)-Q12-R12)
A13: 46291 | B13: 토 | C13: =SUM(D13:G13) | D13: =D12+I13-M13+Q13+R13+S13 | E13: =E12+J13-Q13 | F13: =F12+K13-R13 | G13: =G12+L13-S13 | H13: ='4주일별계획'!G13+'4주일별계획'!L13 | I13: =H13*0.437547 | J13: =H13*0.020312 | K13: =H13*0.211322 | L13: =H13*0.330819 | M13: ='4주일별계획'!M13+'4주일별계획'!N13+'4주일별계획'!O13 | N13: =Q13 | O13: =R13+S13 | P13: =IF(D13<-0.5,"전 계좌 소진 — 부족 "&TEXT(-D13,"#,##0")&"원","") | Q13: =MIN(MAX(0,E12+J13),MAX(0,M13-D12-I13)) | R13: =MIN(MAX(0,F12+K13),MAX(0,M13-D12-I13)-Q13) | S13: =MIN(MAX(0,G12+L13),MAX(0,M13-D12-I13)-Q13-R13)
A14: 46292 | B14: 일 | C14: =SUM(D14:G14) | D14: =D13+I14-M14+Q14+R14+S14 | E14: =E13+J14-Q14 | F14: =F13+K14-R14 | G14: =G13+L14-S14 | H14: ='4주일별계획'!G14+'4주일별계획'!L14 | I14: =H14*0.437547 | J14: =H14*0.020312 | K14: =H14*0.211322 | L14: =H14*0.330819 | M14: ='4주일별계획'!M14+'4주일별계획'!N14+'4주일별계획'!O14 | N14: =Q14 | O14: =R14+S14 | P14: =IF(D14<-0.5,"전 계좌 소진 — 부족 "&TEXT(-D14,"#,##0")&"원","") | Q14: =MIN(MAX(0,E13+J14),MAX(0,M14-D13-I14)) | R14: =MIN(MAX(0,F13+K14),MAX(0,M14-D13-I14)-Q14) | S14: =MIN(MAX(0,G13+L14),MAX(0,M14-D13-I14)-Q14-R14)
A15: 46293 | B15: 월 | C15: =SUM(D15:G15) | D15: =D14+I15-M15+Q15+R15+S15 | E15: =E14+J15-Q15 | F15: =F14+K15-R15 | G15: =G14+L15-S15 | H15: ='4주일별계획'!G15+'4주일별계획'!L15 | I15: =H15*0.437547 | J15: =H15*0.020312 | K15: =H15*0.211322 | L15: =H15*0.330819 | M15: ='4주일별계획'!M15+'4주일별계획'!N15+'4주일별계획'!O15 | N15: =Q15 | O15: =R15+S15 | P15: =IF(D15<-0.5,"전 계좌 소진 — 부족 "&TEXT(-D15,"#,##0")&"원","") | Q15: =MIN(MAX(0,E14+J15),MAX(0,M15-D14-I15)) | R15: =MIN(MAX(0,F14+K15),MAX(0,M15-D14-I15)-Q15) | S15: =MIN(MAX(0,G14+L15),MAX(0,M15-D14-I15)-Q15-R15)
A16: 46294 | B16: 화 | C16: =SUM(D16:G16) | D16: =D15+I16-M16+Q16+R16+S16 | E16: =E15+J16-Q16 | F16: =F15+K16-R16 | G16: =G15+L16-S16 | H16: ='4주일별계획'!G16+'4주일별계획'!L16 | I16: =H16*0.437547 | J16: =H16*0.020312 | K16: =H16*0.211322 | L16: =H16*0.330819 | M16: ='4주일별계획'!M16+'4주일별계획'!N16+'4주일별계획'!O16 | N16: =Q16 | O16: =R16+S16 | P16: =IF(D16<-0.5,"전 계좌 소진 — 부족 "&TEXT(-D16,"#,##0")&"원","") | Q16: =MIN(MAX(0,E15+J16),MAX(0,M16-D15-I16)) | R16: =MIN(MAX(0,F15+K16),MAX(0,M16-D15-I16)-Q16) | S16: =MIN(MAX(0,G15+L16),MAX(0,M16-D15-I16)-Q16-R16)
A17: 46295 | B17: 수 | C17: =SUM(D17:G17) | D17: =D16+I17-M17+Q17+R17+S17 | E17: =E16+J17-Q17 | F17: =F16+K17-R17 | G17: =G16+L17-S17 | H17: ='4주일별계획'!G17+'4주일별계획'!L17 | I17: =H17*0.437547 | J17: =H17*0.020312 | K17: =H17*0.211322 | L17: =H17*0.330819 | M17: ='4주일별계획'!M17+'4주일별계획'!N17+'4주일별계획'!O17 | N17: =Q17 | O17: =R17+S17 | P17: =IF(D17<-0.5,"전 계좌 소진 — 부족 "&TEXT(-D17,"#,##0")&"원","") | Q17: =MIN(MAX(0,E16+J17),MAX(0,M17-D16-I17)) | R17: =MIN(MAX(0,F16+K17),MAX(0,M17-D16-I17)-Q17) | S17: =MIN(MAX(0,G16+L17),MAX(0,M17-D16-I17)-Q17-R17)
A18: 46296 | B18: 목 | C18: =SUM(D18:G18) | D18: =D17+I18-M18+Q18+R18+S18 | E18: =E17+J18-Q18 | F18: =F17+K18-R18 | G18: =G17+L18-S18 | H18: ='4주일별계획'!G18+'4주일별계획'!L18 | I18: =H18*0.437547 | J18: =H18*0.020312 | K18: =H18*0.211322 | L18: =H18*0.330819 | M18: ='4주일별계획'!M18+'4주일별계획'!N18+'4주일별계획'!O18 | N18: =Q18 | O18: =R18+S18 | P18: =IF(D18<-0.5,"전 계좌 소진 — 부족 "&TEXT(-D18,"#,##0")&"원","") | Q18: =MIN(MAX(0,E17+J18),MAX(0,M18-D17-I18)) | R18: =MIN(MAX(0,F17+K18),MAX(0,M18-D17-I18)-Q18) | S18: =MIN(MAX(0,G17+L18),MAX(0,M18-D17-I18)-Q18-R18)
A19: 46297 | B19: 금 | C19: =SUM(D19:G19) | D19: =D18+I19-M19+Q19+R19+S19 | E19: =E18+J19-Q19 | F19: =F18+K19-R19 | G19: =G18+L19-S19 | H19: ='4주일별계획'!G19+'4주일별계획'!L19 | I19: =H19*0.437547 | J19: =H19*0.020312 | K19: =H19*0.211322 | L19: =H19*0.330819 | M19: ='4주일별계획'!M19+'4주일별계획'!N19+'4주일별계획'!O19 | N19: =Q19 | O19: =R19+S19 | P19: =IF(D19<-0.5,"전 계좌 소진 — 부족 "&TEXT(-D19,"#,##0")&"원","") | Q19: =MIN(MAX(0,E18+J19),MAX(0,M19-D18-I19)) | R19: =MIN(MAX(0,F18+K19),MAX(0,M19-D18-I19)-Q19) | S19: =MIN(MAX(0,G18+L19),MAX(0,M19-D18-I19)-Q19-R19)
A20: 46298 | B20: 토 | C20: =SUM(D20:G20) | D20: =D19+I20-M20+Q20+R20+S20 | E20: =E19+J20-Q20 | F20: =F19+K20-R20 | G20: =G19+L20-S20 | H20: ='4주일별계획'!G20+'4주일별계획'!L20 | I20: =H20*0.437547 | J20: =H20*0.020312 | K20: =H20*0.211322 | L20: =H20*0.330819 | M20: ='4주일별계획'!M20+'4주일별계획'!N20+'4주일별계획'!O20 | N20: =Q20 | O20: =R20+S20 | P20: =IF(D20<-0.5,"전 계좌 소진 — 부족 "&TEXT(-D20,"#,##0")&"원","") | Q20: =MIN(MAX(0,E19+J20),MAX(0,M20-D19-I20)) | R20: =MIN(MAX(0,F19+K20),MAX(0,M20-D19-I20)-Q20) | S20: =MIN(MAX(0,G19+L20),MAX(0,M20-D19-I20)-Q20-R20)
A21: 46299 | B21: 일 | C21: =SUM(D21:G21) | D21: =D20+I21-M21+Q21+R21+S21 | E21: =E20+J21-Q21 | F21: =F20+K21-R21 | G21: =G20+L21-S21 | H21: ='4주일별계획'!G21+'4주일별계획'!L21 | I21: =H21*0.437547 | J21: =H21*0.020312 | K21: =H21*0.211322 | L21: =H21*0.330819 | M21: ='4주일별계획'!M21+'4주일별계획'!N21+'4주일별계획'!O21 | N21: =Q21 | O21: =R21+S21 | P21: =IF(D21<-0.5,"전 계좌 소진 — 부족 "&TEXT(-D21,"#,##0")&"원","") | Q21: =MIN(MAX(0,E20+J21),MAX(0,M21-D20-I21)) | R21: =MIN(MAX(0,F20+K21),MAX(0,M21-D20-I21)-Q21) | S21: =MIN(MAX(0,G20+L21),MAX(0,M21-D20-I21)-Q21-R21)
A22: 46300 | B22: 월 | C22: =SUM(D22:G22) | D22: =D21+I22-M22+Q22+R22+S22 | E22: =E21+J22-Q22 | F22: =F21+K22-R22 | G22: =G21+L22-S22 | H22: ='4주일별계획'!G22+'4주일별계획'!L22 | I22: =H22*0.437547 | J22: =H22*0.020312 | K22: =H22*0.211322 | L22: =H22*0.330819 | M22: ='4주일별계획'!M22+'4주일별계획'!N22+'4주일별계획'!O22 | N22: =Q22 | O22: =R22+S22 | P22: =IF(D22<-0.5,"전 계좌 소진 — 부족 "&TEXT(-D22,"#,##0")&"원","") | Q22: =MIN(MAX(0,E21+J22),MAX(0,M22-D21-I22)) | R22: =MIN(MAX(0,F21+K22),MAX(0,M22-D21-I22)-Q22) | S22: =MIN(MAX(0,G21+L22),MAX(0,M22-D21-I22)-Q22-R22)
... A35: 46313 | B35: 일 | C35: =SUM(D35:G35) | D35: =D34+I35-M35+Q35+R35+S35 | E35: =E34+J35-Q35 | F35: =F34+K35-R35 | G35: =G34+L35-S35 | H35: ='4주일별계획'!G35+'4주일별계획'!L35 | I35: =H35*0.437547 | J35: =H35*0.020312 | K35: =H35*0.211322 | L35: =H35*0.330819 | M35: ='4주일별계획'!M35+'4주일별계획'!N35+'4주일별계획'!O35 | N35: =Q35 | O35: =R35+S35 | P35: =IF(D35<-0.5,"전 계좌 소진 — 부족 "&TEXT(-D35,"#,##0")&"원","") | Q35: =MIN(MAX(0,E34+J35),MAX(0,M35-D34-I35)) | R35: =MIN(MAX(0,F34+K35),MAX(0,M35-D34-I35)-Q35) | S35: =MIN(MAX(0,G34+L35),MAX(0,M35-D34-I35)-Q35-R35)

Sheet 13주주별계획
A2: 향후 13주 주별 자금계획
A3: ="온라인 예상입금 반영률 "&TEXT('요약'!$B$13,"0%")&" 적용. 1~4주는 일별 계획 합계, 5~13주는 자동 예상입금과 입력한 주간 계획을 반영합니다."
A5: 주차 | B5: 기간 | C5: 온라인 예상입금 | D5: 확정·기타입금 | E5: 송금예정 | F5: 카드결제 | G5: 조정·추정 지출 | H5: 추가 주간조정 | I5: 순현금흐름 | J5: 기말잔액 | K5: 상태
A6: 1주차 | B6: 2026-09-21 ~ 2026-09-27 | C6: =SUMIFS('4주일별계획'!$G$8:$G$35,'4주일별계획'!$A$8:$A$35,">="&DATE(2026,9,21),'4주일별계획'!$A$8:$A$35,"<="&DATE(2026,9,27)) | D6: =SUMIFS('4주일별계획'!$L$8:$L$35,'4주일별계획'!$A$8:$A$35,">="&DATE(2026,9,21),'4주일별계획'!$A$8:$A$35,"<="&DATE(2026,9,27)) | E6: =SUMIFS('4주일별계획'!$M$8:$M$35,'4주일별계획'!$A$8:$A$35,">="&DATE(2026,9,21),'4주일별계획'!$A$8:$A$35,"<="&DATE(2026,9,27)) | F6: =SUMIFS('4주일별계획'!$N$8:$N$35,'4주일별계획'!$A$8:$A$35,">="&DATE(2026,9,21),'4주일별계획'!$A$8:$A$35,"<="&DATE(2026,9,27)) | G6: =SUMIFS('4주일별계획'!$O$8:$O$35,'4주일별계획'!$A$8:$A$35,">="&DATE(2026,9,21),'4주일별계획'!$A$8:$A$35,"<="&DATE(2026,9,27)) | I6: =C6+D6-E6-F6-G6+H6 | J6: ='요약'!$B$6+I6 | K6: =IF(J6<0,"자금부족",IF(J6<'요약'!$B$6*0.2,"주의","정상"))
A7: 2주차 | B7: 2026-09-28 ~ 2026-10-04 | C7: =SUMIFS('4주일별계획'!$G$8:$G$35,'4주일별계획'!$A$8:$A$35,">="&DATE(2026,9,28),'4주일별계획'!$A$8:$A$35,"<="&DATE(2026,10,4)) | D7: =SUMIFS('4주일별계획'!$L$8:$L$35,'4주일별계획'!$A$8:$A$35,">="&DATE(2026,9,28),'4주일별계획'!$A$8:$A$35,"<="&DATE(2026,10,4)) | E7: =SUMIFS('4주일별계획'!$M$8:$M$35,'4주일별계획'!$A$8:$A$35,">="&DATE(2026,9,28),'4주일별계획'!$A$8:$A$35,"<="&DATE(2026,10,4)) | F7: =SUMIFS('4주일별계획'!$N$8:$N$35,'4주일별계획'!$A$8:$A$35,">="&DATE(2026,9,28),'4주일별계획'!$A$8:$A$35,"<="&DATE(2026,10,4)) | G7: =SUMIFS('4주일별계획'!$O$8:$O$35,'4주일별계획'!$A$8:$A$35,">="&DATE(2026,9,28),'4주일별계획'!$A$8:$A$35,"<="&DATE(2026,10,4)) | I7: =C7+D7-E7-F7-G7+H7 | J7: =J6+I7 | K7: =IF(J7<0,"자금부족",IF(J7<'요약'!$B$6*0.2,"주의","정상"))
A8: 3주차 | B8: 2026-10-05 ~ 2026-10-11 | C8: =SUMIFS('4주일별계획'!$G$8:$G$35,'4주일별계획'!$A$8:$A$35,">="&DATE(2026,10,5),'4주일별계획'!$A$8:$A$35,"<="&DATE(2026,10,11)) | D8: =SUMIFS('4주일별계획'!$L$8:$L$35,'4주일별계획'!$A$8:$A$35,">="&DATE(2026,10,5),'4주일별계획'!$A$8:$A$35,"<="&DATE(2026,10,11)) | E8: =SUMIFS('4주일별계획'!$M$8:$M$35,'4주일별계획'!$A$8:$A$35,">="&DATE(2026,10,5),'4주일별계획'!$A$8:$A$35,"<="&DATE(2026,10,11)) | F8: =SUMIFS('4주일별계획'!$N$8:$N$35,'4주일별계획'!$A$8:$A$35,">="&DATE(2026,10,5),'4주일별계획'!$A$8:$A$35,"<="&DATE(2026,10,11)) | G8: =SUMIFS('4주일별계획'!$O$8:$O$35,'4주일별계획'!$A$8:$A$35,">="&DATE(2026,10,5),'4주일별계획'!$A$8:$A$35,"<="&DATE(2026,10,11)) | I8: =C8+D8-E8-F8-G8+H8 | J8: =J7+I8 | K8: =IF(J8<0,"자금부족",IF(J8<'요약'!$B$6*0.2,"주의","정상"))
A9: 4주차 | B9: 2026-10-12 ~ 2026-10-18 | C9: =SUMIFS('4주일별계획'!$G$8:$G$35,'4주일별계획'!$A$8:$A$35,">="&DATE(2026,10,12),'4주일별계획'!$A$8:$A$35,"<="&DATE(2026,10,18)) | D9: =SUMIFS('4주일별계획'!$L$8:$L$35,'4주일별계획'!$A$8:$A$35,">="&DATE(2026,10,12),'4주일별계획'!$A$8:$A$35,"<="&DATE(2026,10,18)) | E9: =SUMIFS('4주일별계획'!$M$8:$M$35,'4주일별계획'!$A$8:$A$35,">="&DATE(2026,10,12),'4주일별계획'!$A$8:$A$35,"<="&DATE(2026,10,18)) | F9: =SUMIFS('4주일별계획'!$N$8:$N$35,'4주일별계획'!$A$8:$A$35,">="&DATE(2026,10,12),'4주일별계획'!$A$8:$A$35,"<="&DATE(2026,10,18)) | G9: =SUMIFS('4주일별계획'!$O$8:$O$35,'4주일별계획'!$A$8:$A$35,">="&DATE(2026,10,12),'4주일별계획'!$A$8:$A$35,"<="&DATE(2026,10,18)) | I9: =C9+D9-E9-F9-G9+H9 | J9: =J8+I9 | K9: =IF(J9<0,"자금부족",IF(J9<'요약'!$B$6*0.2,"주의","정상"))
A10: 5주차 | B10: 2026-10-19 ~ 2026-10-25 | C10: =SUM('설정및분류'!$C$6:$C$12)*'요약'!$B$13 | F10: 2975000 | I10: =C10+D10-E10-F10-G10+H10 | J10: =J9+I10 | K10: =IF(J10<0,"자금부족",IF(J10<'요약'!$B$6*0.2,"주의","정상"))
A11: 6주차 | B11: 2026-10-26 ~ 2026-11-01 | C11: =SUM('설정및분류'!$C$6:$C$12)*'요약'!$B$13 | D11: 10021867 | I11: =C11+D11-E11-F11-G11+H11 | J11: =J10+I11 | K11: =IF(J11<0,"자금부족",IF(J11<'요약'!$B$6*0.2,"주의","정상"))
A12: 7주차 | B12: 2026-11-02 ~ 2026-11-08 | C12: =SUM('설정및분류'!$C$6:$C$12)*'요약'!$B$13 | I12: =C12+D12-E12-F12-G12+H12 | J12: =J11+I12 | K12: =IF(J12<0,"자금부족",IF(J12<'요약'!$B$6*0.2,"주의","정상"))
A13: 8주차 | B13: 2026-11-09 ~ 2026-11-15 | C13: =SUM('설정및분류'!$C$6:$C$12)*'요약'!$B$13 | I13: =C13+D13-E13-F13-G13+H13 | J13: =J12+I13 | K13: =IF(J13<0,"자금부족",IF(J13<'요약'!$B$6*0.2,"주의","정상"))
A14: 9주차 | B14: 2026-11-16 ~ 2026-11-22 | C14: =SUM('설정및분류'!$C$6:$C$12)*'요약'!$B$13 | I14: =C14+D14-E14-F14-G14+H14 | J14: =J13+I14 | K14: =IF(J14<0,"자금부족",IF(J14<'요약'!$B$6*0.2,"주의","정상"))
A15: 10주차 | B15: 2026-11-23 ~ 2026-11-29 | C15: =SUM('설정및분류'!$C$6:$C$12)*'요약'!$B$13 | I15: =C15+D15-E15-F15-G15+H15 | J15: =J14+I15 | K15: =IF(J15<0,"자금부족",IF(J15<'요약'!$B$6*0.2,"주의","정상"))
A16: 11주차 | B16: 2026-11-30 ~ 2026-12-06 | C16: =SUM('설정및분류'!$C$6:$C$12)*'요약'!$B$13 | D16: 10021867 | I16: =C16+D16-E16-F16-G16+H16 | J16: =J15+I16 | K16: =IF(J16<0,"자금부족",IF(J16<'요약'!$B$6*0.2,"주의","정상"))
A17: 12주차 | B17: 2026-12-07 ~ 2026-12-13 | C17: =SUM('설정및분류'!$C$6:$C$12)*'요약'!$B$13 | I17: =C17+D17-E17-F17-G17+H17 | J17: =J16+I17 | K17: =IF(J17<0,"자금부족",IF(J17<'요약'!$B$6*0.2,"주의","정상"))
A18: 13주차 | B18: 2026-12-14 ~ 2026-12-20 | C18: =SUM('설정및분류'!$C$6:$C$12)*'요약'!$B$13 | I18: =C18+D18-E18-F18-G18+H18 | J18: =J17+I18 | K18: =IF(J18<0,"자금부족",IF(J18<'요약'!$B$6*0.2,"주의","정상"))

Sheet 지출계획_취합
A2: 팀 지출계획 취합 (자동 반영)
A3: 매 실행마다 팀 제출 파일에서 자동 갱신됩니다. 대외비는 분류·총액만 표시됩니다. 경영보고와 같은 실행일~차주 금요일 기간만 표시합니다 (그 밖의 반영일 행은 숨김 — 행 숨기기 해제로 전체 확인).
A5: 요청ID | B5: 팀명 | C5: 신청자 | D5: 품의승인 | E5: 지급예정일 | F5: 자금계획 반영일 | G5: 거래처 | H5: 지출내용 | I5: 예상금액 | J5: 지급방법 | K5: 카드구분 | L5: 확정여부 | M5: 진행상태 | N5: 최종수정일 | O5: 원본파일 | P5: 반영상태 | Q5: 확인사항
A6: 경영-20260918-011 | B6: 경영지원팀 | C6: 송채은 | E6: 46283 | F6: 46283 | G6: 이앤씨이노비즈타워 | H6: 본사관리비 | I6: 1553720 | J6: 계좌송금 | L6: 확정 | M6: 신규 | N6: 46283 | O6: 지출계획_2026-09-23.xlsx | P6: 에이팜 별도관리
A7: 건강-20260918-001 | B7: 건강사업팀 | C7: 양혜원 | E7: 46286 | F7: 46286 | G7: 트라이앵글하모니 | H7: 카카오톡선물하기 베리시톨 리뷰작업 | I7: 1996000 | J7: 계좌송금 | L7: 확정 | M7: 신규 | N7: 46283 | O7: 지출계획_2026-09-23.xlsx | P7: 정상반영
A8: 건강-20260918-003 | B8: 건강사업팀 | C8: 전은신 | E8: 46286 | F8: 46286 | G8: 네이버SA&GFA | H8: 네이버 SA&GFA 광고비 충전 | I8: 3498000 | J8: 계좌송금 | L8: 확정 | M8: 변경 | N8: 46283 | O8: 지출계획_2026-09-23.xlsx | P8: 정상반영
A9: 경영-20260918-005 | B9: 경영지원팀 | C9: 김수희 | E9: 46286 | F9: 46286 | G9: 메트라이프 | H9: 달러경영인정기보험_63회차/55회차 | I9: 4900000 | J9: 자동이체 | L9: 확정 | M9: 변경 | N9: 46283 | O9: 지출계획_2026-09-23.xlsx | P9: 정상반영
A10: 경영-20260918-006 | B10: 경영지원팀 | C10: 김수희 | E10: 46286 | F10: 46286 | G10: SK브로드밴드 | H10: 사내전화 | I10: 220000 | J10: 자동이체 | L10: 확정 | M10: 신규 | N10: 46283 | O10: 지출계획_2026-09-23.xlsx | P10: 정상반영
A11: 건강-20260918-002 | B11: 건강사업팀 | C11: 양혜원 | E11: 46287 | F11: 46287 | G11: 네이버 | H11: 네이버 톡톡 발송 | I11: 500000 | J11: 계좌송금 | L11: 확정 | M11: 신규 | N11: 46283 | O11: 지출계획_2026-09-23.xlsx | P11: 정상반영
A12: 경영-20260918-015 | B12: 경영지원팀 | C12: 김정원 | E12: 46287 | F12: 46287 | G12: 엠에스바이오텍 | H12: 외상매입금 | I12: 20000000 | J12: 계좌송금 | L12: 확정 | M12: 변경 | N12: 46284 | O12: 지출계획_2026-09-23.xlsx | P12: 정상반영
A13: 경영-20260922-001 | B13: 경영지원팀 | C13: 송채은 | E13: 46287 | F13: 46287 | G13: 추석 상여금 | H13: 추석 상여금 | I13: 4600000 | J13: 계좌송금 | L13: 확정 | M13: 변경 | N13: 46287 | O13: 지출계획_2026-09-23.xlsx | P13: 에이팜 별도관리
A14: 경영-20260922-002 | B14: 경영지원팀 | C14: 송채은 | E14: 46287 | F14: 46287 | G14: 추석 상여금 | H14: 추석 상여금 | I14: 7800000 | J14: 계좌송금 | L14: 확정 | M14: 변경 | N14: 46287 | O14: 지출계획_2026-09-23.xlsx | P14: 정상반영
A15: 경영-20260922-003 | B15: 경영지원팀 | C15: 김수희 | E15: 46287 | F15: 46287 | G15: 임대규(대청하이츠) | H15: 기숙사 월세 및 관리비 | I15: 350000 | J15: 계좌송금 | L15: 확정 | M15: 신규 | N15: 46287 | O15: 지출계획_2026-09-23.xlsx | P15: 정상반영
A16: 경영-20260922-004 | B16: 경영지원팀 | C16: 김수희 | E16: 46287 | F16: 46287 | G16: 엠에스바이오텍 | H16: 락토프리미엄 대금 지급 1차 | I16: 20000000 | J16: 계좌송금 | L16: 확정 | M16: 신규 | N16: 46287 | O16: 지출계획_2026-09-23.xlsx | P16: 정상반영
A17: 경영-20260922-005 | B17: 경영지원팀 | C17: 김수희 | E17: 46287 | F17: 46287 | G17: 대구상공회의소 | H17: 26년도 하반기 회비 | I17: 250000 | J17: 계좌송금 | L17: 확정 | M17: 신규 | N17: 46287 | O17: 지출계획_2026-09-23.xlsx | P17: 정상반영
... A45: 연구-20260923-001 | B45: 연구팀 | C45: 이수민 | E45: 46295 | F45: 46295 | G45: 특허법인다옴 | H45: 수출바우처 해외상표출원 | I45: 91730 | J45: 계좌송금 | L45: 확정 | M45: 변경 | N45: 46288 | O45: 지출계획_2026-09-23.xlsx | P45: 정상반영
A46: 건강-20260923-001 | B46: 건강사업팀 | C46: 김솔이 | E46: 46293 | F46: 46318 | G46: 카페24 | H46: sms 충전 | I46: 1000000 | J46: 법인카드 | K46: 우리카드 | L46: 확정 | M46: 신규 | N46: 46288 | O46: 지출계획_2026-09-23.xlsx | P46: 정상반영
A47: 경영-20260922-008 | B47: 경영지원팀 | C47: 장은총 | E47: 46293 | F47: 46318 | G47: 위버 | H47: 워크샵 (1부/2부) 이용료 | I47: 1675000 | J47: 법인카드 | K47: 우리카드 | L47: 확정 | M47: 신규 | N47: 46287 | O47: 지출계획_2026-09-23.xlsx | P47: 정상반영
A48: 경영-20260923-005 | B48: 경영지원팀 | C48: 김수희 | E48: 46295 | F48: 46318 | G48: 쿠팡 | H48: 직원 간식 구매 | I48: 300000 | J48: 법인카드 | K48: 우리카드 | L48: 확정 | M48: 신규 | N48: 46288 | O48: 지출계획_2026-09-23.xlsx | P48: 정상반영

Sheet 에이팜 지출계획
A2: 에이팜 지출계획 (자동 반영)
A3: 지출계획 비고에 '에이팜'으로 표시한 건은 자금계획(4주·13주)에 반영하지 않고 여기서만 관리합니다. '반영' 표시 건은 자금계획에 포함된 에이팜 관련 참고 항목입니다.
A5: 일자 | B5: 요일 | C5: 출처 | D5: 자금계획 반영 | E5: 팀명 | F5: 거래처 | G5: 지출내용 | H5: 예상금액 | I5: 지급방법 | J5: 비고
A6: 46283 | B6: 금 | C6: 팀 지출계획 | D6: 미반영(별도 관리) | E6: 경영지원팀 | F6: 이앤씨이노비즈타워 | G6: 본사관리비 | H6: 1553720 | I6: 계좌송금 | J6: 에이팜
A7: 46287 | B7: 화 | C7: 팀 지출계획 | D7: 미반영(별도 관리) | E7: 경영지원팀 | F7: (대외비) | G7: 급여·인건비(대외비) | H7: 4600000 | I7: 계좌송금 | J7: 에이팜
A8: 46288 | B8: 수 | C8: 팀 지출계획 | D8: 미반영(별도 관리) | E8: 경영지원팀 | F8: 비씨카드 | G8: 8월카드대금 | H8: 269810 | I8: 계좌송금 | J8: 에이팜
A9: 46295 | B9: 수 | C9: 팀 지출계획 | D9: 미반영(별도 관리) | E9: 경영지원팀 | F9: 서원회계법인 | G9: 기장료 | H9: 330000 | I9: 계좌송금 | J9: 에이팜
A10: 46295 | B10: 수 | C10: 팀 지출계획 | D10: 미반영(별도 관리) | E10: 경영지원팀 | F10: 달서구청 | G10: 2026년 토지재산세 | H10: 315520 | I10: 계좌송금 | J10: 에이팜
A11: 46295 | B11: 수 | C11: 팀 지출계획 | D11: 미반영(별도 관리) | E11: 경영지원팀 | F11: 가가사무기 | G11: 복합기 9월 임대비용 | H11: 280000 | I11: 계좌송금 | J11: 에이팜
A12: 46295 | B12: 수 | C12: 팀 지출계획 | D12: 미반영(별도 관리) | E12: 경영지원팀 | F12: 대구상공회의소 | G12: 하반기연회비 | H12: 250000 | I12: 계좌송금 | J12: 에이팜
G13: 합계(자금계획 미반영) | H13: 7599050

Sheet 계좌내역통합_RAW
A1: 거래일시 | B1: 거래일 | C1: 은행 | D1: 계좌 | E1: 출금액 | F1: 입금액 | G1: 거래후잔액 | H1: 적요 | I1: 기재내용·상대방 | J1: 취급점 | K1: 자동분류 | L1: 내부이체 | M1: 정기지출후보 | N1: 현금유출입 | O1: 원본파일 | P1: 반영상태
A2: 46106.435 | B2: 46106 | C2: 국민은행 | D2: 국민 169124 | E2: 0 | F2: 2497000 | G2: 3871400 | H2: 기일입금 | I2: (주)에이팜건강 | J2: 진천역 | K2: 계좌간이체 | L2: Y | M2: N | N2: 0 | O2: 농협계좌_6개월(20260913).xls | P2: 기존내역
A3: 46106.665 | B3: 46106 | C3: 국민은행 | D3: 국민 169124 | E3: 0 | F3: 110000000 | G3: 113871400 | H3: FBS입금 | I3: 한화생중도인출 | J3: ERP사 | K3: 보험 중도인출·보험금 입금 | L3: N | M3: N | N3: 110000000 | O3: 농협계좌_6개월(20260913).xls | P3: 기존내역
A4: 46106.833 | B4: 46106 | C4: 국민은행 | D4: 국민 169124 | E4: 2497000 | F4: 0 | G4: 111374400 | H4: CMS 공동 | I4: METLIFE03036 | J4: ERP사 | K4: 기타지출 | L4: N | M4: Y | N4: -2497000 | O4: 농협계좌_6개월(20260913).xls | P4: 기존내역
A5: 46106.839 | B5: 46106 | C5: 국민은행 | D5: 국민 169124 | E5: 110000000 | F5: 0 | G5: 1374400 | H5: FBS출금 | I5: 푸본현02-002 | J5: ERP사 | K5: 보험료 | L5: N | M5: N | N5: -110000000 | O5: 농협계좌_6개월(20260913).xls | P5: 기존내역
A6: 46107.488 | B6: 46107 | C6: 국민은행 | D6: 국민 169124 | E6: 1374400 | F6: 0 | G6: 0 | H6: 스마트출금 | I6: (주)에이팜건강 | J6: 진천역 | K6: 계좌간이체 | L6: Y | M6: N | N6: 0 | O6: 농협계좌_6개월(20260913).xls | P6: 기존내역
A7: 46115.726 | B7: 46115 | C7: 국민은행 | D7: 국민 169124 | E7: 0 | F7: 3003000 | G7: 3003000 | H7: 전자금융 | I7: 주식회사에이팜건강 | J7: 우리은행 | K7: 관계사 입금 | L7: N | M7: N | N7: 3003000 | O7: 국민은행_계좌 조회 6개월(20260913).xls | P7: 기존내역
A8: 46118.429 | B8: 46118 | C8: 국민은행 | D8: 국민 169124 | E8: 0 | F8: 5240400 | G8: 48764600 | H8: 기일입금 | I8: (주)에이팜건강 | J8: 진천역 | K8: 계좌간이체 | L8: Y | M8: N | N8: 0 | O8: 국민은행_계좌 조회 6개월(20260913).xls | P8: 기존내역
A9: 46118.429 | B9: 46118 | C9: 국민은행 | D9: 국민 169124 | E9: 0 | F9: 500000 | G9: 43524200 | H9: 기일입금 | I9: (주)에이팜건강 | J9: 진천역 | K9: 계좌간이체 | L9: Y | M9: N | N9: 0 | O9: 국민은행_계좌 조회 6개월(20260913).xls | P9: 기존내역
A10: 46118.429 | B10: 46118 | C10: 국민은행 | D10: 국민 169124 | E10: 0 | F10: 30000000 | G10: 43024200 | H10: 기일입금 | I10: (주)에이팜건강 | J10: 진천역 | K10: 기타입금 | L10: N | M10: N | N10: 30000000 | O10: 국민은행_계좌 조회 6개월(20260913).xls | P10: 기존내역
A11: 46118.429 | B11: 46118 | C11: 국민은행 | D11: 국민 169124 | E11: 0 | F11: 10021200 | G11: 13024200 | H11: 기일입금 | I11: (주)에이팜건강 | J11: 진천역 | K11: 계좌간이체 | L11: Y | M11: N | N11: 0 | O11: 우리은행 거래내역조회 20260913.xlsx | P11: 기존내역
A12: 46118.796 | B12: 46118 | C12: 국민은행 | D12: 국민 169124 | E12: 40521200 | F12: 0 | G12: 8243400 | H12: FBS출금 | I12: 한화생04-03 | J12: ERP사 | K12: 보험료 | L12: N | M12: Y | N12: -40521200 | O12: 우리은행 거래내역조회 20260913.xlsx | P12: 기존내역
A13: 46118.809 | B13: 46118 | C13: 국민은행 | D13: 국민 169124 | E13: 8243400 | F13: 0 | G13: 0 | H13: FBS출금 | I13: 삼성04002건 | J13: ERP사 | K13: 보험료 | L13: N | M13: Y | N13: -8243400 | O13: 우리은행 거래내역조회 20260913.xlsx | P13: 기존내역
... A127: 46287.698 | B127: 46287 | C127: 우리은행 | D127: 우리 220351 | E127: 350000 | F127: 0 | G127: 9421750 | H127: 인터넷 | I127: 아이임대규 | J127: 성서공단금융센터 | K127: 기타지출 | L127: N | M127: N | N127: -350000 | O127: 우리은행 거래내역조회 20260913.xlsx | P127: 기존내역
A128: 46287.709 | B128: 46287 | C128: 국민은행 | D128: 국민 154577 | E128: 7800000 | F128: 0 | G128: 36085938 | H128: TOP출금 | J128: 진천역 | K128: 확인필요 | L128: N | M128: N | N128: -7800000 | O128: 우리은행 거래내역조회 20260913.xlsx | P128: 기존내역
A129: 46288.103 | B129: 46288 | C129: 우리은행 | D129: 우리 220351 | E129: 0 | F129: 5580156 | G129: 14506389 | H129: 펌뱅킹 | I129: 스마트스토어정산 | J129: 두산타워기업영업지원팀 | K129: 온라인매출입금 | L129: N | M129: N | N129: 5580156 | O129: 우리은행 거래내역조회 20260913.xlsx | P129: 기존내역
A130: 46288.135 | B130: 46288 | C130: 우리은행 | D130: 우리 220351 | E130: 14506389 | F130: 0 | G130: 0 | H130: 우리카드 | I130: 우리카드결제대금 | J130: 리테일영업총괄부(카드) | K130: 우리카드 결제 | L130: N | M130: N | N130: -14506389 | O130: 국민은행_계좌 조회 6개월(20260913).xls | P130: 기존내역
A131: 46288.142 | B131: 46288 | C131: 국민은행 | D131: 국민 154577 | E131: 0 | F131: 76239 | G131: 36162177 | H131: 전자금융 | I131: Npay정산 | J131: SC은행 | K131: 온라인매출입금 | L131: N | M131: N | N131: 76239 | O131: 국민은행_계좌 조회 6개월(20260913).xls | P131: 기존내역
A132: 46288.218 | B132: 46288 | C132: 농협 | D132: 농협 569003 | E132: 0 | F132: 39066 | G132: 2266495 | H132: BC카드 | I132: 726168386BC | J132: 농협 000998 | K132: 기타입금 | L132: N | M132: N | N132: 39066 | O132: 우리은행 거래내역조회 20260913.xlsx | P132: 기존내역
A133: 46288.447 | B133: 46288 | C133: 국민은행 | D133: 국민 154577 | E133: 0 | F133: 228129 | G133: 36390306 | H133: 전자금융 | I133: KG이니시스 | J133: 하나은행 | K133: 온라인매출입금 | L133: N | M133: N | N133: 228129 | O133: 우리은행 거래내역조회 20260913.xlsx | P133: 기존내역
A134: 46288.45 | B134: 46288 | C134: 국민은행 | D134: 국민 154577 | E134: 0 | F134: 1533549 | G134: 37923855 | H134: 전자금융 | I134: KG이니시스 | J134: 하나은행 | K134: 온라인매출입금 | L134: N | M134: N | N134: 1533549 | O134: 우리은행 거래내역조회 20260913.xlsx | P134: 기존내역
A135: 46288.491 | B135: 46288 | C135: 농협 | D135: 농협 569003 | E135: 0 | F135: 45000 | G135: 2311495 | H135: 폰국민은행 | I135: 허수원 | J135: 국민 0068398 | K135: 기타입금 | L135: N | M135: N | N135: 45000 | O135: 우리은행 거래내역조회 20260913.xlsx | P135: 기존내역
A136: 46288.493 | B136: 46288 | C136: 국민은행 | D136: 국민 154577 | E136: 0 | F136: 8591494 | G136: 48033349 | H136: FBS입금 | I136: 쿠팡(주) | J136: ERP사 | K136: 온라인매출입금 | L136: N | M136: N | N136: 8591494 | O136: 국민은행_계좌 조회 6개월(20260913).xls | P136: 기존내역
A137: 46288.493 | B137: 46288 | C137: 국민은행 | D137: 국민 154577 | E137: 0 | F137: 1518000 | G137: 39441855 | H137: FBS입금 | I137: 쿠팡(주) | J137: ERP사 | K137: 온라인매출입금 | L137: N | M137: N | N137: 1518000 | O137: 농협계좌_6개월(20260913).xls | P137: 기존내역
A138: 46288.51 | B138: 46288 | C138: 국민은행 | D138: 국민 154577 | E138: 4675000 | F138: 0 | G138: 43358349 | H138: 스마트출금 | I138: 네이버 aphar | J138: 진천역 | K138: 기타지출 | L138: N | M138: N | N138: -4675000 | O138: 국민은행_계좌 조회 6개월(20260913).xls | P138: 기존내역
A139: 46288.512 | B139: 46288 | C139: 국민은행 | D139: 국민 154577 | E139: 330000 | F139: 0 | G139: 43028349 | H139: 스마트출금 | I139: 네이버 에이팜건강 | J139: 진천역 | K139: 기타지출 | L139: N | M139: N | N139: -330000 | O139: 국민은행_계좌 조회 6개월(20260913).xls | P139: 기존내역
A140: 46288.513 | B140: 46288 | C140: 국민은행 | D140: 국민 154577 | E140: 990000 | F140: 0 | G140: 42038349 | H140: 스마트출금 | I140: 네이버 ddi50 | J140: 진천역 | K140: 기타지출 | L140: N | M140: N | N140: -990000 | O140: 농협계좌_6개월(20260913).xls | P140: 기존내역
... A147: 46288.692 | B147: 46288 | C147: 우리은행 | D147: 우리 220351 | E147: 4905200 | F147: 0 | G147: 0 | H147: 우리카드 | I147: 우리카드결제대금 | J147: 리테일영업총괄부(카드) | K147: 우리카드 결제 | L147: N | M147: N | N147: -4905200 | O147: 우리은행 거래내역조회 20260913.xlsx | P147: 기존내역
O148: 우리은행 거래내역조회 20260913.xlsx | P148: 기존내역
O149: 우리은행 거래내역조회 20260913.xlsx | P149: 기존내역
O150: 우리은행 거래내역조회 20260913.xlsx | P150: 기존내역
O151: 우리은행 거래내역조회 20260913.xlsx | P151: 기존내역
O152: 국민은행_계좌 조회 6개월(20260913).xls | P152: 기존내역
O153: 국민은행_계좌 조회 6개월(20260913).xls | P153: 기존내역
O154: 국민은행_계좌 조회 6개월(20260913).xls | P154: 기존내역
O155: 국민은행_계좌 조회 6개월(20260913).xls | P155: 기존내역
O156: 국민은행_계좌 조회 6개월(20260913).xls | P156: 기존내역
O157: 국민은행_계좌 조회 6개월(20260913).xls | P157: 기존내역
O158: 농협계좌_6개월(20260913).xls | P158: 기존내역
O159: 국민은행_계좌 조회 6개월(20260913).xls | P159: 기존내역
...

Sheet 설정및분류
A2: 예측 설정 및 자동분류 기준
A5: 요일번호 | B5: 요일 | C5: 최근 12주 온라인입금 일평균 | E5: 분류 | F5: 대표 키워드 | H5: 반영률 선택값
A6: 1 | B6: 월 | C6: 10677756 | E6: 온라인매출입금 | F6: 스마트스토어, KG이니시스, Npay, NHN페이, 카드가맹점 | H6: 0.6
A7: 2 | B7: 화 | C7: 22255001 | E7: 계좌간이체 | F7: 에이팜건강 표시(광고·네이버 제외) | H7: 0.7
A8: 3 | B8: 수 | C8: 14296943 | E8: 4대보험 | F8: 우리은행의 사회보험·건강보험 | H8: 0.8
A9: 4 | B9: 목 | C9: 13264811 | E9: 원천세·국세 | F9: 우리은행의 국고·원천세 | H9: 0.9
A10: 5 | B10: 금 | C10: 10320905 | E10: 법인카드결제 | F10: 우리카드결제대금, KB카드출금 | H10: 1
A11: 6 | B11: 토 | C11: 0 | E11: 보험료(기타) | F11: 한화생명, 메트라이프, ABL생명, 미래에셋
A12: 7 | B12: 일 | C12: 0 | E12: 광고선전비 | F12: 네이버, 광고, 비즈월렛, 캐시워크
E13: 급여·인건비(대외비) | F13: 급여, 상여, 퇴직, 국민은행 월말 TOP출금
E14: 대출·이자 | F14: 대출, 이자
E15: 기타입출금 | F15: 위 기준에 해당하지 않는 거래
