Workbook

Sheet 요약
A2: (주)에이팜건강 자금계획 기초 현황
A3: 기준일 2026-10-12 | 농협·우리은행·국민은행 계좌 거래내역 통합 (자동 갱신)
A5: 항목 | B5: 금액 | D5: 계좌 | E5: 최종 거래일 | F5: 잔액
A6: 현재 계좌잔액 | B6: 120868218 | D6: 국민 154577 | E6: 46311 | F6: 62178003
A7: 6개월 외부입금 | B7: 3591245039 | D7: 국민 169124 | E7: 46310 | F7: 20687200
A8: 6개월 외부출금 | B8: 3829559411 | D8: 국민 170616 | E8: 46311 | F8: 31550000
A9: 온라인매출 입금 | B9: 2227530456 | D9: 농협 569003 | E9: 46309 | F9: 441400
A10: 최근 12주 주평균 온라인입금 | B10: 65399150 | D10: 우리 220351 | E10: 46311 | F10: 6011615
A12: 계획 설정 | B12: 값 | D12: 사용 방법
A13: 입금 예측 반영률 | B13: ='경영보고'!$F$12 | D13: 1. 입력·수정은 전부 '경영보고' 시트의 노란 칸에서 합니다 — 나머지 시트는 수식으로 자동 재계산됩니다.
A14: 4주 예상 기말잔액 | B14: ='4주일별계획'!T35 | D14: 2. '대표보고' 시트는 그대로 인쇄(A4 한 장), 일별 상세는 '4주일별계획' 시트에서 봅니다.
A15: 4주 최저 예상잔액 | B15: =MIN('4주일별계획'!T8:T35) | D15: ="3. 온라인 입금은 최근 12주 요일별 평균의 "&TEXT($B$13,"0%")&"로 예측합니다."
A16: 13주 예상 기말잔액 | B16: ='13주주별계획'!J18 | D16: 4. 계좌 간 이체는 내부이체로 표시해 입출금 합계에서 제외합니다.
D17: 5. 무엇을 고치면 어디가 바뀌는지는 아래 '경영보고 시트 수정 방법' 표를 보세요.
A19: 경영보고 시트 수정 방법 — 무엇을 고치면 어디가 바뀌나 (전부 수식 자동 반영)
A20: 수정하는 곳 (경영보고 노란 칸) | B20: 이렇게 수정 | D20: 바뀌는 곳 (수정 즉시 자동 재계산)
A21: F12 · 입금 반영률 (총잔액 옆) | B21: 60~100%에서 선택 | D21: 경영보고 ③ 일별 온라인 예상입금·④ 잔액과 판정 → 4주일별계획 온라인 예상입금 열 → 계좌별시나리오·13주 → 요약 B13~B16 → 대표보고 시나리오 표
A22: ② 지출예정 A열(지급일)·E열(금액) | B22: 일자·금액을 바로 고침 (숨은 예비 행을 펴면 새 지출 추가) | D22: 경영보고 ② 합계 E110·④ 그 날짜의 지출·잔액·지출 내역 → 4주일별계획 송금·카드·조정 열과 잔액 → 계좌별시나리오 → 대표보고
A23: ② G열(실지출·은행 확인) | B23: 실제 나간 금액을 입력 | D23: ② H열(차이)만 자동 계산 — 계획 대비 대조 기록용이라 다른 시트 숫자는 바뀌지 않음
A24: ② I열(확인 드롭다운) | B24: 적용 / 보류 선택 (빈칸 = 적용) | D24: '보류' 행은 ② 합계 E110·④ 일별 흐름·4주일별계획·대표보고에서 전부 빠짐 — 이 파일 안에서만 유효
A25: ③ 입금예정 확정입금 행 A(일자)·E(금액) | B25: 확정입금 일자·금액을 고침 | D25: 경영보고 ④ 그 날짜 입금·잔액 → 4주일별계획 확정·기타입금 열 → 계좌별시나리오 → 대표보고
A26: C172 · 목표 최저잔액 | B26: 안정 목표 금액을 입력 | D26: ⑤ 필요 추가 입금(반영률 시나리오별 부족액)만 다시 계산
A27: ※ 이 파일에서 한 수정은 이 파일 안에서만 유효합니다 — 다음 실행 결과는 팀 지출계획·확인 단계 기준으로 새로 계산됩니다. 숨겨진 날짜·예비 행은 행 숨기기 해제로 볼 수 있습니다.

Sheet 업데이트운영
A2: 이 파일 사용·업데이트 안내
A3: 매주 실행 때마다 05_결과 폴더에 새 주간자금계획 파일이 만들어집니다 — 열어 볼 파일은 최신 파일 하나입니다. 이 안내는 실행할 때마다 자동으로 새로 쓰입니다.
A5: ① 매주 운영 순서
A6: 1. 은행 파일 | B6: 월요일 아침 농협·우리은행·국민은행에서 최근 거래내역(엑셀)을 내려받아 03_은행거래내역 폴더에 넣습니다 — 조회기간이 겹쳐도 중복 거래는 자동 제외되고, 지난 파일은 자동 보관됩니다.
A7: 2. 팀 지출계획 | B7: 각 팀 주간 지출계획 파일을 01_지출계획 폴더에 넣습니다 (경영지원 대외비 파일은 02_경영지원_대외비 폴더).
A8: 3. 자동 실행 | B8: 월요일 09:10 자동 실행됩니다 (트레이 아이콘 → '지금 실행'으로 언제든 수동 실행 가능). 먼저 06_확인필요 폴더에 확인 파일이 열립니다.
A9: 4. 확인·저장 | B9: 확인 파일의 시트(확인필요·정기지출누락·정기지출분석)를 검토하고 '안내' 시트 B2를 '예'로 바꿔 저장하면 몇 분 안에 이 결과 파일이 만들어집니다.
A10: 5. 수정·보고 | B10: 이 파일의 '경영보고' 시트 노란 칸에서 일정·금액을 수정하고(전 시트 자동 반영 — 요약 시트의 표 참고), '대표보고' 시트를 그대로 A4 인쇄해 보고합니다.
A11: 6. 금요일 대조 | B11: 금요일 17:00 은행 파일을 새로 받아 넣으면 06_확인필요에 주간대조 파일이 생성됩니다 — 이번 주 계획 vs 실제 입출금 차이를 확인합니다.
A13: ② 이 파일의 시트 구성
A14: 요약 | B14: 잔액·통계 요약 + 경영보고 수정 방법 표
A15: 업데이트운영 | B15: 이 안내 (운영 순서·시트 구성·은행 자료 현황)
A16: 경영보고 | B16: ★ 입력 기준 시트 — ①현황 ②지출예정 ③입금예정 ④일별 흐름 ⑤필요 추가 입금 ⑥메모. 노란 칸을 고치면 전 시트 자동 재계산
A17: 대표보고 | B17: A4 한 장 인쇄용 요약 — 경영보고에 수식으로 연동
A18: 4주일별계획 | B18: 일별 상세(실무용) — 경영보고 수정에 자동 연동
A19: 계좌별시나리오 | B19: 계좌별 잔액·입금 배분·부족분 이체 계획
A20: 지출계획_취합 | B20: 팀 지출계획 취합 (대외비는 분류·총액만)
A21: 에이팜 지출계획 | B21: 에이팜 지출 상세
A22: 계좌내역통합_RAW | B22: 은행 3사 거래내역 통합 원본
A23: 설정및분류 | B23: 요일평균 등 내부 계산용 (수정 불필요)
A24: 13주주별계획 (숨김) | B24: 13주 주별 전망 — 시트 숨기기 해제로 열람
A26: ③ 현재 반영된 은행 자료 (자동 집계)
A27: 은행 | B27: 반영 거래건수 | C27: 자료 시작일 | D27: 최종 거래일
A28: 국민은행 | B28: 90 | C28: 46296 | D28: 46311
A29: 농협 | B29: 16 | C29: 46301 | D29: 46309
A30: 우리은행 | B30: 52 | C30: 46307 | D30: 46311
A32: ※ 은행 파일에서 읽은 거래 기준입니다. 최종 거래일이 오래됐으면 새 은행 파일을 03_은행거래내역 폴더에 넣고 다시 실행하세요.

Sheet 경영보고
A1: 주간 자금 경영보고 — (주)에이팜건강
A2: 기준주 2026-10-12 (월) ~ 2026-10-18 (일) · 작성 2026-10-17 21:21:14 · 실행일~차주 금요일만 표시 (그 밖의 일자 행은 숨김 — 행 숨기기 해제로 열람 가능)
A3: 노란 칸(입금 반영률 F12·② 지출 지급일·금액·③ 확정입금·목표 최저잔액)을 고치면 이 시트의 ④ 일별 흐름과 라이브 시트 전체가 즉시 다시 계산됩니다. ② 지출예정에서 실지출과 차이 나는 행(주황)은 확인(I열) 드롭다운으로 표시하세요.
A5: ① 현재 자금 현황
A6: 국민 154577 | C6: 62178003 | D6: 최종 거래일 2026-10-16
A7: 국민 169124 | C7: 20687200 | D7: 최종 거래일 2026-10-15
A8: 국민 170616 | C8: 31550000 | D8: 최종 거래일 2026-10-16
A9: 농협 569003 | C9: 441400 | D9: 최종 거래일 2026-10-14
A10: 우리 220351 | C10: 6011615 | D10: 최종 거래일 2026-10-16
A12: 총잔액 | C12: =SUM(C6:C11) | E12: 입금 반영률 | F12: 0.8
A14: ② 반영된 지출예정 (실행일~차주 금요일 표시) — 지급일·금액(노란 칸)을 고치면 아래 ④ 일별 흐름과 라이브 시트 전체가 다시 계산됩니다 · 실지출(G)을 적으면 차이(H) 자동 계산 · 확인(I)에서 '보류'를 고른 행은 계획에서 제외
A15: 지급일 | B15: 요일 | C15: 구분 | D15: 내용 | E15: 금액 | F15: 지급방법 | G15: 실지출(은행 확인) | H15: 차이(잔여) | I15: 확인
B16: =IF(A16="","",MID("월화수목금토일",WEEKDAY(A16,2),1)) | H16: =IF(OR(G16="",E16=""),"",E16-G16)
B17: =IF(A17="","",MID("월화수목금토일",WEEKDAY(A17,2),1)) | H17: =IF(OR(G17="",E17=""),"",E17-G17)
B18: =IF(A18="","",MID("월화수목금토일",WEEKDAY(A18,2),1)) | H18: =IF(OR(G18="",E18=""),"",E18-G18)
B19: =IF(A19="","",MID("월화수목금토일",WEEKDAY(A19,2),1)) | H19: =IF(OR(G19="",E19=""),"",E19-G19)
B20: =IF(A20="","",MID("월화수목금토일",WEEKDAY(A20,2),1)) | H20: =IF(OR(G20="",E20=""),"",E20-G20)
B21: =IF(A21="","",MID("월화수목금토일",WEEKDAY(A21,2),1)) | H21: =IF(OR(G21="",E21=""),"",E21-G21)
B22: =IF(A22="","",MID("월화수목금토일",WEEKDAY(A22,2),1)) | H22: =IF(OR(G22="",E22=""),"",E22-G22)
B23: =IF(A23="","",MID("월화수목금토일",WEEKDAY(A23,2),1)) | H23: =IF(OR(G23="",E23=""),"",E23-G23)
B24: =IF(A24="","",MID("월화수목금토일",WEEKDAY(A24,2),1)) | H24: =IF(OR(G24="",E24=""),"",E24-G24)
B25: =IF(A25="","",MID("월화수목금토일",WEEKDAY(A25,2),1)) | H25: =IF(OR(G25="",E25=""),"",E25-G25)
B26: =IF(A26="","",MID("월화수목금토일",WEEKDAY(A26,2),1)) | H26: =IF(OR(G26="",E26=""),"",E26-G26)
B27: =IF(A27="","",MID("월화수목금토일",WEEKDAY(A27,2),1)) | H27: =IF(OR(G27="",E27=""),"",E27-G27)
... B109: =IF(A109="","",MID("월화수목금토일",WEEKDAY(A109,2),1)) | H109: =IF(OR(G109="",E109=""),"",E109-G109)
D110: 합계(숨긴 행 포함 4주 전체 · 보류 제외) | E110: =SUMIFS(E16:E109,I16:I109,"<>보류")
A112: ③ 반영된 입금예정 (실행일~차주 금요일) — 예상은 반영률(F12) 연동 · 실입금은 은행 확인 값
A113: 입금일 | B113: 요일 | C113: 구분 | D113: 내용 | E113: 예상금액 | F113: 실입금(은행 확인) | G113: 차이
A114: 46312 | B114: 토 | C114: 온라인 예상 | D114: 12주 요일평균 × 반영률 | E114: =ROUND(J145*$F$12,0) | G114: =IF(OR(F114="",E114=""),"",F114-E114)
A115: 46313 | B115: 일 | C115: 온라인 예상 | D115: 12주 요일평균 × 반영률 | E115: =ROUND(J146*$F$12,0) | G115: =IF(OR(F115="",E115=""),"",F115-E115)
A116: 46314 | B116: 월 | C116: 온라인 예상 | D116: 12주 요일평균 × 반영률 | E116: =ROUND(J147*$F$12,0) | G116: =IF(OR(F116="",E116=""),"",F116-E116)
A117: 46315 | B117: 화 | C117: 온라인 예상 | D117: 12주 요일평균 × 반영률 | E117: =ROUND(J148*$F$12,0) | G117: =IF(OR(F117="",E117=""),"",F117-E117)
A118: 46316 | B118: 수 | C118: 온라인 예상 | D118: 12주 요일평균 × 반영률 | E118: =ROUND(J149*$F$12,0) | G118: =IF(OR(F118="",E118=""),"",F118-E118)
A119: 46317 | B119: 목 | C119: 온라인 예상 | D119: 12주 요일평균 × 반영률 | E119: =ROUND(J150*$F$12,0) | G119: =IF(OR(F119="",E119=""),"",F119-E119)
A120: 46318 | B120: 금 | C120: 온라인 예상 | D120: 12주 요일평균 × 반영률 | E120: =ROUND(J151*$F$12,0) | G120: =IF(OR(F120="",E120=""),"",F120-E120)
A121: 46326 | B121: 토 | C121: 확정입금 | D121: 관계사 외상대 입금 추정(주식회사에이팜, 말일) | E121: 10021867 | G121: =IF(OR(F121="",E121=""),"",F121-E121)
D136: 합계(표시 구간) | E136: =SUM(E114:E135) | F136: =SUM(F114:F135)
A138: ④ 향후 4주 일별 자금 흐름 — ② 지출·③ 입금 수정과 반영률(F12)에 즉시 연동 (실행일~차주 금요일만 표시 · 계산은 4주 전체)
A139: 일자 | B139: 요일 | C139: 입금 | D139: 지출 | E139: 예상잔액 | F139: 지출 내역 | K139: 121673505
A140: 46307 | B140: 월 | C140: 31313038 | D140: 32379416 | E140: =$K$139+C140-D140 | F140: 실적(은행 확인) | J140: 9149149 | K140: 11217233
...

Sheet 대표보고
A1: (주)에이팜건강 주간 자금계획 보고
A2: ="기준일 2026-10-12 · 작성 2026-10-17 21:21:14 · 입금 반영률 "&TEXT('경영보고'!$F$12,"0%")&" (경영보고 시트와 실시간 연동)"
A4: 핵심 요약
A5: 현재 전체 계좌잔액 | C5: ='경영보고'!C12
A6: 4주 예상 기말잔액 | C6: ='경영보고'!E167
A7: 4주 최저 예상잔액 | C7: ='경영보고'!C168 | D7: =TEXT(INDEX('경영보고'!$A$140:$A$167,MATCH('경영보고'!C168,'경영보고'!$E$140:$E$167,0)),"m/d 예상")
A8: 향후 4주 확정지출 | C8: ='경영보고'!E110
A9: 카드 결제 예정액(4주) | C9: =SUMIFS('경영보고'!$E$16:$E$109,'경영보고'!$F$16:$F$109,"법인카드",'경영보고'!$I$16:$I$109,"<>보류")
A10: 자금부족 예상일 | C10: =IFERROR(TEXT(INDEX('경영보고'!$A$140:$A$167,MATCH(TRUE,INDEX('경영보고'!$E$140:$E$167<0,0),0)),"yyyy-mm-dd"),"없음")
A11: 확인필요 건수 | C11: 45건
A12: 자료 미제출 팀 | C12: 없음
A14: ='경영보고'!A169
A16: 차주 일별 잔액 전망 (월~금) — 반영률·지출 수정과 실시간 연동
A17: 일자 | B17: 요일 | C17: 예상 기말잔액 | D17: 상태
A18: ='경영보고'!A147 | B18: 월 | C18: ='경영보고'!E147 | D18: =IF(C18<0,"부족","")
A19: ='경영보고'!A148 | B19: 화 | C19: ='경영보고'!E148 | D19: =IF(C19<0,"부족","")
A20: ='경영보고'!A149 | B20: 수 | C20: ='경영보고'!E149 | D20: =IF(C20<0,"부족","")
A21: ='경영보고'!A150 | B21: 목 | C21: ='경영보고'!E150 | D21: =IF(C21<0,"부족","")
A22: ='경영보고'!A151 | B22: 금 | C22: ='경영보고'!E151 | D22: =IF(C22<0,"부족","")
A24: 입금 반영률 시나리오 (80·90·100%) — 필요 추가 입금
A25: 반영률 | C25: 4주 기말잔액 | D25: 4주 최저잔액 | E25: 필요 추가 입금
A26: ='경영보고'!A174 | C26: ='경영보고'!C174 | D26: ='경영보고'!D174 | E26: ='경영보고'!F174
A27: ='경영보고'!A175 | C27: ='경영보고'!C175 | D27: ='경영보고'!D175 | E27: ='경영보고'!F175
A28: ='경영보고'!A176 | C28: ='경영보고'!C176 | D28: ='경영보고'!D176 | E28: ='경영보고'!F176
A30: ="· 목표 최저잔액 "&TEXT('경영보고'!$C$172,"#,##0")&"원 기준. 시나리오 값은 실행 시점 계산이며, 반영률·지출 수정은 위 표와 경영보고에 즉시 반영됩니다."
A31: · 대외비 항목은 분류·총액으로만 표시됩니다. 상세 내역은 같은 파일의 경영보고·지출계획_취합 시트를 확인하십시오.

Sheet 4주일별계획
A2: 향후 4주 일별 자금계획
A3: 온라인 예상입금은 최근 12주 요일별 평균 × 입금 반영률('경영보고' F12 연동)로 계산됩니다. 지급일·금액·확정입금은 '경영보고' 시트의 ③·④ 표에서 고치세요 — 이 표는 자동으로 따라옵니다. | 실잔고(은행 최근 확인): 우리 220351 6,011,615(10-16) · 농협 569003 441,400(10-14) · 국민 154577 62,178,003(10-16) · 국민 170616 31,550,000(10-16) · 국민 169124 20,687,200(10-15) — 실행일 행은 은행 파일 그대로 실적으로 마감(기말 = 오늘 실잔고)하고, 아직 안 나간 예정(보류 제외)은 익일로 이월합니다. 자금 예산은 익일부터 오늘 실잔고에서 출발합니다(반영률 B13 연동)
C4: 계좌별 예상잔고 | I4: 계좌별 입금 배분(예상)
A5: 일자 | B5: 요일 | C5: 우리 220351 | D5: 농협 569003 | E5: 국민 154577 | F5: 국민 170616 | G5: 국민 169124 | H5: 온라인 예상입금 | I5: 우리 220351 | J5: 농협 569003 | K5: 국민 154577 | L5: 국민 170616 | M5: 국민 169124 | N5: 확정·기타입금 | O5: 송금예정 | P5: 카드결제 | Q5: 조정·추정 지출 | R5: 순현금흐름 | S5: 기초잔액 | T5: 기말잔액 | U5: 비고
A6: 46311 | B6: 금 | C6: ='계좌별시나리오'!D6 | D6: ='계좌별시나리오'!E6 | E6: ='계좌별시나리오'!F6 | F6: ='계좌별시나리오'!G6 | G6: ='계좌별시나리오'!H6 | T6: ='계좌별시나리오'!C6 | U6: 전일 마감 실잔고 — 여기서 계획 시작
A7: 46312 | B7: 토 | C7: ='계좌별시나리오'!D7 | D7: ='계좌별시나리오'!E7 | E7: ='계좌별시나리오'!F7 | F7: ='계좌별시나리오'!G7 | G7: ='계좌별시나리오'!H7 | T7: ='요약'!$B$6 | U7: 오늘 실잔고(은행 확인)·실제 입금·출금 — 참고 (이중계산 안 됨)
A8: 46307 | B8: 월 | C8: ='계좌별시나리오'!D8 | D8: ='계좌별시나리오'!E8 | E8: ='계좌별시나리오'!F8 | F8: ='계좌별시나리오'!G8 | G8: ='계좌별시나리오'!H8 | H8: 20095805 | I8: ='계좌별시나리오'!J8 | J8: ='계좌별시나리오'!K8 | K8: ='계좌별시나리오'!L8 | L8: ='계좌별시나리오'!M8 | M8: ='계좌별시나리오'!N8 | N8: 11217233 | Q8: 32379416 | R8: =H8+N8-O8-P8-Q8 | S8: 121673505 | T8: =S8+R8 | U8: 실적 | 지출: 2609사회보험 13,821,900, 주식회사에이팜건강 9,260,903, 국고_주식회사 4,533,630 외 8건 | 기타입금: 주식회사에이팜건강 9,260,403, 송경민 1,512,000 외 4건
A9: 46308 | B9: 화 | C9: ='계좌별시나리오'!D9 | D9: ='계좌별시나리오'!E9 | E9: ='계좌별시나리오'!F9 | F9: ='계좌별시나리오'!G9 | G9: ='계좌별시나리오'!H9 | H9: 21355339 | I9: ='계좌별시나리오'!J9 | J9: ='계좌별시나리오'!K9 | K9: ='계좌별시나리오'!L9 | L9: ='계좌별시나리오'!M9 | M9: ='계좌별시나리오'!N9 | N9: 290620 | Q9: 9561292 | R9: =H9+N9-O9-P9-Q9 | S9: =T8 | T9: =S9+R9 | U9: 실적 | 지출: 기업에이비제트 주식 3,300,000, 기업(주)써치엠 1,932,506, 기업(주)써치엠 1,487,786 외 4건 | 기타입금: (사)약령시보존위원 126,000, 허수원 87,000 외 3건
A10: 46309 | B10: 수 | C10: ='계좌별시나리오'!D10 | D10: ='계좌별시나리오'!E10 | E10: ='계좌별시나리오'!F10 | F10: ='계좌별시나리오'!G10 | G10: ='계좌별시나리오'!H10 | H10: 10161328 | I10: ='계좌별시나리오'!J10 | J10: ='계좌별시나리오'!K10 | K10: ='계좌별시나리오'!L10 | L10: ='계좌별시나리오'!M10 | M10: ='계좌별시나리오'!N10 | N10: 687080 | Q10: 1804000 | R10: =H10+N10-O10-P10-Q10 | S10: =T9 | T10: =S10+R10 | U10: 실적 | 지출: 국민SA 1,254,000, 국민GFA 330,000, 국민GFA 220,000 | 기타입금: 김지희 224,850, 김솔이 156,000 외 4건
A11: 46310 | B11: 목 | C11: ='계좌별시나리오'!D11 | D11: ='계좌별시나리오'!E11 | E11: ='계좌별시나리오'!F11 | F11: ='계좌별시나리오'!G11 | G11: ='계좌별시나리오'!H11 | H11: 14056940 | I11: ='계좌별시나리오'!J11 | J11: ='계좌별시나리오'!K11 | K11: ='계좌별시나리오'!L11 | L11: ='계좌별시나리오'!M11 | M11: ='계좌별시나리오'!N11 | N11: 212710 | Q11: 17314072 | R11: =H11+N11-O11-P11-Q11 | S11: =T10 | T11: =S11+R11 | U11: 실적 | 지출: 국민주식회사 원정대 5,500,000, ABL생명10011 5,001,750, 국민주식회사 캐시워 1,100,000 외 19건 | 기타입금: 에스케이엠앤서비스 179,710, 나가윤 33,000
A12: 46311 | B12: 금 | C12: ='계좌별시나리오'!D12 | D12: ='계좌별시나리오'!E12 | E12: ='계좌별시나리오'!F12 | F12: ='계좌별시나리오'!G12 | G12: ='계좌별시나리오'!H12 | H12: 8577438 | I12: ='계좌별시나리오'!J12 | J12: ='계좌별시나리오'!K12 | K12: ='계좌별시나리오'!L12 | L12: ='계좌별시나리오'!M12 | M12: ='계좌별시나리오'!N12 | Q12: 26401000 | R12: =H12+N12-O12-P12-Q12 | S12: =T11 | T12: =S12+R12 | U12: 실적 | 지출: 기업엠에스바이오텍( 10,000,000, (재)한국기계전기전 5,000,000, 국민주식회사 아이디 3,300,000 외 6건
A13: 46312 | B13: 토 | C13: ='계좌별시나리오'!D13 | D13: ='계좌별시나리오'!E13 | E13: ='계좌별시나리오'!F13 | F13: ='계좌별시나리오'!G13 | G13: ='계좌별시나리오'!H13 | H13: =INDEX('설정및분류'!$C$6:$C$12,WEEKDAY(A13,2))*'요약'!$B$13 | I13: ='계좌별시나리오'!J13 | J13: ='계좌별시나리오'!K13 | K13: ='계좌별시나리오'!L13 | L13: ='계좌별시나리오'!M13 | M13: ='계좌별시나리오'!N13 | N13: =SUMIFS('경영보고'!$E$114:$E$135,'경영보고'!$A$114:$A$135,$A13,'경영보고'!$C$114:$C$135,"확정입금") | O13: =SUMIFS('경영보고'!$E$16:$E$109,'경영보고'!$A$16:$A$109,$A13,'경영보고'!$I$16:$I$109,"<>보류",'경영보고'!$F$16:$F$109,"계좌송금") | P13: =SUMIFS('경영보고'!$E$16:$E$109,'경영보고'!$A$16:$A$109,$A13,'경영보고'!$I$16:$I$109,"<>보류",'경영보고'!$F$16:$F$109,"법인카드") | Q13: =SUMIFS('경영보고'!$E$16:$E$109,'경영보고'!$A$16:$A$109,$A13,'경영보고'!$I$16:$I$109,"<>보류")-O13-P13 | R13: =H13+N13-O13-P13-Q13 | S13: =T12 | T13: =S13+R13
A14: 46313 | B14: 일 | C14: ='계좌별시나리오'!D14 | D14: ='계좌별시나리오'!E14 | E14: ='계좌별시나리오'!F14 | F14: ='계좌별시나리오'!G14 | G14: ='계좌별시나리오'!H14 | H14: =INDEX('설정및분류'!$C$6:$C$12,WEEKDAY(A14,2))*'요약'!$B$13 | I14: ='계좌별시나리오'!J14 | J14: ='계좌별시나리오'!K14 | K14: ='계좌별시나리오'!L14 | L14: ='계좌별시나리오'!M14 | M14: ='계좌별시나리오'!N14 | N14: =SUMIFS('경영보고'!$E$114:$E$135,'경영보고'!$A$114:$A$135,$A14,'경영보고'!$C$114:$C$135,"확정입금") | O14: =SUMIFS('경영보고'!$E$16:$E$109,'경영보고'!$A$16:$A$109,$A14,'경영보고'!$I$16:$I$109,"<>보류",'경영보고'!$F$16:$F$109,"계좌송금") | P14: =SUMIFS('경영보고'!$E$16:$E$109,'경영보고'!$A$16:$A$109,$A14,'경영보고'!$I$16:$I$109,"<>보류",'경영보고'!$F$16:$F$109,"법인카드") | Q14: =SUMIFS('경영보고'!$E$16:$E$109,'경영보고'!$A$16:$A$109,$A14,'경영보고'!$I$16:$I$109,"<>보류")-O14-P14 | R14: =H14+N14-O14-P14-Q14 | S14: =T13 | T14: =S14+R14
A15: 46314 | B15: 월 | C15: ='계좌별시나리오'!D15 | D15: ='계좌별시나리오'!E15 | E15: ='계좌별시나리오'!F15 | F15: ='계좌별시나리오'!G15 | G15: ='계좌별시나리오'!H15 | H15: =INDEX('설정및분류'!$C$6:$C$12,WEEKDAY(A15,2))*'요약'!$B$13 | I15: ='계좌별시나리오'!J15 | J15: ='계좌별시나리오'!K15 | K15: ='계좌별시나리오'!L15 | L15: ='계좌별시나리오'!M15 | M15: ='계좌별시나리오'!N15 | N15: =SUMIFS('경영보고'!$E$114:$E$135,'경영보고'!$A$114:$A$135,$A15,'경영보고'!$C$114:$C$135,"확정입금") | O15: =SUMIFS('경영보고'!$E$16:$E$109,'경영보고'!$A$16:$A$109,$A15,'경영보고'!$I$16:$I$109,"<>보류",'경영보고'!$F$16:$F$109,"계좌송금") | P15: =SUMIFS('경영보고'!$E$16:$E$109,'경영보고'!$A$16:$A$109,$A15,'경영보고'!$I$16:$I$109,"<>보류",'경영보고'!$F$16:$F$109,"법인카드") | Q15: =SUMIFS('경영보고'!$E$16:$E$109,'경영보고'!$A$16:$A$109,$A15,'경영보고'!$I$16:$I$109,"<>보류")-O15-P15 | R15: =H15+N15-O15-P15-Q15 | S15: =T14 | T15: =S15+R15
A16: 46315 | B16: 화 | C16: ='계좌별시나리오'!D16 | D16: ='계좌별시나리오'!E16 | E16: ='계좌별시나리오'!F16 | F16: ='계좌별시나리오'!G16 | G16: ='계좌별시나리오'!H16 | H16: =INDEX('설정및분류'!$C$6:$C$12,WEEKDAY(A16,2))*'요약'!$B$13 | I16: ='계좌별시나리오'!J16 | J16: ='계좌별시나리오'!K16 | K16: ='계좌별시나리오'!L16 | L16: ='계좌별시나리오'!M16 | M16: ='계좌별시나리오'!N16 | N16: =SUMIFS('경영보고'!$E$114:$E$135,'경영보고'!$A$114:$A$135,$A16,'경영보고'!$C$114:$C$135,"확정입금") | O16: =SUMIFS('경영보고'!$E$16:$E$109,'경영보고'!$A$16:$A$109,$A16,'경영보고'!$I$16:$I$109,"<>보류",'경영보고'!$F$16:$F$109,"계좌송금") | P16: =SUMIFS('경영보고'!$E$16:$E$109,'경영보고'!$A$16:$A$109,$A16,'경영보고'!$I$16:$I$109,"<>보류",'경영보고'!$F$16:$F$109,"법인카드") | Q16: =SUMIFS('경영보고'!$E$16:$E$109,'경영보고'!$A$16:$A$109,$A16,'경영보고'!$I$16:$I$109,"<>보류")-O16-P16 | R16: =H16+N16-O16-P16-Q16 | S16: =T15 | T16: =S16+R16
A17: 46316 | B17: 수 | C17: ='계좌별시나리오'!D17 | D17: ='계좌별시나리오'!E17 | E17: ='계좌별시나리오'!F17 | F17: ='계좌별시나리오'!G17 | G17: ='계좌별시나리오'!H17 | H17: =INDEX('설정및분류'!$C$6:$C$12,WEEKDAY(A17,2))*'요약'!$B$13 | I17: ='계좌별시나리오'!J17 | J17: ='계좌별시나리오'!K17 | K17: ='계좌별시나리오'!L17 | L17: ='계좌별시나리오'!M17 | M17: ='계좌별시나리오'!N17 | N17: =SUMIFS('경영보고'!$E$114:$E$135,'경영보고'!$A$114:$A$135,$A17,'경영보고'!$C$114:$C$135,"확정입금") | O17: =SUMIFS('경영보고'!$E$16:$E$109,'경영보고'!$A$16:$A$109,$A17,'경영보고'!$I$16:$I$109,"<>보류",'경영보고'!$F$16:$F$109,"계좌송금") | P17: =SUMIFS('경영보고'!$E$16:$E$109,'경영보고'!$A$16:$A$109,$A17,'경영보고'!$I$16:$I$109,"<>보류",'경영보고'!$F$16:$F$109,"법인카드") | Q17: =SUMIFS('경영보고'!$E$16:$E$109,'경영보고'!$A$16:$A$109,$A17,'경영보고'!$I$16:$I$109,"<>보류")-O17-P17 | R17: =H17+N17-O17-P17-Q17 | S17: =T16 | T17: =S17+R17
A18: 46317 | B18: 목 | C18: ='계좌별시나리오'!D18 | D18: ='계좌별시나리오'!E18 | E18: ='계좌별시나리오'!F18 | F18: ='계좌별시나리오'!G18 | G18: ='계좌별시나리오'!H18 | H18: =INDEX('설정및분류'!$C$6:$C$12,WEEKDAY(A18,2))*'요약'!$B$13 | I18: ='계좌별시나리오'!J18 | J18: ='계좌별시나리오'!K18 | K18: ='계좌별시나리오'!L18 | L18: ='계좌별시나리오'!M18 | M18: ='계좌별시나리오'!N18 | N18: =SUMIFS('경영보고'!$E$114:$E$135,'경영보고'!$A$114:$A$135,$A18,'경영보고'!$C$114:$C$135,"확정입금") | O18: =SUMIFS('경영보고'!$E$16:$E$109,'경영보고'!$A$16:$A$109,$A18,'경영보고'!$I$16:$I$109,"<>보류",'경영보고'!$F$16:$F$109,"계좌송금") | P18: =SUMIFS('경영보고'!$E$16:$E$109,'경영보고'!$A$16:$A$109,$A18,'경영보고'!$I$16:$I$109,"<>보류",'경영보고'!$F$16:$F$109,"법인카드") | Q18: =SUMIFS('경영보고'!$E$16:$E$109,'경영보고'!$A$16:$A$109,$A18,'경영보고'!$I$16:$I$109,"<>보류")-O18-P18 | R18: =H18+N18-O18-P18-Q18 | S18: =T17 | T18: =S18+R18
A19: 46318 | B19: 금 | C19: ='계좌별시나리오'!D19 | D19: ='계좌별시나리오'!E19 | E19: ='계좌별시나리오'!F19 | F19: ='계좌별시나리오'!G19 | G19: ='계좌별시나리오'!H19 | H19: =INDEX('설정및분류'!$C$6:$C$12,WEEKDAY(A19,2))*'요약'!$B$13 | I19: ='계좌별시나리오'!J19 | J19: ='계좌별시나리오'!K19 | K19: ='계좌별시나리오'!L19 | L19: ='계좌별시나리오'!M19 | M19: ='계좌별시나리오'!N19 | N19: =SUMIFS('경영보고'!$E$114:$E$135,'경영보고'!$A$114:$A$135,$A19,'경영보고'!$C$114:$C$135,"확정입금") | O19: =SUMIFS('경영보고'!$E$16:$E$109,'경영보고'!$A$16:$A$109,$A19,'경영보고'!$I$16:$I$109,"<>보류",'경영보고'!$F$16:$F$109,"계좌송금") | P19: =SUMIFS('경영보고'!$E$16:$E$109,'경영보고'!$A$16:$A$109,$A19,'경영보고'!$I$16:$I$109,"<>보류",'경영보고'!$F$16:$F$109,"법인카드") | Q19: =SUMIFS('경영보고'!$E$16:$E$109,'경영보고'!$A$16:$A$109,$A19,'경영보고'!$I$16:$I$109,"<>보류")-O19-P19 | R19: =H19+N19-O19-P19-Q19 | S19: =T18 | T19: =S19+R19
A20: 46319 | B20: 토 | C20: ='계좌별시나리오'!D20 | D20: ='계좌별시나리오'!E20 | E20: ='계좌별시나리오'!F20 | F20: ='계좌별시나리오'!G20 | G20: ='계좌별시나리오'!H20 | H20: =INDEX('설정및분류'!$C$6:$C$12,WEEKDAY(A20,2))*'요약'!$B$13 | I20: ='계좌별시나리오'!J20 | J20: ='계좌별시나리오'!K20 | K20: ='계좌별시나리오'!L20 | L20: ='계좌별시나리오'!M20 | M20: ='계좌별시나리오'!N20 | N20: =SUMIFS('경영보고'!$E$114:$E$135,'경영보고'!$A$114:$A$135,$A20,'경영보고'!$C$114:$C$135,"확정입금") | O20: =SUMIFS('경영보고'!$E$16:$E$109,'경영보고'!$A$16:$A$109,$A20,'경영보고'!$I$16:$I$109,"<>보류",'경영보고'!$F$16:$F$109,"계좌송금") | P20: =SUMIFS('경영보고'!$E$16:$E$109,'경영보고'!$A$16:$A$109,$A20,'경영보고'!$I$16:$I$109,"<>보류",'경영보고'!$F$16:$F$109,"법인카드") | Q20: =SUMIFS('경영보고'!$E$16:$E$109,'경영보고'!$A$16:$A$109,$A20,'경영보고'!$I$16:$I$109,"<>보류")-O20-P20 | R20: =H20+N20-O20-P20-Q20 | S20: =T19 | T20: =S20+R20
A21: 46320 | B21: 일 | C21: ='계좌별시나리오'!D21 | D21: ='계좌별시나리오'!E21 | E21: ='계좌별시나리오'!F21 | F21: ='계좌별시나리오'!G21 | G21: ='계좌별시나리오'!H21 | H21: =INDEX('설정및분류'!$C$6:$C$12,WEEKDAY(A21,2))*'요약'!$B$13 | I21: ='계좌별시나리오'!J21 | J21: ='계좌별시나리오'!K21 | K21: ='계좌별시나리오'!L21 | L21: ='계좌별시나리오'!M21 | M21: ='계좌별시나리오'!N21 | N21: =SUMIFS('경영보고'!$E$114:$E$135,'경영보고'!$A$114:$A$135,$A21,'경영보고'!$C$114:$C$135,"확정입금") | O21: =SUMIFS('경영보고'!$E$16:$E$109,'경영보고'!$A$16:$A$109,$A21,'경영보고'!$I$16:$I$109,"<>보류",'경영보고'!$F$16:$F$109,"계좌송금") | P21: =SUMIFS('경영보고'!$E$16:$E$109,'경영보고'!$A$16:$A$109,$A21,'경영보고'!$I$16:$I$109,"<>보류",'경영보고'!$F$16:$F$109,"법인카드") | Q21: =SUMIFS('경영보고'!$E$16:$E$109,'경영보고'!$A$16:$A$109,$A21,'경영보고'!$I$16:$I$109,"<>보류")-O21-P21 | R21: =H21+N21-O21-P21-Q21 | S21: =T20 | T21: =S21+R21
A22: 46321 | B22: 월 | C22: ='계좌별시나리오'!D22 | D22: ='계좌별시나리오'!E22 | E22: ='계좌별시나리오'!F22 | F22: ='계좌별시나리오'!G22 | G22: ='계좌별시나리오'!H22 | H22: =INDEX('설정및분류'!$C$6:$C$12,WEEKDAY(A22,2))*'요약'!$B$13 | I22: ='계좌별시나리오'!J22 | J22: ='계좌별시나리오'!K22 | K22: ='계좌별시나리오'!L22 | L22: ='계좌별시나리오'!M22 | M22: ='계좌별시나리오'!N22 | N22: =SUMIFS('경영보고'!$E$114:$E$135,'경영보고'!$A$114:$A$135,$A22,'경영보고'!$C$114:$C$135,"확정입금") | O22: =SUMIFS('경영보고'!$E$16:$E$109,'경영보고'!$A$16:$A$109,$A22,'경영보고'!$I$16:$I$109,"<>보류",'경영보고'!$F$16:$F$109,"계좌송금") | P22: =SUMIFS('경영보고'!$E$16:$E$109,'경영보고'!$A$16:$A$109,$A22,'경영보고'!$I$16:$I$109,"<>보류",'경영보고'!$F$16:$F$109,"법인카드") | Q22: =SUMIFS('경영보고'!$E$16:$E$109,'경영보고'!$A$16:$A$109,$A22,'경영보고'!$I$16:$I$109,"<>보류")-O22-P22 | R22: =H22+N22-O22-P22-Q22 | S22: =T21 | T22: =S22+R22
A23: 46322 | B23: 화 | C23: ='계좌별시나리오'!D23 | D23: ='계좌별시나리오'!E23 | E23: ='계좌별시나리오'!F23 | F23: ='계좌별시나리오'!G23 | G23: ='계좌별시나리오'!H23 | H23: =INDEX('설정및분류'!$C$6:$C$12,WEEKDAY(A23,2))*'요약'!$B$13 | I23: ='계좌별시나리오'!J23 | J23: ='계좌별시나리오'!K23 | K23: ='계좌별시나리오'!L23 | L23: ='계좌별시나리오'!M23 | M23: ='계좌별시나리오'!N23 | N23: =SUMIFS('경영보고'!$E$114:$E$135,'경영보고'!$A$114:$A$135,$A23,'경영보고'!$C$114:$C$135,"확정입금") | O23: =SUMIFS('경영보고'!$E$16:$E$109,'경영보고'!$A$16:$A$109,$A23,'경영보고'!$I$16:$I$109,"<>보류",'경영보고'!$F$16:$F$109,"계좌송금") | P23: =SUMIFS('경영보고'!$E$16:$E$109,'경영보고'!$A$16:$A$109,$A23,'경영보고'!$I$16:$I$109,"<>보류",'경영보고'!$F$16:$F$109,"법인카드") | Q23: =SUMIFS('경영보고'!$E$16:$E$109,'경영보고'!$A$16:$A$109,$A23,'경영보고'!$I$16:$I$109,"<>보류")-O23-P23 | R23: =H23+N23-O23-P23-Q23 | S23: =T22 | T23: =S23+R23
A24: 46323 | B24: 수 | C24: ='계좌별시나리오'!D24 | D24: ='계좌별시나리오'!E24 | E24: ='계좌별시나리오'!F24 | F24: ='계좌별시나리오'!G24 | G24: ='계좌별시나리오'!H24 | H24: =INDEX('설정및분류'!$C$6:$C$12,WEEKDAY(A24,2))*'요약'!$B$13 | I24: ='계좌별시나리오'!J24 | J24: ='계좌별시나리오'!K24 | K24: ='계좌별시나리오'!L24 | L24: ='계좌별시나리오'!M24 | M24: ='계좌별시나리오'!N24 | N24: =SUMIFS('경영보고'!$E$114:$E$135,'경영보고'!$A$114:$A$135,$A24,'경영보고'!$C$114:$C$135,"확정입금") | O24: =SUMIFS('경영보고'!$E$16:$E$109,'경영보고'!$A$16:$A$109,$A24,'경영보고'!$I$16:$I$109,"<>보류",'경영보고'!$F$16:$F$109,"계좌송금") | P24: =SUMIFS('경영보고'!$E$16:$E$109,'경영보고'!$A$16:$A$109,$A24,'경영보고'!$I$16:$I$109,"<>보류",'경영보고'!$F$16:$F$109,"법인카드") | Q24: =SUMIFS('경영보고'!$E$16:$E$109,'경영보고'!$A$16:$A$109,$A24,'경영보고'!$I$16:$I$109,"<>보류")-O24-P24 | R24: =H24+N24-O24-P24-Q24 | S24: =T23 | T24: =S24+R24
... A26: 46325 | B26: 금 | C26: ='계좌별시나리오'!D26 | D26: ='계좌별시나리오'!E26 | E26: ='계좌별시나리오'!F26 | F26: ='계좌별시나리오'!G26 | G26: ='계좌별시나리오'!H26 | H26: =INDEX('설정및분류'!$C$6:$C$12,WEEKDAY(A26,2))*'요약'!$B$13 | I26: ='계좌별시나리오'!J26 | J26: ='계좌별시나리오'!K26 | K26: ='계좌별시나리오'!L26 | L26: ='계좌별시나리오'!M26 | M26: ='계좌별시나리오'!N26 | N26: =SUMIFS('경영보고'!$E$114:$E$135,'경영보고'!$A$114:$A$135,$A26,'경영보고'!$C$114:$C$135,"확정입금") | O26: =SUMIFS('경영보고'!$E$16:$E$109,'경영보고'!$A$16:$A$109,$A26,'경영보고'!$I$16:$I$109,"<>보류",'경영보고'!$F$16:$F$109,"계좌송금") | P26: =SUMIFS('경영보고'!$E$16:$E$109,'경영보고'!$A$16:$A$109,$A26,'경영보고'!$I$16:$I$109,"<>보류",'경영보고'!$F$16:$F$109,"법인카드") | Q26: =SUMIFS('경영보고'!$E$16:$E$109,'경영보고'!$A$16:$A$109,$A26,'경영보고'!$I$16:$I$109,"<>보류")-O26-P26 | R26: =H26+N26-O26-P26-Q26 | S26: =T25 | T26: =S26+R26
A27: 46326 | B27: 토 | C27: ='계좌별시나리오'!D27 | D27: ='계좌별시나리오'!E27 | E27: ='계좌별시나리오'!F27 | F27: ='계좌별시나리오'!G27 | G27: ='계좌별시나리오'!H27 | H27: =INDEX('설정및분류'!$C$6:$C$12,WEEKDAY(A27,2))*'요약'!$B$13 | I27: ='계좌별시나리오'!J27 | J27: ='계좌별시나리오'!K27 | K27: ='계좌별시나리오'!L27 | L27: ='계좌별시나리오'!M27 | M27: ='계좌별시나리오'!N27 | N27: =SUMIFS('경영보고'!$E$114:$E$135,'경영보고'!$A$114:$A$135,$A27,'경영보고'!$C$114:$C$135,"확정입금") | O27: =SUMIFS('경영보고'!$E$16:$E$109,'경영보고'!$A$16:$A$109,$A27,'경영보고'!$I$16:$I$109,"<>보류",'경영보고'!$F$16:$F$109,"계좌송금") | P27: =SUMIFS('경영보고'!$E$16:$E$109,'경영보고'!$A$16:$A$109,$A27,'경영보고'!$I$16:$I$109,"<>보류",'경영보고'!$F$16:$F$109,"법인카드") | Q27: =SUMIFS('경영보고'!$E$16:$E$109,'경영보고'!$A$16:$A$109,$A27,'경영보고'!$I$16:$I$109,"<>보류")-O27-P27 | R27: =H27+N27-O27-P27-Q27 | S27: =T26 | T27: =S27+R27 | U27: 관계사 외상대 입금 추정(주식회사에이팜, 말일)
A28: 46327 | B28: 일 | C28: ='계좌별시나리오'!D28 | D28: ='계좌별시나리오'!E28 | E28: ='계좌별시나리오'!F28 | F28: ='계좌별시나리오'!G28 | G28: ='계좌별시나리오'!H28 | H28: =INDEX('설정및분류'!$C$6:$C$12,WEEKDAY(A28,2))*'요약'!$B$13 | I28: ='계좌별시나리오'!J28 | J28: ='계좌별시나리오'!K28 | K28: ='계좌별시나리오'!L28 | L28: ='계좌별시나리오'!M28 | M28: ='계좌별시나리오'!N28 | N28: =SUMIFS('경영보고'!$E$114:$E$135,'경영보고'!$A$114:$A$135,$A28,'경영보고'!$C$114:$C$135,"확정입금") | O28: =SUMIFS('경영보고'!$E$16:$E$109,'경영보고'!$A$16:$A$109,$A28,'경영보고'!$I$16:$I$109,"<>보류",'경영보고'!$F$16:$F$109,"계좌송금") | P28: =SUMIFS('경영보고'!$E$16:$E$109,'경영보고'!$A$16:$A$109,$A28,'경영보고'!$I$16:$I$109,"<>보류",'경영보고'!$F$16:$F$109,"법인카드") | Q28: =SUMIFS('경영보고'!$E$16:$E$109,'경영보고'!$A$16:$A$109,$A28,'경영보고'!$I$16:$I$109,"<>보류")-O28-P28 | R28: =H28+N28-O28-P28-Q28 | S28: =T27 | T28: =S28+R28
A29: 46328 | B29: 월 | C29: ='계좌별시나리오'!D29 | D29: ='계좌별시나리오'!E29 | E29: ='계좌별시나리오'!F29 | F29: ='계좌별시나리오'!G29 | G29: ='계좌별시나리오'!H29 | H29: =INDEX('설정및분류'!$C$6:$C$12,WEEKDAY(A29,2))*'요약'!$B$13 | I29: ='계좌별시나리오'!J29 | J29: ='계좌별시나리오'!K29 | K29: ='계좌별시나리오'!L29 | L29: ='계좌별시나리오'!M29 | M29: ='계좌별시나리오'!N29 | N29: =SUMIFS('경영보고'!$E$114:$E$135,'경영보고'!$A$114:$A$135,$A29,'경영보고'!$C$114:$C$135,"확정입금") | O29: =SUMIFS('경영보고'!$E$16:$E$109,'경영보고'!$A$16:$A$109,$A29,'경영보고'!$I$16:$I$109,"<>보류",'경영보고'!$F$16:$F$109,"계좌송금") | P29: =SUMIFS('경영보고'!$E$16:$E$109,'경영보고'!$A$16:$A$109,$A29,'경영보고'!$I$16:$I$109,"<>보류",'경영보고'!$F$16:$F$109,"법인카드") | Q29: =SUMIFS('경영보고'!$E$16:$E$109,'경영보고'!$A$16:$A$109,$A29,'경영보고'!$I$16:$I$109,"<>보류")-O29-P29 | R29: =H29+N29-O29-P29-Q29 | S29: =T28 | T29: =S29+R29
A30: 46329 | B30: 화 | C30: ='계좌별시나리오'!D30 | D30: ='계좌별시나리오'!E30 | E30: ='계좌별시나리오'!F30 | F30: ='계좌별시나리오'!G30 | G30: ='계좌별시나리오'!H30 | H30: =INDEX('설정및분류'!$C$6:$C$12,WEEKDAY(A30,2))*'요약'!$B$13 | I30: ='계좌별시나리오'!J30 | J30: ='계좌별시나리오'!K30 | K30: ='계좌별시나리오'!L30 | L30: ='계좌별시나리오'!M30 | M30: ='계좌별시나리오'!N30 | N30: =SUMIFS('경영보고'!$E$114:$E$135,'경영보고'!$A$114:$A$135,$A30,'경영보고'!$C$114:$C$135,"확정입금") | O30: =SUMIFS('경영보고'!$E$16:$E$109,'경영보고'!$A$16:$A$109,$A30,'경영보고'!$I$16:$I$109,"<>보류",'경영보고'!$F$16:$F$109,"계좌송금") | P30: =SUMIFS('경영보고'!$E$16:$E$109,'경영보고'!$A$16:$A$109,$A30,'경영보고'!$I$16:$I$109,"<>보류",'경영보고'!$F$16:$F$109,"법인카드") | Q30: =SUMIFS('경영보고'!$E$16:$E$109,'경영보고'!$A$16:$A$109,$A30,'경영보고'!$I$16:$I$109,"<>보류")-O30-P30 | R30: =H30+N30-O30-P30-Q30 | S30: =T29 | T30: =S30+R30
A31: 46330 | B31: 수 | C31: ='계좌별시나리오'!D31 | D31: ='계좌별시나리오'!E31 | E31: ='계좌별시나리오'!F31 | F31: ='계좌별시나리오'!G31 | G31: ='계좌별시나리오'!H31 | H31: =INDEX('설정및분류'!$C$6:$C$12,WEEKDAY(A31,2))*'요약'!$B$13 | I31: ='계좌별시나리오'!J31 | J31: ='계좌별시나리오'!K31 | K31: ='계좌별시나리오'!L31 | L31: ='계좌별시나리오'!M31 | M31: ='계좌별시나리오'!N31 | N31: =SUMIFS('경영보고'!$E$114:$E$135,'경영보고'!$A$114:$A$135,$A31,'경영보고'!$C$114:$C$135,"확정입금") | O31: =SUMIFS('경영보고'!$E$16:$E$109,'경영보고'!$A$16:$A$109,$A31,'경영보고'!$I$16:$I$109,"<>보류",'경영보고'!$F$16:$F$109,"계좌송금") | P31: =SUMIFS('경영보고'!$E$16:$E$109,'경영보고'!$A$16:$A$109,$A31,'경영보고'!$I$16:$I$109,"<>보류",'경영보고'!$F$16:$F$109,"법인카드") | Q31: =SUMIFS('경영보고'!$E$16:$E$109,'경영보고'!$A$16:$A$109,$A31,'경영보고'!$I$16:$I$109,"<>보류")-O31-P31 | R31: =H31+N31-O31-P31-Q31 | S31: =T30 | T31: =S31+R31
A32: 46331 | B32: 목 | C32: ='계좌별시나리오'!D32 | D32: ='계좌별시나리오'!E32 | E32: ='계좌별시나리오'!F32 | F32: ='계좌별시나리오'!G32 | G32: ='계좌별시나리오'!H32 | H32: =INDEX('설정및분류'!$C$6:$C$12,WEEKDAY(A32,2))*'요약'!$B$13 | I32: ='계좌별시나리오'!J32 | J32: ='계좌별시나리오'!K32 | K32: ='계좌별시나리오'!L32 | L32: ='계좌별시나리오'!M32 | M32: ='계좌별시나리오'!N32 | N32: =SUMIFS('경영보고'!$E$114:$E$135,'경영보고'!$A$114:$A$135,$A32,'경영보고'!$C$114:$C$135,"확정입금") | O32: =SUMIFS('경영보고'!$E$16:$E$109,'경영보고'!$A$16:$A$109,$A32,'경영보고'!$I$16:$I$109,"<>보류",'경영보고'!$F$16:$F$109,"계좌송금") | P32: =SUMIFS('경영보고'!$E$16:$E$109,'경영보고'!$A$16:$A$109,$A32,'경영보고'!$I$16:$I$109,"<>보류",'경영보고'!$F$16:$F$109,"법인카드") | Q32: =SUMIFS('경영보고'!$E$16:$E$109,'경영보고'!$A$16:$A$109,$A32,'경영보고'!$I$16:$I$109,"<>보류")-O32-P32 | R32: =H32+N32-O32-P32-Q32 | S32: =T31 | T32: =S32+R32
A33: 46332 | B33: 금 | C33: ='계좌별시나리오'!D33 | D33: ='계좌별시나리오'!E33 | E33: ='계좌별시나리오'!F33 | F33: ='계좌별시나리오'!G33 | G33: ='계좌별시나리오'!H33 | H33: =INDEX('설정및분류'!$C$6:$C$12,WEEKDAY(A33,2))*'요약'!$B$13 | I33: ='계좌별시나리오'!J33 | J33: ='계좌별시나리오'!K33 | K33: ='계좌별시나리오'!L33 | L33: ='계좌별시나리오'!M33 | M33: ='계좌별시나리오'!N33 | N33: =SUMIFS('경영보고'!$E$114:$E$135,'경영보고'!$A$114:$A$135,$A33,'경영보고'!$C$114:$C$135,"확정입금") | O33: =SUMIFS('경영보고'!$E$16:$E$109,'경영보고'!$A$16:$A$109,$A33,'경영보고'!$I$16:$I$109,"<>보류",'경영보고'!$F$16:$F$109,"계좌송금") | P33: =SUMIFS('경영보고'!$E$16:$E$109,'경영보고'!$A$16:$A$109,$A33,'경영보고'!$I$16:$I$109,"<>보류",'경영보고'!$F$16:$F$109,"법인카드") | Q33: =SUMIFS('경영보고'!$E$16:$E$109,'경영보고'!$A$16:$A$109,$A33,'경영보고'!$I$16:$I$109,"<>보류")-O33-P33 | R33: =H33+N33-O33-P33-Q33 | S33: =T32 | T33: =S33+R33
A34: 46333 | B34: 토 | C34: ='계좌별시나리오'!D34 | D34: ='계좌별시나리오'!E34 | E34: ='계좌별시나리오'!F34 | F34: ='계좌별시나리오'!G34 | G34: ='계좌별시나리오'!H34 | H34: =INDEX('설정및분류'!$C$6:$C$12,WEEKDAY(A34,2))*'요약'!$B$13 | I34: ='계좌별시나리오'!J34 | J34: ='계좌별시나리오'!K34 | K34: ='계좌별시나리오'!L34 | L34: ='계좌별시나리오'!M34 | M34: ='계좌별시나리오'!N34 | N34: =SUMIFS('경영보고'!$E$114:$E$135,'경영보고'!$A$114:$A$135,$A34,'경영보고'!$C$114:$C$135,"확정입금") | O34: =SUMIFS('경영보고'!$E$16:$E$109,'경영보고'!$A$16:$A$109,$A34,'경영보고'!$I$16:$I$109,"<>보류",'경영보고'!$F$16:$F$109,"계좌송금") | P34: =SUMIFS('경영보고'!$E$16:$E$109,'경영보고'!$A$16:$A$109,$A34,'경영보고'!$I$16:$I$109,"<>보류",'경영보고'!$F$16:$F$109,"법인카드") | Q34: =SUMIFS('경영보고'!$E$16:$E$109,'경영보고'!$A$16:$A$109,$A34,'경영보고'!$I$16:$I$109,"<>보류")-O34-P34 | R34: =H34+N34-O34-P34-Q34 | S34: =T33 | T34: =S34+R34
A35: 46334 | B35: 일 | C35: ='계좌별시나리오'!D35 | D35: ='계좌별시나리오'!E35 | E35: ='계좌별시나리오'!F35 | F35: ='계좌별시나리오'!G35 | G35: ='계좌별시나리오'!H35 | H35: =INDEX('설정및분류'!$C$6:$C$12,WEEKDAY(A35,2))*'요약'!$B$13 | I35: ='계좌별시나리오'!J35 | J35: ='계좌별시나리오'!K35 | K35: ='계좌별시나리오'!L35 | L35: ='계좌별시나리오'!M35 | M35: ='계좌별시나리오'!N35 | N35: =SUMIFS('경영보고'!$E$114:$E$135,'경영보고'!$A$114:$A$135,$A35,'경영보고'!$C$114:$C$135,"확정입금") | O35: =SUMIFS('경영보고'!$E$16:$E$109,'경영보고'!$A$16:$A$109,$A35,'경영보고'!$I$16:$I$109,"<>보류",'경영보고'!$F$16:$F$109,"계좌송금") | P35: =SUMIFS('경영보고'!$E$16:$E$109,'경영보고'!$A$16:$A$109,$A35,'경영보고'!$I$16:$I$109,"<>보류",'경영보고'!$F$16:$F$109,"법인카드") | Q35: =SUMIFS('경영보고'!$E$16:$E$109,'경영보고'!$A$16:$A$109,$A35,'경영보고'!$I$16:$I$109,"<>보류")-O35-P35 | R35: =H35+N35-O35-P35-Q35 | S35: =T34 | T35: =S35+R35

Sheet 계좌별시나리오
A2: 계좌별 일별 잔액 시나리오 (자동 반영)
A3: 읽는 법: 오늘 총잔액 = 전날 총잔액 + ② 입금 합계 − ③ 지출. 지출은 전액 우리은행에서 집행하고, 모자라면 ④처럼 농협 → 국민 순으로 우리은행에 이체해 채웁니다. '요약' 시트의 입금 반영률(B13)을 바꾸면 이 표도 즉시 다시 계산됩니다. 지난 실적 일자 행은 숨김(마지막 실적일 잔액에서 출발), 실수 방지를 위해 시트 보호(암호 없음). ② 배분 비중(최근 입금 실적): 우리 220351 44% · 농협 569003 2% · 국민 154577 34% · 국민 170616 0% · 국민 169124 19%
A4: 일자 | B4: 요일 | C4: ① 잔액 (총잔액 · 계좌별) | I4: ② 오늘 들어오는 돈 — 예상입금 배분 | O4: ③ 지출 | P4: ④ 부족분 이체 | R4: 비고
C5: 총잔액 | D5: 우리 220351 | E5: 농협 569003 | F5: 국민 154577 | G5: 국민 170616 | H5: 국민 169124 | I5: 합계 | J5: 우리 220351 | K5: 농협 569003 | L5: 국민 154577 | M5: 국민 170616 | N5: 국민 169124 | O5: 우리은행 집행 | P5: 농협→우리 | Q5: 국민→우리
A6: 46311 | B6: 금 | C6: =SUM(D6:H6) | D6: 6011615 | E6: 441400 | F6: 62178003 | G6: 31550000 | H6: 20687200 | R6: 전일 마감 실잔고 — 여기서 출발
A7: 46312 | B7: 토 | C7: =SUM(D7:H7) | D7: 6011615 | E7: 441400 | F7: 62178003 | G7: 31550000 | H7: 20687200 | R7: 오늘 실잔고(은행 확인) — 참고
A8: 46307 | B8: 월 | R8: 실적 구간
A9: 46308 | B9: 화 | R9: 실적 구간
A10: 46309 | B10: 수 | R10: 실적 구간
A11: 46310 | B11: 목 | R11: 실적 구간
A12: 46311 | B12: 금 | C12: 120868218 | D12: 6011615 | E12: 441400 | F12: 62178003 | G12: 31550000 | H12: 20687200 | R12: 실적 구간
A13: 46312 | B13: 토 | C13: =SUM(D13:H13) | D13: =D12+J13-O13+S13+T13+U13+V13 | E13: =E12+K13-S13 | F13: =F12+L13-T13 | G13: =G12+M13-U13 | H13: =H12+N13-V13 | I13: ='4주일별계획'!H13+'4주일별계획'!N13 | J13: =I13*0.442625 | K13: =I13*0.022831 | L13: =I13*0.342410 | M13: =I13*0.000000 | N13: =I13*0.192134 | O13: ='4주일별계획'!O13+'4주일별계획'!P13+'4주일별계획'!Q13 | P13: =S13 | Q13: =T13+U13+V13 | R13: =IF(D13<-0.5,"전 계좌 소진 — 부족 "&TEXT(-D13,"#,##0")&"원","") | S13: =MIN(MAX(0,E12+K13),MAX(0,O13-D12-J13)) | T13: =MIN(MAX(0,F12+L13),MAX(0,O13-D12-J13)-S13) | U13: =MIN(MAX(0,G12+M13),MAX(0,O13-D12-J13)-S13-T13) | V13: =MIN(MAX(0,H12+N13),MAX(0,O13-D12-J13)-S13-T13-U13)
A14: 46313 | B14: 일 | C14: =SUM(D14:H14) | D14: =D13+J14-O14+S14+T14+U14+V14 | E14: =E13+K14-S14 | F14: =F13+L14-T14 | G14: =G13+M14-U14 | H14: =H13+N14-V14 | I14: ='4주일별계획'!H14+'4주일별계획'!N14 | J14: =I14*0.442625 | K14: =I14*0.022831 | L14: =I14*0.342410 | M14: =I14*0.000000 | N14: =I14*0.192134 | O14: ='4주일별계획'!O14+'4주일별계획'!P14+'4주일별계획'!Q14 | P14: =S14 | Q14: =T14+U14+V14 | R14: =IF(D14<-0.5,"전 계좌 소진 — 부족 "&TEXT(-D14,"#,##0")&"원","") | S14: =MIN(MAX(0,E13+K14),MAX(0,O14-D13-J14)) | T14: =MIN(MAX(0,F13+L14),MAX(0,O14-D13-J14)-S14) | U14: =MIN(MAX(0,G13+M14),MAX(0,O14-D13-J14)-S14-T14) | V14: =MIN(MAX(0,H13+N14),MAX(0,O14-D13-J14)-S14-T14-U14)
A15: 46314 | B15: 월 | C15: =SUM(D15:H15) | D15: =D14+J15-O15+S15+T15+U15+V15 | E15: =E14+K15-S15 | F15: =F14+L15-T15 | G15: =G14+M15-U15 | H15: =H14+N15-V15 | I15: ='4주일별계획'!H15+'4주일별계획'!N15 | J15: =I15*0.442625 | K15: =I15*0.022831 | L15: =I15*0.342410 | M15: =I15*0.000000 | N15: =I15*0.192134 | O15: ='4주일별계획'!O15+'4주일별계획'!P15+'4주일별계획'!Q15 | P15: =S15 | Q15: =T15+U15+V15 | R15: =IF(D15<-0.5,"전 계좌 소진 — 부족 "&TEXT(-D15,"#,##0")&"원","") | S15: =MIN(MAX(0,E14+K15),MAX(0,O15-D14-J15)) | T15: =MIN(MAX(0,F14+L15),MAX(0,O15-D14-J15)-S15) | U15: =MIN(MAX(0,G14+M15),MAX(0,O15-D14-J15)-S15-T15) | V15: =MIN(MAX(0,H14+N15),MAX(0,O15-D14-J15)-S15-T15-U15)
A16: 46315 | B16: 화 | C16: =SUM(D16:H16) | D16: =D15+J16-O16+S16+T16+U16+V16 | E16: =E15+K16-S16 | F16: =F15+L16-T16 | G16: =G15+M16-U16 | H16: =H15+N16-V16 | I16: ='4주일별계획'!H16+'4주일별계획'!N16 | J16: =I16*0.442625 | K16: =I16*0.022831 | L16: =I16*0.342410 | M16: =I16*0.000000 | N16: =I16*0.192134 | O16: ='4주일별계획'!O16+'4주일별계획'!P16+'4주일별계획'!Q16 | P16: =S16 | Q16: =T16+U16+V16 | R16: =IF(D16<-0.5,"전 계좌 소진 — 부족 "&TEXT(-D16,"#,##0")&"원","") | S16: =MIN(MAX(0,E15+K16),MAX(0,O16-D15-J16)) | T16: =MIN(MAX(0,F15+L16),MAX(0,O16-D15-J16)-S16) | U16: =MIN(MAX(0,G15+M16),MAX(0,O16-D15-J16)-S16-T16) | V16: =MIN(MAX(0,H15+N16),MAX(0,O16-D15-J16)-S16-T16-U16)
A17: 46316 | B17: 수 | C17: =SUM(D17:H17) | D17: =D16+J17-O17+S17+T17+U17+V17 | E17: =E16+K17-S17 | F17: =F16+L17-T17 | G17: =G16+M17-U17 | H17: =H16+N17-V17 | I17: ='4주일별계획'!H17+'4주일별계획'!N17 | J17: =I17*0.442625 | K17: =I17*0.022831 | L17: =I17*0.342410 | M17: =I17*0.000000 | N17: =I17*0.192134 | O17: ='4주일별계획'!O17+'4주일별계획'!P17+'4주일별계획'!Q17 | P17: =S17 | Q17: =T17+U17+V17 | R17: =IF(D17<-0.5,"전 계좌 소진 — 부족 "&TEXT(-D17,"#,##0")&"원","") | S17: =MIN(MAX(0,E16+K17),MAX(0,O17-D16-J17)) | T17: =MIN(MAX(0,F16+L17),MAX(0,O17-D16-J17)-S17) | U17: =MIN(MAX(0,G16+M17),MAX(0,O17-D16-J17)-S17-T17) | V17: =MIN(MAX(0,H16+N17),MAX(0,O17-D16-J17)-S17-T17-U17)
A18: 46317 | B18: 목 | C18: =SUM(D18:H18) | D18: =D17+J18-O18+S18+T18+U18+V18 | E18: =E17+K18-S18 | F18: =F17+L18-T18 | G18: =G17+M18-U18 | H18: =H17+N18-V18 | I18: ='4주일별계획'!H18+'4주일별계획'!N18 | J18: =I18*0.442625 | K18: =I18*0.022831 | L18: =I18*0.342410 | M18: =I18*0.000000 | N18: =I18*0.192134 | O18: ='4주일별계획'!O18+'4주일별계획'!P18+'4주일별계획'!Q18 | P18: =S18 | Q18: =T18+U18+V18 | R18: =IF(D18<-0.5,"전 계좌 소진 — 부족 "&TEXT(-D18,"#,##0")&"원","") | S18: =MIN(MAX(0,E17+K18),MAX(0,O18-D17-J18)) | T18: =MIN(MAX(0,F17+L18),MAX(0,O18-D17-J18)-S18) | U18: =MIN(MAX(0,G17+M18),MAX(0,O18-D17-J18)-S18-T18) | V18: =MIN(MAX(0,H17+N18),MAX(0,O18-D17-J18)-S18-T18-U18)
A19: 46318 | B19: 금 | C19: =SUM(D19:H19) | D19: =D18+J19-O19+S19+T19+U19+V19 | E19: =E18+K19-S19 | F19: =F18+L19-T19 | G19: =G18+M19-U19 | H19: =H18+N19-V19 | I19: ='4주일별계획'!H19+'4주일별계획'!N19 | J19: =I19*0.442625 | K19: =I19*0.022831 | L19: =I19*0.342410 | M19: =I19*0.000000 | N19: =I19*0.192134 | O19: ='4주일별계획'!O19+'4주일별계획'!P19+'4주일별계획'!Q19 | P19: =S19 | Q19: =T19+U19+V19 | R19: =IF(D19<-0.5,"전 계좌 소진 — 부족 "&TEXT(-D19,"#,##0")&"원","") | S19: =MIN(MAX(0,E18+K19),MAX(0,O19-D18-J19)) | T19: =MIN(MAX(0,F18+L19),MAX(0,O19-D18-J19)-S19) | U19: =MIN(MAX(0,G18+M19),MAX(0,O19-D18-J19)-S19-T19) | V19: =MIN(MAX(0,H18+N19),MAX(0,O19-D18-J19)-S19-T19-U19)
A20: 46319 | B20: 토 | C20: =SUM(D20:H20) | D20: =D19+J20-O20+S20+T20+U20+V20 | E20: =E19+K20-S20 | F20: =F19+L20-T20 | G20: =G19+M20-U20 | H20: =H19+N20-V20 | I20: ='4주일별계획'!H20+'4주일별계획'!N20 | J20: =I20*0.442625 | K20: =I20*0.022831 | L20: =I20*0.342410 | M20: =I20*0.000000 | N20: =I20*0.192134 | O20: ='4주일별계획'!O20+'4주일별계획'!P20+'4주일별계획'!Q20 | P20: =S20 | Q20: =T20+U20+V20 | R20: =IF(D20<-0.5,"전 계좌 소진 — 부족 "&TEXT(-D20,"#,##0")&"원","") | S20: =MIN(MAX(0,E19+K20),MAX(0,O20-D19-J20)) | T20: =MIN(MAX(0,F19+L20),MAX(0,O20-D19-J20)-S20) | U20: =MIN(MAX(0,G19+M20),MAX(0,O20-D19-J20)-S20-T20) | V20: =MIN(MAX(0,H19+N20),MAX(0,O20-D19-J20)-S20-T20-U20)
A21: 46320 | B21: 일 | C21: =SUM(D21:H21) | D21: =D20+J21-O21+S21+T21+U21+V21 | E21: =E20+K21-S21 | F21: =F20+L21-T21 | G21: =G20+M21-U21 | H21: =H20+N21-V21 | I21: ='4주일별계획'!H21+'4주일별계획'!N21 | J21: =I21*0.442625 | K21: =I21*0.022831 | L21: =I21*0.342410 | M21: =I21*0.000000 | N21: =I21*0.192134 | O21: ='4주일별계획'!O21+'4주일별계획'!P21+'4주일별계획'!Q21 | P21: =S21 | Q21: =T21+U21+V21 | R21: =IF(D21<-0.5,"전 계좌 소진 — 부족 "&TEXT(-D21,"#,##0")&"원","") | S21: =MIN(MAX(0,E20+K21),MAX(0,O21-D20-J21)) | T21: =MIN(MAX(0,F20+L21),MAX(0,O21-D20-J21)-S21) | U21: =MIN(MAX(0,G20+M21),MAX(0,O21-D20-J21)-S21-T21) | V21: =MIN(MAX(0,H20+N21),MAX(0,O21-D20-J21)-S21-T21-U21)
A22: 46321 | B22: 월 | C22: =SUM(D22:H22) | D22: =D21+J22-O22+S22+T22+U22+V22 | E22: =E21+K22-S22 | F22: =F21+L22-T22 | G22: =G21+M22-U22 | H22: =H21+N22-V22 | I22: ='4주일별계획'!H22+'4주일별계획'!N22 | J22: =I22*0.442625 | K22: =I22*0.022831 | L22: =I22*0.342410 | M22: =I22*0.000000 | N22: =I22*0.192134 | O22: ='4주일별계획'!O22+'4주일별계획'!P22+'4주일별계획'!Q22 | P22: =S22 | Q22: =T22+U22+V22 | R22: =IF(D22<-0.5,"전 계좌 소진 — 부족 "&TEXT(-D22,"#,##0")&"원","") | S22: =MIN(MAX(0,E21+K22),MAX(0,O22-D21-J22)) | T22: =MIN(MAX(0,F21+L22),MAX(0,O22-D21-J22)-S22) | U22: =MIN(MAX(0,G21+M22),MAX(0,O22-D21-J22)-S22-T22) | V22: =MIN(MAX(0,H21+N22),MAX(0,O22-D21-J22)-S22-T22-U22)
A23: 46322 | B23: 화 | C23: =SUM(D23:H23) | D23: =D22+J23-O23+S23+T23+U23+V23 | E23: =E22+K23-S23 | F23: =F22+L23-T23 | G23: =G22+M23-U23 | H23: =H22+N23-V23 | I23: ='4주일별계획'!H23+'4주일별계획'!N23 | J23: =I23*0.442625 | K23: =I23*0.022831 | L23: =I23*0.342410 | M23: =I23*0.000000 | N23: =I23*0.192134 | O23: ='4주일별계획'!O23+'4주일별계획'!P23+'4주일별계획'!Q23 | P23: =S23 | Q23: =T23+U23+V23 | R23: =IF(D23<-0.5,"전 계좌 소진 — 부족 "&TEXT(-D23,"#,##0")&"원","") | S23: =MIN(MAX(0,E22+K23),MAX(0,O23-D22-J23)) | T23: =MIN(MAX(0,F22+L23),MAX(0,O23-D22-J23)-S23) | U23: =MIN(MAX(0,G22+M23),MAX(0,O23-D22-J23)-S23-T23) | V23: =MIN(MAX(0,H22+N23),MAX(0,O23-D22-J23)-S23-T23-U23)
A24: 46323 | B24: 수 | C24: =SUM(D24:H24) | D24: =D23+J24-O24+S24+T24+U24+V24 | E24: =E23+K24-S24 | F24: =F23+L24-T24 | G24: =G23+M24-U24 | H24: =H23+N24-V24 | I24: ='4주일별계획'!H24+'4주일별계획'!N24 | J24: =I24*0.442625 | K24: =I24*0.022831 | L24: =I24*0.342410 | M24: =I24*0.000000 | N24: =I24*0.192134 | O24: ='4주일별계획'!O24+'4주일별계획'!P24+'4주일별계획'!Q24 | P24: =S24 | Q24: =T24+U24+V24 | R24: =IF(D24<-0.5,"전 계좌 소진 — 부족 "&TEXT(-D24,"#,##0")&"원","") | S24: =MIN(MAX(0,E23+K24),MAX(0,O24-D23-J24)) | T24: =MIN(MAX(0,F23+L24),MAX(0,O24-D23-J24)-S24) | U24: =MIN(MAX(0,G23+M24),MAX(0,O24-D23-J24)-S24-T24) | V24: =MIN(MAX(0,H23+N24),MAX(0,O24-D23-J24)-S24-T24-U24)
... A35: 46334 | B35: 일 | C35: =SUM(D35:H35) | D35: =D34+J35-O35+S35+T35+U35+V35 | E35: =E34+K35-S35 | F35: =F34+L35-T35 | G35: =G34+M35-U35 | H35: =H34+N35-V35 | I35: ='4주일별계획'!H35+'4주일별계획'!N35 | J35: =I35*0.442625 | K35: =I35*0.022831 | L35: =I35*0.342410 | M35: =I35*0.000000 | N35: =I35*0.192134 | O35: ='4주일별계획'!O35+'4주일별계획'!P35+'4주일별계획'!Q35 | P35: =S35 | Q35: =T35+U35+V35 | R35: =IF(D35<-0.5,"전 계좌 소진 — 부족 "&TEXT(-D35,"#,##0")&"원","") | S35: =MIN(MAX(0,E34+K35),MAX(0,O35-D34-J35)) | T35: =MIN(MAX(0,F34+L35),MAX(0,O35-D34-J35)-S35) | U35: =MIN(MAX(0,G34+M35),MAX(0,O35-D34-J35)-S35-T35) | V35: =MIN(MAX(0,H34+N35),MAX(0,O35-D34-J35)-S35-T35-U35)

Sheet 13주주별계획
A2: 향후 13주 주별 자금계획
A3: ="온라인 예상입금 반영률 "&TEXT('요약'!$B$13,"0%")&" 적용. 1~4주는 일별 계획 합계, 5~13주는 자동 예상입금과 입력한 주간 계획을 반영합니다."
A5: 주차 | B5: 기간 | C5: 온라인 예상입금 | D5: 확정·기타입금 | E5: 송금예정 | F5: 카드결제 | G5: 조정·추정 지출 | H5: 추가 주간조정 | I5: 순현금흐름 | J5: 기말잔액 | K5: 상태
A6: 1주차 | B6: 2026-10-12 ~ 2026-10-18 | C6: =SUMIFS('4주일별계획'!$H$8:$H$35,'4주일별계획'!$A$8:$A$35,">="&DATE(2026,10,12),'4주일별계획'!$A$8:$A$35,"<="&DATE(2026,10,18)) | D6: =SUMIFS('4주일별계획'!$N$8:$N$35,'4주일별계획'!$A$8:$A$35,">="&DATE(2026,10,12),'4주일별계획'!$A$8:$A$35,"<="&DATE(2026,10,18)) | E6: =SUMIFS('4주일별계획'!$O$8:$O$35,'4주일별계획'!$A$8:$A$35,">="&DATE(2026,10,12),'4주일별계획'!$A$8:$A$35,"<="&DATE(2026,10,18)) | F6: =SUMIFS('4주일별계획'!$P$8:$P$35,'4주일별계획'!$A$8:$A$35,">="&DATE(2026,10,12),'4주일별계획'!$A$8:$A$35,"<="&DATE(2026,10,18)) | G6: =SUMIFS('4주일별계획'!$Q$8:$Q$35,'4주일별계획'!$A$8:$A$35,">="&DATE(2026,10,12),'4주일별계획'!$A$8:$A$35,"<="&DATE(2026,10,18)) | I6: =C6+D6-E6-F6-G6+H6 | J6: ='요약'!$B$6+I6 | K6: =IF(J6<0,"자금부족",IF(J6<'요약'!$B$6*0.2,"주의","정상"))
A7: 2주차 | B7: 2026-10-19 ~ 2026-10-25 | C7: =SUMIFS('4주일별계획'!$H$8:$H$35,'4주일별계획'!$A$8:$A$35,">="&DATE(2026,10,19),'4주일별계획'!$A$8:$A$35,"<="&DATE(2026,10,25)) | D7: =SUMIFS('4주일별계획'!$N$8:$N$35,'4주일별계획'!$A$8:$A$35,">="&DATE(2026,10,19),'4주일별계획'!$A$8:$A$35,"<="&DATE(2026,10,25)) | E7: =SUMIFS('4주일별계획'!$O$8:$O$35,'4주일별계획'!$A$8:$A$35,">="&DATE(2026,10,19),'4주일별계획'!$A$8:$A$35,"<="&DATE(2026,10,25)) | F7: =SUMIFS('4주일별계획'!$P$8:$P$35,'4주일별계획'!$A$8:$A$35,">="&DATE(2026,10,19),'4주일별계획'!$A$8:$A$35,"<="&DATE(2026,10,25)) | G7: =SUMIFS('4주일별계획'!$Q$8:$Q$35,'4주일별계획'!$A$8:$A$35,">="&DATE(2026,10,19),'4주일별계획'!$A$8:$A$35,"<="&DATE(2026,10,25)) | I7: =C7+D7-E7-F7-G7+H7 | J7: =J6+I7 | K7: =IF(J7<0,"자금부족",IF(J7<'요약'!$B$6*0.2,"주의","정상"))
A8: 3주차 | B8: 2026-10-26 ~ 2026-11-01 | C8: =SUMIFS('4주일별계획'!$H$8:$H$35,'4주일별계획'!$A$8:$A$35,">="&DATE(2026,10,26),'4주일별계획'!$A$8:$A$35,"<="&DATE(2026,11,1)) | D8: =SUMIFS('4주일별계획'!$N$8:$N$35,'4주일별계획'!$A$8:$A$35,">="&DATE(2026,10,26),'4주일별계획'!$A$8:$A$35,"<="&DATE(2026,11,1)) | E8: =SUMIFS('4주일별계획'!$O$8:$O$35,'4주일별계획'!$A$8:$A$35,">="&DATE(2026,10,26),'4주일별계획'!$A$8:$A$35,"<="&DATE(2026,11,1)) | F8: =SUMIFS('4주일별계획'!$P$8:$P$35,'4주일별계획'!$A$8:$A$35,">="&DATE(2026,10,26),'4주일별계획'!$A$8:$A$35,"<="&DATE(2026,11,1)) | G8: =SUMIFS('4주일별계획'!$Q$8:$Q$35,'4주일별계획'!$A$8:$A$35,">="&DATE(2026,10,26),'4주일별계획'!$A$8:$A$35,"<="&DATE(2026,11,1)) | I8: =C8+D8-E8-F8-G8+H8 | J8: =J7+I8 | K8: =IF(J8<0,"자금부족",IF(J8<'요약'!$B$6*0.2,"주의","정상"))
A9: 4주차 | B9: 2026-11-02 ~ 2026-11-08 | C9: =SUMIFS('4주일별계획'!$H$8:$H$35,'4주일별계획'!$A$8:$A$35,">="&DATE(2026,11,2),'4주일별계획'!$A$8:$A$35,"<="&DATE(2026,11,8)) | D9: =SUMIFS('4주일별계획'!$N$8:$N$35,'4주일별계획'!$A$8:$A$35,">="&DATE(2026,11,2),'4주일별계획'!$A$8:$A$35,"<="&DATE(2026,11,8)) | E9: =SUMIFS('4주일별계획'!$O$8:$O$35,'4주일별계획'!$A$8:$A$35,">="&DATE(2026,11,2),'4주일별계획'!$A$8:$A$35,"<="&DATE(2026,11,8)) | F9: =SUMIFS('4주일별계획'!$P$8:$P$35,'4주일별계획'!$A$8:$A$35,">="&DATE(2026,11,2),'4주일별계획'!$A$8:$A$35,"<="&DATE(2026,11,8)) | G9: =SUMIFS('4주일별계획'!$Q$8:$Q$35,'4주일별계획'!$A$8:$A$35,">="&DATE(2026,11,2),'4주일별계획'!$A$8:$A$35,"<="&DATE(2026,11,8)) | I9: =C9+D9-E9-F9-G9+H9 | J9: =J8+I9 | K9: =IF(J9<0,"자금부족",IF(J9<'요약'!$B$6*0.2,"주의","정상"))
A10: 5주차 | B10: 2026-11-09 ~ 2026-11-15 | C10: =SUM('설정및분류'!$C$6:$C$12)*'요약'!$B$13 | I10: =C10+D10-E10-F10-G10+H10 | J10: =J9+I10 | K10: =IF(J10<0,"자금부족",IF(J10<'요약'!$B$6*0.2,"주의","정상"))
A11: 6주차 | B11: 2026-11-16 ~ 2026-11-22 | C11: =SUM('설정및분류'!$C$6:$C$12)*'요약'!$B$13 | I11: =C11+D11-E11-F11-G11+H11 | J11: =J10+I11 | K11: =IF(J11<0,"자금부족",IF(J11<'요약'!$B$6*0.2,"주의","정상"))
A12: 7주차 | B12: 2026-11-23 ~ 2026-11-29 | C12: =SUM('설정및분류'!$C$6:$C$12)*'요약'!$B$13 | F12: 1975000 | I12: =C12+D12-E12-F12-G12+H12 | J12: =J11+I12 | K12: =IF(J12<0,"자금부족",IF(J12<'요약'!$B$6*0.2,"주의","정상"))
A13: 8주차 | B13: 2026-11-30 ~ 2026-12-06 | C13: =SUM('설정및분류'!$C$6:$C$12)*'요약'!$B$13 | D13: 10021867 | I13: =C13+D13-E13-F13-G13+H13 | J13: =J12+I13 | K13: =IF(J13<0,"자금부족",IF(J13<'요약'!$B$6*0.2,"주의","정상"))
A14: 9주차 | B14: 2026-12-07 ~ 2026-12-13 | C14: =SUM('설정및분류'!$C$6:$C$12)*'요약'!$B$13 | I14: =C14+D14-E14-F14-G14+H14 | J14: =J13+I14 | K14: =IF(J14<0,"자금부족",IF(J14<'요약'!$B$6*0.2,"주의","정상"))
A15: 10주차 | B15: 2026-12-14 ~ 2026-12-20 | C15: =SUM('설정및분류'!$C$6:$C$12)*'요약'!$B$13 | I15: =C15+D15-E15-F15-G15+H15 | J15: =J14+I15 | K15: =IF(J15<0,"자금부족",IF(J15<'요약'!$B$6*0.2,"주의","정상"))
A16: 11주차 | B16: 2026-12-21 ~ 2026-12-27 | C16: =SUM('설정및분류'!$C$6:$C$12)*'요약'!$B$13 | I16: =C16+D16-E16-F16-G16+H16 | J16: =J15+I16 | K16: =IF(J16<0,"자금부족",IF(J16<'요약'!$B$6*0.2,"주의","정상"))
A17: 12주차 | B17: 2026-12-28 ~ 2027-01-03 | C17: =SUM('설정및분류'!$C$6:$C$12)*'요약'!$B$13 | I17: =C17+D17-E17-F17-G17+H17 | J17: =J16+I17 | K17: =IF(J17<0,"자금부족",IF(J17<'요약'!$B$6*0.2,"주의","정상"))
A18: 13주차 | B18: 2027-01-04 ~ 2027-01-10 | C18: =SUM('설정및분류'!$C$6:$C$12)*'요약'!$B$13 | I18: =C18+D18-E18-F18-G18+H18 | J18: =J17+I18 | K18: =IF(J18<0,"자금부족",IF(J18<'요약'!$B$6*0.2,"주의","정상"))

Sheet 지출계획_취합
A2: 팀 지출계획 취합 (자동 반영)
A3: 매 실행마다 팀 제출 파일에서 자동 갱신됩니다. 대외비는 분류·총액만 표시됩니다. 경영보고와 같은 실행일~차주 금요일 기간만 표시합니다 (그 밖의 반영일 행은 숨김 — 행 숨기기 해제로 전체 확인).
A5: 요청ID | B5: 팀명 | C5: 신청자 | D5: 품의승인 | E5: 지급예정일 | F5: 자금계획 반영일 | G5: 거래처 | H5: 지출내용 | I5: 예상금액 | J5: 지급방법 | K5: 카드구분 | L5: 확정여부 | M5: 진행상태 | N5: 최종수정일 | O5: 원본파일 | P5: 반영상태 | Q5: 확인사항
A6: 건강-20261012-001 | B6: 건강사업팀 | C6: 전은신 | E6: 46307 | F6: 46307 | G6: 네이버 | H6: 네이버 SA&GFA 광고 비용 | I6: 1683000 | J6: 계좌송금 | L6: 확정 | M6: 신규 | N6: 46307 | O6: 지출계획_2026-10-17.xlsx | P6: 정상반영
A7: 경영-20261012-003 | B7: 경영지원팀 | C7: 송채은 | E7: 46307 | F7: 46307 | G7: 원천세 | H7: 9월 원천세 | I7: 3511130 | J7: 계좌송금 | L7: 확정 | M7: 신규 | N7: 46307 | O7: 지출계획_2026-10-17.xlsx | P7: 에이팜 별도관리
A8: 경영-20261012-004 | B8: 경영지원팀 | C8: 송채은 | E8: 46307 | F8: 46307 | G8: 4대보험 | H8: 9월 4대보험료 | I8: 4576870 | J8: 자동이체 | L8: 확정 | M8: 신규 | N8: 46307 | O8: 지출계획_2026-10-17.xlsx | P8: 에이팜 별도관리
A9: 건강-20260918-004 | B9: 건강사업팀 | C9: 전은신 | E9: 46308 | F9: 46308 | G9: 인포크비즈니스 | H9: 베리시톨 인플루언서 비용 | I9: 3300000 | J9: 계좌송금 | L9: 확정 | M9: 변경 | N9: 46307 | O9: 지출계획_2026-10-17.xlsx | P9: 정상반영
A10: 건강-20260918-005 | B10: 건강사업팀 | C10: 전은신 | E10: 46308 | F10: 46308 | G10: 써치엠 | H10: 메타 광고 대행 수수 | I10: 1487786 | J10: 계좌송금 | L10: 확정 | M10: 변경 | N10: 46307 | O10: 지출계획_2026-10-17.xlsx | P10: 정상반영
A11: 건강-20261012-002 | B11: 건강사업팀 | C11: 전은신 | E11: 46308 | F11: 46308 | G11: 네이버 | H11: 네이버 SA&GFA 광고 비용 | I11: 1683000 | J11: 계좌송금 | L11: 확정 | M11: 신규 | N11: 46307 | O11: 지출계획_2026-10-17.xlsx | P11: 정상반영
A12: 경영-20261012-001 | B12: 경영지원팀 | C12: 송채은 | E12: 46308 | F12: 46308 | G12: 일신푸드 | H12: 9월 식대 | I12: 222000 | J12: 계좌송금 | L12: 확정 | M12: 신규 | N12: 46307 | O12: 지출계획_2026-10-17.xlsx | P12: 에이팜 별도관리
A13: 경영-20261012-002 | B13: 경영지원팀 | C13: 송채은 | E13: 46308 | F13: 46308 | G13: 일신푸드 | H13: 9월 식대 | I13: 1158000 | J13: 계좌송금 | L13: 확정 | M13: 신규 | N13: 46307 | O13: 지출계획_2026-10-17.xlsx | P13: 정상반영
A14: 건강-20261012-003 | B14: 건강사업팀 | C14: 전은신 | E14: 46309 | F14: 46309 | G14: 네이버 | H14: 네이버 SA&GFA 광고 비용 | I14: 3157000 | J14: 계좌송금 | L14: 확정 | M14: 신규 | N14: 46307 | O14: 지출계획_2026-10-17.xlsx | P14: 정상반영
A15: 건강-20261012-005 | B15: 건강사업팀 | C15: 전은신 | E15: 46309 | F15: 46309 | G15: ADN | H15: ADN 배너 광고 비용 | I15: 330000 | J15: 계좌송금 | L15: 확정 | M15: 신규 | N15: 46307 | O15: 지출계획_2026-10-17.xlsx | P15: 정상반영
A16: 건강-20261012-007 | B16: 건강사업팀 | C16: 전은신 | E16: 46309 | F16: 46309 | G16: 원정대 | H16: 베리시톨 GFA&META | I16: 5500000 | J16: 계좌송금 | L16: 확정 | M16: 신규 | N16: 46307 | O16: 지출계획_2026-10-17.xlsx | P16: 정상반영
A17: 건강-20261012-010 | B17: 건강사업팀 | C17: 양혜원 | E17: 46309 | F17: 46309 | G17: 캐시워크 | H17: 10월 라이브 시청자 유입 건 입금 | I17: 1100000 | J17: 계좌송금 | L17: 확정 | M17: 신규 | N17: 46307 | O17: 지출계획_2026-10-17.xlsx | P17: 정상반영
... A24: 경영-20261016-001 | B24: 경영지원팀 | C24: 김정원 | E24: 46311 | F24: 46311 | G24: 엠에스바이오텍 | H24: 외상대 지급(락토프리미엄_2차) | I24: 10000000 | J24: 계좌송금 | L24: 확정 | M24: 신규 | N24: 46311 | O24: 지출계획_2026-10-17.xlsx | P24: 정상반영
A25: 건강-20261012-008 | B25: 건강사업팀 | C25: 양혜원 | E25: 46308 | F25: 46349 | G25: 비즈콘 | H25: 브랜드스토어 이벤트 경품 지급 | I25: 300000 | J25: 법인카드 | K25: 우리카드 | L25: 확정 | M25: 신규 | N25: 46307 | O25: 지출계획_2026-10-17.xlsx | P25: 정상반영
A26: 경영-20260922-008 | B26: 경영지원팀 | C26: 장은총 | E26: 46309 | F26: 46349 | G26: 위버 | H26: 워크샵 (1부/2부) 이용료 | I26: 1675000 | J26: 법인카드 | K26: 우리카드 | L26: 확정 | M26: 변경 | N26: 46307 | O26: 지출계획_2026-10-17.xlsx | P26: 정상반영

Sheet 에이팜 지출계획
A2: 에이팜 지출계획 (자동 반영)
A3: 지출계획 비고에 '에이팜'으로 표시한 건은 자금계획(4주·13주)에 반영하지 않고 여기서만 관리합니다. '반영' 표시 건은 자금계획에 포함된 에이팜 관련 참고 항목입니다.
A5: 일자 | B5: 요일 | C5: 출처 | D5: 자금계획 반영 | E5: 팀명 | F5: 거래처 | G5: 지출내용 | H5: 예상금액 | I5: 지급방법 | J5: 비고
A6: 46307 | B6: 월 | C6: 팀 지출계획 | D6: 미반영(별도 관리) | E6: 경영지원팀 | F6: (대외비) | G6: 세금·보험(대외비) | H6: 4576870 | I6: 자동이체 | J6: 에이팜
A7: 46307 | B7: 월 | C7: 팀 지출계획 | D7: 미반영(별도 관리) | E7: 경영지원팀 | F7: (대외비) | G7: 세금·보험(대외비) | H7: 3511130 | I7: 계좌송금 | J7: 에이팜
A8: 46308 | B8: 화 | C8: 팀 지출계획 | D8: 미반영(별도 관리) | E8: 경영지원팀 | F8: 일신푸드 | G8: 9월 식대 | H8: 222000 | I8: 계좌송금 | J8: 에이팜
A9: 46310 | B9: 목 | C9: 팀 지출계획 | D9: 미반영(별도 관리) | E9: 경영지원팀 | F9: 국민카드 | G9: KB국민카드대금 지출건(9월분) | H9: 1246115 | I9: 자동이체 | J9: 에이팜
G10: 합계(자금계획 미반영) | H10: 9556115

Sheet 계좌내역통합_RAW
A1: 거래일시 | B1: 거래일 | C1: 은행 | D1: 계좌 | E1: 출금액 | F1: 입금액 | G1: 거래후잔액 | H1: 적요 | I1: 기재내용·상대방 | J1: 취급점 | K1: 자동분류 | L1: 내부이체 | M1: 정기지출후보 | N1: 현금유출입 | O1: 원본파일 | P1: 반영상태
A2: 46296.075 | B2: 46296 | C2: 국민은행 | D2: 국민 154577 | E2: 9000000 | F2: 0 | G2: 36063478 | H2: 스마트출금 | I2: 김정원 | J2: 진천역 | K2: 기타지출 | L2: N | M2: N | N2: -9000000 | O2: 농협계좌_6개월(20260913).xls | P2: 기존내역
A3: 46296.377 | B3: 46296 | C3: 국민은행 | D3: 국민 154577 | E3: 0 | F3: 251135 | G3: 36314613 | H3: FBS입금 | I3: 카카오페이정산 | J3: ERP사 | K3: 온라인매출입금 | L3: N | M3: N | N3: 251135 | O3: 농협계좌_6개월(20260913).xls | P3: 기존내역
A4: 46296.463 | B4: 46296 | C4: 국민은행 | D4: 국민 154577 | E4: 0 | F4: 2872584 | G4: 39187197 | H4: 전자금융 | I4: KG이니시스 | J4: 하나은행 | K4: 온라인매출입금 | L4: N | M4: N | N4: 2872584 | O4: 농협계좌_6개월(20260913).xls | P4: 기존내역
A5: 46296.466 | B5: 46296 | C5: 국민은행 | D5: 국민 154577 | E5: 0 | F5: 487545 | G5: 39674742 | H5: 전자금융 | I5: KG이니시스 | J5: 하나은행 | K5: 온라인매출입금 | L5: N | M5: N | N5: 487545 | O5: 농협계좌_6개월(20260913).xls | P5: 기존내역
A6: 46296.476 | B6: 46296 | C6: 국민은행 | D6: 국민 154577 | E6: 0 | F6: 444600 | G6: 40821342 | H6: FBS입금 | I6: 쿠팡(주) | J6: ERP사 | K6: 온라인매출입금 | L6: N | M6: N | N6: 444600 | O6: 농협계좌_6개월(20260913).xls | P6: 기존내역
A7: 46296.476 | B7: 46296 | C7: 국민은행 | D7: 국민 154577 | E7: 0 | F7: 702000 | G7: 40376742 | H7: FBS입금 | I7: 쿠팡(주) | J7: ERP사 | K7: 온라인매출입금 | L7: N | M7: N | N7: 702000 | O7: 국민은행_계좌 조회 6개월(20260913).xls | P7: 기존내역
A8: 46296.691 | B8: 46296 | C8: 국민은행 | D8: 국민 154577 | E8: 0 | F8: 6000 | G8: 40827342 | H8: 스마트입금 | I8: 강철왕 | J8: 여서동 | K8: 기타입금 | L8: N | M8: N | N8: 6000 | O8: 국민은행_계좌 조회 6개월(20260913).xls | P8: 기존내역
A9: 46296.817 | B9: 46296 | C9: 국민은행 | D9: 국민 154577 | E9: 2797570 | F9: 0 | G9: 38029772 | H9: FBS출금 | I9: KB7008 | J9: ERP사 | K9: 기타지출 | L9: N | M9: Y | N9: -2797570 | O9: 국민은행_계좌 조회 6개월(20260913).xls | P9: 기존내역
A10: 46297.099 | B10: 46297 | C10: 국민은행 | D10: 국민 154577 | E10: 0 | F10: 96068 | G10: 38125840 | H10: 전자금융 | I10: Npay정산 | J10: SC은행 | K10: 온라인매출입금 | L10: N | M10: N | N10: 96068 | O10: 국민은행_계좌 조회 6개월(20260913).xls | P10: 기존내역
A11: 46297.376 | B11: 46297 | C11: 국민은행 | D11: 국민 154577 | E11: 0 | F11: 330345 | G11: 38456185 | H11: FBS입금 | I11: 카카오페이정산 | J11: ERP사 | K11: 온라인매출입금 | L11: N | M11: N | N11: 330345 | O11: 우리은행 거래내역조회 20260913.xlsx | P11: 기존내역
A12: 46297.458 | B12: 46297 | C12: 국민은행 | D12: 국민 154577 | E12: 0 | F12: 644436 | G12: 39100621 | H12: 전자금융 | I12: KG이니시스 | J12: 하나은행 | K12: 온라인매출입금 | L12: N | M12: N | N12: 644436 | O12: 우리은행 거래내역조회 20260913.xlsx | P12: 기존내역
A13: 46297.469 | B13: 46297 | C13: 국민은행 | D13: 국민 154577 | E13: 0 | F13: 127804 | G13: 39228425 | H13: 전자금융 | I13: KG이니시스 | J13: 하나은행 | K13: 온라인매출입금 | L13: N | M13: N | N13: 127804 | O13: 우리은행 거래내역조회 20260913.xlsx | P13: 기존내역
... A159: 46311.685 | B159: 46311 | C159: 국민은행 | D159: 국민 170616 | E159: 5000000 | F159: 0 | G159: 31550000 | H159: 스마트출금 | I159: (재)한국기계전기전 | J159: 진천역 | K159: 기타지출 | L159: N | M159: N | N159: -5000000 | O159: 국민은행_계좌 조회 6개월(20260913).xls | P159: 기존내역
O160: 국민은행_계좌 조회 6개월(20260913).xls | P160: 기존내역
O161: 우리은행 거래내역조회 20260913.xlsx | P161: 기존내역
O162: 국민은행_계좌 조회 6개월(20260913).xls | P162: 기존내역
O163: 국민은행_계좌 조회 6개월(20260913).xls | P163: 기존내역
O164: 국민은행_계좌 조회 6개월(20260913).xls | P164: 기존내역
O165: 국민은행_계좌 조회 6개월(20260913).xls | P165: 기존내역
O166: 우리은행 거래내역조회 20260913.xlsx | P166: 기존내역
O167: 우리은행 거래내역조회 20260913.xlsx | P167: 기존내역
O168: 우리은행 거래내역조회 20260913.xlsx | P168: 기존내역
O169: 우리은행 거래내역조회 20260913.xlsx | P169: 기존내역
O170: 우리은행 거래내역조회 20260913.xlsx | P170: 기존내역
O171: 우리은행 거래내역조회 20260913.xlsx | P171: 기존내역
... O2092: 국민은행_계좌 조회 6개월(20260913).xls | P2092: 기존내역
O2093: =IF($A2093="","","주간붙여넣기_농협") | P2093: =IF($A2093="","",IF(COUNTIFS($C$2:$C$2092,$C2093,$B$2:$B$2092,$B2093,$E$2:$E$2092,$E2093,$F$2:$F$2092,$F2093,$G$2:$G$2092,$G2093)>0,"중복제외","신규반영"))
O2094: =IF($A2094="","","주간붙여넣기_농협") | P2094: =IF($A2094="","",IF(COUNTIFS($C$2:$C$2093,$C2094,$B$2:$B$2093,$B2094,$E$2:$E$2093,$E2094,$F$2:$F$2093,$F2094,$G$2:$G$2093,$G2094)>0,"중복제외","신규반영"))
O2095: =IF($A2095="","","주간붙여넣기_농협") | P2095: =IF($A2095="","",IF(COUNTIFS($C$2:$C$2094,$C2095,$B$2:$B$2094,$B2095,$E$2:$E$2094,$E2095,$F$2:$F$2094,$F2095,$G$2:$G$2094,$G2095)>0,"중복제외","신규반영"))
O2096: =IF($A2096="","","주간붙여넣기_농협") | P2096: =IF($A2096="","",IF(COUNTIFS($C$2:$C$2095,$C2096,$B$2:$B$2095,$B2096,$E$2:$E$2095,$E2096,$F$2:$F$2095,$F2096,$G$2:$G$2095,$G2096)>0,"중복제외","신규반영"))
O2097: =IF($A2097="","","주간붙여넣기_농협") | P2097: =IF($A2097="","",IF(COUNTIFS($C$2:$C$2096,$C2097,$B$2:$B$2096,$B2097,$E$2:$E$2096,$E2097,$F$2:$F$2096,$F2097,$G$2:$G$2096,$G2097)>0,"중복제외","신규반영"))
O2098: =IF($A2098="","","주간붙여넣기_농협") | P2098: =IF($A2098="","",IF(COUNTIFS($C$2:$C$2097,$C2098,$B$2:$B$2097,$B2098,$E$2:$E$2097,$E2098,$F$2:$F$2097,$F2098,$G$2:$G$2097,$G2098)>0,"중복제외","신규반영"))
O2099: =IF($A2099="","","주간붙여넣기_농협") | P2099: =IF($A2099="","",IF(COUNTIFS($C$2:$C$2098,$C2099,$B$2:$B$2098,$B2099,$E$2:$E$2098,$E2099,$F$2:$F$2098,$F2099,$G$2:$G$2098,$G2099)>0,"중복제외","신규반영"))
O2100: =IF($A2100="","","주간붙여넣기_농협") | P2100: =IF($A2100="","",IF(COUNTIFS($C$2:$C$2099,$C2100,$B$2:$B$2099,$B2100,$E$2:$E$2099,$E2100,$F$2:$F$2099,$F2100,$G$2:$G$2099,$G2100)>0,"중복제외","신규반영"))
O2101: =IF($A2101="","","주간붙여넣기_농협") | P2101: =IF($A2101="","",IF(COUNTIFS($C$2:$C$2100,$C2101,$B$2:$B$2100,$B2101,$E$2:$E$2100,$E2101,$F$2:$F$2100,$F2101,$G$2:$G$2100,$G2101)>0,"중복제외","신규반영"))
O2102: =IF($A2102="","","주간붙여넣기_농협") | P2102: =IF($A2102="","",IF(COUNTIFS($C$2:$C$2101,$C2102,$B$2:$B$2101,$B2102,$E$2:$E$2101,$E2102,$F$2:$F$2101,$F2102,$G$2:$G$2101,$G2102)>0,"중복제외","신규반영"))
O2103: =IF($A2103="","","주간붙여넣기_농협") | P2103: =IF($A2103="","",IF(COUNTIFS($C$2:$C$2102,$C2103,$B$2:$B$2102,$B2103,$E$2:$E$2102,$E2103,$F$2:$F$2102,$F2103,$G$2:$G$2102,$G2103)>0,"중복제외","신규반영"))
O2104: =IF($A2104="","","주간붙여넣기_농협") | P2104: =IF($A2104="","",IF(COUNTIFS($C$2:$C$2103,$C2104,$B$2:$B$2103,$B2104,$E$2:$E$2103,$E2104,$F$2:$F$2103,$F2104,$G$2:$G$2103,$G2104)>0,"중복제외","신규반영"))
O2105: =IF($A2105="","","주간붙여넣기_농협") | P2105: =IF($A2105="","",IF(COUNTIFS($C$2:$C$2104,$C2105,$B$2:$B$2104,$B2105,$E$2:$E$2104,$E2105,$F$2:$F$2104,$F2105,$G$2:$G$2104,$G2105)>0,"중복제외","신규반영"))
...

Sheet 설정및분류
A2: 예측 설정 및 자동분류 기준
A5: 요일번호 | B5: 요일 | C5: 최근 12주 온라인입금 일평균 | E5: 분류 | F5: 대표 키워드 | H5: 반영률 선택값
A6: 1 | B6: 월 | C6: 9149149 | E6: 온라인매출입금 | F6: 스마트스토어, KG이니시스, Npay, NHN페이, 카드가맹점 | H6: 0.6
A7: 2 | B7: 화 | C7: 22299776 | E7: 계좌간이체 | F7: 에이팜건강 표시(광고·네이버 제외) | H7: 0.7
A8: 3 | B8: 수 | C8: 15522234 | E8: 4대보험 | F8: 우리은행의 사회보험·건강보험 | H8: 0.8
A9: 4 | B9: 목 | C9: 11514900 | E9: 원천세·국세 | F9: 우리은행의 국고·원천세 | H9: 0.9
A10: 5 | B10: 금 | C10: 6913091 | E10: 법인카드결제 | F10: 우리카드결제대금, KB카드출금 | H10: 1
A11: 6 | B11: 토 | C11: 0 | E11: 보험료(기타) | F11: 한화생명, 메트라이프, ABL생명, 미래에셋
A12: 7 | B12: 일 | C12: 0 | E12: 광고선전비 | F12: 네이버, 광고, 비즈월렛, 캐시워크
E13: 급여·인건비(대외비) | F13: 급여, 상여, 퇴직, 국민은행 월말 TOP출금
E14: 대출·이자 | F14: 대출, 이자
E15: 기타입출금 | F15: 위 기준에 해당하지 않는 거래
