Workbook

Sheet 요약
A2: (주)에이팜건강 자금계획 기초 현황
A3: 기준일 2026-09-21 | 농협·우리은행·국민은행 계좌 거래내역 통합 (자동 갱신)
A5: 항목 | B5: 금액 | D5: 계좌 | E5: 최종 거래일 | F5: 잔액
A6: 현재 계좌잔액 | B6: 140020847 | D6: 국민 154577 | E6: 46285 | F6: 20184954
A7: 6개월 외부입금 | B7: 2667659335 | D7: 국민 169124 | E7: 46280 | F7: 100687200
A8: 6개월 외부출금 | B8: 3070029191 | D8: 농협 569003 | E8: 46283 | F8: 1834429
A9: 온라인매출 입금 | B9: 1976158603 | D9: 우리 220351 | E9: 46286 | F9: 17314264
A10: 최근 12주 주평균 온라인입금 | B10: 70815416
A12: 계획 설정 | B12: 값 | D12: 사용 방법
A13: 입금 예측 반영률 | B13: 0.8 | D13: 1. 새 계좌파일을 올리면 RAW 통합표에 이어 붙입니다.
A14: 4주 예상 기말잔액 | B14: ='4주일별계획'!R33 -> 2.5340784e+08 | D14: 2. 노란색 칸에 확정 입금·지출계획을 입력합니다.
A15: 4주 최저 예상잔액 | B15: =MIN('4주일별계획'!R6:R33) -> 91877902 | D15: ="3. 온라인 입금은 최근 12주 요일별 평균의 "&TEXT($B$13,"0%")&"로 예측합니다." -> 3. 온라인 입금은 최근 12주 요일별 평균의 80%로 예측합니다.
A16: 13주 예상 기말잔액 | B16: ='13주주별계획'!J18 -> 3.1455929e+08 | D16: 4. 계좌 간 이체는 내부이체로 표시해 입출금 합계에서 제외합니다.
D17: 5. 정기지출분석의 '확인필요' 항목은 성격을 확인 후 확정합니다.

Sheet 업데이트운영
A2: 계좌 거래내역 업데이트 운영 방법
A3: 6개월 자료는 최초 1회만 필요합니다. 이후에는 매주 은행 원본파일을 그대로 업로드하면 됩니다.
A5: 항목 | B5: 권장 운영 기준 | D5: 처리단계 | E5: 자동 처리 내용 | F5: 중복 판정 기준 | G5: 결과 | H5: 사용자 작업
A6: 업로드 주기 | B6: 주 1회. 월요일 오전에 전주 월요일~일요일 거래내역을 내려받습니다. | D6: 1. 파일 인식 | E6: 은행별 머리글과 데이터 시작행 판별 | F6: 은행·계좌 | G6: 은행 형식 통일 | H6: 파일 첨부
A7: 권장 조회기간 | B7: 누락 방지를 위해 최근 14일을 조회해도 됩니다. 중복 거래는 자동으로 제외합니다. | D7: 2. 거래 표준화 | E7: 거래일시·입금·출금·잔액·적요 변환 | F7: 거래일시·입출금액·잔액·적요 | G7: RAW 한 표로 통합 | H7: 없음
A8: 업로드 장소 | B8: 이 대화창에 농협·우리은행·국민은행 원본파일을 첨부합니다. | D8: 3. 중복 제거 | E8: 기존 거래와 신규 거래 비교 | F8: 계좌+일시+금액+잔액+적요 | G8: 겹친 조회기간 제거 | H8: 없음
A9: 권장 파일형식 | B9: 은행에서 내려받은 XLS, XLSX, CSV 원본을 권장합니다. | D9: 4. 자동 분류 | E9: 매출·내부이체·세금·보험·카드 등 분류 | F9: 적요 키워드 | G9: 분류 및 정기지출 표시 | H9: 확인필요만 검토
A10: 지양할 형식 | B10: PDF, 사진, 화면 캡처는 열 구조가 일정하지 않아 자동처리에 불리합니다. | D10: 5. 잔액 갱신 | E10: 계좌별 최종 거래 잔액 반영 | F10: 가장 최근 거래일시 | G10: 전체 가용잔액 갱신 | H10: 없음
A11: 파일명 | B11: 은행이 만들어 준 원래 파일명을 그대로 사용해도 됩니다. | D11: 6. 계획 갱신 | E11: 최근 12주 패턴 및 선택 반영률 적용 | F11: 드롭다운 반영률 | G11: 4주·13주 전망 변경 | H11: 예정 지출만 보완
A12: 업데이트 요청문 | B12: '이번 주 계좌내역 반영해서 자금계획 업데이트해줘'라고 입력합니다.
A13: 직접 입력 | B13: 거래내역은 복사·붙여넣지 않습니다. 향후 확정 입금·지출계획만 노란색 칸에 입력합니다.
A16: 은행 | B16: 현재 기준 원본파일 | C16: 조회 시작 | D16: 조회 종료 | E16: 반영 거래건수 | F16: 상태
A17: 농협 | B17: 농협계좌_6개월(20260913).xls | C17: 46094 | D17: 46278 | E17: 234 | F17: 반영완료
A18: 우리은행 | B18: 우리은행 거래내역조회 20260913.xlsx | C18: 46095 | D18: 46278 | E18: 862 | F18: 반영완료
A19: 국민은행 | B19: 국민은행_계좌 조회 6개월(20260913).xls | C19: 46095 | D19: 46278 | E19: 995 | F19: 반영완료

Sheet 4주일별계획
A2: 향후 4주 일별 자금계획
A3: 온라인 예상입금은 최근 12주 요일별 평균 × 입금 반영률(요약 B13)로 계산됩니다. 노란색 칸만 입력하세요. | 실잔고(은행 최근 확인): 우리 220351 17,314,264(09-21) · 농협 569003 1,834,429(09-18) · 국민 169124 100,687,200(09-15) · 국민 154577 20,184,954(09-20) | 출발(전일 마감) 잔액: 우리 220351 11,948,137 · 농협 569003 1,834,429 · 국민 169124 100,687,200 · 국민 154577 20,184,954 — 예상잔고는 출발 잔액에 예상입금·지출·이체를 반영한 하루 마감 기준 값(반영률 B13 연동, 당일 이미 반영된 실적은 중복 계산 안 함)
C4: 계좌별 예상잔고 | H4: 계좌별 입금 배분(예상)
A5: 일자 | B5: 요일 | C5: 우리 220351 | D5: 농협 569003 | E5: 국민 169124 | F5: 국민 154577 | G5: 온라인 예상입금 | H5: 우리 220351 | I5: 농협 569003 | J5: 국민 169124 | K5: 국민 154577 | L5: 확정·기타입금 | M5: 송금예정 | N5: 카드결제 | O5: 조정·추정 지출 | P5: 순현금흐름 | Q5: 기초잔액 | R5: 기말잔액 | S5: 비고
A6: 46286 | B6: 월 | C6: =계좌별시나리오!D6 -> 5632523.2 | D6: =계좌별시나리오!E6 -> 2049538.8 | E6: =계좌별시나리오!F6 -> 1.0232029e+08 | F6: =계좌별시나리오!G6 -> 22580573 | G6: =INDEX(설정및분류!$C$6:$C$12,WEEKDAY(A6,2))*요약!$B$13 -> 8542204.8 | H6: =계좌별시나리오!I6 -> 4298386.2 | I6: =계좌별시나리오!J6 -> 215109.8 | J6: =계좌별시나리오!K6 -> 1633090.2 | K6: =계좌별시나리오!L6 -> 2395618.6 | M6: 5494000 | O6: 5120000 | P6: =G6+L6-M6-N6-O6 -> -2071795.2 | Q6: 134654720 | R6: =Q6+P6 -> 1.3258292e+08 | S6: 메트라이프 4,900,000, 네이버SA&GFA 3,498,000, 트라이앵글하모니 1,996,000, SK브로드밴드 220,000
A7: 46287 | B7: 화 | C7: =계좌별시나리오!D7 -> 0 | D7: =계좌별시나리오!E7 -> 0 | E7: =계좌별시나리오!F7 -> 1.012902e+08 | F7: =계좌별시나리오!G7 -> 27573616 | G7: =INDEX(설정및분류!$C$6:$C$12,WEEKDAY(A7,2))*요약!$B$13 -> 17804001 | H7: =계좌별시나리오!I7 -> 8958866.4 | I7: =계좌별시나리오!J7 -> 448340.35 | J7: =계좌별시나리오!K7 -> 3403751.1 | K7: =계좌별시나리오!L7 -> 4993043 | M7: 21523110 | P7: =G7+L7-M7-N7-O7 -> -3719109.2 | Q7: =R6 -> 1.3258292e+08 | R7: =Q7+P7 -> 1.2886382e+08 | S7: 엠에스바이오텍 20,000,000, 와이투홀딩스 1,023,110, 네이버 500,000
A8: 46288 | B8: 수 | C8: =계좌별시나리오!D8 -> 0 | D8: =계좌별시나리오!E8 -> 0 | E8: =계좌별시나리오!F8 -> 63703131 | F8: =계좌별시나리오!G8 -> 30781221 | G8: =INDEX(설정및분류!$C$6:$C$12,WEEKDAY(A8,2))*요약!$B$13 -> 11437554 | H8: =계좌별시나리오!I8 -> 5755308.7 | I8: =계좌별시나리오!J8 -> 288020.49 | J8: =계좌별시나리오!K8 -> 2186620.2 | K8: =계좌별시나리오!L8 -> 3207604.9 | M8: 13642786 | O8: 32174232 | P8: =G8+L8-M8-N8-O8 -> -34379464 | Q8: =R7 -> 1.2886382e+08 | R8: =Q8+P8 -> 94484352 | S8: 우리카드 25,346,349, 네이버SA&GFA 8,305,000, 농협카드 6,827,883, 인포크비즈니스 3,300,000, 써치엠 1,487,786, ADN 550,000
A9: 46289 | B9: 목 | C9: =계좌별시나리오!D9 -> 0 | D9: =계좌별시나리오!E9 -> 0 | E9: =계좌별시나리오!F9 -> 63703131 | F9: =계좌별시나리오!G9 -> 30781221 | G9: 0 | H9: =계좌별시나리오!I9 -> 0 | I9: =계좌별시나리오!J9 -> 0 | J9: =계좌별시나리오!K9 -> 0 | K9: =계좌별시나리오!L9 -> 0 | P9: =G9+L9-M9-N9-O9 -> 0 | Q9: =R8 -> 94484352 | R9: =Q9+P9 -> 94484352
A10: 46290 | B10: 금 | C10: =계좌별시나리오!D10 -> 0 | D10: =계좌별시나리오!E10 -> 0 | E10: =계좌별시나리오!F10 -> 61096681 | F10: =계좌별시나리오!G10 -> 30781221 | G10: 0 | H10: =계좌별시나리오!I10 -> 0 | I10: =계좌별시나리오!J10 -> 0 | J10: =계좌별시나리오!K10 -> 0 | K10: =계좌별시나리오!L10 -> 0 | O10: 2606450 | P10: =G10+L10-M10-N10-O10 -> -2606450 | Q10: =R9 -> 94484352 | R10: =Q10+P10 -> 91877902 | S10: 메트라이프 2,497,000, KT 109,450
A11: 46291 | B11: 토 | C11: =계좌별시나리오!D11 -> 0 | D11: =계좌별시나리오!E11 -> 0 | E11: =계좌별시나리오!F11 -> 61096681 | F11: =계좌별시나리오!G11 -> 30781221 | G11: 0 | H11: =계좌별시나리오!I11 -> 0 | I11: =계좌별시나리오!J11 -> 0 | J11: =계좌별시나리오!K11 -> 0 | K11: =계좌별시나리오!L11 -> 0 | P11: =G11+L11-M11-N11-O11 -> 0 | Q11: =R10 -> 91877902 | R11: =Q11+P11 -> 91877902
A12: 46292 | B12: 일 | C12: =계좌별시나리오!D12 -> 0 | D12: =계좌별시나리오!E12 -> 0 | E12: =계좌별시나리오!F12 -> 61096681 | F12: =계좌별시나리오!G12 -> 30781221 | G12: =INDEX(설정및분류!$C$6:$C$12,WEEKDAY(A12,2))*요약!$B$13 -> 0 | H12: =계좌별시나리오!I12 -> 0 | I12: =계좌별시나리오!J12 -> 0 | J12: =계좌별시나리오!K12 -> 0 | K12: =계좌별시나리오!L12 -> 0 | P12: =G12+L12-M12-N12-O12 -> 0 | Q12: =R11 -> 91877902 | R12: =Q12+P12 -> 91877902
A13: 46293 | B13: 월 | C13: =계좌별시나리오!D13 -> 2648386.2 | D13: =계좌별시나리오!E13 -> 215109.8 | E13: =계좌별시나리오!F13 -> 62729772 | F13: =계좌별시나리오!G13 -> 33176839 | G13: =INDEX(설정및분류!$C$6:$C$12,WEEKDAY(A13,2))*요약!$B$13 -> 8542204.8 | H13: =계좌별시나리오!I13 -> 4298386.2 | I13: =계좌별시나리오!J13 -> 215109.8 | J13: =계좌별시나리오!K13 -> 1633090.2 | K13: =계좌별시나리오!L13 -> 2395618.6 | M13: 1650000 | P13: =G13+L13-M13-N13-O13 -> 6892204.8 | Q13: =R12 -> 91877902 | R13: =Q13+P13 -> 98770107 | S13: 엘앤에이치컴퍼니 1,650,000
A14: 46294 | B14: 화 | C14: =계좌별시나리오!D14 -> 11607253 | D14: =계좌별시나리오!E14 -> 663450.15 | E14: =계좌별시나리오!F14 -> 66133523 | F14: =계좌별시나리오!G14 -> 38169882 | G14: =INDEX(설정및분류!$C$6:$C$12,WEEKDAY(A14,2))*요약!$B$13 -> 17804001 | H14: =계좌별시나리오!I14 -> 8958866.4 | I14: =계좌별시나리오!J14 -> 448340.35 | J14: =계좌별시나리오!K14 -> 3403751.1 | K14: =계좌별시나리오!L14 -> 4993043 | P14: =G14+L14-M14-N14-O14 -> 17804001 | Q14: =R13 -> 98770107 | R14: =Q14+P14 -> 1.1657411e+08
A15: 46295 | B15: 수 | C15: =계좌별시나리오!D15 -> 22405505 | D15: =계좌별시나리오!E15 -> 1203841.3 | E15: =계좌별시나리오!F15 -> 70236113 | F15: =계좌별시나리오!G15 -> 44188070 | G15: =INDEX(설정및분류!$C$6:$C$12,WEEKDAY(A15,2))*요약!$B$13 -> 11437554 | H15: =계좌별시나리오!I15 -> 10798252 | I15: =계좌별시나리오!J15 -> 540391.15 | J15: =계좌별시나리오!K15 -> 4102590.7 | K15: =계좌별시나리오!L15 -> 6018187.4 | L15: 10021867 | P15: =G15+L15-M15-N15-O15 -> 21459421 | Q15: =R14 -> 1.1657411e+08 | R15: =Q15+P15 -> 138033529 | S15: 관계사 외상대 입금 추정(주식회사에이팜, 말일)
A16: 46296 | B16: 목 | C16: =계좌별시나리오!D16 -> 27745323 | D16: =계좌별시나리오!E16 -> 1471068.9 | E16: =계좌별시나리오!F16 -> 72264876 | F16: =계좌별시나리오!G16 -> 47164110 | G16: =INDEX(설정및분류!$C$6:$C$12,WEEKDAY(A16,2))*요약!$B$13 -> 10611849 | H16: =계좌별시나리오!I16 -> 5339818.6 | I16: =계좌별시나리오!J16 -> 267227.58 | J16: =계좌별시나리오!K16 -> 2028762.6 | K16: =계좌별시나리오!L16 -> 2976039.9 | P16: =G16+L16-M16-N16-O16 -> 10611849 | Q16: =R15 -> 138033529 | R16: =Q16+P16 -> 1.4864538e+08
A17: 46297 | B17: 금 | C17: =계좌별시나리오!D17 -> 31900057 | D17: =계좌별시나리오!E17 -> 1678989.7 | E17: =계좌별시나리오!F17 -> 73843388 | F17: =계좌별시나리오!G17 -> 49479667 | G17: =INDEX(설정및분류!$C$6:$C$12,WEEKDAY(A17,2))*요약!$B$13 -> 8256724 | H17: =계좌별시나리오!I17 -> 4154734 | I17: =계좌별시나리오!J17 -> 207920.82 | J17: =계좌별시나리오!K17 -> 1578512.2 | K17: =계좌별시나리오!L17 -> 2315557 | P17: =G17+L17-M17-N17-O17 -> 8256724 | Q17: =R16 -> 1.4864538e+08 | R17: =Q17+P17 -> 1.569021e+08
A18: 46298 | B18: 토 | C18: =계좌별시나리오!D18 -> 31900057 | D18: =계좌별시나리오!E18 -> 1678989.7 | E18: =계좌별시나리오!F18 -> 73843388 | F18: =계좌별시나리오!G18 -> 49479667 | G18: 0 | H18: =계좌별시나리오!I18 -> 0 | I18: =계좌별시나리오!J18 -> 0 | J18: =계좌별시나리오!K18 -> 0 | K18: =계좌별시나리오!L18 -> 0 | P18: =G18+L18-M18-N18-O18 -> 0 | Q18: =R17 -> 1.569021e+08 | R18: =Q18+P18 -> 1.569021e+08
A19: 46299 | B19: 일 | C19: =계좌별시나리오!D19 -> 31900057 | D19: =계좌별시나리오!E19 -> 1678989.7 | E19: =계좌별시나리오!F19 -> 73843388 | F19: =계좌별시나리오!G19 -> 49479667 | G19: =INDEX(설정및분류!$C$6:$C$12,WEEKDAY(A19,2))*요약!$B$13 -> 0 | H19: =계좌별시나리오!I19 -> 0 | I19: =계좌별시나리오!J19 -> 0 | J19: =계좌별시나리오!K19 -> 0 | K19: =계좌별시나리오!L19 -> 0 | P19: =G19+L19-M19-N19-O19 -> 0 | Q19: =R18 -> 1.569021e+08 | R19: =Q19+P19 -> 1.569021e+08
A20: 46300 | B20: 월 | C20: =계좌별시나리오!D20 -> 31900057 | D20: =계좌별시나리오!E20 -> 1678989.7 | E20: =계좌별시나리오!F20 -> 73843388 | F20: =계좌별시나리오!G20 -> 49479667 | G20: 0 | H20: =계좌별시나리오!I20 -> 0 | I20: =계좌별시나리오!J20 -> 0 | J20: =계좌별시나리오!K20 -> 0 | K20: =계좌별시나리오!L20 -> 0 | P20: =G20+L20-M20-N20-O20 -> 0 | Q20: =R19 -> 1.569021e+08 | R20: =Q20+P20 -> 1.569021e+08
A21: 46301 | B21: 화 | C21: =계좌별시나리오!D21 -> 40858924 | D21: =계좌별시나리오!E21 -> 2127330 | E21: =계좌별시나리오!F21 -> 77247139 | F21: =계좌별시나리오!G21 -> 54472710 | G21: =INDEX(설정및분류!$C$6:$C$12,WEEKDAY(A21,2))*요약!$B$13 -> 17804001 | H21: =계좌별시나리오!I21 -> 8958866.4 | I21: =계좌별시나리오!J21 -> 448340.35 | J21: =계좌별시나리오!K21 -> 3403751.1 | K21: =계좌별시나리오!L21 -> 4993043 | P21: =G21+L21-M21-N21-O21 -> 17804001 | Q21: =R20 -> 1.569021e+08 | R21: =Q21+P21 -> 1.747061e+08
A22: 46302 | B22: 수 | C22: =계좌별시나리오!D22 -> 46614232 | D22: =계좌별시나리오!E22 -> 2415350.5 | E22: =계좌별시나리오!F22 -> 79433760 | F22: =계좌별시나리오!G22 -> 57680314 | G22: =INDEX(설정및분류!$C$6:$C$12,WEEKDAY(A22,2))*요약!$B$13 -> 11437554 | H22: =계좌별시나리오!I22 -> 5755308.7 | I22: =계좌별시나리오!J22 -> 288020.49 | J22: =계좌별시나리오!K22 -> 2186620.2 | K22: =계좌별시나리오!L22 -> 3207604.9 | P22: =G22+L22-M22-N22-O22 -> 11437554 | Q22: =R21 -> 1.747061e+08 | R22: =Q22+P22 -> 1.8614366e+08
A23: 46303 | B23: 목 | C23: =계좌별시나리오!D23 -> 51954051 | D23: =계좌별시나리오!E23 -> 2682578.1 | E23: =계좌별시나리오!F23 -> 81462522 | F23: =계좌별시나리오!G23 -> 60656354 | G23: =INDEX(설정및분류!$C$6:$C$12,WEEKDAY(A23,2))*요약!$B$13 -> 10611849 | H23: =계좌별시나리오!I23 -> 5339818.6 | I23: =계좌별시나리오!J23 -> 267227.58 | J23: =계좌별시나리오!K23 -> 2028762.6 | K23: =계좌별시나리오!L23 -> 2976039.9 | P23: =G23+L23-M23-N23-O23 -> 10611849 | Q23: =R22 -> 1.8614366e+08 | R23: =Q23+P23 -> 1.9675551e+08
A24: 46304 | B24: 금 | C24: =계좌별시나리오!D24 -> 51954051 | D24: =계좌별시나리오!E24 -> 2682578.1 | E24: =계좌별시나리오!F24 -> 81462522 | F24: =계좌별시나리오!G24 -> 60656354 | G24: 0 | H24: =계좌별시나리오!I24 -> 0 | I24: =계좌별시나리오!J24 -> 0 | J24: =계좌별시나리오!K24 -> 0 | K24: =계좌별시나리오!L24 -> 0 | P24: =G24+L24-M24-N24-O24 -> 0 | Q24: =R23 -> 1.9675551e+08 | R24: =Q24+P24 -> 1.9675551e+08
A25: 46305 | B25: 토 | C25: =계좌별시나리오!D25 -> 51954051 | D25: =계좌별시나리오!E25 -> 2682578.1 | E25: =계좌별시나리오!F25 -> 81462522 | F25: =계좌별시나리오!G25 -> 60656354 | G25: =INDEX(설정및분류!$C$6:$C$12,WEEKDAY(A25,2))*요약!$B$13 -> 0 | H25: =계좌별시나리오!I25 -> 0 | I25: =계좌별시나리오!J25 -> 0 | J25: =계좌별시나리오!K25 -> 0 | K25: =계좌별시나리오!L25 -> 0 | P25: =G25+L25-M25-N25-O25 -> 0 | Q25: =R24 -> 1.9675551e+08 | R25: =Q25+P25 -> 1.9675551e+08
A26: 46306 | B26: 일 | C26: =계좌별시나리오!D26 -> 51954051 | D26: =계좌별시나리오!E26 -> 2682578.1 | E26: =계좌별시나리오!F26 -> 81462522 | F26: =계좌별시나리오!G26 -> 60656354 | G26: =INDEX(설정및분류!$C$6:$C$12,WEEKDAY(A26,2))*요약!$B$13 -> 0 | H26: =계좌별시나리오!I26 -> 0 | I26: =계좌별시나리오!J26 -> 0 | J26: =계좌별시나리오!K26 -> 0 | K26: =계좌별시나리오!L26 -> 0 | P26: =G26+L26-M26-N26-O26 -> 0 | Q26: =R25 -> 1.9675551e+08 | R26: =Q26+P26 -> 1.9675551e+08
A27: 46307 | B27: 월 | C27: =계좌별시나리오!D27 -> 56252437 | D27: =계좌별시나리오!E27 -> 2897687.9 | E27: =계좌별시나리오!F27 -> 83095612 | F27: =계좌별시나리오!G27 -> 63051973 | G27: =INDEX(설정및분류!$C$6:$C$12,WEEKDAY(A27,2))*요약!$B$13 -> 8542204.8 | H27: =계좌별시나리오!I27 -> 4298386.2 | I27: =계좌별시나리오!J27 -> 215109.8 | J27: =계좌별시나리오!K27 -> 1633090.2 | K27: =계좌별시나리오!L27 -> 2395618.6 | P27: =G27+L27-M27-N27-O27 -> 8542204.8 | Q27: =R26 -> 1.9675551e+08 | R27: =Q27+P27 -> 2.0529771e+08
A28: 46308 | B28: 화 | C28: =계좌별시나리오!D28 -> 65211304 | D28: =계좌별시나리오!E28 -> 3346028.3 | E28: =계좌별시나리오!F28 -> 86499363 | F28: =계좌별시나리오!G28 -> 68045016 | G28: =INDEX(설정및분류!$C$6:$C$12,WEEKDAY(A28,2))*요약!$B$13 -> 17804001 | H28: =계좌별시나리오!I28 -> 8958866.4 | I28: =계좌별시나리오!J28 -> 448340.35 | J28: =계좌별시나리오!K28 -> 3403751.1 | K28: =계좌별시나리오!L28 -> 4993043 | P28: =G28+L28-M28-N28-O28 -> 17804001 | Q28: =R27 -> 2.0529771e+08 | R28: =Q28+P28 -> 2.2310171e+08
A29: 46309 | B29: 수 | C29: =계좌별시나리오!D29 -> 70966612 | D29: =계좌별시나리오!E29 -> 3634048.8 | E29: =계좌별시나리오!F29 -> 88685984 | F29: =계좌별시나리오!G29 -> 71252621 | G29: =INDEX(설정및분류!$C$6:$C$12,WEEKDAY(A29,2))*요약!$B$13 -> 11437554 | H29: =계좌별시나리오!I29 -> 5755308.7 | I29: =계좌별시나리오!J29 -> 288020.49 | J29: =계좌별시나리오!K29 -> 2186620.2 | K29: =계좌별시나리오!L29 -> 3207604.9 | P29: =G29+L29-M29-N29-O29 -> 11437554 | Q29: =R28 -> 2.2310171e+08 | R29: =Q29+P29 -> 2.3453927e+08
A30: 46310 | B30: 목 | C30: =계좌별시나리오!D30 -> 76306431 | D30: =계좌별시나리오!E30 -> 3901276.3 | E30: =계좌별시나리오!F30 -> 90714746 | F30: =계좌별시나리오!G30 -> 74228661 | G30: =INDEX(설정및분류!$C$6:$C$12,WEEKDAY(A30,2))*요약!$B$13 -> 10611849 | H30: =계좌별시나리오!I30 -> 5339818.6 | I30: =계좌별시나리오!J30 -> 267227.58 | J30: =계좌별시나리오!K30 -> 2028762.6 | K30: =계좌별시나리오!L30 -> 2976039.9 | P30: =G30+L30-M30-N30-O30 -> 10611849 | Q30: =R29 -> 2.3453927e+08 | R30: =Q30+P30 -> 2.4515111e+08
A31: 46311 | B31: 금 | C31: =계좌별시나리오!D31 -> 80461165 | D31: =계좌별시나리오!E31 -> 4109197.2 | E31: =계좌별시나리오!F31 -> 92293259 | F31: =계좌별시나리오!G31 -> 76544218 | G31: =INDEX(설정및분류!$C$6:$C$12,WEEKDAY(A31,2))*요약!$B$13 -> 8256724 | H31: =계좌별시나리오!I31 -> 4154734 | I31: =계좌별시나리오!J31 -> 207920.82 | J31: =계좌별시나리오!K31 -> 1578512.2 | K31: =계좌별시나리오!L31 -> 2315557 | P31: =G31+L31-M31-N31-O31 -> 8256724 | Q31: =R30 -> 2.4515111e+08 | R31: =Q31+P31 -> 2.5340784e+08
A32: 46312 | B32: 토 | C32: =계좌별시나리오!D32 -> 80461165 | D32: =계좌별시나리오!E32 -> 4109197.2 | E32: =계좌별시나리오!F32 -> 92293259 | F32: =계좌별시나리오!G32 -> 76544218 | G32: =INDEX(설정및분류!$C$6:$C$12,WEEKDAY(A32,2))*요약!$B$13 -> 0 | H32: =계좌별시나리오!I32 -> 0 | I32: =계좌별시나리오!J32 -> 0 | J32: =계좌별시나리오!K32 -> 0 | K32: =계좌별시나리오!L32 -> 0 | P32: =G32+L32-M32-N32-O32 -> 0 | Q32: =R31 -> 2.5340784e+08 | R32: =Q32+P32 -> 2.5340784e+08
A33: 46313 | B33: 일 | C33: =계좌별시나리오!D33 -> 80461165 | D33: =계좌별시나리오!E33 -> 4109197.2 | E33: =계좌별시나리오!F33 -> 92293259 | F33: =계좌별시나리오!G33 -> 76544218 | G33: =INDEX(설정및분류!$C$6:$C$12,WEEKDAY(A33,2))*요약!$B$13 -> 0 | H33: =계좌별시나리오!I33 -> 0 | I33: =계좌별시나리오!J33 -> 0 | J33: =계좌별시나리오!K33 -> 0 | K33: =계좌별시나리오!L33 -> 0 | P33: =G33+L33-M33-N33-O33 -> 0 | Q33: =R32 -> 2.5340784e+08 | R33: =Q33+P33 -> 2.5340784e+08

Sheet 계좌별시나리오
A2: 계좌별 일별 잔액 시나리오 (자동 반영)
A3: 읽는 법: 오늘 총잔액 = 전날 총잔액 + ② 입금 합계 − ③ 지출. 지출은 전액 우리은행에서 집행하고, 모자라면 ④처럼 농협 → 국민 순으로 우리은행에 이체해 채웁니다. '요약' 시트의 입금 반영률(B13)을 바꾸면 이 표도 즉시 다시 계산됩니다. 지난 실적 일자 행은 숨김(마지막 실적일 잔액에서 출발), 실수 방지를 위해 시트 보호(암호 없음). ② 배분 비중(최근 입금 실적): 우리 220351 50% · 농협 569003 3% · 국민 169124 19% · 국민 154577 28%
A4: 일자 | B4: 요일 | C4: ① 잔액 (총잔액 · 계좌별) | H4: ② 오늘 들어오는 돈 — 예상입금 배분 | M4: ③ 지출 | N4: ④ 부족분 이체 | P4: 비고
C5: 총잔액 | D5: 우리 220351 | E5: 농협 569003 | F5: 국민 169124 | G5: 국민 154577 | H5: 합계 | I5: 우리 220351 | J5: 농협 569003 | K5: 국민 169124 | L5: 국민 154577 | M5: 우리은행 집행 | N5: 농협→우리 | O5: 국민→우리
A6: 46286 | B6: 월 | C6: =SUM(D6:G6) -> 1.3258292e+08 | D6: =11948137+I6-M6+Q6+R6+S6 -> 5632523.2 | E6: =1834429+J6-Q6 -> 2049538.8 | F6: =100687200+K6-R6 -> 1.0232029e+08 | G6: =20184954+L6-S6 -> 22580573 | H6: ='4주일별계획'!G6+'4주일별계획'!L6 -> 8542204.8 | I6: =H6*0.503194 -> 4298386.2 | J6: =H6*0.025182 -> 215109.8 | K6: =H6*0.191179 -> 1633090.2 | L6: =H6*0.280445 -> 2395618.6 | M6: ='4주일별계획'!M6+'4주일별계획'!N6+'4주일별계획'!O6 -> 10614000 | N6: =Q6 -> 0 | O6: =R6+S6 -> 0 | P6: =IF(D6<-0.5,"전 계좌 소진 — 부족 "&TEXT(-D6,"#,##0")&"원","") | Q6: =MIN(MAX(0,1834429+J6),MAX(0,M6-11948137-I6)) -> 0 | R6: =MIN(MAX(0,100687200+K6),MAX(0,M6-11948137-I6)-Q6) -> 0 | S6: =MIN(MAX(0,20184954+L6),MAX(0,M6-11948137-I6)-Q6-R6) -> 0
A7: 46287 | B7: 화 | C7: =SUM(D7:G7) -> 1.2886382e+08 | D7: =D6+I7-M7+Q7+R7+S7 -> 0 | E7: =E6+J7-Q7 -> 0 | F7: =F6+K7-R7 -> 1.012902e+08 | G7: =G6+L7-S7 -> 27573616 | H7: ='4주일별계획'!G7+'4주일별계획'!L7 -> 17804001 | I7: =H7*0.503194 -> 8958866.4 | J7: =H7*0.025182 -> 448340.35 | K7: =H7*0.191179 -> 3403751.1 | L7: =H7*0.280445 -> 4993043 | M7: ='4주일별계획'!M7+'4주일별계획'!N7+'4주일별계획'!O7 -> 21523110 | N7: =Q7 -> 2497879.1 | O7: =R7+S7 -> 4433841.3 | P7: =IF(D7<-0.5,"전 계좌 소진 — 부족 "&TEXT(-D7,"#,##0")&"원","") | Q7: =MIN(MAX(0,E6+J7),MAX(0,M7-D6-I7)) -> 2497879.1 | R7: =MIN(MAX(0,F6+K7),MAX(0,M7-D6-I7)-Q7) -> 4433841.3 | S7: =MIN(MAX(0,G6+L7),MAX(0,M7-D6-I7)-Q7-R7) -> 0
A8: 46288 | B8: 수 | C8: =SUM(D8:G8) -> 94484352 | D8: =D7+I8-M8+Q8+R8+S8 -> 0 | E8: =E7+J8-Q8 -> 0 | F8: =F7+K8-R8 -> 63703131 | G8: =G7+L8-S8 -> 30781221 | H8: ='4주일별계획'!G8+'4주일별계획'!L8 -> 11437554 | I8: =H8*0.503194 -> 5755308.7 | J8: =H8*0.025182 -> 288020.49 | K8: =H8*0.191179 -> 2186620.2 | L8: =H8*0.280445 -> 3207604.9 | M8: ='4주일별계획'!M8+'4주일별계획'!N8+'4주일별계획'!O8 -> 45817018 | N8: =Q8 -> 288020.49 | O8: =R8+S8 -> 39773689 | P8: =IF(D8<-0.5,"전 계좌 소진 — 부족 "&TEXT(-D8,"#,##0")&"원","") | Q8: =MIN(MAX(0,E7+J8),MAX(0,M8-D7-I8)) -> 288020.49 | R8: =MIN(MAX(0,F7+K8),MAX(0,M8-D7-I8)-Q8) -> 39773689 | S8: =MIN(MAX(0,G7+L8),MAX(0,M8-D7-I8)-Q8-R8) -> 0
A9: 46289 | B9: 목 | C9: =SUM(D9:G9) -> 94484352 | D9: =D8+I9-M9+Q9+R9+S9 -> 0 | E9: =E8+J9-Q9 -> 0 | F9: =F8+K9-R9 -> 63703131 | G9: =G8+L9-S9 -> 30781221 | H9: ='4주일별계획'!G9+'4주일별계획'!L9 -> 0 | I9: =H9*0.503194 -> 0 | J9: =H9*0.025182 -> 0 | K9: =H9*0.191179 -> 0 | L9: =H9*0.280445 -> 0 | M9: ='4주일별계획'!M9+'4주일별계획'!N9+'4주일별계획'!O9 -> 0 | N9: =Q9 -> 0 | O9: =R9+S9 -> 0 | P9: =IF(D9<-0.5,"전 계좌 소진 — 부족 "&TEXT(-D9,"#,##0")&"원","") | Q9: =MIN(MAX(0,E8+J9),MAX(0,M9-D8-I9)) -> 0 | R9: =MIN(MAX(0,F8+K9),MAX(0,M9-D8-I9)-Q9) -> 0 | S9: =MIN(MAX(0,G8+L9),MAX(0,M9-D8-I9)-Q9-R9) -> 0
A10: 46290 | B10: 금 | C10: =SUM(D10:G10) -> 91877902 | D10: =D9+I10-M10+Q10+R10+S10 -> 0 | E10: =E9+J10-Q10 -> 0 | F10: =F9+K10-R10 -> 61096681 | G10: =G9+L10-S10 -> 30781221 | H10: ='4주일별계획'!G10+'4주일별계획'!L10 -> 0 | I10: =H10*0.503194 -> 0 | J10: =H10*0.025182 -> 0 | K10: =H10*0.191179 -> 0 | L10: =H10*0.280445 -> 0 | M10: ='4주일별계획'!M10+'4주일별계획'!N10+'4주일별계획'!O10 -> 2606450 | N10: =Q10 -> 0 | O10: =R10+S10 -> 2606450 | P10: =IF(D10<-0.5,"전 계좌 소진 — 부족 "&TEXT(-D10,"#,##0")&"원","") | Q10: =MIN(MAX(0,E9+J10),MAX(0,M10-D9-I10)) -> 0 | R10: =MIN(MAX(0,F9+K10),MAX(0,M10-D9-I10)-Q10) -> 2606450 | S10: =MIN(MAX(0,G9+L10),MAX(0,M10-D9-I10)-Q10-R10) -> 0
A11: 46291 | B11: 토 | C11: =SUM(D11:G11) -> 91877902 | D11: =D10+I11-M11+Q11+R11+S11 -> 0 | E11: =E10+J11-Q11 -> 0 | F11: =F10+K11-R11 -> 61096681 | G11: =G10+L11-S11 -> 30781221 | H11: ='4주일별계획'!G11+'4주일별계획'!L11 -> 0 | I11: =H11*0.503194 -> 0 | J11: =H11*0.025182 -> 0 | K11: =H11*0.191179 -> 0 | L11: =H11*0.280445 -> 0 | M11: ='4주일별계획'!M11+'4주일별계획'!N11+'4주일별계획'!O11 -> 0 | N11: =Q11 -> 0 | O11: =R11+S11 -> 0 | P11: =IF(D11<-0.5,"전 계좌 소진 — 부족 "&TEXT(-D11,"#,##0")&"원","") | Q11: =MIN(MAX(0,E10+J11),MAX(0,M11-D10-I11)) -> 0 | R11: =MIN(MAX(0,F10+K11),MAX(0,M11-D10-I11)-Q11) -> 0 | S11: =MIN(MAX(0,G10+L11),MAX(0,M11-D10-I11)-Q11-R11) -> 0
A12: 46292 | B12: 일 | C12: =SUM(D12:G12) -> 91877902 | D12: =D11+I12-M12+Q12+R12+S12 -> 0 | E12: =E11+J12-Q12 -> 0 | F12: =F11+K12-R12 -> 61096681 | G12: =G11+L12-S12 -> 30781221 | H12: ='4주일별계획'!G12+'4주일별계획'!L12 -> 0 | I12: =H12*0.503194 -> 0 | J12: =H12*0.025182 -> 0 | K12: =H12*0.191179 -> 0 | L12: =H12*0.280445 -> 0 | M12: ='4주일별계획'!M12+'4주일별계획'!N12+'4주일별계획'!O12 -> 0 | N12: =Q12 -> 0 | O12: =R12+S12 -> 0 | P12: =IF(D12<-0.5,"전 계좌 소진 — 부족 "&TEXT(-D12,"#,##0")&"원","") | Q12: =MIN(MAX(0,E11+J12),MAX(0,M12-D11-I12)) -> 0 | R12: =MIN(MAX(0,F11+K12),MAX(0,M12-D11-I12)-Q12) -> 0 | S12: =MIN(MAX(0,G11+L12),MAX(0,M12-D11-I12)-Q12-R12) -> 0
A13: 46293 | B13: 월 | C13: =SUM(D13:G13) -> 98770107 | D13: =D12+I13-M13+Q13+R13+S13 -> 2648386.2 | E13: =E12+J13-Q13 -> 215109.8 | F13: =F12+K13-R13 -> 62729772 | G13: =G12+L13-S13 -> 33176839 | H13: ='4주일별계획'!G13+'4주일별계획'!L13 -> 8542204.8 | I13: =H13*0.503194 -> 4298386.2 | J13: =H13*0.025182 -> 215109.8 | K13: =H13*0.191179 -> 1633090.2 | L13: =H13*0.280445 -> 2395618.6 | M13: ='4주일별계획'!M13+'4주일별계획'!N13+'4주일별계획'!O13 -> 1650000 | N13: =Q13 -> 0 | O13: =R13+S13 -> 0 | P13: =IF(D13<-0.5,"전 계좌 소진 — 부족 "&TEXT(-D13,"#,##0")&"원","") | Q13: =MIN(MAX(0,E12+J13),MAX(0,M13-D12-I13)) -> 0 | R13: =MIN(MAX(0,F12+K13),MAX(0,M13-D12-I13)-Q13) -> 0 | S13: =MIN(MAX(0,G12+L13),MAX(0,M13-D12-I13)-Q13-R13) -> 0
A14: 46294 | B14: 화 | C14: =SUM(D14:G14) -> 1.1657411e+08 | D14: =D13+I14-M14+Q14+R14+S14 -> 11607253 | E14: =E13+J14-Q14 -> 663450.15 | F14: =F13+K14-R14 -> 66133523 | G14: =G13+L14-S14 -> 38169882 | H14: ='4주일별계획'!G14+'4주일별계획'!L14 -> 17804001 | I14: =H14*0.503194 -> 8958866.4 | J14: =H14*0.025182 -> 448340.35 | K14: =H14*0.191179 -> 3403751.1 | L14: =H14*0.280445 -> 4993043 | M14: ='4주일별계획'!M14+'4주일별계획'!N14+'4주일별계획'!O14 -> 0 | N14: =Q14 -> 0 | O14: =R14+S14 -> 0 | P14: =IF(D14<-0.5,"전 계좌 소진 — 부족 "&TEXT(-D14,"#,##0")&"원","") | Q14: =MIN(MAX(0,E13+J14),MAX(0,M14-D13-I14)) -> 0 | R14: =MIN(MAX(0,F13+K14),MAX(0,M14-D13-I14)-Q14) -> 0 | S14: =MIN(MAX(0,G13+L14),MAX(0,M14-D13-I14)-Q14-R14) -> 0
A15: 46295 | B15: 수 | C15: =SUM(D15:G15) -> 138033529 | D15: =D14+I15-M15+Q15+R15+S15 -> 22405505 | E15: =E14+J15-Q15 -> 1203841.3 | F15: =F14+K15-R15 -> 70236113 | G15: =G14+L15-S15 -> 44188070 | H15: ='4주일별계획'!G15+'4주일별계획'!L15 -> 21459421 | I15: =H15*0.503194 -> 10798252 | J15: =H15*0.025182 -> 540391.15 | K15: =H15*0.191179 -> 4102590.7 | L15: =H15*0.280445 -> 6018187.4 | M15: ='4주일별계획'!M15+'4주일별계획'!N15+'4주일별계획'!O15 -> 0 | N15: =Q15 -> 0 | O15: =R15+S15 -> 0 | P15: =IF(D15<-0.5,"전 계좌 소진 — 부족 "&TEXT(-D15,"#,##0")&"원","") | Q15: =MIN(MAX(0,E14+J15),MAX(0,M15-D14-I15)) -> 0 | R15: =MIN(MAX(0,F14+K15),MAX(0,M15-D14-I15)-Q15) -> 0 | S15: =MIN(MAX(0,G14+L15),MAX(0,M15-D14-I15)-Q15-R15) -> 0
A16: 46296 | B16: 목 | C16: =SUM(D16:G16) -> 1.4864538e+08 | D16: =D15+I16-M16+Q16+R16+S16 -> 27745323 | E16: =E15+J16-Q16 -> 1471068.9 | F16: =F15+K16-R16 -> 72264876 | G16: =G15+L16-S16 -> 47164110 | H16: ='4주일별계획'!G16+'4주일별계획'!L16 -> 10611849 | I16: =H16*0.503194 -> 5339818.6 | J16: =H16*0.025182 -> 267227.58 | K16: =H16*0.191179 -> 2028762.6 | L16: =H16*0.280445 -> 2976039.9 | M16: ='4주일별계획'!M16+'4주일별계획'!N16+'4주일별계획'!O16 -> 0 | N16: =Q16 -> 0 | O16: =R16+S16 -> 0 | P16: =IF(D16<-0.5,"전 계좌 소진 — 부족 "&TEXT(-D16,"#,##0")&"원","") | Q16: =MIN(MAX(0,E15+J16),MAX(0,M16-D15-I16)) -> 0 | R16: =MIN(MAX(0,F15+K16),MAX(0,M16-D15-I16)-Q16) -> 0 | S16: =MIN(MAX(0,G15+L16),MAX(0,M16-D15-I16)-Q16-R16) -> 0
A17: 46297 | B17: 금 | C17: =SUM(D17:G17) -> 1.569021e+08 | D17: =D16+I17-M17+Q17+R17+S17 -> 31900057 | E17: =E16+J17-Q17 -> 1678989.7 | F17: =F16+K17-R17 -> 73843388 | G17: =G16+L17-S17 -> 49479667 | H17: ='4주일별계획'!G17+'4주일별계획'!L17 -> 8256724 | I17: =H17*0.503194 -> 4154734 | J17: =H17*0.025182 -> 207920.82 | K17: =H17*0.191179 -> 1578512.2 | L17: =H17*0.280445 -> 2315557 | M17: ='4주일별계획'!M17+'4주일별계획'!N17+'4주일별계획'!O17 -> 0 | N17: =Q17 -> 0 | O17: =R17+S17 -> 0 | P17: =IF(D17<-0.5,"전 계좌 소진 — 부족 "&TEXT(-D17,"#,##0")&"원","") | Q17: =MIN(MAX(0,E16+J17),MAX(0,M17-D16-I17)) -> 0 | R17: =MIN(MAX(0,F16+K17),MAX(0,M17-D16-I17)-Q17) -> 0 | S17: =MIN(MAX(0,G16+L17),MAX(0,M17-D16-I17)-Q17-R17) -> 0
A18: 46298 | B18: 토 | C18: =SUM(D18:G18) -> 1.569021e+08 | D18: =D17+I18-M18+Q18+R18+S18 -> 31900057 | E18: =E17+J18-Q18 -> 1678989.7 | F18: =F17+K18-R18 -> 73843388 | G18: =G17+L18-S18 -> 49479667 | H18: ='4주일별계획'!G18+'4주일별계획'!L18 -> 0 | I18: =H18*0.503194 -> 0 | J18: =H18*0.025182 -> 0 | K18: =H18*0.191179 -> 0 | L18: =H18*0.280445 -> 0 | M18: ='4주일별계획'!M18+'4주일별계획'!N18+'4주일별계획'!O18 -> 0 | N18: =Q18 -> 0 | O18: =R18+S18 -> 0 | P18: =IF(D18<-0.5,"전 계좌 소진 — 부족 "&TEXT(-D18,"#,##0")&"원","") | Q18: =MIN(MAX(0,E17+J18),MAX(0,M18-D17-I18)) -> 0 | R18: =MIN(MAX(0,F17+K18),MAX(0,M18-D17-I18)-Q18) -> 0 | S18: =MIN(MAX(0,G17+L18),MAX(0,M18-D17-I18)-Q18-R18) -> 0
... A33: 46313 | B33: 일 | C33: =SUM(D33:G33) -> 2.5340784e+08 | D33: =D32+I33-M33+Q33+R33+S33 -> 80461165 | E33: =E32+J33-Q33 -> 4109197.2 | F33: =F32+K33-R33 -> 92293259 | G33: =G32+L33-S33 -> 76544218 | H33: ='4주일별계획'!G33+'4주일별계획'!L33 -> 0 | I33: =H33*0.503194 -> 0 | J33: =H33*0.025182 -> 0 | K33: =H33*0.191179 -> 0 | L33: =H33*0.280445 -> 0 | M33: ='4주일별계획'!M33+'4주일별계획'!N33+'4주일별계획'!O33 -> 0 | N33: =Q33 -> 0 | O33: =R33+S33 -> 0 | P33: =IF(D33<-0.5,"전 계좌 소진 — 부족 "&TEXT(-D33,"#,##0")&"원","") | Q33: =MIN(MAX(0,E32+J33),MAX(0,M33-D32-I33)) -> 0 | R33: =MIN(MAX(0,F32+K33),MAX(0,M33-D32-I33)-Q33) -> 0 | S33: =MIN(MAX(0,G32+L33),MAX(0,M33-D32-I33)-Q33-R33) -> 0

Sheet 13주주별계획
A2: 향후 13주 주별 자금계획
A3: ="온라인 예상입금 반영률 "&TEXT(요약!$B$13,"0%")&" 적용. 1~4주는 일별 계획 합계, 5~13주는 자동 예상입금과 입력한 주간 계획을 반영합니다." -> 온라인 예상입금 반영률 80% 적용. 1~4주는 일별 계획 합계, 5~13주는 자동 예상입금과 입력한 주간 계획을 반영합니다.
A5: 주차 | B5: 기간 | C5: 온라인 예상입금 | D5: 확정·기타입금 | E5: 송금예정 | F5: 카드결제 | G5: 조정·추정 지출 | H5: 추가 주간조정 | I5: 순현금흐름 | J5: 기말잔액 | K5: 상태
A6: 1주차 | B6: 2026-09-21 ~ 2026-09-27 | C6: =SUMIFS('4주일별계획'!$G$6:$G$33,'4주일별계획'!$A$6:$A$33,">="&DATE(2026,9,21),'4주일별계획'!$A$6:$A$33,"<="&DATE(2026,9,27)) -> 37783760 | D6: =SUMIFS('4주일별계획'!$L$6:$L$33,'4주일별계획'!$A$6:$A$33,">="&DATE(2026,9,21),'4주일별계획'!$A$6:$A$33,"<="&DATE(2026,9,27)) -> 0 | E6: =SUMIFS('4주일별계획'!$M$6:$M$33,'4주일별계획'!$A$6:$A$33,">="&DATE(2026,9,21),'4주일별계획'!$A$6:$A$33,"<="&DATE(2026,9,27)) -> 40659896 | F6: =SUMIFS('4주일별계획'!$N$6:$N$33,'4주일별계획'!$A$6:$A$33,">="&DATE(2026,9,21),'4주일별계획'!$A$6:$A$33,"<="&DATE(2026,9,27)) -> 0 | G6: =SUMIFS('4주일별계획'!$O$6:$O$33,'4주일별계획'!$A$6:$A$33,">="&DATE(2026,9,21),'4주일별계획'!$A$6:$A$33,"<="&DATE(2026,9,27)) -> 39900682 | I6: =C6+D6-E6-F6-G6+H6 -> -42776818 | J6: =요약!$B$6+I6 -> 97244029 | K6: =IF(J6<0,"자금부족",IF(J6<요약!$B$6*0.2,"주의","정상")) -> 정상
A7: 2주차 | B7: 2026-09-28 ~ 2026-10-04 | C7: =SUMIFS('4주일별계획'!$G$6:$G$33,'4주일별계획'!$A$6:$A$33,">="&DATE(2026,9,28),'4주일별계획'!$A$6:$A$33,"<="&DATE(2026,10,4)) -> 56652333 | D7: =SUMIFS('4주일별계획'!$L$6:$L$33,'4주일별계획'!$A$6:$A$33,">="&DATE(2026,9,28),'4주일별계획'!$A$6:$A$33,"<="&DATE(2026,10,4)) -> 10021867 | E7: =SUMIFS('4주일별계획'!$M$6:$M$33,'4주일별계획'!$A$6:$A$33,">="&DATE(2026,9,28),'4주일별계획'!$A$6:$A$33,"<="&DATE(2026,10,4)) -> 1650000 | F7: =SUMIFS('4주일별계획'!$N$6:$N$33,'4주일별계획'!$A$6:$A$33,">="&DATE(2026,9,28),'4주일별계획'!$A$6:$A$33,"<="&DATE(2026,10,4)) -> 0 | G7: =SUMIFS('4주일별계획'!$O$6:$O$33,'4주일별계획'!$A$6:$A$33,">="&DATE(2026,9,28),'4주일별계획'!$A$6:$A$33,"<="&DATE(2026,10,4)) -> 0 | I7: =C7+D7-E7-F7-G7+H7 -> 65024200 | J7: =J6+I7 -> 1.6226823e+08 | K7: =IF(J7<0,"자금부족",IF(J7<요약!$B$6*0.2,"주의","정상")) -> 정상
A8: 3주차 | B8: 2026-10-05 ~ 2026-10-11 | C8: =SUMIFS('4주일별계획'!$G$6:$G$33,'4주일별계획'!$A$6:$A$33,">="&DATE(2026,10,5),'4주일별계획'!$A$6:$A$33,"<="&DATE(2026,10,11)) -> 39853404 | D8: =SUMIFS('4주일별계획'!$L$6:$L$33,'4주일별계획'!$A$6:$A$33,">="&DATE(2026,10,5),'4주일별계획'!$A$6:$A$33,"<="&DATE(2026,10,11)) -> 0 | E8: =SUMIFS('4주일별계획'!$M$6:$M$33,'4주일별계획'!$A$6:$A$33,">="&DATE(2026,10,5),'4주일별계획'!$A$6:$A$33,"<="&DATE(2026,10,11)) -> 0 | F8: =SUMIFS('4주일별계획'!$N$6:$N$33,'4주일별계획'!$A$6:$A$33,">="&DATE(2026,10,5),'4주일별계획'!$A$6:$A$33,"<="&DATE(2026,10,11)) -> 0 | G8: =SUMIFS('4주일별계획'!$O$6:$O$33,'4주일별계획'!$A$6:$A$33,">="&DATE(2026,10,5),'4주일별계획'!$A$6:$A$33,"<="&DATE(2026,10,11)) -> 0 | I8: =C8+D8-E8-F8-G8+H8 -> 39853404 | J8: =J7+I8 -> 2.0212163e+08 | K8: =IF(J8<0,"자금부족",IF(J8<요약!$B$6*0.2,"주의","정상")) -> 정상
A9: 4주차 | B9: 2026-10-12 ~ 2026-10-18 | C9: =SUMIFS('4주일별계획'!$G$6:$G$33,'4주일별계획'!$A$6:$A$33,">="&DATE(2026,10,12),'4주일별계획'!$A$6:$A$33,"<="&DATE(2026,10,18)) -> 56652333 | D9: =SUMIFS('4주일별계획'!$L$6:$L$33,'4주일별계획'!$A$6:$A$33,">="&DATE(2026,10,12),'4주일별계획'!$A$6:$A$33,"<="&DATE(2026,10,18)) -> 0 | E9: =SUMIFS('4주일별계획'!$M$6:$M$33,'4주일별계획'!$A$6:$A$33,">="&DATE(2026,10,12),'4주일별계획'!$A$6:$A$33,"<="&DATE(2026,10,18)) -> 0 | F9: =SUMIFS('4주일별계획'!$N$6:$N$33,'4주일별계획'!$A$6:$A$33,">="&DATE(2026,10,12),'4주일별계획'!$A$6:$A$33,"<="&DATE(2026,10,18)) -> 0 | G9: =SUMIFS('4주일별계획'!$O$6:$O$33,'4주일별계획'!$A$6:$A$33,">="&DATE(2026,10,12),'4주일별계획'!$A$6:$A$33,"<="&DATE(2026,10,18)) -> 0 | I9: =C9+D9-E9-F9-G9+H9 -> 56652333 | J9: =J8+I9 -> 2.5877397e+08 | K9: =IF(J9<0,"자금부족",IF(J9<요약!$B$6*0.2,"주의","정상")) -> 정상
A10: 5주차 | B10: 2026-10-19 ~ 2026-10-25 | C10: =SUM(설정및분류!$C$6:$C$12)*요약!$B$13 -> 56652333 | F10: 6066502 | G10: 7864831 | I10: =C10+D10-E10-F10-G10+H10 -> 42721000 | J10: =J9+I10 -> 3.0149497e+08 | K10: =IF(J10<0,"자금부족",IF(J10<요약!$B$6*0.2,"주의","정상")) -> 정상
A11: 6주차 | B11: 2026-10-26 ~ 2026-11-01 | C11: =SUM(설정및분류!$C$6:$C$12)*요약!$B$13 -> 56652333 | D11: 10021867 | F11: 25712983 | G11: 73310994 | I11: =C11+D11-E11-F11-G11+H11 -> -32349777 | J11: =J10+I11 -> 2.6914519e+08 | K11: =IF(J11<0,"자금부족",IF(J11<요약!$B$6*0.2,"주의","정상")) -> 정상
A12: 7주차 | B12: 2026-11-02 ~ 2026-11-08 | C12: =SUM(설정및분류!$C$6:$C$12)*요약!$B$13 -> 56652333 | G12: 34494000 | I12: =C12+D12-E12-F12-G12+H12 -> 22158333 | J12: =J11+I12 -> 2.9130352e+08 | K12: =IF(J12<0,"자금부족",IF(J12<요약!$B$6*0.2,"주의","정상")) -> 정상
A13: 8주차 | B13: 2026-11-09 ~ 2026-11-15 | C13: =SUM(설정및분류!$C$6:$C$12)*요약!$B$13 -> 56652333 | G13: 84413290 | I13: =C13+D13-E13-F13-G13+H13 -> -27760957 | J13: =J12+I13 -> 2.6354256e+08 | K13: =IF(J13<0,"자금부족",IF(J13<요약!$B$6*0.2,"주의","정상")) -> 정상
A14: 9주차 | B14: 2026-11-16 ~ 2026-11-22 | C14: =SUM(설정및분류!$C$6:$C$12)*요약!$B$13 -> 56652333 | F14: 155361 | G14: 5046740 | I14: =C14+D14-E14-F14-G14+H14 -> 51450232 | J14: =J13+I14 -> 3.149928e+08 | K14: =IF(J14<0,"자금부족",IF(J14<요약!$B$6*0.2,"주의","정상")) -> 정상
A15: 10주차 | B15: 2026-11-23 ~ 2026-11-29 | C15: =SUM(설정및분류!$C$6:$C$12)*요약!$B$13 -> 56652333 | F15: 31779485 | G15: 7978464 | I15: =C15+D15-E15-F15-G15+H15 -> 16894384 | J15: =J14+I15 -> 3.3188718e+08 | K15: =IF(J15<0,"자금부족",IF(J15<요약!$B$6*0.2,"주의","정상")) -> 정상
A16: 11주차 | B16: 2026-11-30 ~ 2026-12-06 | C16: =SUM(설정및분류!$C$6:$C$12)*요약!$B$13 -> 56652333 | D16: 10021867 | G16: 103197361 | I16: =C16+D16-E16-F16-G16+H16 -> -36523161 | J16: =J15+I16 -> 2.9536402e+08 | K16: =IF(J16<0,"자금부족",IF(J16<요약!$B$6*0.2,"주의","정상")) -> 정상
A17: 12주차 | B17: 2026-12-07 ~ 2026-12-13 | C17: =SUM(설정및분류!$C$6:$C$12)*요약!$B$13 -> 56652333 | G17: 88907290 | I17: =C17+D17-E17-F17-G17+H17 -> -32254957 | J17: =J16+I17 -> 2.6310906e+08 | K17: =IF(J17<0,"자금부족",IF(J17<요약!$B$6*0.2,"주의","정상")) -> 정상
A18: 13주차 | B18: 2026-12-14 ~ 2026-12-20 | C18: =SUM(설정및분류!$C$6:$C$12)*요약!$B$13 -> 56652333 | F18: 155361 | G18: 5046740 | I18: =C18+D18-E18-F18-G18+H18 -> 51450232 | J18: =J17+I18 -> 3.1455929e+08 | K18: =IF(J18<0,"자금부족",IF(J18<요약!$B$6*0.2,"주의","정상")) -> 정상

Sheet 지출계획_취합
A2: 팀 지출계획 취합 (자동 반영)
A3: 매 실행마다 팀 제출 파일에서 자동 갱신됩니다. 대외비는 분류·총액만 표시됩니다. 경영보고와 같은 실행일~차주 금요일 기간만 표시합니다 (그 밖의 반영일 행은 숨김 — 행 숨기기 해제로 전체 확인).
A5: 요청ID | B5: 팀명 | C5: 신청자 | D5: 품의승인 | E5: 지급예정일 | F5: 자금계획 반영일 | G5: 거래처 | H5: 지출내용 | I5: 예상금액 | J5: 지급방법 | K5: 카드구분 | L5: 확정여부 | M5: 진행상태 | N5: 최종수정일 | O5: 원본파일 | P5: 반영상태 | Q5: 확인사항
A6: 경영-20260918-011 | B6: 경영지원팀 | C6: 송채은 | E6: 46283 | F6: 46283 | G6: 이앤씨이노비즈타워 | H6: 본사관리비 | I6: 1553720 | J6: 계좌송금 | L6: 확정 | M6: 신규 | N6: 46283 | O6: 지출계획_2026-09-21.xlsx | P6: 에이팜 별도관리
A7: 건강-20260918-001 | B7: 건강사업팀 | C7: 양혜원 | E7: 46286 | F7: 46286 | G7: 트라이앵글하모니 | H7: 카카오톡선물하기 베리시톨 리뷰작업 | I7: 1996000 | J7: 계좌송금 | L7: 확정 | M7: 신규 | N7: 46283 | O7: 지출계획_2026-09-21.xlsx | P7: 정상반영
A8: 건강-20260918-003 | B8: 건강사업팀 | C8: 전은신 | E8: 46286 | F8: 46286 | G8: 네이버SA&GFA | H8: 네이버 SA&GFA 광고비 충전 | I8: 3498000 | J8: 계좌송금 | L8: 확정 | M8: 변경 | N8: 46283 | O8: 지출계획_2026-09-21.xlsx | P8: 정상반영
A9: 경영-20260918-005 | B9: 경영지원팀 | C9: 김수희 | E9: 46286 | F9: 46286 | G9: 메트라이프 | H9: 달러경영인정기보험_63회차/55회차 | I9: 4900000 | J9: 자동이체 | L9: 확정 | M9: 변경 | N9: 46283 | O9: 지출계획_2026-09-21.xlsx | P9: 정상반영
A10: 경영-20260918-006 | B10: 경영지원팀 | C10: 김수희 | E10: 46286 | F10: 46286 | G10: SK브로드밴드 | H10: 사내전화 | I10: 220000 | J10: 자동이체 | L10: 확정 | M10: 신규 | N10: 46283 | O10: 지출계획_2026-09-21.xlsx | P10: 정상반영
A11: 건강-20260918-002 | B11: 건강사업팀 | C11: 양혜원 | E11: 46287 | F11: 46287 | G11: 네이버 | H11: 네이버 톡톡 발송 | I11: 500000 | J11: 계좌송금 | L11: 확정 | M11: 신규 | N11: 46283 | O11: 지출계획_2026-09-21.xlsx | P11: 정상반영
A12: 경영-20260918-007 | B12: 경영지원팀 | C12: 송채은 | E12: 46287 | F12: 46287 | G12: 와이투홀딩스 | H12: 직원 추석 선물세트 구입 | I12: 1023110 | J12: 계좌송금 | L12: 확정 | M12: 변경 | N12: 46283 | O12: 지출계획_2026-09-21.xlsx | P12: 정상반영
A13: 경영-20260918-015 | B13: 경영지원팀 | C13: 김정원 | E13: 46287 | F13: 46287 | G13: 엠에스바이오텍 | H13: 외상매입금 | I13: 20000000 | J13: 계좌송금 | L13: 확정 | M13: 변경 | N13: 46284 | O13: 지출계획_2026-09-21.xlsx | P13: 정상반영
A14: 건강-20260918-004 | B14: 건강사업팀 | C14: 전은신 | E14: 46288 | F14: 46288 | G14: 인포크비즈니스 | H14: 베리시톨 인플루언서 비용 | I14: 3300000 | J14: 계좌송금 | L14: 확정 | M14: 변경 | N14: 46286 | O14: 지출계획_2026-09-21.xlsx | P14: 정상반영
A15: 건강-20260918-005 | B15: 건강사업팀 | C15: 전은신 | E15: 46288 | F15: 46288 | G15: 써치엠 | H15: 메타 광고 대행 수수 | I15: 1487786 | J15: 계좌송금 | L15: 확정 | M15: 신규 | N15: 46283 | O15: 지출계획_2026-09-21.xlsx | P15: 정상반영
A16: 건강-20260918-006 | B16: 건강사업팀 | C16: 전은신 | E16: 46288 | F16: 46288 | G16: 네이버SA&GFA | H16: 네이버SA&GFA 광고 비용 충전 | I16: 8305000 | J16: 계좌송금 | L16: 확정 | M16: 신규 | N16: 46283 | O16: 지출계획_2026-09-21.xlsx | P16: 정상반영
A17: 건강-20260918-007 | B17: 건강사업팀 | C17: 전은신 | E17: 46288 | F17: 46288 | G17: ADN | H17: ADN 광고-추석 유입 | I17: 550000 | J17: 계좌송금 | L17: 확정 | M17: 신규 | N17: 46283 | O17: 지출계획_2026-09-21.xlsx | P17: 정상반영
... A26: 경영-20260918-014 | B26: 경영지원팀 | C26: 송채은 | E26: 46295 | F26: 46295 | G26: 대구상공회의소 | H26: 하반기연회비 | I26: 250000 | J26: 계좌송금 | L26: 확정 | M26: 신규 | N26: 46283 | O26: 지출계획_2026-09-21.xlsx | P26: 에이팜 별도관리

Sheet 에이팜 지출계획
A2: 에이팜 지출계획 (자동 반영)
A3: 지출계획 비고에 '에이팜'으로 표시한 건은 자금계획(4주·13주)에 반영하지 않고 여기서만 관리합니다. '반영' 표시 건은 자금계획에 포함된 에이팜 관련 참고 항목입니다.
A5: 일자 | B5: 요일 | C5: 출처 | D5: 자금계획 반영 | E5: 팀명 | F5: 거래처 | G5: 지출내용 | H5: 예상금액 | I5: 지급방법 | J5: 비고
A6: 46283 | B6: 금 | C6: 팀 지출계획 | D6: 미반영(별도 관리) | E6: 경영지원팀 | F6: 이앤씨이노비즈타워 | G6: 본사관리비 | H6: 1553720 | I6: 계좌송금 | J6: 에이팜
A7: 46288 | B7: 수 | C7: 팀 지출계획 | D7: 미반영(별도 관리) | E7: 경영지원팀 | F7: 비씨카드 | G7: 8월카드대금 | H7: 269810 | I7: 계좌송금 | J7: 에이팜
A8: 46295 | B8: 수 | C8: 팀 지출계획 | D8: 미반영(별도 관리) | E8: 경영지원팀 | F8: 서원회계법인 | G8: 기장료 | H8: 330000 | I8: 계좌송금 | J8: 에이팜
A9: 46295 | B9: 수 | C9: 팀 지출계획 | D9: 미반영(별도 관리) | E9: 경영지원팀 | F9: 가가사무기 | G9: 복합기 9월 임대비용 | H9: 280000 | I9: 계좌송금 | J9: 에이팜
A10: 46295 | B10: 수 | C10: 팀 지출계획 | D10: 미반영(별도 관리) | E10: 경영지원팀 | F10: 대구상공회의소 | G10: 하반기연회비 | H10: 250000 | I10: 계좌송금 | J10: 에이팜
G11: 합계(자금계획 미반영) | H11: 2683530

Sheet 계좌내역통합_RAW
A1: 거래일시 | B1: 거래일 | C1: 은행 | D1: 계좌 | E1: 출금액 | F1: 입금액 | G1: 거래후잔액 | H1: 적요 | I1: 기재내용·상대방 | J1: 취급점 | K1: 자동분류 | L1: 내부이체 | M1: 정기지출후보 | N1: 현금유출입 | O1: 원본파일 | P1: 반영상태
A2: 46106.435 | B2: 46106 | C2: 국민은행 | D2: 국민 169124 | E2: 0 | F2: 2497000 | G2: 3871400 | H2: 기일입금 | I2: (주)에이팜건강 | J2: 진천역 | K2: 계좌간이체 | L2: Y | M2: N | N2: 0 | O2: 농협계좌_6개월(20260913).xls | P2: 기존내역
A3: 46106.665 | B3: 46106 | C3: 국민은행 | D3: 국민 169124 | E3: 0 | F3: 110000000 | G3: 113871400 | H3: FBS입금 | I3: 한화생중도인출 | J3: ERP사 | K3: 보험 중도인출·보험금 입금 | L3: N | M3: N | N3: 110000000 | O3: 농협계좌_6개월(20260913).xls | P3: 기존내역
A4: 46106.833 | B4: 46106 | C4: 국민은행 | D4: 국민 169124 | E4: 2497000 | F4: 0 | G4: 111374400 | H4: CMS 공동 | I4: METLIFE03036 | J4: ERP사 | K4: 기타지출 | L4: N | M4: Y | N4: -2497000 | O4: 농협계좌_6개월(20260913).xls | P4: 기존내역
A5: 46106.839 | B5: 46106 | C5: 국민은행 | D5: 국민 169124 | E5: 110000000 | F5: 0 | G5: 1374400 | H5: FBS출금 | I5: 푸본현02-002 | J5: ERP사 | K5: 보험료 | L5: N | M5: N | N5: -110000000 | O5: 농협계좌_6개월(20260913).xls | P5: 기존내역
A6: 46107.488 | B6: 46107 | C6: 국민은행 | D6: 국민 169124 | E6: 1374400 | F6: 0 | G6: 0 | H6: 스마트출금 | I6: (주)에이팜건강 | J6: 진천역 | K6: 계좌간이체 | L6: Y | M6: N | N6: 0 | O6: 농협계좌_6개월(20260913).xls | P6: 기존내역
A7: 46115.726 | B7: 46115 | C7: 국민은행 | D7: 국민 169124 | E7: 0 | F7: 3003000 | G7: 3003000 | H7: 전자금융 | I7: 주식회사에이팜건강 | J7: 우리은행 | K7: 계좌간이체 | L7: Y | M7: N | N7: 0 | O7: 국민은행_계좌 조회 6개월(20260913).xls | P7: 기존내역
A8: 46118.429 | B8: 46118 | C8: 국민은행 | D8: 국민 169124 | E8: 0 | F8: 5240400 | G8: 48764600 | H8: 기일입금 | I8: (주)에이팜건강 | J8: 진천역 | K8: 계좌간이체 | L8: Y | M8: N | N8: 0 | O8: 국민은행_계좌 조회 6개월(20260913).xls | P8: 기존내역
A9: 46118.429 | B9: 46118 | C9: 국민은행 | D9: 국민 169124 | E9: 0 | F9: 500000 | G9: 43524200 | H9: 기일입금 | I9: (주)에이팜건강 | J9: 진천역 | K9: 계좌간이체 | L9: Y | M9: N | N9: 0 | O9: 국민은행_계좌 조회 6개월(20260913).xls | P9: 기존내역
A10: 46118.429 | B10: 46118 | C10: 국민은행 | D10: 국민 169124 | E10: 0 | F10: 30000000 | G10: 43024200 | H10: 기일입금 | I10: (주)에이팜건강 | J10: 진천역 | K10: 계좌간이체 | L10: Y | M10: N | N10: 0 | O10: 국민은행_계좌 조회 6개월(20260913).xls | P10: 기존내역
A11: 46118.429 | B11: 46118 | C11: 국민은행 | D11: 국민 169124 | E11: 0 | F11: 10021200 | G11: 13024200 | H11: 기일입금 | I11: (주)에이팜건강 | J11: 진천역 | K11: 계좌간이체 | L11: Y | M11: N | N11: 0 | O11: 우리은행 거래내역조회 20260913.xlsx | P11: 기존내역
A12: 46118.796 | B12: 46118 | C12: 국민은행 | D12: 국민 169124 | E12: 40521200 | F12: 0 | G12: 8243400 | H12: FBS출금 | I12: 한화생04-03 | J12: ERP사 | K12: 보험료 | L12: N | M12: Y | N12: -40521200 | O12: 우리은행 거래내역조회 20260913.xlsx | P12: 기존내역
A13: 46118.809 | B13: 46118 | C13: 국민은행 | D13: 국민 169124 | E13: 8243400 | F13: 0 | G13: 0 | H13: FBS출금 | I13: 삼성04002건 | J13: ERP사 | K13: 보험료 | L13: N | M13: Y | N13: -8243400 | O13: 우리은행 거래내역조회 20260913.xlsx | P13: 기존내역
... A146: 46286.219 | B146: 46286 | C146: 우리은행 | D146: 우리 220351 | E146: 0 | F146: 5694170 | G146: 17314264 | H146: 펌뱅킹 | I146: 스마트스토어정산 | J146: 두산타워기업영업지원팀 | K146: 온라인매출입금 | L146: N | M146: N | N146: 5694170 | O146: 우리은행 거래내역조회 20260913.xlsx | P146: 기존내역
O147: 우리은행 거래내역조회 20260913.xlsx | P147: 기존내역
O148: 우리은행 거래내역조회 20260913.xlsx | P148: 기존내역
O149: 우리은행 거래내역조회 20260913.xlsx | P149: 기존내역
O150: 우리은행 거래내역조회 20260913.xlsx | P150: 기존내역
O151: 우리은행 거래내역조회 20260913.xlsx | P151: 기존내역
O152: 국민은행_계좌 조회 6개월(20260913).xls | P152: 기존내역
O153: 국민은행_계좌 조회 6개월(20260913).xls | P153: 기존내역
O154: 국민은행_계좌 조회 6개월(20260913).xls | P154: 기존내역
O155: 국민은행_계좌 조회 6개월(20260913).xls | P155: 기존내역
O156: 국민은행_계좌 조회 6개월(20260913).xls | P156: 기존내역
O157: 국민은행_계좌 조회 6개월(20260913).xls | P157: 기존내역
O158: 농협계좌_6개월(20260913).xls | P158: 기존내역
... O2092: 국민은행_계좌 조회 6개월(20260913).xls | P2092: 기존내역
O2093: =IF($A2093="","","주간붙여넣기_농협") | P2093: =IF($A2093="","",IF(COUNTIFS($C$2:$C$2092,$C2093,$B$2:$B$2092,$B2093,$E$2:$E$2092,$E2093,$F$2:$F$2092,$F2093,$G$2:$G$2092,$G2093)>0,"중복제외","신규반영"))
O2094: =IF($A2094="","","주간붙여넣기_농협") | P2094: =IF($A2094="","",IF(COUNTIFS($C$2:$C$2093,$C2094,$B$2:$B$2093,$B2094,$E$2:$E$2093,$E2094,$F$2:$F$2093,$F2094,$G$2:$G$2093,$G2094)>0,"중복제외","신규반영"))
O2095: =IF($A2095="","","주간붙여넣기_농협") | P2095: =IF($A2095="","",IF(COUNTIFS($C$2:$C$2094,$C2095,$B$2:$B$2094,$B2095,$E$2:$E$2094,$E2095,$F$2:$F$2094,$F2095,$G$2:$G$2094,$G2095)>0,"중복제외","신규반영"))
O2096: =IF($A2096="","","주간붙여넣기_농협") | P2096: =IF($A2096="","",IF(COUNTIFS($C$2:$C$2095,$C2096,$B$2:$B$2095,$B2096,$E$2:$E$2095,$E2096,$F$2:$F$2095,$F2096,$G$2:$G$2095,$G2096)>0,"중복제외","신규반영"))
O2097: =IF($A2097="","","주간붙여넣기_농협") | P2097: =IF($A2097="","",IF(COUNTIFS($C$2:$C$2096,$C2097,$B$2:$B$2096,$B2097,$E$2:$E$2096,$E2097,$F$2:$F$2096,$F2097,$G$2:$G$2096,$G2097)>0,"중복제외","신규반영"))
O2098: =IF($A2098="","","주간붙여넣기_농협") | P2098: =IF($A2098="","",IF(COUNTIFS($C$2:$C$2097,$C2098,$B$2:$B$2097,$B2098,$E$2:$E$2097,$E2098,$F$2:$F$2097,$F2098,$G$2:$G$2097,$G2098)>0,"중복제외","신규반영"))
O2099: =IF($A2099="","","주간붙여넣기_농협") | P2099: =IF($A2099="","",IF(COUNTIFS($C$2:$C$2098,$C2099,$B$2:$B$2098,$B2099,$E$2:$E$2098,$E2099,$F$2:$F$2098,$F2099,$G$2:$G$2098,$G2099)>0,"중복제외","신규반영"))
O2100: =IF($A2100="","","주간붙여넣기_농협") | P2100: =IF($A2100="","",IF(COUNTIFS($C$2:$C$2099,$C2100,$B$2:$B$2099,$B2100,$E$2:$E$2099,$E2100,$F$2:$F$2099,$F2100,$G$2:$G$2099,$G2100)>0,"중복제외","신규반영"))
O2101: =IF($A2101="","","주간붙여넣기_농협") | P2101: =IF($A2101="","",IF(COUNTIFS($C$2:$C$2100,$C2101,$B$2:$B$2100,$B2101,$E$2:$E$2100,$E2101,$F$2:$F$2100,$F2101,$G$2:$G$2100,$G2101)>0,"중복제외","신규반영"))
O2102: =IF($A2102="","","주간붙여넣기_농협") | P2102: =IF($A2102="","",IF(COUNTIFS($C$2:$C$2101,$C2102,$B$2:$B$2101,$B2102,$E$2:$E$2101,$E2102,$F$2:$F$2101,$F2102,$G$2:$G$2101,$G2102)>0,"중복제외","신규반영"))
O2103: =IF($A2103="","","주간붙여넣기_농협") | P2103: =IF($A2103="","",IF(COUNTIFS($C$2:$C$2102,$C2103,$B$2:$B$2102,$B2103,$E$2:$E$2102,$E2103,$F$2:$F$2102,$F2103,$G$2:$G$2102,$G2103)>0,"중복제외","신규반영"))
O2104: =IF($A2104="","","주간붙여넣기_농협") | P2104: =IF($A2104="","",IF(COUNTIFS($C$2:$C$2103,$C2104,$B$2:$B$2103,$B2104,$E$2:$E$2103,$E2104,$F$2:$F$2103,$F2104,$G$2:$G$2103,$G2104)>0,"중복제외","신규반영"))
O2105: =IF($A2105="","","주간붙여넣기_농협") | P2105: =IF($A2105="","",IF(COUNTIFS($C$2:$C$2104,$C2105,$B$2:$B$2104,$B2105,$E$2:$E$2104,$E2105,$F$2:$F$2104,$F2105,$G$2:$G$2104,$G2105)>0,"중복제외","신규반영"))
...

Sheet 설정및분류
A2: 예측 설정 및 자동분류 기준
A5: 요일번호 | B5: 요일 | C5: 최근 12주 온라인입금 일평균 | E5: 분류 | F5: 대표 키워드 | H5: 반영률 선택값
A6: 1 | B6: 월 | C6: 10677756 | E6: 온라인매출입금 | F6: 스마트스토어, KG이니시스, Npay, NHN페이, 카드가맹점 | H6: 0.6
A7: 2 | B7: 화 | C7: 22255001 | E7: 계좌간이체 | F7: 에이팜건강 표시(광고·네이버 제외) | H7: 0.7
A8: 3 | B8: 수 | C8: 14296943 | E8: 4대보험 | F8: 우리은행의 사회보험·건강보험 | H8: 0.8
A9: 4 | B9: 목 | C9: 13264811 | E9: 원천세·국세 | F9: 우리은행의 국고·원천세 | H9: 0.9
A10: 5 | B10: 금 | C10: 10320905 | E10: 법인카드결제 | F10: 우리카드결제대금, KB카드출금 | H10: 1
A11: 6 | B11: 토 | C11: 0 | E11: 보험료(기타) | F11: 한화생명, 메트라이프, ABL생명, 미래에셋
A12: 7 | B12: 일 | C12: 0 | E12: 광고선전비 | F12: 네이버, 광고, 비즈월렛, 캐시워크
E13: 급여·인건비(대외비) | F13: 급여, 상여, 퇴직, 국민은행 월말 TOP출금
E14: 대출·이자 | F14: 대출, 이자
E15: 기타입출금 | F15: 위 기준에 해당하지 않는 거래
