Workbook

Sheet 요약
A2: (주)에이팜건강 자금계획 기초 현황
A3: 기준일 2026-09-21 | 농협·우리은행·국민은행 계좌 거래내역 통합 (자동 갱신)
A5: 항목 | B5: 금액 | D5: 계좌 | E5: 최종 거래일 | F5: 잔액
A6: 현재 계좌잔액 | B6: 148422317 | D6: 국민 154577 | E6: 46287 | F6: 36085938
A7: 6개월 외부입금 | B7: 3302536289 | D7: 국민 169124 | E7: 46280 | F7: 100687200
A8: 6개월 외부출금 | B8: 3490589815 | D8: 농협 569003 | E8: 46287 | F8: 2227429
A9: 온라인매출 입금 | B9: 2010798876 | D9: 우리 220351 | E9: 46287 | F9: 9421750
A10: 최근 12주 주평균 온라인입금 | B10: 70815416
A12: 계획 설정 | B12: 값 | D12: 사용 방법
A13: 입금 예측 반영률 | B13: 0.8 | D13: 1. 새 계좌파일을 올리면 RAW 통합표에 이어 붙입니다.
A14: 4주 예상 기말잔액 | B14: ='4주일별계획'!R35 | D14: 2. 노란색 칸에 확정 입금·지출계획을 입력합니다.
A15: 4주 최저 예상잔액 | B15: =MIN('4주일별계획'!R8:R35) | D15: ="3. 온라인 입금은 최근 12주 요일별 평균의 "&TEXT($B$13,"0%")&"로 예측합니다."
A16: 13주 예상 기말잔액 | B16: ='13주주별계획'!J18 | D16: 4. 계좌 간 이체는 내부이체로 표시해 입출금 합계에서 제외합니다.
D17: 5. 정기지출분석의 '확인필요' 항목은 성격을 확인 후 확정합니다.

Sheet 업데이트운영
A2: 계좌 거래내역 업데이트 운영 방법
A3: 6개월 자료는 최초 1회만 필요합니다. 이후에는 매주 은행 원본파일을 그대로 업로드하면 됩니다.
A5: 항목 | B5: 권장 운영 기준 | D5: 처리단계 | E5: 자동 처리 내용 | F5: 중복 판정 기준 | G5: 결과 | H5: 사용자 작업
A6: 업로드 주기 | B6: 주 1회. 월요일 오전에 전주 월요일~일요일 거래내역을 내려받습니다. | D6: 1. 파일 인식 | E6: 은행별 머리글과 데이터 시작행 판별 | F6: 은행·계좌 | G6: 은행 형식 통일 | H6: 파일 첨부
A7: 권장 조회기간 | B7: 누락 방지를 위해 최근 14일을 조회해도 됩니다. 중복 거래는 자동으로 제외합니다. | D7: 2. 거래 표준화 | E7: 거래일시·입금·출금·잔액·적요 변환 | F7: 거래일시·입출금액·잔액·적요 | G7: RAW 한 표로 통합 | H7: 없음
A8: 업로드 장소 | B8: 이 대화창에 농협·우리은행·국민은행 원본파일을 첨부합니다. | D8: 3. 중복 제거 | E8: 기존 거래와 신규 거래 비교 | F8: 계좌+일시+금액+잔액+적요 | G8: 겹친 조회기간 제거 | H8: 없음
A9: 권장 파일형식 | B9: 은행에서 내려받은 XLS, XLSX, CSV 원본을 권장합니다. | D9: 4. 자동 분류 | E9: 매출·내부이체·세금·보험·카드 등 분류 | F9: 적요 키워드 | G9: 분류 및 정기지출 표시 | H9: 확인필요만 검토
A10: 지양할 형식 | B10: PDF, 사진, 화면 캡처는 열 구조가 일정하지 않아 자동처리에 불리합니다. | D10: 5. 잔액 갱신 | E10: 계좌별 최종 거래 잔액 반영 | F10: 가장 최근 거래일시 | G10: 전체 가용잔액 갱신 | H10: 없음
A11: 파일명 | B11: 은행이 만들어 준 원래 파일명을 그대로 사용해도 됩니다. | D11: 6. 계획 갱신 | E11: 최근 12주 패턴 및 선택 반영률 적용 | F11: 드롭다운 반영률 | G11: 4주·13주 전망 변경 | H11: 예정 지출만 보완
A12: 업데이트 요청문 | B12: '이번 주 계좌내역 반영해서 자금계획 업데이트해줘'라고 입력합니다.
A13: 직접 입력 | B13: 거래내역은 복사·붙여넣지 않습니다. 향후 확정 입금·지출계획만 노란색 칸에 입력합니다.
A16: 은행 | B16: 현재 기준 원본파일 | C16: 조회 시작 | D16: 조회 종료 | E16: 반영 거래건수 | F16: 상태
A17: 농협 | B17: 농협계좌_6개월(20260913).xls | C17: 46094 | D17: 46278 | E17: 234 | F17: 반영완료
A18: 우리은행 | B18: 우리은행 거래내역조회 20260913.xlsx | C18: 46095 | D18: 46278 | E18: 862 | F18: 반영완료
A19: 국민은행 | B19: 국민은행_계좌 조회 6개월(20260913).xls | C19: 46095 | D19: 46278 | E19: 995 | F19: 반영완료

Sheet 4주일별계획
A2: 향후 4주 일별 자금계획
A3: 온라인 예상입금은 최근 12주 요일별 평균 × 입금 반영률(요약 B13)로 계산됩니다. 노란색 칸만 입력하세요. | 실잔고(은행 최근 확인): 우리 220351 9,421,750(09-22) · 농협 569003 2,227,429(09-22) · 국민 169124 100,687,200(09-15) · 국민 154577 36,085,938(09-22) — 실행일 행은 은행 파일 그대로 실적으로 마감(기말 = 오늘 실잔고)하고, 아직 안 나간 예정(보류 제외)은 익일로 이월합니다. 자금 예산은 익일부터 오늘 실잔고에서 출발합니다(반영률 B13 연동)
C4: 계좌별 예상잔고 | H4: 계좌별 입금 배분(예상)
A5: 일자 | B5: 요일 | C5: 우리 220351 | D5: 농협 569003 | E5: 국민 169124 | F5: 국민 154577 | G5: 온라인 예상입금 | H5: 우리 220351 | I5: 농협 569003 | J5: 국민 169124 | K5: 국민 154577 | L5: 확정·기타입금 | M5: 송금예정 | N5: 카드결제 | O5: 조정·추정 지출 | P5: 순현금흐름 | Q5: 기초잔액 | R5: 기말잔액 | S5: 비고
A6: 46286 | B6: 월 | C6: ='계좌별시나리오'!D6 | D6: ='계좌별시나리오'!E6 | E6: ='계좌별시나리오'!F6 | F6: ='계좌별시나리오'!G6 | R6: ='계좌별시나리오'!C6 | S6: 전일 마감 실잔고 — 여기서 계획 시작
A7: 46287 | B7: 화 | C7: ='계좌별시나리오'!D7 | D7: ='계좌별시나리오'!E7 | E7: ='계좌별시나리오'!F7 | F7: ='계좌별시나리오'!G7 | G7: 19586633 | L7: 529613 | O7: 28895517 | P7: -8779271 | R7: ='요약'!$B$6 | S7: 오늘 실잔고(은행 확인)·실제 입금·출금 — 참고 (이중계산 안 됨)
A8: 46286 | B8: 월 | C8: ='계좌별시나리오'!D8 | D8: ='계좌별시나리오'!E8 | E8: ='계좌별시나리오'!F8 | F8: ='계좌별시나리오'!G8 | G8: 20747810 | H8: ='계좌별시나리오'!I8 | I8: ='계좌별시나리오'!J8 | J8: ='계좌별시나리오'!K8 | K8: ='계좌별시나리오'!L8 | L8: 40220000 | O8: 16528386 | P8: =G8+L8-M8-N8-O8 | Q8: 112762164 | R8: =Q8+P8 | S8: 실적 | 지출: METLIFE09002 4,795,900, METLIFE09002 4,795,900, 국민네이버 ａｐｈａ 2,178,000 외 11건 | 기타입금: 허용 20,000,000, 허용 20,000,000 외 2건
A9: 46287 | B9: 화 | C9: ='계좌별시나리오'!D9 | D9: ='계좌별시나리오'!E9 | E9: ='계좌별시나리오'!F9 | F9: ='계좌별시나리오'!G9 | G9: 19586633 | H9: ='계좌별시나리오'!I9 | I9: ='계좌별시나리오'!J9 | J9: ='계좌별시나리오'!K9 | K9: ='계좌별시나리오'!L9 | L9: 529613 | M9: 28895517 | P9: =G9+L9-M9-N9-O9 | Q9: =R8 | R9: =Q9+P9 | S9: 엠에스바이오텍 20,000,000, 엠에스바이오텍 20,000,000, 추석 상여금 7,800,000, 네이버 500,000, 임대규(대청하이츠) 350,000, 대구상공회의소 250,000; 실적(은행 확인): 입금 20,116,246·출금 28,895,517 — 미집행 예정 20,000,000 익일 이월 / 보류 제외: 네이버 4,483
A10: 46288 | B10: 수 | C10: ='계좌별시나리오'!D10 | D10: ='계좌별시나리오'!E10 | E10: ='계좌별시나리오'!F10 | F10: ='계좌별시나리오'!G10 | G10: =INDEX('설정및분류'!$C$6:$C$12,WEEKDAY(A10,2))*'요약'!$B$13 | H10: ='계좌별시나리오'!I10 | I10: ='계좌별시나리오'!J10 | J10: ='계좌별시나리오'!K10 | K10: ='계좌별시나리오'!L10 | M10: 34665896 | O10: 2227429 | P10: =G10+L10-M10-N10-O10 | Q10: =R9 | R10: =Q10+P10 | S10: 네이버SA&GFA 8,305,000, 인포크비즈니스 3,300,000, 농협카드 2,227,429, 써치엠 1,487,786, 와이투홀딩스 1,023,110, ADN 550,000; 전일 미집행 예정 20,000,000 이월 반영
A11: 46289 | B11: 목 | C11: ='계좌별시나리오'!D11 | D11: ='계좌별시나리오'!E11 | E11: ='계좌별시나리오'!F11 | F11: ='계좌별시나리오'!G11 | G11: 0 | H11: ='계좌별시나리오'!I11 | I11: ='계좌별시나리오'!J11 | J11: ='계좌별시나리오'!K11 | K11: ='계좌별시나리오'!L11 | P11: =G11+L11-M11-N11-O11 | Q11: =R10 | R11: =Q11+P11
A12: 46290 | B12: 금 | C12: ='계좌별시나리오'!D12 | D12: ='계좌별시나리오'!E12 | E12: ='계좌별시나리오'!F12 | F12: ='계좌별시나리오'!G12 | G12: 0 | H12: ='계좌별시나리오'!I12 | I12: ='계좌별시나리오'!J12 | J12: ='계좌별시나리오'!K12 | K12: ='계좌별시나리오'!L12 | P12: =G12+L12-M12-N12-O12 | Q12: =R11 | R12: =Q12+P12
A13: 46291 | B13: 토 | C13: ='계좌별시나리오'!D13 | D13: ='계좌별시나리오'!E13 | E13: ='계좌별시나리오'!F13 | F13: ='계좌별시나리오'!G13 | G13: 0 | H13: ='계좌별시나리오'!I13 | I13: ='계좌별시나리오'!J13 | J13: ='계좌별시나리오'!K13 | K13: ='계좌별시나리오'!L13 | P13: =G13+L13-M13-N13-O13 | Q13: =R12 | R13: =Q13+P13
A14: 46292 | B14: 일 | C14: ='계좌별시나리오'!D14 | D14: ='계좌별시나리오'!E14 | E14: ='계좌별시나리오'!F14 | F14: ='계좌별시나리오'!G14 | G14: =INDEX('설정및분류'!$C$6:$C$12,WEEKDAY(A14,2))*'요약'!$B$13 | H14: ='계좌별시나리오'!I14 | I14: ='계좌별시나리오'!J14 | J14: ='계좌별시나리오'!K14 | K14: ='계좌별시나리오'!L14 | P14: =G14+L14-M14-N14-O14 | Q14: =R13 | R14: =Q14+P14
A15: 46293 | B15: 월 | C15: ='계좌별시나리오'!D15 | D15: ='계좌별시나리오'!E15 | E15: ='계좌별시나리오'!F15 | F15: ='계좌별시나리오'!G15 | G15: =INDEX('설정및분류'!$C$6:$C$12,WEEKDAY(A15,2))*'요약'!$B$13 | H15: ='계좌별시나리오'!I15 | I15: ='계좌별시나리오'!J15 | J15: ='계좌별시나리오'!K15 | K15: ='계좌별시나리오'!L15 | M15: 1650000 | O15: 32562799 | P15: =G15+L15-M15-N15-O15 | Q15: =R14 | R15: =Q15+P15 | S15: 우리카드 25,346,349, 농협카드 4,610,000, 메트라이프 2,497,000, 엘앤에이치컴퍼니 1,650,000, KT 109,450
A16: 46294 | B16: 화 | C16: ='계좌별시나리오'!D16 | D16: ='계좌별시나리오'!E16 | E16: ='계좌별시나리오'!F16 | F16: ='계좌별시나리오'!G16 | G16: =INDEX('설정및분류'!$C$6:$C$12,WEEKDAY(A16,2))*'요약'!$B$13 | H16: ='계좌별시나리오'!I16 | I16: ='계좌별시나리오'!J16 | J16: ='계좌별시나리오'!K16 | K16: ='계좌별시나리오'!L16 | M16: 1000000 | P16: =G16+L16-M16-N16-O16 | Q16: =R15 | R16: =Q16+P16 | S16: 네이버 500,000, 정상은(이준이서맘) 500,000
A17: 46295 | B17: 수 | C17: ='계좌별시나리오'!D17 | D17: ='계좌별시나리오'!E17 | E17: ='계좌별시나리오'!F17 | F17: ='계좌별시나리오'!G17 | G17: =INDEX('설정및분류'!$C$6:$C$12,WEEKDAY(A17,2))*'요약'!$B$13 | H17: ='계좌별시나리오'!I17 | I17: ='계좌별시나리오'!J17 | J17: ='계좌별시나리오'!K17 | K17: ='계좌별시나리오'!L17 | L17: 10021867 | M17: 1080000 | P17: =G17+L17-M17-N17-O17 | Q17: =R16 | R17: =Q17+P17 | S17: (주) 오애드 880,000, 카카오톡 비즈니스 200,000; 관계사 외상대 입금 추정(주식회사에이팜, 말일)
A18: 46296 | B18: 목 | C18: ='계좌별시나리오'!D18 | D18: ='계좌별시나리오'!E18 | E18: ='계좌별시나리오'!F18 | F18: ='계좌별시나리오'!G18 | G18: =INDEX('설정및분류'!$C$6:$C$12,WEEKDAY(A18,2))*'요약'!$B$13 | H18: ='계좌별시나리오'!I18 | I18: ='계좌별시나리오'!J18 | J18: ='계좌별시나리오'!K18 | K18: ='계좌별시나리오'!L18 | P18: =G18+L18-M18-N18-O18 | Q18: =R17 | R18: =Q18+P18
A19: 46297 | B19: 금 | C19: ='계좌별시나리오'!D19 | D19: ='계좌별시나리오'!E19 | E19: ='계좌별시나리오'!F19 | F19: ='계좌별시나리오'!G19 | G19: =INDEX('설정및분류'!$C$6:$C$12,WEEKDAY(A19,2))*'요약'!$B$13 | H19: ='계좌별시나리오'!I19 | I19: ='계좌별시나리오'!J19 | J19: ='계좌별시나리오'!K19 | K19: ='계좌별시나리오'!L19 | P19: =G19+L19-M19-N19-O19 | Q19: =R18 | R19: =Q19+P19
A20: 46298 | B20: 토 | C20: ='계좌별시나리오'!D20 | D20: ='계좌별시나리오'!E20 | E20: ='계좌별시나리오'!F20 | F20: ='계좌별시나리오'!G20 | G20: 0 | H20: ='계좌별시나리오'!I20 | I20: ='계좌별시나리오'!J20 | J20: ='계좌별시나리오'!K20 | K20: ='계좌별시나리오'!L20 | P20: =G20+L20-M20-N20-O20 | Q20: =R19 | R20: =Q20+P20
A21: 46299 | B21: 일 | C21: ='계좌별시나리오'!D21 | D21: ='계좌별시나리오'!E21 | E21: ='계좌별시나리오'!F21 | F21: ='계좌별시나리오'!G21 | G21: =INDEX('설정및분류'!$C$6:$C$12,WEEKDAY(A21,2))*'요약'!$B$13 | H21: ='계좌별시나리오'!I21 | I21: ='계좌별시나리오'!J21 | J21: ='계좌별시나리오'!K21 | K21: ='계좌별시나리오'!L21 | P21: =G21+L21-M21-N21-O21 | Q21: =R20 | R21: =Q21+P21
A22: 46300 | B22: 월 | C22: ='계좌별시나리오'!D22 | D22: ='계좌별시나리오'!E22 | E22: ='계좌별시나리오'!F22 | F22: ='계좌별시나리오'!G22 | G22: 0 | H22: ='계좌별시나리오'!I22 | I22: ='계좌별시나리오'!J22 | J22: ='계좌별시나리오'!K22 | K22: ='계좌별시나리오'!L22 | P22: =G22+L22-M22-N22-O22 | Q22: =R21 | R22: =Q22+P22
A23: 46301 | B23: 화 | C23: ='계좌별시나리오'!D23 | D23: ='계좌별시나리오'!E23 | E23: ='계좌별시나리오'!F23 | F23: ='계좌별시나리오'!G23 | G23: =INDEX('설정및분류'!$C$6:$C$12,WEEKDAY(A23,2))*'요약'!$B$13 | H23: ='계좌별시나리오'!I23 | I23: ='계좌별시나리오'!J23 | J23: ='계좌별시나리오'!K23 | K23: ='계좌별시나리오'!L23 | P23: =G23+L23-M23-N23-O23 | Q23: =R22 | R23: =Q23+P23
A24: 46302 | B24: 수 | C24: ='계좌별시나리오'!D24 | D24: ='계좌별시나리오'!E24 | E24: ='계좌별시나리오'!F24 | F24: ='계좌별시나리오'!G24 | G24: =INDEX('설정및분류'!$C$6:$C$12,WEEKDAY(A24,2))*'요약'!$B$13 | H24: ='계좌별시나리오'!I24 | I24: ='계좌별시나리오'!J24 | J24: ='계좌별시나리오'!K24 | K24: ='계좌별시나리오'!L24 | P24: =G24+L24-M24-N24-O24 | Q24: =R23 | R24: =Q24+P24
A25: 46303 | B25: 목 | C25: ='계좌별시나리오'!D25 | D25: ='계좌별시나리오'!E25 | E25: ='계좌별시나리오'!F25 | F25: ='계좌별시나리오'!G25 | G25: =INDEX('설정및분류'!$C$6:$C$12,WEEKDAY(A25,2))*'요약'!$B$13 | H25: ='계좌별시나리오'!I25 | I25: ='계좌별시나리오'!J25 | J25: ='계좌별시나리오'!K25 | K25: ='계좌별시나리오'!L25 | P25: =G25+L25-M25-N25-O25 | Q25: =R24 | R25: =Q25+P25
A26: 46304 | B26: 금 | C26: ='계좌별시나리오'!D26 | D26: ='계좌별시나리오'!E26 | E26: ='계좌별시나리오'!F26 | F26: ='계좌별시나리오'!G26 | G26: 0 | H26: ='계좌별시나리오'!I26 | I26: ='계좌별시나리오'!J26 | J26: ='계좌별시나리오'!K26 | K26: ='계좌별시나리오'!L26 | P26: =G26+L26-M26-N26-O26 | Q26: =R25 | R26: =Q26+P26
A27: 46305 | B27: 토 | C27: ='계좌별시나리오'!D27 | D27: ='계좌별시나리오'!E27 | E27: ='계좌별시나리오'!F27 | F27: ='계좌별시나리오'!G27 | G27: =INDEX('설정및분류'!$C$6:$C$12,WEEKDAY(A27,2))*'요약'!$B$13 | H27: ='계좌별시나리오'!I27 | I27: ='계좌별시나리오'!J27 | J27: ='계좌별시나리오'!K27 | K27: ='계좌별시나리오'!L27 | P27: =G27+L27-M27-N27-O27 | Q27: =R26 | R27: =Q27+P27
A28: 46306 | B28: 일 | C28: ='계좌별시나리오'!D28 | D28: ='계좌별시나리오'!E28 | E28: ='계좌별시나리오'!F28 | F28: ='계좌별시나리오'!G28 | G28: =INDEX('설정및분류'!$C$6:$C$12,WEEKDAY(A28,2))*'요약'!$B$13 | H28: ='계좌별시나리오'!I28 | I28: ='계좌별시나리오'!J28 | J28: ='계좌별시나리오'!K28 | K28: ='계좌별시나리오'!L28 | P28: =G28+L28-M28-N28-O28 | Q28: =R27 | R28: =Q28+P28
A29: 46307 | B29: 월 | C29: ='계좌별시나리오'!D29 | D29: ='계좌별시나리오'!E29 | E29: ='계좌별시나리오'!F29 | F29: ='계좌별시나리오'!G29 | G29: =INDEX('설정및분류'!$C$6:$C$12,WEEKDAY(A29,2))*'요약'!$B$13 | H29: ='계좌별시나리오'!I29 | I29: ='계좌별시나리오'!J29 | J29: ='계좌별시나리오'!K29 | K29: ='계좌별시나리오'!L29 | P29: =G29+L29-M29-N29-O29 | Q29: =R28 | R29: =Q29+P29
A30: 46308 | B30: 화 | C30: ='계좌별시나리오'!D30 | D30: ='계좌별시나리오'!E30 | E30: ='계좌별시나리오'!F30 | F30: ='계좌별시나리오'!G30 | G30: =INDEX('설정및분류'!$C$6:$C$12,WEEKDAY(A30,2))*'요약'!$B$13 | H30: ='계좌별시나리오'!I30 | I30: ='계좌별시나리오'!J30 | J30: ='계좌별시나리오'!K30 | K30: ='계좌별시나리오'!L30 | P30: =G30+L30-M30-N30-O30 | Q30: =R29 | R30: =Q30+P30
A31: 46309 | B31: 수 | C31: ='계좌별시나리오'!D31 | D31: ='계좌별시나리오'!E31 | E31: ='계좌별시나리오'!F31 | F31: ='계좌별시나리오'!G31 | G31: =INDEX('설정및분류'!$C$6:$C$12,WEEKDAY(A31,2))*'요약'!$B$13 | H31: ='계좌별시나리오'!I31 | I31: ='계좌별시나리오'!J31 | J31: ='계좌별시나리오'!K31 | K31: ='계좌별시나리오'!L31 | P31: =G31+L31-M31-N31-O31 | Q31: =R30 | R31: =Q31+P31
A32: 46310 | B32: 목 | C32: ='계좌별시나리오'!D32 | D32: ='계좌별시나리오'!E32 | E32: ='계좌별시나리오'!F32 | F32: ='계좌별시나리오'!G32 | G32: =INDEX('설정및분류'!$C$6:$C$12,WEEKDAY(A32,2))*'요약'!$B$13 | H32: ='계좌별시나리오'!I32 | I32: ='계좌별시나리오'!J32 | J32: ='계좌별시나리오'!K32 | K32: ='계좌별시나리오'!L32 | P32: =G32+L32-M32-N32-O32 | Q32: =R31 | R32: =Q32+P32
A33: 46311 | B33: 금 | C33: ='계좌별시나리오'!D33 | D33: ='계좌별시나리오'!E33 | E33: ='계좌별시나리오'!F33 | F33: ='계좌별시나리오'!G33 | G33: =INDEX('설정및분류'!$C$6:$C$12,WEEKDAY(A33,2))*'요약'!$B$13 | H33: ='계좌별시나리오'!I33 | I33: ='계좌별시나리오'!J33 | J33: ='계좌별시나리오'!K33 | K33: ='계좌별시나리오'!L33 | P33: =G33+L33-M33-N33-O33 | Q33: =R32 | R33: =Q33+P33
A34: 46312 | B34: 토 | C34: ='계좌별시나리오'!D34 | D34: ='계좌별시나리오'!E34 | E34: ='계좌별시나리오'!F34 | F34: ='계좌별시나리오'!G34 | G34: =INDEX('설정및분류'!$C$6:$C$12,WEEKDAY(A34,2))*'요약'!$B$13 | H34: ='계좌별시나리오'!I34 | I34: ='계좌별시나리오'!J34 | J34: ='계좌별시나리오'!K34 | K34: ='계좌별시나리오'!L34 | P34: =G34+L34-M34-N34-O34 | Q34: =R33 | R34: =Q34+P34
A35: 46313 | B35: 일 | C35: ='계좌별시나리오'!D35 | D35: ='계좌별시나리오'!E35 | E35: ='계좌별시나리오'!F35 | F35: ='계좌별시나리오'!G35 | G35: =INDEX('설정및분류'!$C$6:$C$12,WEEKDAY(A35,2))*'요약'!$B$13 | H35: ='계좌별시나리오'!I35 | I35: ='계좌별시나리오'!J35 | J35: ='계좌별시나리오'!K35 | K35: ='계좌별시나리오'!L35 | P35: =G35+L35-M35-N35-O35 | Q35: =R34 | R35: =Q35+P35

Sheet 계좌별시나리오
A2: 계좌별 일별 잔액 시나리오 (자동 반영)
A3: 읽는 법: 오늘 총잔액 = 전날 총잔액 + ② 입금 합계 − ③ 지출. 지출은 전액 우리은행에서 집행하고, 모자라면 ④처럼 농협 → 국민 순으로 우리은행에 이체해 채웁니다. '요약' 시트의 입금 반영률(B13)을 바꾸면 이 표도 즉시 다시 계산됩니다. 지난 실적 일자 행은 숨김(마지막 실적일 잔액에서 출발), 실수 방지를 위해 시트 보호(암호 없음). ② 배분 비중(최근 입금 실적): 우리 220351 44% · 농협 569003 2% · 국민 169124 21% · 국민 154577 33%
A4: 일자 | B4: 요일 | C4: ① 잔액 (총잔액 · 계좌별) | H4: ② 오늘 들어오는 돈 — 예상입금 배분 | M4: ③ 지출 | N4: ④ 부족분 이체 | P4: 비고
C5: 총잔액 | D5: 우리 220351 | E5: 농협 569003 | F5: 국민 169124 | G5: 국민 154577 | H5: 합계 | I5: 우리 220351 | J5: 농협 569003 | K5: 국민 169124 | L5: 국민 154577 | M5: 우리은행 집행 | N5: 농협→우리 | O5: 국민→우리
A6: 46286 | B6: 월 | C6: =SUM(D6:G6) | D6: 14669531 | E6: 1944429 | F6: 100687200 | G6: 39900428 | P6: 전일 마감 실잔고 — 여기서 출발
A7: 46287 | B7: 화 | C7: =SUM(D7:G7) | D7: 9421750 | E7: 2227429 | F7: 100687200 | G7: 36085938 | P7: 오늘 실잔고(은행 확인) — 참고
A8: 46286 | B8: 월 | C8: 157201588 | D8: 14669531 | E8: 1944429 | F8: 100687200 | G8: 39900428 | P8: 실적 구간
A9: 46287 | B9: 화 | C9: 148422317 | D9: 9421750 | E9: 2227429 | F9: 100687200 | G9: 36085938 | P9: 실적(은행 확인) — 여기서 예산 출발
A10: 46288 | B10: 수 | C10: =SUM(D10:G10) | D10: =D9+I10-M10+Q10+R10+S10 | E10: =E9+J10-Q10 | F10: =F9+K10-R10 | G10: =G9+L10-S10 | H10: ='4주일별계획'!G10+'4주일별계획'!L10 | I10: =H10*0.435521 | J10: =H10*0.020493 | K10: =H10*0.213477 | L10: =H10*0.330509 | M10: ='4주일별계획'!M10+'4주일별계획'!N10+'4주일별계획'!O10 | N10: =Q10 | O10: =R10+S10 | P10: =IF(D10<-0.5,"전 계좌 소진 — 부족 "&TEXT(-D10,"#,##0")&"원","") | Q10: =MIN(MAX(0,E9+J10),MAX(0,M10-D9-I10)) | R10: =MIN(MAX(0,F9+K10),MAX(0,M10-D9-I10)-Q10) | S10: =MIN(MAX(0,G9+L10),MAX(0,M10-D9-I10)-Q10-R10)
A11: 46289 | B11: 목 | C11: =SUM(D11:G11) | D11: =D10+I11-M11+Q11+R11+S11 | E11: =E10+J11-Q11 | F11: =F10+K11-R11 | G11: =G10+L11-S11 | H11: ='4주일별계획'!G11+'4주일별계획'!L11 | I11: =H11*0.435521 | J11: =H11*0.020493 | K11: =H11*0.213477 | L11: =H11*0.330509 | M11: ='4주일별계획'!M11+'4주일별계획'!N11+'4주일별계획'!O11 | N11: =Q11 | O11: =R11+S11 | P11: =IF(D11<-0.5,"전 계좌 소진 — 부족 "&TEXT(-D11,"#,##0")&"원","") | Q11: =MIN(MAX(0,E10+J11),MAX(0,M11-D10-I11)) | R11: =MIN(MAX(0,F10+K11),MAX(0,M11-D10-I11)-Q11) | S11: =MIN(MAX(0,G10+L11),MAX(0,M11-D10-I11)-Q11-R11)
A12: 46290 | B12: 금 | C12: =SUM(D12:G12) | D12: =D11+I12-M12+Q12+R12+S12 | E12: =E11+J12-Q12 | F12: =F11+K12-R12 | G12: =G11+L12-S12 | H12: ='4주일별계획'!G12+'4주일별계획'!L12 | I12: =H12*0.435521 | J12: =H12*0.020493 | K12: =H12*0.213477 | L12: =H12*0.330509 | M12: ='4주일별계획'!M12+'4주일별계획'!N12+'4주일별계획'!O12 | N12: =Q12 | O12: =R12+S12 | P12: =IF(D12<-0.5,"전 계좌 소진 — 부족 "&TEXT(-D12,"#,##0")&"원","") | Q12: =MIN(MAX(0,E11+J12),MAX(0,M12-D11-I12)) | R12: =MIN(MAX(0,F11+K12),MAX(0,M12-D11-I12)-Q12) | S12: =MIN(MAX(0,G11+L12),MAX(0,M12-D11-I12)-Q12-R12)
A13: 46291 | B13: 토 | C13: =SUM(D13:G13) | D13: =D12+I13-M13+Q13+R13+S13 | E13: =E12+J13-Q13 | F13: =F12+K13-R13 | G13: =G12+L13-S13 | H13: ='4주일별계획'!G13+'4주일별계획'!L13 | I13: =H13*0.435521 | J13: =H13*0.020493 | K13: =H13*0.213477 | L13: =H13*0.330509 | M13: ='4주일별계획'!M13+'4주일별계획'!N13+'4주일별계획'!O13 | N13: =Q13 | O13: =R13+S13 | P13: =IF(D13<-0.5,"전 계좌 소진 — 부족 "&TEXT(-D13,"#,##0")&"원","") | Q13: =MIN(MAX(0,E12+J13),MAX(0,M13-D12-I13)) | R13: =MIN(MAX(0,F12+K13),MAX(0,M13-D12-I13)-Q13) | S13: =MIN(MAX(0,G12+L13),MAX(0,M13-D12-I13)-Q13-R13)
A14: 46292 | B14: 일 | C14: =SUM(D14:G14) | D14: =D13+I14-M14+Q14+R14+S14 | E14: =E13+J14-Q14 | F14: =F13+K14-R14 | G14: =G13+L14-S14 | H14: ='4주일별계획'!G14+'4주일별계획'!L14 | I14: =H14*0.435521 | J14: =H14*0.020493 | K14: =H14*0.213477 | L14: =H14*0.330509 | M14: ='4주일별계획'!M14+'4주일별계획'!N14+'4주일별계획'!O14 | N14: =Q14 | O14: =R14+S14 | P14: =IF(D14<-0.5,"전 계좌 소진 — 부족 "&TEXT(-D14,"#,##0")&"원","") | Q14: =MIN(MAX(0,E13+J14),MAX(0,M14-D13-I14)) | R14: =MIN(MAX(0,F13+K14),MAX(0,M14-D13-I14)-Q14) | S14: =MIN(MAX(0,G13+L14),MAX(0,M14-D13-I14)-Q14-R14)
A15: 46293 | B15: 월 | C15: =SUM(D15:G15) | D15: =D14+I15-M15+Q15+R15+S15 | E15: =E14+J15-Q15 | F15: =F14+K15-R15 | G15: =G14+L15-S15 | H15: ='4주일별계획'!G15+'4주일별계획'!L15 | I15: =H15*0.435521 | J15: =H15*0.020493 | K15: =H15*0.213477 | L15: =H15*0.330509 | M15: ='4주일별계획'!M15+'4주일별계획'!N15+'4주일별계획'!O15 | N15: =Q15 | O15: =R15+S15 | P15: =IF(D15<-0.5,"전 계좌 소진 — 부족 "&TEXT(-D15,"#,##0")&"원","") | Q15: =MIN(MAX(0,E14+J15),MAX(0,M15-D14-I15)) | R15: =MIN(MAX(0,F14+K15),MAX(0,M15-D14-I15)-Q15) | S15: =MIN(MAX(0,G14+L15),MAX(0,M15-D14-I15)-Q15-R15)
A16: 46294 | B16: 화 | C16: =SUM(D16:G16) | D16: =D15+I16-M16+Q16+R16+S16 | E16: =E15+J16-Q16 | F16: =F15+K16-R16 | G16: =G15+L16-S16 | H16: ='4주일별계획'!G16+'4주일별계획'!L16 | I16: =H16*0.435521 | J16: =H16*0.020493 | K16: =H16*0.213477 | L16: =H16*0.330509 | M16: ='4주일별계획'!M16+'4주일별계획'!N16+'4주일별계획'!O16 | N16: =Q16 | O16: =R16+S16 | P16: =IF(D16<-0.5,"전 계좌 소진 — 부족 "&TEXT(-D16,"#,##0")&"원","") | Q16: =MIN(MAX(0,E15+J16),MAX(0,M16-D15-I16)) | R16: =MIN(MAX(0,F15+K16),MAX(0,M16-D15-I16)-Q16) | S16: =MIN(MAX(0,G15+L16),MAX(0,M16-D15-I16)-Q16-R16)
A17: 46295 | B17: 수 | C17: =SUM(D17:G17) | D17: =D16+I17-M17+Q17+R17+S17 | E17: =E16+J17-Q17 | F17: =F16+K17-R17 | G17: =G16+L17-S17 | H17: ='4주일별계획'!G17+'4주일별계획'!L17 | I17: =H17*0.435521 | J17: =H17*0.020493 | K17: =H17*0.213477 | L17: =H17*0.330509 | M17: ='4주일별계획'!M17+'4주일별계획'!N17+'4주일별계획'!O17 | N17: =Q17 | O17: =R17+S17 | P17: =IF(D17<-0.5,"전 계좌 소진 — 부족 "&TEXT(-D17,"#,##0")&"원","") | Q17: =MIN(MAX(0,E16+J17),MAX(0,M17-D16-I17)) | R17: =MIN(MAX(0,F16+K17),MAX(0,M17-D16-I17)-Q17) | S17: =MIN(MAX(0,G16+L17),MAX(0,M17-D16-I17)-Q17-R17)
A18: 46296 | B18: 목 | C18: =SUM(D18:G18) | D18: =D17+I18-M18+Q18+R18+S18 | E18: =E17+J18-Q18 | F18: =F17+K18-R18 | G18: =G17+L18-S18 | H18: ='4주일별계획'!G18+'4주일별계획'!L18 | I18: =H18*0.435521 | J18: =H18*0.020493 | K18: =H18*0.213477 | L18: =H18*0.330509 | M18: ='4주일별계획'!M18+'4주일별계획'!N18+'4주일별계획'!O18 | N18: =Q18 | O18: =R18+S18 | P18: =IF(D18<-0.5,"전 계좌 소진 — 부족 "&TEXT(-D18,"#,##0")&"원","") | Q18: =MIN(MAX(0,E17+J18),MAX(0,M18-D17-I18)) | R18: =MIN(MAX(0,F17+K18),MAX(0,M18-D17-I18)-Q18) | S18: =MIN(MAX(0,G17+L18),MAX(0,M18-D17-I18)-Q18-R18)
A19: 46297 | B19: 금 | C19: =SUM(D19:G19) | D19: =D18+I19-M19+Q19+R19+S19 | E19: =E18+J19-Q19 | F19: =F18+K19-R19 | G19: =G18+L19-S19 | H19: ='4주일별계획'!G19+'4주일별계획'!L19 | I19: =H19*0.435521 | J19: =H19*0.020493 | K19: =H19*0.213477 | L19: =H19*0.330509 | M19: ='4주일별계획'!M19+'4주일별계획'!N19+'4주일별계획'!O19 | N19: =Q19 | O19: =R19+S19 | P19: =IF(D19<-0.5,"전 계좌 소진 — 부족 "&TEXT(-D19,"#,##0")&"원","") | Q19: =MIN(MAX(0,E18+J19),MAX(0,M19-D18-I19)) | R19: =MIN(MAX(0,F18+K19),MAX(0,M19-D18-I19)-Q19) | S19: =MIN(MAX(0,G18+L19),MAX(0,M19-D18-I19)-Q19-R19)
A20: 46298 | B20: 토 | C20: =SUM(D20:G20) | D20: =D19+I20-M20+Q20+R20+S20 | E20: =E19+J20-Q20 | F20: =F19+K20-R20 | G20: =G19+L20-S20 | H20: ='4주일별계획'!G20+'4주일별계획'!L20 | I20: =H20*0.435521 | J20: =H20*0.020493 | K20: =H20*0.213477 | L20: =H20*0.330509 | M20: ='4주일별계획'!M20+'4주일별계획'!N20+'4주일별계획'!O20 | N20: =Q20 | O20: =R20+S20 | P20: =IF(D20<-0.5,"전 계좌 소진 — 부족 "&TEXT(-D20,"#,##0")&"원","") | Q20: =MIN(MAX(0,E19+J20),MAX(0,M20-D19-I20)) | R20: =MIN(MAX(0,F19+K20),MAX(0,M20-D19-I20)-Q20) | S20: =MIN(MAX(0,G19+L20),MAX(0,M20-D19-I20)-Q20-R20)
A21: 46299 | B21: 일 | C21: =SUM(D21:G21) | D21: =D20+I21-M21+Q21+R21+S21 | E21: =E20+J21-Q21 | F21: =F20+K21-R21 | G21: =G20+L21-S21 | H21: ='4주일별계획'!G21+'4주일별계획'!L21 | I21: =H21*0.435521 | J21: =H21*0.020493 | K21: =H21*0.213477 | L21: =H21*0.330509 | M21: ='4주일별계획'!M21+'4주일별계획'!N21+'4주일별계획'!O21 | N21: =Q21 | O21: =R21+S21 | P21: =IF(D21<-0.5,"전 계좌 소진 — 부족 "&TEXT(-D21,"#,##0")&"원","") | Q21: =MIN(MAX(0,E20+J21),MAX(0,M21-D20-I21)) | R21: =MIN(MAX(0,F20+K21),MAX(0,M21-D20-I21)-Q21) | S21: =MIN(MAX(0,G20+L21),MAX(0,M21-D20-I21)-Q21-R21)
... A35: 46313 | B35: 일 | C35: =SUM(D35:G35) | D35: =D34+I35-M35+Q35+R35+S35 | E35: =E34+J35-Q35 | F35: =F34+K35-R35 | G35: =G34+L35-S35 | H35: ='4주일별계획'!G35+'4주일별계획'!L35 | I35: =H35*0.435521 | J35: =H35*0.020493 | K35: =H35*0.213477 | L35: =H35*0.330509 | M35: ='4주일별계획'!M35+'4주일별계획'!N35+'4주일별계획'!O35 | N35: =Q35 | O35: =R35+S35 | P35: =IF(D35<-0.5,"전 계좌 소진 — 부족 "&TEXT(-D35,"#,##0")&"원","") | Q35: =MIN(MAX(0,E34+J35),MAX(0,M35-D34-I35)) | R35: =MIN(MAX(0,F34+K35),MAX(0,M35-D34-I35)-Q35) | S35: =MIN(MAX(0,G34+L35),MAX(0,M35-D34-I35)-Q35-R35)

Sheet 13주주별계획
A2: 향후 13주 주별 자금계획
A3: ="온라인 예상입금 반영률 "&TEXT('요약'!$B$13,"0%")&" 적용. 1~4주는 일별 계획 합계, 5~13주는 자동 예상입금과 입력한 주간 계획을 반영합니다."
A5: 주차 | B5: 기간 | C5: 온라인 예상입금 | D5: 확정·기타입금 | E5: 송금예정 | F5: 카드결제 | G5: 조정·추정 지출 | H5: 추가 주간조정 | I5: 순현금흐름 | J5: 기말잔액 | K5: 상태
A6: 1주차 | B6: 2026-09-21 ~ 2026-09-27 | C6: =SUMIFS('4주일별계획'!$G$8:$G$35,'4주일별계획'!$A$8:$A$35,">="&DATE(2026,9,21),'4주일별계획'!$A$8:$A$35,"<="&DATE(2026,9,27)) | D6: =SUMIFS('4주일별계획'!$L$8:$L$35,'4주일별계획'!$A$8:$A$35,">="&DATE(2026,9,21),'4주일별계획'!$A$8:$A$35,"<="&DATE(2026,9,27)) | E6: =SUMIFS('4주일별계획'!$M$8:$M$35,'4주일별계획'!$A$8:$A$35,">="&DATE(2026,9,21),'4주일별계획'!$A$8:$A$35,"<="&DATE(2026,9,27)) | F6: =SUMIFS('4주일별계획'!$N$8:$N$35,'4주일별계획'!$A$8:$A$35,">="&DATE(2026,9,21),'4주일별계획'!$A$8:$A$35,"<="&DATE(2026,9,27)) | G6: =SUMIFS('4주일별계획'!$O$8:$O$35,'4주일별계획'!$A$8:$A$35,">="&DATE(2026,9,21),'4주일별계획'!$A$8:$A$35,"<="&DATE(2026,9,27)) | I6: =C6+D6-E6-F6-G6+H6 | J6: ='요약'!$B$6+I6 | K6: =IF(J6<0,"자금부족",IF(J6<'요약'!$B$6*0.2,"주의","정상"))
A7: 2주차 | B7: 2026-09-28 ~ 2026-10-04 | C7: =SUMIFS('4주일별계획'!$G$8:$G$35,'4주일별계획'!$A$8:$A$35,">="&DATE(2026,9,28),'4주일별계획'!$A$8:$A$35,"<="&DATE(2026,10,4)) | D7: =SUMIFS('4주일별계획'!$L$8:$L$35,'4주일별계획'!$A$8:$A$35,">="&DATE(2026,9,28),'4주일별계획'!$A$8:$A$35,"<="&DATE(2026,10,4)) | E7: =SUMIFS('4주일별계획'!$M$8:$M$35,'4주일별계획'!$A$8:$A$35,">="&DATE(2026,9,28),'4주일별계획'!$A$8:$A$35,"<="&DATE(2026,10,4)) | F7: =SUMIFS('4주일별계획'!$N$8:$N$35,'4주일별계획'!$A$8:$A$35,">="&DATE(2026,9,28),'4주일별계획'!$A$8:$A$35,"<="&DATE(2026,10,4)) | G7: =SUMIFS('4주일별계획'!$O$8:$O$35,'4주일별계획'!$A$8:$A$35,">="&DATE(2026,9,28),'4주일별계획'!$A$8:$A$35,"<="&DATE(2026,10,4)) | I7: =C7+D7-E7-F7-G7+H7 | J7: =J6+I7 | K7: =IF(J7<0,"자금부족",IF(J7<'요약'!$B$6*0.2,"주의","정상"))
A8: 3주차 | B8: 2026-10-05 ~ 2026-10-11 | C8: =SUMIFS('4주일별계획'!$G$8:$G$35,'4주일별계획'!$A$8:$A$35,">="&DATE(2026,10,5),'4주일별계획'!$A$8:$A$35,"<="&DATE(2026,10,11)) | D8: =SUMIFS('4주일별계획'!$L$8:$L$35,'4주일별계획'!$A$8:$A$35,">="&DATE(2026,10,5),'4주일별계획'!$A$8:$A$35,"<="&DATE(2026,10,11)) | E8: =SUMIFS('4주일별계획'!$M$8:$M$35,'4주일별계획'!$A$8:$A$35,">="&DATE(2026,10,5),'4주일별계획'!$A$8:$A$35,"<="&DATE(2026,10,11)) | F8: =SUMIFS('4주일별계획'!$N$8:$N$35,'4주일별계획'!$A$8:$A$35,">="&DATE(2026,10,5),'4주일별계획'!$A$8:$A$35,"<="&DATE(2026,10,11)) | G8: =SUMIFS('4주일별계획'!$O$8:$O$35,'4주일별계획'!$A$8:$A$35,">="&DATE(2026,10,5),'4주일별계획'!$A$8:$A$35,"<="&DATE(2026,10,11)) | I8: =C8+D8-E8-F8-G8+H8 | J8: =J7+I8 | K8: =IF(J8<0,"자금부족",IF(J8<'요약'!$B$6*0.2,"주의","정상"))
A9: 4주차 | B9: 2026-10-12 ~ 2026-10-18 | C9: =SUMIFS('4주일별계획'!$G$8:$G$35,'4주일별계획'!$A$8:$A$35,">="&DATE(2026,10,12),'4주일별계획'!$A$8:$A$35,"<="&DATE(2026,10,18)) | D9: =SUMIFS('4주일별계획'!$L$8:$L$35,'4주일별계획'!$A$8:$A$35,">="&DATE(2026,10,12),'4주일별계획'!$A$8:$A$35,"<="&DATE(2026,10,18)) | E9: =SUMIFS('4주일별계획'!$M$8:$M$35,'4주일별계획'!$A$8:$A$35,">="&DATE(2026,10,12),'4주일별계획'!$A$8:$A$35,"<="&DATE(2026,10,18)) | F9: =SUMIFS('4주일별계획'!$N$8:$N$35,'4주일별계획'!$A$8:$A$35,">="&DATE(2026,10,12),'4주일별계획'!$A$8:$A$35,"<="&DATE(2026,10,18)) | G9: =SUMIFS('4주일별계획'!$O$8:$O$35,'4주일별계획'!$A$8:$A$35,">="&DATE(2026,10,12),'4주일별계획'!$A$8:$A$35,"<="&DATE(2026,10,18)) | I9: =C9+D9-E9-F9-G9+H9 | J9: =J8+I9 | K9: =IF(J9<0,"자금부족",IF(J9<'요약'!$B$6*0.2,"주의","정상"))
A10: 5주차 | B10: 2026-10-19 ~ 2026-10-25 | C10: =SUM('설정및분류'!$C$6:$C$12)*'요약'!$B$13 | F10: 1675000 | I10: =C10+D10-E10-F10-G10+H10 | J10: =J9+I10 | K10: =IF(J10<0,"자금부족",IF(J10<'요약'!$B$6*0.2,"주의","정상"))
A11: 6주차 | B11: 2026-10-26 ~ 2026-11-01 | C11: =SUM('설정및분류'!$C$6:$C$12)*'요약'!$B$13 | D11: 10021867 | I11: =C11+D11-E11-F11-G11+H11 | J11: =J10+I11 | K11: =IF(J11<0,"자금부족",IF(J11<'요약'!$B$6*0.2,"주의","정상"))
A12: 7주차 | B12: 2026-11-02 ~ 2026-11-08 | C12: =SUM('설정및분류'!$C$6:$C$12)*'요약'!$B$13 | I12: =C12+D12-E12-F12-G12+H12 | J12: =J11+I12 | K12: =IF(J12<0,"자금부족",IF(J12<'요약'!$B$6*0.2,"주의","정상"))
A13: 8주차 | B13: 2026-11-09 ~ 2026-11-15 | C13: =SUM('설정및분류'!$C$6:$C$12)*'요약'!$B$13 | I13: =C13+D13-E13-F13-G13+H13 | J13: =J12+I13 | K13: =IF(J13<0,"자금부족",IF(J13<'요약'!$B$6*0.2,"주의","정상"))
A14: 9주차 | B14: 2026-11-16 ~ 2026-11-22 | C14: =SUM('설정및분류'!$C$6:$C$12)*'요약'!$B$13 | I14: =C14+D14-E14-F14-G14+H14 | J14: =J13+I14 | K14: =IF(J14<0,"자금부족",IF(J14<'요약'!$B$6*0.2,"주의","정상"))
A15: 10주차 | B15: 2026-11-23 ~ 2026-11-29 | C15: =SUM('설정및분류'!$C$6:$C$12)*'요약'!$B$13 | I15: =C15+D15-E15-F15-G15+H15 | J15: =J14+I15 | K15: =IF(J15<0,"자금부족",IF(J15<'요약'!$B$6*0.2,"주의","정상"))
A16: 11주차 | B16: 2026-11-30 ~ 2026-12-06 | C16: =SUM('설정및분류'!$C$6:$C$12)*'요약'!$B$13 | D16: 10021867 | I16: =C16+D16-E16-F16-G16+H16 | J16: =J15+I16 | K16: =IF(J16<0,"자금부족",IF(J16<'요약'!$B$6*0.2,"주의","정상"))
A17: 12주차 | B17: 2026-12-07 ~ 2026-12-13 | C17: =SUM('설정및분류'!$C$6:$C$12)*'요약'!$B$13 | I17: =C17+D17-E17-F17-G17+H17 | J17: =J16+I17 | K17: =IF(J17<0,"자금부족",IF(J17<'요약'!$B$6*0.2,"주의","정상"))
A18: 13주차 | B18: 2026-12-14 ~ 2026-12-20 | C18: =SUM('설정및분류'!$C$6:$C$12)*'요약'!$B$13 | I18: =C18+D18-E18-F18-G18+H18 | J18: =J17+I18 | K18: =IF(J18<0,"자금부족",IF(J18<'요약'!$B$6*0.2,"주의","정상"))

Sheet 지출계획_취합
A2: 팀 지출계획 취합 (자동 반영)
A3: 매 실행마다 팀 제출 파일에서 자동 갱신됩니다. 대외비는 분류·총액만 표시됩니다. 경영보고와 같은 실행일~차주 금요일 기간만 표시합니다 (그 밖의 반영일 행은 숨김 — 행 숨기기 해제로 전체 확인).
A5: 요청ID | B5: 팀명 | C5: 신청자 | D5: 품의승인 | E5: 지급예정일 | F5: 자금계획 반영일 | G5: 거래처 | H5: 지출내용 | I5: 예상금액 | J5: 지급방법 | K5: 카드구분 | L5: 확정여부 | M5: 진행상태 | N5: 최종수정일 | O5: 원본파일 | P5: 반영상태 | Q5: 확인사항
A6: 경영-20260918-011 | B6: 경영지원팀 | C6: 송채은 | E6: 46283 | F6: 46283 | G6: 이앤씨이노비즈타워 | H6: 본사관리비 | I6: 1553720 | J6: 계좌송금 | L6: 확정 | M6: 신규 | N6: 46283 | O6: 지출계획_2026-09-22.xlsx | P6: 에이팜 별도관리
A7: 건강-20260918-001 | B7: 건강사업팀 | C7: 양혜원 | E7: 46286 | F7: 46286 | G7: 트라이앵글하모니 | H7: 카카오톡선물하기 베리시톨 리뷰작업 | I7: 1996000 | J7: 계좌송금 | L7: 확정 | M7: 신규 | N7: 46283 | O7: 지출계획_2026-09-22.xlsx | P7: 정상반영
A8: 건강-20260918-003 | B8: 건강사업팀 | C8: 전은신 | E8: 46286 | F8: 46286 | G8: 네이버SA&GFA | H8: 네이버 SA&GFA 광고비 충전 | I8: 3498000 | J8: 계좌송금 | L8: 확정 | M8: 변경 | N8: 46283 | O8: 지출계획_2026-09-22.xlsx | P8: 정상반영
A9: 경영-20260918-005 | B9: 경영지원팀 | C9: 김수희 | E9: 46286 | F9: 46286 | G9: 메트라이프 | H9: 달러경영인정기보험_63회차/55회차 | I9: 4900000 | J9: 자동이체 | L9: 확정 | M9: 변경 | N9: 46283 | O9: 지출계획_2026-09-22.xlsx | P9: 정상반영
A10: 경영-20260918-006 | B10: 경영지원팀 | C10: 김수희 | E10: 46286 | F10: 46286 | G10: SK브로드밴드 | H10: 사내전화 | I10: 220000 | J10: 자동이체 | L10: 확정 | M10: 신규 | N10: 46283 | O10: 지출계획_2026-09-22.xlsx | P10: 정상반영
A11: 건강-20260918-002 | B11: 건강사업팀 | C11: 양혜원 | E11: 46287 | F11: 46287 | G11: 네이버 | H11: 네이버 톡톡 발송 | I11: 500000 | J11: 계좌송금 | L11: 확정 | M11: 신규 | N11: 46283 | O11: 지출계획_2026-09-22.xlsx | P11: 정상반영
A12: 경영-20260918-015 | B12: 경영지원팀 | C12: 김정원 | E12: 46287 | F12: 46287 | G12: 엠에스바이오텍 | H12: 외상매입금 | I12: 20000000 | J12: 계좌송금 | L12: 확정 | M12: 변경 | N12: 46284 | O12: 지출계획_2026-09-22.xlsx | P12: 정상반영
A13: 경영-20260922-001 | B13: 경영지원팀 | C13: 송채은 | E13: 46287 | F13: 46287 | G13: 추석 상여금 | H13: 추석 상여금 | I13: 4600000 | J13: 계좌송금 | L13: 확정 | M13: 변경 | N13: 46287 | O13: 지출계획_2026-09-22.xlsx | P13: 에이팜 별도관리
A14: 경영-20260922-002 | B14: 경영지원팀 | C14: 송채은 | E14: 46287 | F14: 46287 | G14: 추석 상여금 | H14: 추석 상여금 | I14: 7800000 | J14: 계좌송금 | L14: 확정 | M14: 변경 | N14: 46287 | O14: 지출계획_2026-09-22.xlsx | P14: 정상반영
A15: 경영-20260922-003 | B15: 경영지원팀 | C15: 김수희 | E15: 46287 | F15: 46287 | G15: 임대규(대청하이츠) | H15: 기숙사 월세 및 관리비 | I15: 350000 | J15: 계좌송금 | L15: 확정 | M15: 신규 | N15: 46287 | O15: 지출계획_2026-09-22.xlsx | P15: 정상반영
A16: 경영-20260922-004 | B16: 경영지원팀 | C16: 김수희 | E16: 46287 | F16: 46287 | G16: 엠에스바이오텍 | H16: 락토프리미엄 대금 지급 1차 | I16: 20000000 | J16: 계좌송금 | L16: 확정 | M16: 신규 | N16: 46287 | O16: 지출계획_2026-09-22.xlsx | P16: 정상반영
A17: 경영-20260922-005 | B17: 경영지원팀 | C17: 김수희 | E17: 46287 | F17: 46287 | G17: 대구상공회의소 | H17: 26년도 하반기 회비 | I17: 250000 | J17: 계좌송금 | L17: 확정 | M17: 신규 | N17: 46287 | O17: 지출계획_2026-09-22.xlsx | P17: 정상반영
... A37: 경영-20260922-006 | B37: 경영지원팀 | C37: 송채은 | E37: 46295 | F37: 46295 | G37: 달서구청 | H37: 2026년 토지재산세 | I37: 315520 | J37: 계좌송금 | L37: 확정 | M37: 신규 | N37: 46287 | O37: 지출계획_2026-09-22.xlsx | P37: 에이팜 별도관리
A38: 경영-20260922-008 | B38: 경영지원팀 | C38: 장은총 | E38: 46293 | F38: 46318 | G38: 위버 | H38: 워크샵 (1부/2부) 이용료 | I38: 1675000 | J38: 법인카드 | K38: 우리카드 | L38: 확정 | M38: 신규 | N38: 46287 | O38: 지출계획_2026-09-22.xlsx | P38: 정상반영

Sheet 에이팜 지출계획
A2: 에이팜 지출계획 (자동 반영)
A3: 지출계획 비고에 '에이팜'으로 표시한 건은 자금계획(4주·13주)에 반영하지 않고 여기서만 관리합니다. '반영' 표시 건은 자금계획에 포함된 에이팜 관련 참고 항목입니다.
A5: 일자 | B5: 요일 | C5: 출처 | D5: 자금계획 반영 | E5: 팀명 | F5: 거래처 | G5: 지출내용 | H5: 예상금액 | I5: 지급방법 | J5: 비고
A6: 46283 | B6: 금 | C6: 팀 지출계획 | D6: 미반영(별도 관리) | E6: 경영지원팀 | F6: 이앤씨이노비즈타워 | G6: 본사관리비 | H6: 1553720 | I6: 계좌송금 | J6: 에이팜
A7: 46287 | B7: 화 | C7: 팀 지출계획 | D7: 미반영(별도 관리) | E7: 경영지원팀 | F7: (대외비) | G7: 급여·인건비(대외비) | H7: 4600000 | I7: 계좌송금 | J7: 에이팜
A8: 46288 | B8: 수 | C8: 팀 지출계획 | D8: 미반영(별도 관리) | E8: 경영지원팀 | F8: 비씨카드 | G8: 8월카드대금 | H8: 269810 | I8: 계좌송금 | J8: 에이팜
A9: 46295 | B9: 수 | C9: 팀 지출계획 | D9: 미반영(별도 관리) | E9: 경영지원팀 | F9: 서원회계법인 | G9: 기장료 | H9: 330000 | I9: 계좌송금 | J9: 에이팜
A10: 46295 | B10: 수 | C10: 팀 지출계획 | D10: 미반영(별도 관리) | E10: 경영지원팀 | F10: 달서구청 | G10: 2026년 토지재산세 | H10: 315520 | I10: 계좌송금 | J10: 에이팜
A11: 46295 | B11: 수 | C11: 팀 지출계획 | D11: 미반영(별도 관리) | E11: 경영지원팀 | F11: 가가사무기 | G11: 복합기 9월 임대비용 | H11: 280000 | I11: 계좌송금 | J11: 에이팜
A12: 46295 | B12: 수 | C12: 팀 지출계획 | D12: 미반영(별도 관리) | E12: 경영지원팀 | F12: 대구상공회의소 | G12: 하반기연회비 | H12: 250000 | I12: 계좌송금 | J12: 에이팜
G13: 합계(자금계획 미반영) | H13: 7599050

Sheet 계좌내역통합_RAW
A1: 거래일시 | B1: 거래일 | C1: 은행 | D1: 계좌 | E1: 출금액 | F1: 입금액 | G1: 거래후잔액 | H1: 적요 | I1: 기재내용·상대방 | J1: 취급점 | K1: 자동분류 | L1: 내부이체 | M1: 정기지출후보 | N1: 현금유출입 | O1: 원본파일 | P1: 반영상태
A2: 46106.435 | B2: 46106 | C2: 국민은행 | D2: 국민 169124 | E2: 0 | F2: 2497000 | G2: 3871400 | H2: 기일입금 | I2: (주)에이팜건강 | J2: 진천역 | K2: 계좌간이체 | L2: Y | M2: N | N2: 0 | O2: 농협계좌_6개월(20260913).xls | P2: 기존내역
A3: 46106.665 | B3: 46106 | C3: 국민은행 | D3: 국민 169124 | E3: 0 | F3: 110000000 | G3: 113871400 | H3: FBS입금 | I3: 한화생중도인출 | J3: ERP사 | K3: 보험 중도인출·보험금 입금 | L3: N | M3: N | N3: 110000000 | O3: 농협계좌_6개월(20260913).xls | P3: 기존내역
A4: 46106.833 | B4: 46106 | C4: 국민은행 | D4: 국민 169124 | E4: 2497000 | F4: 0 | G4: 111374400 | H4: CMS 공동 | I4: METLIFE03036 | J4: ERP사 | K4: 기타지출 | L4: N | M4: Y | N4: -2497000 | O4: 농협계좌_6개월(20260913).xls | P4: 기존내역
A5: 46106.839 | B5: 46106 | C5: 국민은행 | D5: 국민 169124 | E5: 110000000 | F5: 0 | G5: 1374400 | H5: FBS출금 | I5: 푸본현02-002 | J5: ERP사 | K5: 보험료 | L5: N | M5: N | N5: -110000000 | O5: 농협계좌_6개월(20260913).xls | P5: 기존내역
A6: 46107.488 | B6: 46107 | C6: 국민은행 | D6: 국민 169124 | E6: 1374400 | F6: 0 | G6: 0 | H6: 스마트출금 | I6: (주)에이팜건강 | J6: 진천역 | K6: 계좌간이체 | L6: Y | M6: N | N6: 0 | O6: 농협계좌_6개월(20260913).xls | P6: 기존내역
A7: 46115.726 | B7: 46115 | C7: 국민은행 | D7: 국민 169124 | E7: 0 | F7: 3003000 | G7: 3003000 | H7: 전자금융 | I7: 주식회사에이팜건강 | J7: 우리은행 | K7: 관계사 입금 | L7: N | M7: N | N7: 3003000 | O7: 국민은행_계좌 조회 6개월(20260913).xls | P7: 기존내역
A8: 46118.429 | B8: 46118 | C8: 국민은행 | D8: 국민 169124 | E8: 0 | F8: 5240400 | G8: 48764600 | H8: 기일입금 | I8: (주)에이팜건강 | J8: 진천역 | K8: 계좌간이체 | L8: Y | M8: N | N8: 0 | O8: 국민은행_계좌 조회 6개월(20260913).xls | P8: 기존내역
A9: 46118.429 | B9: 46118 | C9: 국민은행 | D9: 국민 169124 | E9: 0 | F9: 500000 | G9: 43524200 | H9: 기일입금 | I9: (주)에이팜건강 | J9: 진천역 | K9: 계좌간이체 | L9: Y | M9: N | N9: 0 | O9: 국민은행_계좌 조회 6개월(20260913).xls | P9: 기존내역
A10: 46118.429 | B10: 46118 | C10: 국민은행 | D10: 국민 169124 | E10: 0 | F10: 30000000 | G10: 43024200 | H10: 기일입금 | I10: (주)에이팜건강 | J10: 진천역 | K10: 기타입금 | L10: N | M10: N | N10: 30000000 | O10: 국민은행_계좌 조회 6개월(20260913).xls | P10: 기존내역
A11: 46118.429 | B11: 46118 | C11: 국민은행 | D11: 국민 169124 | E11: 0 | F11: 10021200 | G11: 13024200 | H11: 기일입금 | I11: (주)에이팜건강 | J11: 진천역 | K11: 계좌간이체 | L11: Y | M11: N | N11: 0 | O11: 우리은행 거래내역조회 20260913.xlsx | P11: 기존내역
A12: 46118.796 | B12: 46118 | C12: 국민은행 | D12: 국민 169124 | E12: 40521200 | F12: 0 | G12: 8243400 | H12: FBS출금 | I12: 한화생04-03 | J12: ERP사 | K12: 보험료 | L12: N | M12: Y | N12: -40521200 | O12: 우리은행 거래내역조회 20260913.xlsx | P12: 기존내역
A13: 46118.809 | B13: 46118 | C13: 국민은행 | D13: 국민 169124 | E13: 8243400 | F13: 0 | G13: 0 | H13: FBS출금 | I13: 삼성04002건 | J13: ERP사 | K13: 보험료 | L13: N | M13: Y | N13: -8243400 | O13: 우리은행 거래내역조회 20260913.xlsx | P13: 기존내역
... A108: 46283.701 | B108: 46283 | C108: 우리은행 | D108: 우리 220351 | E108: 990000 | F108: 0 | G108: 11945285 | H108: 인터넷 | I108: 국민네이버 ddi5 | J108: 성서공단금융센터 | K108: 기타지출 | L108: N | M108: N | N108: -990000 | O108: 국민은행_계좌 조회 6개월(20260913).xls | P108: 기존내역
A109: 46284 | B109: 46284 | C109: 국민은행 | D109: 국민 154577 | E109: 0 | F109: 0 | G109: 20147954 | H109: 전일잔액 | K109: 기타지출 | L109: N | M109: N | N109: 0 | O109: 국민은행_계좌 조회 6개월(20260913).xls | P109: 기존내역
A110: 46284.396 | B110: 46284 | C110: 우리은행 | D110: 우리 220351 | E110: 0 | F110: 2852 | G110: 11948137 | H110: 예금결산 | I110: 예금결산이자 | J110: 성서공단금융센터 | K110: 기타입금 | L110: N | M110: N | N110: 2852 | O110: 농협계좌_6개월(20260913).xls | P110: 기존내역
A111: 46285 | B111: 46285 | C111: 우리은행 | D111: 우리 220351 | E111: 0 | F111: 0 | G111: 11948137 | H111: 전일잔액 | K111: 기타지출 | L111: N | M111: N | N111: 0 | O111: 국민은행_계좌 조회 6개월(20260913).xls | P111: 기존내역
A112: 46285.824 | B112: 46285 | C112: 국민은행 | D112: 국민 154577 | E112: 0 | F112: 37000 | G112: 20184954 | H112: 전자금융 | I112: 김은미 | J112: 카뱅 | K112: 기타입금 | L112: N | M112: N | N112: 37000 | O112: 농협계좌_6개월(20260913).xls | P112: 기존내역
A113: 46286 | B113: 46286 | C113: 우리은행 | D113: 우리 220351 | E113: 134622 | F113: 0 | G113: 11813515 | H113: SKB6452342048 | K113: 기타지출 | L113: N | M113: N | N113: -134622 | O113: 우리은행 거래내역조회 20260913.xlsx | P113: 기존내역
A114: 46286 | B114: 46286 | C114: 우리은행 | D114: 우리 220351 | E114: 85621 | F114: 0 | G114: 11727894 | H114: SKB6486358411 | K114: 기타지출 | L114: N | M114: N | N114: -85621 | O114: 우리은행 거래내역조회 20260913.xlsx | P114: 기존내역
A115: 46286 | B115: 46286 | C115: 우리은행 | D115: 우리 220351 | E115: 107800 | F115: 0 | G115: 11620094 | H115: S1(N6203178) | K115: 기타지출 | L115: N | M115: N | N115: -107800 | O115: 우리은행 거래내역조회 20260913.xlsx | P115: 기존내역
A116: 46286 | B116: 46286 | C116: 우리은행 | D116: 우리 220351 | E116: 0 | F116: 5694170 | G116: 17314264 | H116: 스마트스토어정산 | K116: 온라인매출입금 | L116: N | M116: N | N116: 5694170 | O116: 우리은행 거래내역조회 20260913.xlsx | P116: 기존내역
A117: 46286 | B117: 46286 | C117: 우리은행 | D117: 우리 220351 | E117: 2178000 | F117: 0 | G117: 15136264 | H117: 국민네이버 ａｐｈａ | K117: 기타지출 | L117: N | M117: N | N117: -2178000 | O117: 우리은행 거래내역조회 20260913.xlsx | P117: 기존내역
A118: 46286 | B118: 46286 | C118: 우리은행 | D118: 우리 220351 | E118: 330000 | F118: 0 | G118: 14806264 | H118: 국민네이버 에이팜건 | K118: 기타지출 | L118: N | M118: N | N118: -330000 | O118: 국민은행_계좌 조회 6개월(20260913).xls | P118: 기존내역
A119: 46286 | B119: 46286 | C119: 우리은행 | D119: 우리 220351 | E119: 632250 | F119: 0 | G119: 14174014 | H119: 국민서울보증보험 | K119: 기타지출 | L119: N | M119: N | N119: -632250 | O119: 농협계좌_6개월(20260913).xls | P119: 기존내역
A120: 46286.429 | B120: 46286 | C120: 농협 | D120: 농협 569003 | E120: 0 | F120: 110000 | G120: 1944429 | H120: E-K뱅크 | I120: 양혜원 | J120: K뱅크 0891002 | K120: 기타입금 | L120: N | M120: N | N120: 110000 | O120: 국민은행_계좌 조회 6개월(20260913).xls | P120: 기존내역
A121: 46286.43 | B121: 46286 | C121: 국민은행 | D121: 국민 154577 | E121: 0 | F121: 750249 | G121: 20935203 | H121: 전자금융 | I121: KG이니시스 | J121: 하나은행 | K121: 온라인매출입금 | L121: N | M121: N | N121: 750249 | O121: 국민은행_계좌 조회 6개월(20260913).xls | P121: 기존내역
A122: 46286.437 | B122: 46286 | C122: 국민은행 | D122: 국민 154577 | E122: 0 | F122: 68816 | G122: 21004019 | H122: 전자금융 | I122: KG이니시스 | J122: 하나은행 | K122: 온라인매출입금 | L122: N | M122: N | N122: 68816 | O122: 국민은행_계좌 조회 6개월(20260913).xls | P122: 기존내역
A123: 46286.47 | B123: 46286 | C123: 국민은행 | D123: 국민 154577 | E123: 0 | F123: 3860670 | G123: 24864689 | H123: FBS입금 | I123: (주)현대이지웰 | J123: ERP사 | K123: 온라인매출입금 | L123: N | M123: N | N123: 3860670 | O123: 농협계좌_6개월(20260913).xls | P123: 기존내역
A124: 46286.486 | B124: 46286 | C124: 국민은행 | D124: 국민 154577 | E124: 0 | F124: 20000000 | G124: 44864689 | H124: 전자금융 | I124: 허용 | J124: 아이엠뱅 | K124: 가지급금 회수 | L124: N | M124: N | N124: 20000000 | O124: 국민은행_계좌 조회 6개월(20260913).xls | P124: 기존내역
A125: 46286.842 | B125: 46286 | C125: 국민은행 | D125: 국민 154577 | E125: 4795900 | F125: 0 | G125: 40068789 | H125: CMS 공동 | I125: METLIFE09002 | J125: ERP사 | K125: 기타지출 | L125: N | M125: N | N125: -4795900 | O125: 농협계좌_6개월(20260913).xls | P125: 기존내역
A126: 46287 | B126: 46287 | C126: 우리은행 | D126: 우리 220351 | E126: 0 | F126: 15847736 | G126: 30021750 | H126: 스마트스토어정산 | K126: 온라인매출입금 | L126: N | M126: N | N126: 15847736 | O126: 국민은행_계좌 조회 6개월(20260913).xls | P126: 기존내역
A127: 46287.206 | B127: 46287 | C127: 국민은행 | D127: 국민 154577 | E127: 0 | F127: 168361 | G127: 40237150 | H127: 전자금융 | I127: Npay정산 | J127: SC은행 | K127: 온라인매출입금 | L127: N | M127: N | N127: 168361 | O127: 우리은행 거래내역조회 20260913.xlsx | P127: 기존내역
A128: 46287.424 | B128: 46287 | C128: 농협 | D128: 농협 569003 | E128: 0 | F128: 1000 | G128: 1945429 | H128: E-K뱅크 | I128: 양혜원 | J128: K뱅크 0891002 | K128: 기타입금 | L128: N | M128: N | N128: 1000 | O128: 우리은행 거래내역조회 20260913.xlsx | P128: 기존내역
A129: 46287.429 | B129: 46287 | C129: 국민은행 | D129: 국민 154577 | E129: 0 | F129: 618283 | G129: 40855433 | H129: 전자금융 | I129: KG이니시스 | J129: 하나은행 | K129: 온라인매출입금 | L129: N | M129: N | N129: 618283 | O129: 우리은행 거래내역조회 20260913.xlsx | P129: 기존내역
A130: 46287.45 | B130: 46287 | C130: 국민은행 | D130: 국민 154577 | E130: 0 | F130: 2739917 | G130: 43595350 | H130: 전자금융 | I130: KG이니시스 | J130: 하나은행 | K130: 온라인매출입금 | L130: N | M130: N | N130: 2739917 | O130: 국민은행_계좌 조회 6개월(20260913).xls | P130: 기존내역
A131: 46287.522 | B131: 46287 | C131: 국민은행 | D131: 국민 154577 | E131: 0 | F131: 246613 | G131: 43841963 | H131: 전자금융 | I131: 화물택배물 | J131: 농협 | K131: 기타입금 | L131: N | M131: N | N131: 246613 | O131: 국민은행_계좌 조회 6개월(20260913).xls | P131: 기존내역
A132: 46287.568 | B132: 46287 | C132: 우리은행 | D132: 우리 220351 | E132: 20000000 | F132: 0 | G132: 10021750 | H132: 인터넷 | I132: 기업엠에스바이오텍( | J132: 성서공단금융센터 | K132: 기타지출 | L132: N | M132: N | N132: -20000000 | O132: 우리은행 거래내역조회 20260913.xlsx | P132: 기존내역
A133: 46287.609 | B133: 46287 | C133: 농협 | D133: 농협 569003 | E133: 0 | F133: 2000 | G133: 1947429 | H133: PC신한은행 | I133: 송채은 | J133: 신한 0267623 | K133: 기타입금 | L133: N | M133: N | N133: 2000 | O133: 우리은행 거래내역조회 20260913.xlsx | P133: 기존내역
A134: 46287.621 | B134: 46287 | C134: 농협 | D134: 농협 569003 | E134: 0 | F134: 280000 | G134: 2227429 | H134: E-아이엠 | I134: 석계아이엔디(주)( | J134: 아이엠 (구)대구 0310017 | K134: 기타입금 | L134: N | M134: N | N134: 280000 | O134: 우리은행 거래내역조회 20260913.xlsx | P134: 기존내역
...

Sheet 설정및분류
A2: 예측 설정 및 자동분류 기준
A5: 요일번호 | B5: 요일 | C5: 최근 12주 온라인입금 일평균 | E5: 분류 | F5: 대표 키워드 | H5: 반영률 선택값
A6: 1 | B6: 월 | C6: 10677756 | E6: 온라인매출입금 | F6: 스마트스토어, KG이니시스, Npay, NHN페이, 카드가맹점 | H6: 0.6
A7: 2 | B7: 화 | C7: 22255001 | E7: 계좌간이체 | F7: 에이팜건강 표시(광고·네이버 제외) | H7: 0.7
A8: 3 | B8: 수 | C8: 14296943 | E8: 4대보험 | F8: 우리은행의 사회보험·건강보험 | H8: 0.8
A9: 4 | B9: 목 | C9: 13264811 | E9: 원천세·국세 | F9: 우리은행의 국고·원천세 | H9: 0.9
A10: 5 | B10: 금 | C10: 10320905 | E10: 법인카드결제 | F10: 우리카드결제대금, KB카드출금 | H10: 1
A11: 6 | B11: 토 | C11: 0 | E11: 보험료(기타) | F11: 한화생명, 메트라이프, ABL생명, 미래에셋
A12: 7 | B12: 일 | C12: 0 | E12: 광고선전비 | F12: 네이버, 광고, 비즈월렛, 캐시워크
E13: 급여·인건비(대외비) | F13: 급여, 상여, 퇴직, 국민은행 월말 TOP출금
E14: 대출·이자 | F14: 대출, 이자
E15: 기타입출금 | F15: 위 기준에 해당하지 않는 거래
