Workbook

Sheet 사용법
A1: 거래처 미수금 관리 양식 — 사용 안내
A2: 홈택스 매출 세금계산서 목록과 은행 입금내역 엑셀을 그대로 붙여넣으면, 거래처별 미수 잔액·30/60/90일 연령 분석·연락할 후보와 문구 초안이 자동으로 만들어집니다.
A4: ■ 작업 순서도
B5: ① 설정 | C5: 회사 이름·기준일(오늘)만 확인 | D5: ◀ 기준일은 비우면 오늘 날짜
B6: ▼
B7: ② 매출원본 | C7: 홈택스 매출 세금계산서 목록을 A8에 붙여넣기 | D7: ◀ 열 설정 노란 칸은 처음 한 번만 확인
B8: ▼
B9: ③ 입금_은행 | C9: 은행 입금내역 엑셀을 A8에 붙여넣기 (계좌 2개까지) | D9: ◀ 보낸 분 이름이 거래처 이름과 맞으면 자동 매칭
B10: ▼
B11: ④ 요약 | C11: ✔가 떴는지, 총 미수 잔액과 구간별 금액 확인 | D11: ◀ 홈택스 합계와 대조하는 선택 칸
B12: ▼
B13: ⑤ 미매칭입금 → 거래처설정 | C13: 맞춰지지 않은 입금은 별칭 등록 (필요한 곳만) | D13: ◀ 입금자명이 대표 이름 등으로 다를 때
B14: ▼
B15: ⑥ 연령분석 · 독촉대상 | C15: (자동) 큰 순서 미수 목록과 연락 후보·문구 초안 | D15: ◀ 연락 결과는 [거래처설정]의 조치 상태에
A17: ■ 시트 안내 (탭 순서대로)
A18: 순서 | B18: 시트 | C18: 역할 | D18: ✍ 직접 입력 | E18: ⚙ 자동 처리
A19: ① | B19: 설정 | C19: 회사 이름·기준일·구간 | D19: 회사 이름, 기준일(비우면 오늘), 30/60/90일, 최소 금액 | E19: —
A20: ② | B20: 매출원본 | C20: 홈택스 매출 목록 붙여넣는 곳 | D20: A8 붙여넣기 + 5행 열 설정(처음 한 번) | E20: 날짜·금액 변환, 거래처 묶기, 승인번호 중복 표시
A21: ③ | B21: 입금_은행1·2 | C21: 은행 입금내역 붙여넣는 곳 | D21: A8 붙여넣기 + 5행 열 설정 | E21: 입금만 골라 이름으로 거래처에 맞춤
A22: ④ | B22: 요약 | C22: 핵심 결과 | D22: 홈택스 합계(선택) | E22: 총 미수·구간별·연락 후보 수·미매칭 건수
A23: ⑤ | B23: 거래처별 | C23: 거래처별 계산 전체 | D23: 없음 | E23: 매출 누계 − 입금 누계, 경과일 구간, 판정, 점검 문구
A24: ⑥ | B24: 연령분석 | C24: 미수 큰 순서 목록 | D24: 없음 | E24: 최대 100곳을 잔액 큰 순으로 정렬
A25: ⑦ | B25: 독촉대상 | C25: 연락 후보와 문구 | D25: 없음 (조치 상태는 거래처설정에) | E25: 오래된 잔액이 큰 순, 문구 초안
A26: ⑧ | B26: 미매칭입금 | C26: 거래처로 안 맞은 입금 | D26: 없음 | E26: 별칭 등록이 필요한 입금 찾기
A27: ⑨ | B27: 거래처설정 | C27: 별칭·기초 미수금·조치 상태 | D27: 필요한 거래처만 적기 | E27: 새로 붙여넣어도 유지됨
A29: ■ 붙여넣기, 이렇게 하면 됩니다
A30: 1. 홈택스 → 전자(세금)계산서 목록조회에서 매출·기간을 정해 조회한 뒤 엑셀로 내려받습니다. 외상 기간을 길게 보려면 최근 6개월~1년을 한 번에 조회하세요.
A31: · 내려받은 파일을 열었을 때 위에 노란 막대(보호된 보기)가 뜨면 [편집 사용]을 먼저 누르세요.
A32: 2. 파일에서 전체 복사(Ctrl+A → Ctrl+C) → [매출원본] A8 셀 클릭 → 붙여넣기(Ctrl+V). 처음 한 번은 8행 아래 예시를 먼저 지우세요 (8행 아래 전체 선택 → Delete).
A33: 3. 은행(인터넷뱅킹) 거래내역을 기간을 정해 엑셀로 내려받아 [입금_은행1] A8에 붙여넣습니다. 계좌가 둘이면 [입금_은행2]에도. 입금·출금이 섞인 파일 그대로 괜찮습니다.
A34: · 은행마다 열 순서가 다르니 처음 한 번 5행 노란 칸에 날짜·입금액·보낸 분(내용)이 있는 열 문자만 맞춰 주세요 (AA 같은 두 글자도 가능).
A35: 4. [요약]에서 ✔ 표시와 총 미수 잔액을 확인하고, [연령분석]과 [독촉대상]을 봅니다.
A36: 5. 입금자명이 거래처 이름과 달라 안 맞은 입금은 [미매칭입금]에서 찾아 [거래처설정]에 별칭으로 등록합니다. 한 번 등록하면 다음에도 유지됩니다.
A37: 6. 다음 달에는 두 원본 시트에 새 파일을 같은 자리에 덮어 붙여넣고(이전 내용은 먼저 지우기), 기준일만 확인하면 됩니다.
A39: ■ 알아두세요
A40: · 입금은 오래된 세금계산서부터 갚은 것으로 계산합니다(선입선출). 이전 해에서 넘어온 미수금은 [거래처설정]의 '기초 미수금'에 적으세요.
A41: · 경과일은 세금계산서 작성일자 기준입니다. 결제 약속일(월말 마감, 어음 등)은 반영하지 않으니 '약속 기한이 지난 금액'과는 다를 수 있습니다.
... A46: ■ 색 안내
B47: 노란 칸 | C47: 직접 입력하는 곳 — 파란 글씨는 가상 예시값이니 지우고 실제 값을 넣으세요
B48: 회색 작은 글씨 | C48: 자동 계산 수식 — 수정 금지

Sheet 요약
A1: 요약 — 거래처 미수금 한눈에 (자동)
A2: ✍ 직접 입력: 13~14행 노란 칸(홈택스 화면의 건수·합계금액)만 — 선택. ⚙ 나머지는 자동입니다.
A4: ■ 1. 붙여넣기가 잘 되었는지
A5: 매출 세금계산서 | B5: =매출원본!H5
A6: 입금 — 은행1 | B6: =입금_은행1!H5
A7: 입금 — 은행2 | B7: =입금_은행2!H5
A8: 확인 필요 | B8: =TRIM(매출원본!H6&" "&입금_은행1!H6&" "&입금_은행2!H6&IF(SUM(매출원본!$BA$8:$BA$2007)>0," ⚠ 승인번호가 같은 세금계산서가 "&SUM(매출원본!$BA$8:$BA$2007)&"건 더 있습니다 — 같은 파일을 두 번 붙여넣지 않았는지 확인","")&IF(MAX(매출원본!$AW$8:$AW$2007)>300," ⚠ 거래처가 300곳을 넘어 일부가 빠집니다",""))
A10: ■ 2. 홈택스 화면과 대조 (선택)
A11: 홈택스 매출 목록 화면의 합계(건수·합계금액)를 적으면 붙여넣은 파일과 같은지 자동 확인합니다.
A13: 홈택스 화면 건수 | B13: 20 | C13: =IF($B$13="","(입력하면 자동 대조)",IF($B$13=COUNT(매출원본!$AS$8:$AS$2007),"✔ 홈택스와 일치","✖ 차이 "&(COUNT(매출원본!$AS$8:$AS$2007)-$B$13)&"건 — 기간·거래처 구분이 같은지 확인"))
A14: 홈택스 화면 합계금액(원) | B14: 60170000 | C14: =IF($B$14="","(입력하면 자동 대조)",IF($B$14=SUM(매출원본!$AT$8:$AT$2007),"✔ 홈택스와 일치","✖ 차이 "&TEXT(SUM(매출원본!$AT$8:$AT$2007)-$B$14,"#,##0")&"원 — 기간·거래처 구분이 같은지 확인"))
A16: ■ 3. 미수금 한눈에
A17: 기준일 | B17: =설정!$B$5
A18: 총 미수 잔액 | B18: =연령분석!D5 | C18: =COUNT(거래처별!$R$8:$R$307)&"곳"
A19: =거래처별!H7 | B19: =연령분석!E5 | C19: =IF($B$18=0,"",TEXT(B19/$B$18,"0%"))
A20: =거래처별!I7 | B20: =연령분석!F5 | C20: =IF($B$18=0,"",TEXT(B20/$B$18,"0%"))
A21: =거래처별!J7 | B21: =연령분석!G5 | C21: =IF($B$18=0,"",TEXT(B21/$B$18,"0%"))
A22: =거래처별!K7 | B22: =연령분석!H5 | C22: =IF($B$18=0,"",TEXT(B22/$B$18,"0%"))
A23: 선수금·초과입금 | B23: =-SUMIF(거래처별!$G$8:$G$307,"<0") | C23: =COUNTIF(거래처별!$G$8:$G$307,"<0")&"곳 — 확인 필요"
A24: 연락 후보 | B24: ="① "&COUNTIF(거래처별!$O$8:$O$307,1)&"곳 · ② "&COUNTIF(거래처별!$O$8:$O$307,2)&"곳 · ③ "&COUNTIF(거래처별!$O$8:$O$307,3)&"곳" | C24: [독촉대상] 시트에서 문구 초안까지
A25: 미매칭 입금 | B25: =(MAX(입금_은행1!$AD$8:$AD$2007)+MAX(입금_은행2!$AD$8:$AD$2007))&"건" | C25: [미매칭입금] 시트에서 거래처 입금이 있는지 확인
A27: ■ 4. 미수 잔액 상위 5곳
A28: 거래처 | B28: 미수 잔액 | C28: 경과 구간1 초과분 | D28: 판정
A29: =IF(연령분석!B7="","",연령분석!B7) | B29: =IF(연령분석!D7="","",연령분석!D7) | C29: =IF(연령분석!D7="","",연령분석!F7+연령분석!G7+연령분석!H7) | D29: =IF(연령분석!K7="","",연령분석!K7)
A30: =IF(연령분석!B8="","",연령분석!B8) | B30: =IF(연령분석!D8="","",연령분석!D8) | C30: =IF(연령분석!D8="","",연령분석!F8+연령분석!G8+연령분석!H8) | D30: =IF(연령분석!K8="","",연령분석!K8)
A31: =IF(연령분석!B9="","",연령분석!B9) | B31: =IF(연령분석!D9="","",연령분석!D9) | C31: =IF(연령분석!D9="","",연령분석!F9+연령분석!G9+연령분석!H9) | D31: =IF(연령분석!K9="","",연령분석!K9)
A32: =IF(연령분석!B10="","",연령분석!B10) | B32: =IF(연령분석!D10="","",연령분석!D10) | C32: =IF(연령분석!D10="","",연령분석!F10+연령분석!G10+연령분석!H10) | D32: =IF(연령분석!K10="","",연령분석!K10)
A33: =IF(연령분석!B11="","",연령분석!B11) | B33: =IF(연령분석!D11="","",연령분석!D11) | C33: =IF(연령분석!D11="","",연령분석!F11+연령분석!G11+연령분석!H11) | D33: =IF(연령분석!K11="","",연령분석!K11)
A35: ※ 미수 잔액은 장부(회계프로그램)의 외상매출금과 다를 수 있습니다. 이 양식은 세금계산서와 은행 입금만 보고 계산하는 점검용입니다.

Sheet 매출원본
A1: 매출원본 — 홈택스 매출 전자세금계산서 목록 붙여넣기
A2: ✍ 직접 입력: 홈택스에서 내려받은 매출 목록 엑셀을 A8 셀부터 통째로 붙여넣고('값' 붙여넣기 권장), 5행 노란 칸을 확인하세요. 거래처는 공급받는자 쪽입니다.
A3: ⚙ 자동 계산: AR~BA열 회색 수식이 날짜·금액·거래처를 정리합니다 — 수정 금지. 오른쪽 '인식 결과'에 ✔가 뜨면 성공. 처음 쓸 때: 8행 아래 예시를 전체 선택 → Delete 로 먼저 지우세요.
A4: 데이터 시작 행 | B4: 작성일자 열 | C4: 승인번호 열 | D4: 거래처 사업자번호 열 | E4: 거래처 상호 열 | F4: 합계금액 열 | H4: 인식 결과 (자동)
A5: 14 | B5: A | C5: B | D5: J | E5: L | F5: O | H5: =IF(COUNT($AS$8:$AS$2007)=0,"아직 인식된 세금계산서가 없습니다 — 붙여넣기 위치와 열 설정을 확인하세요","✔ 세금계산서 "&COUNT($AS$8:$AS$2007)&"건 · 합계금액 "&TEXT(SUM($AT$8:$AT$2007),"#,##0")&"원 · 거래처 "&MAX($AW$8:$AW$2007)&"곳")
A6: ▼ 8행(A8 셀)부터 붙여넣기 | B6: =IF($B$5="","",IF(LEN(TRIM($B$5))=1,CODE(UPPER(TRIM($B$5)))-64,(CODE(UPPER(LEFT(TRIM($B$5),1)))-64)*26+CODE(UPPER(RIGHT(TRIM($B$5),1)))-64)) | C6: =IF($C$5="","",IF(LEN(TRIM($C$5))=1,CODE(UPPER(TRIM($C$5)))-64,(CODE(UPPER(LEFT(TRIM($C$5),1)))-64)*26+CODE(UPPER(RIGHT(TRIM($C$5),1)))-64)) | D6: =IF($D$5="","",IF(LEN(TRIM($D$5))=1,CODE(UPPER(TRIM($D$5)))-64,(CODE(UPPER(LEFT(TRIM($D$5),1)))-64)*26+CODE(UPPER(RIGHT(TRIM($D$5),1)))-64)) | E6: =IF($E$5="","",IF(LEN(TRIM($E$5))=1,CODE(UPPER(TRIM($E$5)))-64,(CODE(UPPER(LEFT(TRIM($E$5),1)))-64)*26+CODE(UPPER(RIGHT(TRIM($E$5),1)))-64)) | F6: =IF($F$5="","",IF(LEN(TRIM($F$5))=1,CODE(UPPER(TRIM($F$5)))-64,(CODE(UPPER(LEFT(TRIM($F$5),1)))-64)*26+CODE(UPPER(RIGHT(TRIM($F$5),1)))-64)) | H6: =IF(COUNTIF($AX$8:$AX$2007,"999-*")>0,"⚠ 예시 데이터 "&COUNTIF($AX$8:$AX$2007,"999-*")&"줄이 남아 있습니다 — 지우고 쓰세요 (8행 아래 전체 선택 → Delete)","")
AR7: 원본일자(자동) | AS7: 작성일자(자동) | AT7: 합계(자동) | AU7: 거래처키(자동) | AV7: 거래처 상호(자동) | AW7: 거래처순번(자동) | AX7: 원본 사업자번호(자동) | AY7: 거래처번호(자동) | AZ7: 승인번호(자동) | BA7: 중복(자동)
A8: 매출 전자(세금)계산서 목록 (가상 예시) | AR8: =IF(OR($A$5="",$B$6="",ROW()<$A$5),"",IF(INDEX($A:$AP,ROW(),$B$6)="","",INDEX($A:$AP,ROW(),$B$6))) | AS8: =IF($AR8="","",IF(ISNUMBER($AR8),IF($AR8>=10000000,IFERROR(DATE(INT($AR8/10000),MOD(INT($AR8/100),100),MOD($AR8,100)),""),INT($AR8)),IFERROR(DATE(--LEFT(LEFT(SUBSTITUTE(SUBSTITUTE(SUBSTITUTE(SUBSTITUTE(TRIM($AR8),"-",""),".",""),"/","")," ",""),8),4),--MID(LEFT(SUBSTITUTE(SUBSTITUTE(SUBSTITUTE(SUBSTITUTE(TRIM($AR8),"-",""),".",""),"/","")," ",""),8),5,2),--MID(LEFT(SUBSTITUTE(SUBSTITUTE(SUBSTITUTE(SUBSTITUTE(TRIM($AR8),"-",""),".",""),"/","")," ",""),8),7,2)),""))) | AT8: =IF($AS8="","",IF($F$6="",0,IF(ISNUMBER(INDEX($A:$AP,ROW(),$F$6)),INDEX($A:$AP,ROW(),$F$6),IFERROR(--SUBSTITUTE(SUBSTITUTE(TRIM(INDEX($A:$AP,ROW(),$F$6)),",",""),"원",""),0)))) | AU8: =IF($AS8="","",IF($AX8<>"",SUBSTITUTE(SUBSTITUTE($AX8,"-","")," ",""),"N:"&$AV8)) | AV8: =IF(OR($AS8="",$E$6=""),"",TRIM(INDEX($A:$AP,ROW(),$E$6)&"")) | AW8: =IF($AU8="","",IF(MATCH($AU8,$AU$8:$AU$2007,0)=ROW()-7,MAX($AW$7:$AW7)+1,"")) | AX8: =IF(OR($AS8="",$D$6=""),"",TRIM(INDEX($A:$AP,ROW(),$D$6)&"")) | AY8: =IF($AU8="","",INDEX($AW$8:$AW$2007,MATCH($AU8,$AU$8:$AU$2007,0))) | AZ8: =IF(OR($AS8="",$C$6=""),"",TRIM(INDEX($A:$AP,ROW(),$C$6)&"")) | BA8: =IF($AZ8="","",IF(COUNTIF($AZ$8:$AZ8,$AZ8)>1,1,0))
AR9: =IF(OR($A$5="",$B$6="",ROW()<$A$5),"",IF(INDEX($A:$AP,ROW(),$B$6)="","",INDEX($A:$AP,ROW(),$B$6))) | AS9: =IF($AR9="","",IF(ISNUMBER($AR9),IF($AR9>=10000000,IFERROR(DATE(INT($AR9/10000),MOD(INT($AR9/100),100),MOD($AR9,100)),""),INT($AR9)),IFERROR(DATE(--LEFT(LEFT(SUBSTITUTE(SUBSTITUTE(SUBSTITUTE(SUBSTITUTE(TRIM($AR9),"-",""),".",""),"/","")," ",""),8),4),--MID(LEFT(SUBSTITUTE(SUBSTITUTE(SUBSTITUTE(SUBSTITUTE(TRIM($AR9),"-",""),".",""),"/","")," ",""),8),5,2),--MID(LEFT(SUBSTITUTE(SUBSTITUTE(SUBSTITUTE(SUBSTITUTE(TRIM($AR9),"-",""),".",""),"/","")," ",""),8),7,2)),""))) | AT9: =IF($AS9="","",IF($F$6="",0,IF(ISNUMBER(INDEX($A:$AP,ROW(),$F$6)),INDEX($A:$AP,ROW(),$F$6),IFERROR(--SUBSTITUTE(SUBSTITUTE(TRIM(INDEX($A:$AP,ROW(),$F$6)),",",""),"원",""),0)))) | AU9: =IF($AS9="","",IF($AX9<>"",SUBSTITUTE(SUBSTITUTE($AX9,"-","")," ",""),"N:"&$AV9)) | AV9: =IF(OR($AS9="",$E$6=""),"",TRIM(INDEX($A:$AP,ROW(),$E$6)&"")) | AW9: =IF($AU9="","",IF(MATCH($AU9,$AU$8:$AU$2007,0)=ROW()-7,MAX($AW$7:$AW8)+1,"")) | AX9: =IF(OR($AS9="",$D$6=""),"",TRIM(INDEX($A:$AP,ROW(),$D$6)&"")) | AY9: =IF($AU9="","",INDEX($AW$8:$AW$2007,MATCH($AU9,$AU$8:$AU$2007,0))) | AZ9: =IF(OR($AS9="",$C$6=""),"",TRIM(INDEX($A:$AP,ROW(),$C$6)&"")) | BA9: =IF($AZ9="","",IF(COUNTIF($AZ$8:$AZ9,$AZ9)>1,1,0))
A10: 조회기간 : 2026-05 ~ 2026-10 | AR10: =IF(OR($A$5="",$B$6="",ROW()<$A$5),"",IF(INDEX($A:$AP,ROW(),$B$6)="","",INDEX($A:$AP,ROW(),$B$6))) | AS10: =IF($AR10="","",IF(ISNUMBER($AR10),IF($AR10>=10000000,IFERROR(DATE(INT($AR10/10000),MOD(INT($AR10/100),100),MOD($AR10,100)),""),INT($AR10)),IFERROR(DATE(--LEFT(LEFT(SUBSTITUTE(SUBSTITUTE(SUBSTITUTE(SUBSTITUTE(TRIM($AR10),"-",""),".",""),"/","")," ",""),8),4),--MID(LEFT(SUBSTITUTE(SUBSTITUTE(SUBSTITUTE(SUBSTITUTE(TRIM($AR10),"-",""),".",""),"/","")," ",""),8),5,2),--MID(LEFT(SUBSTITUTE(SUBSTITUTE(SUBSTITUTE(SUBSTITUTE(TRIM($AR10),"-",""),".",""),"/","")," ",""),8),7,2)),""))) | AT10: =IF($AS10="","",IF($F$6="",0,IF(ISNUMBER(INDEX($A:$AP,ROW(),$F$6)),INDEX($A:$AP,ROW(),$F$6),IFERROR(--SUBSTITUTE(SUBSTITUTE(TRIM(INDEX($A:$AP,ROW(),$F$6)),",",""),"원",""),0)))) | AU10: =IF($AS10="","",IF($AX10<>"",SUBSTITUTE(SUBSTITUTE($AX10,"-","")," ",""),"N:"&$AV10)) | AV10: =IF(OR($AS10="",$E$6=""),"",TRIM(INDEX($A:$AP,ROW(),$E$6)&"")) | AW10: =IF($AU10="","",IF(MATCH($AU10,$AU$8:$AU$2007,0)=ROW()-7,MAX($AW$7:$AW9)+1,"")) | AX10: =IF(OR($AS10="",$D$6=""),"",TRIM(INDEX($A:$AP,ROW(),$D$6)&"")) | AY10: =IF($AU10="","",INDEX($AW$8:$AW$2007,MATCH($AU10,$AU$8:$AU$2007,0))) | AZ10: =IF(OR($AS10="",$C$6=""),"",TRIM(INDEX($A:$AP,ROW(),$C$6)&"")) | BA10: =IF($AZ10="","",IF(COUNTIF($AZ$8:$AZ10,$AZ10)>1,1,0))
A11: 사업자등록번호 : 999-81-00001 (가상) | AR11: =IF(OR($A$5="",$B$6="",ROW()<$A$5),"",IF(INDEX($A:$AP,ROW(),$B$6)="","",INDEX($A:$AP,ROW(),$B$6))) | AS11: =IF($AR11="","",IF(ISNUMBER($AR11),IF($AR11>=10000000,IFERROR(DATE(INT($AR11/10000),MOD(INT($AR11/100),100),MOD($AR11,100)),""),INT($AR11)),IFERROR(DATE(--LEFT(LEFT(SUBSTITUTE(SUBSTITUTE(SUBSTITUTE(SUBSTITUTE(TRIM($AR11),"-",""),".",""),"/","")," ",""),8),4),--MID(LEFT(SUBSTITUTE(SUBSTITUTE(SUBSTITUTE(SUBSTITUTE(TRIM($AR11),"-",""),".",""),"/","")," ",""),8),5,2),--MID(LEFT(SUBSTITUTE(SUBSTITUTE(SUBSTITUTE(SUBSTITUTE(TRIM($AR11),"-",""),".",""),"/","")," ",""),8),7,2)),""))) | AT11: =IF($AS11="","",IF($F$6="",0,IF(ISNUMBER(INDEX($A:$AP,ROW(),$F$6)),INDEX($A:$AP,ROW(),$F$6),IFERROR(--SUBSTITUTE(SUBSTITUTE(TRIM(INDEX($A:$AP,ROW(),$F$6)),",",""),"원",""),0)))) | AU11: =IF($AS11="","",IF($AX11<>"",SUBSTITUTE(SUBSTITUTE($AX11,"-","")," ",""),"N:"&$AV11)) | AV11: =IF(OR($AS11="",$E$6=""),"",TRIM(INDEX($A:$AP,ROW(),$E$6)&"")) | AW11: =IF($AU11="","",IF(MATCH($AU11,$AU$8:$AU$2007,0)=ROW()-7,MAX($AW$7:$AW10)+1,"")) | AX11: =IF(OR($AS11="",$D$6=""),"",TRIM(INDEX($A:$AP,ROW(),$D$6)&"")) | AY11: =IF($AU11="","",INDEX($AW$8:$AW$2007,MATCH($AU11,$AU$8:$AU$2007,0))) | AZ11: =IF(OR($AS11="",$C$6=""),"",TRIM(INDEX($A:$AP,ROW(),$C$6)&"")) | BA11: =IF($AZ11="","",IF(COUNTIF($AZ$8:$AZ11,$AZ11)>1,1,0))
AR12: =IF(OR($A$5="",$B$6="",ROW()<$A$5),"",IF(INDEX($A:$AP,ROW(),$B$6)="","",INDEX($A:$AP,ROW(),$B$6))) | AS12: =IF($AR12="","",IF(ISNUMBER($AR12),IF($AR12>=10000000,IFERROR(DATE(INT($AR12/10000),MOD(INT($AR12/100),100),MOD($AR12,100)),""),INT($AR12)),IFERROR(DATE(--LEFT(LEFT(SUBSTITUTE(SUBSTITUTE(SUBSTITUTE(SUBSTITUTE(TRIM($AR12),"-",""),".",""),"/","")," ",""),8),4),--MID(LEFT(SUBSTITUTE(SUBSTITUTE(SUBSTITUTE(SUBSTITUTE(TRIM($AR12),"-",""),".",""),"/","")," ",""),8),5,2),--MID(LEFT(SUBSTITUTE(SUBSTITUTE(SUBSTITUTE(SUBSTITUTE(TRIM($AR12),"-",""),".",""),"/","")," ",""),8),7,2)),""))) | AT12: =IF($AS12="","",IF($F$6="",0,IF(ISNUMBER(INDEX($A:$AP,ROW(),$F$6)),INDEX($A:$AP,ROW(),$F$6),IFERROR(--SUBSTITUTE(SUBSTITUTE(TRIM(INDEX($A:$AP,ROW(),$F$6)),",",""),"원",""),0)))) | AU12: =IF($AS12="","",IF($AX12<>"",SUBSTITUTE(SUBSTITUTE($AX12,"-","")," ",""),"N:"&$AV12)) | AV12: =IF(OR($AS12="",$E$6=""),"",TRIM(INDEX($A:$AP,ROW(),$E$6)&"")) | AW12: =IF($AU12="","",IF(MATCH($AU12,$AU$8:$AU$2007,0)=ROW()-7,MAX($AW$7:$AW11)+1,"")) | AX12: =IF(OR($AS12="",$D$6=""),"",TRIM(INDEX($A:$AP,ROW(),$D$6)&"")) | AY12: =IF($AU12="","",INDEX($AW$8:$AW$2007,MATCH($AU12,$AU$8:$AU$2007,0))) | AZ12: =IF(OR($AS12="",$C$6=""),"",TRIM(INDEX($A:$AP,ROW(),$C$6)&"")) | BA12: =IF($AZ12="","",IF(COUNTIF($AZ$8:$AZ12,$AZ12)>1,1,0))
A13: 작성일자 | B13: 승인번호 | C13: 발급일자 | D13: 전송일자 | E13: 공급자사업자등록번호 | F13: 종사업장번호 | G13: 상호 | H13: 대표자명 | I13: 주소 | J13: 공급받는자사업자등록번호 | K13: 종사업장번호 | L13: 상호 | M13: 대표자명 | N13: 주소 | O13: 합계금액 | P13: 공급가액 | Q13: 세액 | R13: 전자세금계산서분류 | S13: 전자세금계산서종류 | T13: 발급유형 | AR13: =IF(OR($A$5="",$B$6="",ROW()<$A$5),"",IF(INDEX($A:$AP,ROW(),$B$6)="","",INDEX($A:$AP,ROW(),$B$6))) | AS13: =IF($AR13="","",IF(ISNUMBER($AR13),IF($AR13>=10000000,IFERROR(DATE(INT($AR13/10000),MOD(INT($AR13/100),100),MOD($AR13,100)),""),INT($AR13)),IFERROR(DATE(--LEFT(LEFT(SUBSTITUTE(SUBSTITUTE(SUBSTITUTE(SUBSTITUTE(TRIM($AR13),"-",""),".",""),"/","")," ",""),8),4),--MID(LEFT(SUBSTITUTE(SUBSTITUTE(SUBSTITUTE(SUBSTITUTE(TRIM($AR13),"-",""),".",""),"/","")," ",""),8),5,2),--MID(LEFT(SUBSTITUTE(SUBSTITUTE(SUBSTITUTE(SUBSTITUTE(TRIM($AR13),"-",""),".",""),"/","")," ",""),8),7,2)),""))) | AT13: =IF($AS13="","",IF($F$6="",0,IF(ISNUMBER(INDEX($A:$AP,ROW(),$F$6)),INDEX($A:$AP,ROW(),$F$6),IFERROR(--SUBSTITUTE(SUBSTITUTE(TRIM(INDEX($A:$AP,ROW(),$F$6)),",",""),"원",""),0)))) | AU13: =IF($AS13="","",IF($AX13<>"",SUBSTITUTE(SUBSTITUTE($AX13,"-","")," ",""),"N:"&$AV13)) | AV13: =IF(OR($AS13="",$E$6=""),"",TRIM(INDEX($A:$AP,ROW(),$E$6)&"")) | AW13: =IF($AU13="","",IF(MATCH($AU13,$AU$8:$AU$2007,0)=ROW()-7,MAX($AW$7:$AW12)+1,"")) | AX13: =IF(OR($AS13="",$D$6=""),"",TRIM(INDEX($A:$AP,ROW(),$D$6)&"")) | AY13: =IF($AU13="","",INDEX($AW$8:$AW$2007,MATCH($AU13,$AU$8:$AU$2007,0))) | AZ13: =IF(OR($AS13="",$C$6=""),"",TRIM(INDEX($A:$AP,ROW(),$C$6)&"")) | BA13: =IF($AZ13="","",IF(COUNTIF($AZ$8:$AZ13,$AZ13)>1,1,0))
A14: 2026-05-10 | B14: 20260510-41000 | C14: 2026-05-10 | D14: 2026-05-10 | E14: 999-81-00001 | G14: (주)가온상사 | H14: 김가온 | I14: 가상 주소 | J14: 999-81-10007 | L14: 한결건설(주) | M14: 대표 | N14: 가상 주소 | O14: 3300000 | P14: 3000000 | Q14: 300000 | R14: 세금계산서 | S14: 일반 | T14: 직접발급 | AR14: =IF(OR($A$5="",$B$6="",ROW()<$A$5),"",IF(INDEX($A:$AP,ROW(),$B$6)="","",INDEX($A:$AP,ROW(),$B$6))) | AS14: =IF($AR14="","",IF(ISNUMBER($AR14),IF($AR14>=10000000,IFERROR(DATE(INT($AR14/10000),MOD(INT($AR14/100),100),MOD($AR14,100)),""),INT($AR14)),IFERROR(DATE(--LEFT(LEFT(SUBSTITUTE(SUBSTITUTE(SUBSTITUTE(SUBSTITUTE(TRIM($AR14),"-",""),".",""),"/","")," ",""),8),4),--MID(LEFT(SUBSTITUTE(SUBSTITUTE(SUBSTITUTE(SUBSTITUTE(TRIM($AR14),"-",""),".",""),"/","")," ",""),8),5,2),--MID(LEFT(SUBSTITUTE(SUBSTITUTE(SUBSTITUTE(SUBSTITUTE(TRIM($AR14),"-",""),".",""),"/","")," ",""),8),7,2)),""))) | AT14: =IF($AS14="","",IF($F$6="",0,IF(ISNUMBER(INDEX($A:$AP,ROW(),$F$6)),INDEX($A:$AP,ROW(),$F$6),IFERROR(--SUBSTITUTE(SUBSTITUTE(TRIM(INDEX($A:$AP,ROW(),$F$6)),",",""),"원",""),0)))) | AU14: =IF($AS14="","",IF($AX14<>"",SUBSTITUTE(SUBSTITUTE($AX14,"-","")," ",""),"N:"&$AV14)) | AV14: =IF(OR($AS14="",$E$6=""),"",TRIM(INDEX($A:$AP,ROW(),$E$6)&"")) | AW14: =IF($AU14="","",IF(MATCH($AU14,$AU$8:$AU$2007,0)=ROW()-7,MAX($AW$7:$AW13)+1,"")) | AX14: =IF(OR($AS14="",$D$6=""),"",TRIM(INDEX($A:$AP,ROW(),$D$6)&"")) | AY14: =IF($AU14="","",INDEX($AW$8:$AW$2007,MATCH($AU14,$AU$8:$AU$2007,0))) | AZ14: =IF(OR($AS14="",$C$6=""),"",TRIM(INDEX($A:$AP,ROW(),$C$6)&"")) | BA14: =IF($AZ14="","",IF(COUNTIF($AZ$8:$AZ14,$AZ14)>1,1,0))
A15: 2026-06-01 | B15: 20260601-41001 | C15: 2026-06-01 | D15: 2026-06-01 | E15: 999-81-00001 | G15: (주)가온상사 | H15: 김가온 | I15: 가상 주소 | J15: 999-81-10008 | L15: 소나무상사 | M15: 대표 | N15: 가상 주소 | O15: 440000 | P15: 400000 | Q15: 40000 | R15: 세금계산서 | S15: 일반 | T15: 직접발급 | AR15: =IF(OR($A$5="",$B$6="",ROW()<$A$5),"",IF(INDEX($A:$AP,ROW(),$B$6)="","",INDEX($A:$AP,ROW(),$B$6))) | AS15: =IF($AR15="","",IF(ISNUMBER($AR15),IF($AR15>=10000000,IFERROR(DATE(INT($AR15/10000),MOD(INT($AR15/100),100),MOD($AR15,100)),""),INT($AR15)),IFERROR(DATE(--LEFT(LEFT(SUBSTITUTE(SUBSTITUTE(SUBSTITUTE(SUBSTITUTE(TRIM($AR15),"-",""),".",""),"/","")," ",""),8),4),--MID(LEFT(SUBSTITUTE(SUBSTITUTE(SUBSTITUTE(SUBSTITUTE(TRIM($AR15),"-",""),".",""),"/","")," ",""),8),5,2),--MID(LEFT(SUBSTITUTE(SUBSTITUTE(SUBSTITUTE(SUBSTITUTE(TRIM($AR15),"-",""),".",""),"/","")," ",""),8),7,2)),""))) | AT15: =IF($AS15="","",IF($F$6="",0,IF(ISNUMBER(INDEX($A:$AP,ROW(),$F$6)),INDEX($A:$AP,ROW(),$F$6),IFERROR(--SUBSTITUTE(SUBSTITUTE(TRIM(INDEX($A:$AP,ROW(),$F$6)),",",""),"원",""),0)))) | AU15: =IF($AS15="","",IF($AX15<>"",SUBSTITUTE(SUBSTITUTE($AX15,"-","")," ",""),"N:"&$AV15)) | AV15: =IF(OR($AS15="",$E$6=""),"",TRIM(INDEX($A:$AP,ROW(),$E$6)&"")) | AW15: =IF($AU15="","",IF(MATCH($AU15,$AU$8:$AU$2007,0)=ROW()-7,MAX($AW$7:$AW14)+1,"")) | AX15: =IF(OR($AS15="",$D$6=""),"",TRIM(INDEX($A:$AP,ROW(),$D$6)&"")) | AY15: =IF($AU15="","",INDEX($AW$8:$AW$2007,MATCH($AU15,$AU$8:$AU$2007,0))) | AZ15: =IF(OR($AS15="",$C$6=""),"",TRIM(INDEX($A:$AP,ROW(),$C$6)&"")) | BA15: =IF($AZ15="","",IF(COUNTIF($AZ$8:$AZ15,$AZ15)>1,1,0))
A16: 2026-06-30 | B16: 20260630-41002 | C16: 2026-06-30 | D16: 2026-06-30 | E16: 999-81-00001 | G16: (주)가온상사 | H16: 김가온 | I16: 가상 주소 | J16: 999-81-10001 | L16: (주)하늘정밀 | M16: 대표 | N16: 가상 주소 | O16: 4620000 | P16: 4200000 | Q16: 420000 | R16: 세금계산서 | S16: 일반 | T16: 직접발급 | AR16: =IF(OR($A$5="",$B$6="",ROW()<$A$5),"",IF(INDEX($A:$AP,ROW(),$B$6)="","",INDEX($A:$AP,ROW(),$B$6))) | AS16: =IF($AR16="","",IF(ISNUMBER($AR16),IF($AR16>=10000000,IFERROR(DATE(INT($AR16/10000),MOD(INT($AR16/100),100),MOD($AR16,100)),""),INT($AR16)),IFERROR(DATE(--LEFT(LEFT(SUBSTITUTE(SUBSTITUTE(SUBSTITUTE(SUBSTITUTE(TRIM($AR16),"-",""),".",""),"/","")," ",""),8),4),--MID(LEFT(SUBSTITUTE(SUBSTITUTE(SUBSTITUTE(SUBSTITUTE(TRIM($AR16),"-",""),".",""),"/","")," ",""),8),5,2),--MID(LEFT(SUBSTITUTE(SUBSTITUTE(SUBSTITUTE(SUBSTITUTE(TRIM($AR16),"-",""),".",""),"/","")," ",""),8),7,2)),""))) | AT16: =IF($AS16="","",IF($F$6="",0,IF(ISNUMBER(INDEX($A:$AP,ROW(),$F$6)),INDEX($A:$AP,ROW(),$F$6),IFERROR(--SUBSTITUTE(SUBSTITUTE(TRIM(INDEX($A:$AP,ROW(),$F$6)),",",""),"원",""),0)))) | AU16: =IF($AS16="","",IF($AX16<>"",SUBSTITUTE(SUBSTITUTE($AX16,"-","")," ",""),"N:"&$AV16)) | AV16: =IF(OR($AS16="",$E$6=""),"",TRIM(INDEX($A:$AP,ROW(),$E$6)&"")) | AW16: =IF($AU16="","",IF(MATCH($AU16,$AU$8:$AU$2007,0)=ROW()-7,MAX($AW$7:$AW15)+1,"")) | AX16: =IF(OR($AS16="",$D$6=""),"",TRIM(INDEX($A:$AP,ROW(),$D$6)&"")) | AY16: =IF($AU16="","",INDEX($AW$8:$AW$2007,MATCH($AU16,$AU$8:$AU$2007,0))) | AZ16: =IF(OR($AS16="",$C$6=""),"",TRIM(INDEX($A:$AP,ROW(),$C$6)&"")) | BA16: =IF($AZ16="","",IF(COUNTIF($AZ$8:$AZ16,$AZ16)>1,1,0))
A17: 2026-07-01 | B17: 20260701-41003 | C17: 2026-07-01 | D17: 2026-07-01 | E17: 999-81-00001 | G17: (주)가온상사 | H17: 김가온 | I17: 가상 주소 | J17: 999-81-10007 | L17: 한결건설(주) | M17: 대표 | N17: 가상 주소 | O17: 4950000 | P17: 4500000 | Q17: 450000 | R17: 세금계산서 | S17: 일반 | T17: 직접발급 | AR17: =IF(OR($A$5="",$B$6="",ROW()<$A$5),"",IF(INDEX($A:$AP,ROW(),$B$6)="","",INDEX($A:$AP,ROW(),$B$6))) | AS17: =IF($AR17="","",IF(ISNUMBER($AR17),IF($AR17>=10000000,IFERROR(DATE(INT($AR17/10000),MOD(INT($AR17/100),100),MOD($AR17,100)),""),INT($AR17)),IFERROR(DATE(--LEFT(LEFT(SUBSTITUTE(SUBSTITUTE(SUBSTITUTE(SUBSTITUTE(TRIM($AR17),"-",""),".",""),"/","")," ",""),8),4),--MID(LEFT(SUBSTITUTE(SUBSTITUTE(SUBSTITUTE(SUBSTITUTE(TRIM($AR17),"-",""),".",""),"/","")," ",""),8),5,2),--MID(LEFT(SUBSTITUTE(SUBSTITUTE(SUBSTITUTE(SUBSTITUTE(TRIM($AR17),"-",""),".",""),"/","")," ",""),8),7,2)),""))) | AT17: =IF($AS17="","",IF($F$6="",0,IF(ISNUMBER(INDEX($A:$AP,ROW(),$F$6)),INDEX($A:$AP,ROW(),$F$6),IFERROR(--SUBSTITUTE(SUBSTITUTE(TRIM(INDEX($A:$AP,ROW(),$F$6)),",",""),"원",""),0)))) | AU17: =IF($AS17="","",IF($AX17<>"",SUBSTITUTE(SUBSTITUTE($AX17,"-","")," ",""),"N:"&$AV17)) | AV17: =IF(OR($AS17="",$E$6=""),"",TRIM(INDEX($A:$AP,ROW(),$E$6)&"")) | AW17: =IF($AU17="","",IF(MATCH($AU17,$AU$8:$AU$2007,0)=ROW()-7,MAX($AW$7:$AW16)+1,"")) | AX17: =IF(OR($AS17="",$D$6=""),"",TRIM(INDEX($A:$AP,ROW(),$D$6)&"")) | AY17: =IF($AU17="","",INDEX($AW$8:$AW$2007,MATCH($AU17,$AU$8:$AU$2007,0))) | AZ17: =IF(OR($AS17="",$C$6=""),"",TRIM(INDEX($A:$AP,ROW(),$C$6)&"")) | BA17: =IF($AZ17="","",IF(COUNTIF($AZ$8:$AZ17,$AZ17)>1,1,0))
A18: 2026-07-03 | B18: 20260703-41004 | C18: 2026-07-03 | D18: 2026-07-03 | E18: 999-81-00001 | G18: (주)가온상사 | H18: 김가온 | I18: 가상 주소 | J18: 999-81-10003 | L18: 새봄유통(주) | M18: 대표 | N18: 가상 주소 | O18: 6600000 | P18: 6000000 | Q18: 600000 | R18: 세금계산서 | S18: 일반 | T18: 직접발급 | AR18: =IF(OR($A$5="",$B$6="",ROW()<$A$5),"",IF(INDEX($A:$AP,ROW(),$B$6)="","",INDEX($A:$AP,ROW(),$B$6))) | AS18: =IF($AR18="","",IF(ISNUMBER($AR18),IF($AR18>=10000000,IFERROR(DATE(INT($AR18/10000),MOD(INT($AR18/100),100),MOD($AR18,100)),""),INT($AR18)),IFERROR(DATE(--LEFT(LEFT(SUBSTITUTE(SUBSTITUTE(SUBSTITUTE(SUBSTITUTE(TRIM($AR18),"-",""),".",""),"/","")," ",""),8),4),--MID(LEFT(SUBSTITUTE(SUBSTITUTE(SUBSTITUTE(SUBSTITUTE(TRIM($AR18),"-",""),".",""),"/","")," ",""),8),5,2),--MID(LEFT(SUBSTITUTE(SUBSTITUTE(SUBSTITUTE(SUBSTITUTE(TRIM($AR18),"-",""),".",""),"/","")," ",""),8),7,2)),""))) | AT18: =IF($AS18="","",IF($F$6="",0,IF(ISNUMBER(INDEX($A:$AP,ROW(),$F$6)),INDEX($A:$AP,ROW(),$F$6),IFERROR(--SUBSTITUTE(SUBSTITUTE(TRIM(INDEX($A:$AP,ROW(),$F$6)),",",""),"원",""),0)))) | AU18: =IF($AS18="","",IF($AX18<>"",SUBSTITUTE(SUBSTITUTE($AX18,"-","")," ",""),"N:"&$AV18)) | AV18: =IF(OR($AS18="",$E$6=""),"",TRIM(INDEX($A:$AP,ROW(),$E$6)&"")) | AW18: =IF($AU18="","",IF(MATCH($AU18,$AU$8:$AU$2007,0)=ROW()-7,MAX($AW$7:$AW17)+1,"")) | AX18: =IF(OR($AS18="",$D$6=""),"",TRIM(INDEX($A:$AP,ROW(),$D$6)&"")) | AY18: =IF($AU18="","",INDEX($AW$8:$AW$2007,MATCH($AU18,$AU$8:$AU$2007,0))) | AZ18: =IF(OR($AS18="",$C$6=""),"",TRIM(INDEX($A:$AP,ROW(),$C$6)&"")) | BA18: =IF($AZ18="","",IF(COUNTIF($AZ$8:$AZ18,$AZ18)>1,1,0))
A19: 2026-07-15 | B19: 20260715-41005 | C19: 2026-07-15 | D19: 2026-07-15 | E19: 999-81-00001 | G19: (주)가온상사 | H19: 김가온 | I19: 가상 주소 | J19: 999-81-10002 | L19: (주)바람테크 | M19: 대표 | N19: 가상 주소 | O19: 1650000 | P19: 1500000 | Q19: 150000 | R19: 세금계산서 | S19: 일반 | T19: 직접발급 | AR19: =IF(OR($A$5="",$B$6="",ROW()<$A$5),"",IF(INDEX($A:$AP,ROW(),$B$6)="","",INDEX($A:$AP,ROW(),$B$6))) | AS19: =IF($AR19="","",IF(ISNUMBER($AR19),IF($AR19>=10000000,IFERROR(DATE(INT($AR19/10000),MOD(INT($AR19/100),100),MOD($AR19,100)),""),INT($AR19)),IFERROR(DATE(--LEFT(LEFT(SUBSTITUTE(SUBSTITUTE(SUBSTITUTE(SUBSTITUTE(TRIM($AR19),"-",""),".",""),"/","")," ",""),8),4),--MID(LEFT(SUBSTITUTE(SUBSTITUTE(SUBSTITUTE(SUBSTITUTE(TRIM($AR19),"-",""),".",""),"/","")," ",""),8),5,2),--MID(LEFT(SUBSTITUTE(SUBSTITUTE(SUBSTITUTE(SUBSTITUTE(TRIM($AR19),"-",""),".",""),"/","")," ",""),8),7,2)),""))) | AT19: =IF($AS19="","",IF($F$6="",0,IF(ISNUMBER(INDEX($A:$AP,ROW(),$F$6)),INDEX($A:$AP,ROW(),$F$6),IFERROR(--SUBSTITUTE(SUBSTITUTE(TRIM(INDEX($A:$AP,ROW(),$F$6)),",",""),"원",""),0)))) | AU19: =IF($AS19="","",IF($AX19<>"",SUBSTITUTE(SUBSTITUTE($AX19,"-","")," ",""),"N:"&$AV19)) | AV19: =IF(OR($AS19="",$E$6=""),"",TRIM(INDEX($A:$AP,ROW(),$E$6)&"")) | AW19: =IF($AU19="","",IF(MATCH($AU19,$AU$8:$AU$2007,0)=ROW()-7,MAX($AW$7:$AW18)+1,"")) | AX19: =IF(OR($AS19="",$D$6=""),"",TRIM(INDEX($A:$AP,ROW(),$D$6)&"")) | AY19: =IF($AU19="","",INDEX($AW$8:$AW$2007,MATCH($AU19,$AU$8:$AU$2007,0))) | AZ19: =IF(OR($AS19="",$C$6=""),"",TRIM(INDEX($A:$AP,ROW(),$C$6)&"")) | BA19: =IF($AZ19="","",IF(COUNTIF($AZ$8:$AZ19,$AZ19)>1,1,0))
A20: 2026-07-20 | B20: 20260720-41006 | C20: 2026-07-20 | D20: 2026-07-20 | E20: 999-81-00001 | G20: (주)가온상사 | H20: 김가온 | I20: 가상 주소 | J20: 999-81-10005 | L20: 해솔물산 | M20: 대표 | N20: 가상 주소 | O20: 1320000 | P20: 1200000 | Q20: 120000 | R20: 세금계산서 | S20: 일반 | T20: 직접발급 | AR20: =IF(OR($A$5="",$B$6="",ROW()<$A$5),"",IF(INDEX($A:$AP,ROW(),$B$6)="","",INDEX($A:$AP,ROW(),$B$6))) | AS20: =IF($AR20="","",IF(ISNUMBER($AR20),IF($AR20>=10000000,IFERROR(DATE(INT($AR20/10000),MOD(INT($AR20/100),100),MOD($AR20,100)),""),INT($AR20)),IFERROR(DATE(--LEFT(LEFT(SUBSTITUTE(SUBSTITUTE(SUBSTITUTE(SUBSTITUTE(TRIM($AR20),"-",""),".",""),"/","")," ",""),8),4),--MID(LEFT(SUBSTITUTE(SUBSTITUTE(SUBSTITUTE(SUBSTITUTE(TRIM($AR20),"-",""),".",""),"/","")," ",""),8),5,2),--MID(LEFT(SUBSTITUTE(SUBSTITUTE(SUBSTITUTE(SUBSTITUTE(TRIM($AR20),"-",""),".",""),"/","")," ",""),8),7,2)),""))) | AT20: =IF($AS20="","",IF($F$6="",0,IF(ISNUMBER(INDEX($A:$AP,ROW(),$F$6)),INDEX($A:$AP,ROW(),$F$6),IFERROR(--SUBSTITUTE(SUBSTITUTE(TRIM(INDEX($A:$AP,ROW(),$F$6)),",",""),"원",""),0)))) | AU20: =IF($AS20="","",IF($AX20<>"",SUBSTITUTE(SUBSTITUTE($AX20,"-","")," ",""),"N:"&$AV20)) | AV20: =IF(OR($AS20="",$E$6=""),"",TRIM(INDEX($A:$AP,ROW(),$E$6)&"")) | AW20: =IF($AU20="","",IF(MATCH($AU20,$AU$8:$AU$2007,0)=ROW()-7,MAX($AW$7:$AW19)+1,"")) | AX20: =IF(OR($AS20="",$D$6=""),"",TRIM(INDEX($A:$AP,ROW(),$D$6)&"")) | AY20: =IF($AU20="","",INDEX($AW$8:$AW$2007,MATCH($AU20,$AU$8:$AU$2007,0))) | AZ20: =IF(OR($AS20="",$C$6=""),"",TRIM(INDEX($A:$AP,ROW(),$C$6)&"")) | BA20: =IF($AZ20="","",IF(COUNTIF($AZ$8:$AZ20,$AZ20)>1,1,0))
A21: 2026-08-05 | B21: 20260805-41007 | C21: 2026-08-05 | D21: 2026-08-05 | E21: 999-81-00001 | G21: (주)가온상사 | H21: 김가온 | I21: 가상 주소 | J21: 999-81-10004 | L21: (주)다온산업 | M21: 대표 | N21: 가상 주소 | O21: 7700000 | P21: 7000000 | Q21: 700000 | R21: 세금계산서 | S21: 일반 | T21: 직접발급 | AR21: =IF(OR($A$5="",$B$6="",ROW()<$A$5),"",IF(INDEX($A:$AP,ROW(),$B$6)="","",INDEX($A:$AP,ROW(),$B$6))) | AS21: =IF($AR21="","",IF(ISNUMBER($AR21),IF($AR21>=10000000,IFERROR(DATE(INT($AR21/10000),MOD(INT($AR21/100),100),MOD($AR21,100)),""),INT($AR21)),IFERROR(DATE(--LEFT(LEFT(SUBSTITUTE(SUBSTITUTE(SUBSTITUTE(SUBSTITUTE(TRIM($AR21),"-",""),".",""),"/","")," ",""),8),4),--MID(LEFT(SUBSTITUTE(SUBSTITUTE(SUBSTITUTE(SUBSTITUTE(TRIM($AR21),"-",""),".",""),"/","")," ",""),8),5,2),--MID(LEFT(SUBSTITUTE(SUBSTITUTE(SUBSTITUTE(SUBSTITUTE(TRIM($AR21),"-",""),".",""),"/","")," ",""),8),7,2)),""))) | AT21: =IF($AS21="","",IF($F$6="",0,IF(ISNUMBER(INDEX($A:$AP,ROW(),$F$6)),INDEX($A:$AP,ROW(),$F$6),IFERROR(--SUBSTITUTE(SUBSTITUTE(TRIM(INDEX($A:$AP,ROW(),$F$6)),",",""),"원",""),0)))) | AU21: =IF($AS21="","",IF($AX21<>"",SUBSTITUTE(SUBSTITUTE($AX21,"-","")," ",""),"N:"&$AV21)) | AV21: =IF(OR($AS21="",$E$6=""),"",TRIM(INDEX($A:$AP,ROW(),$E$6)&"")) | AW21: =IF($AU21="","",IF(MATCH($AU21,$AU$8:$AU$2007,0)=ROW()-7,MAX($AW$7:$AW20)+1,"")) | AX21: =IF(OR($AS21="",$D$6=""),"",TRIM(INDEX($A:$AP,ROW(),$D$6)&"")) | AY21: =IF($AU21="","",INDEX($AW$8:$AW$2007,MATCH($AU21,$AU$8:$AU$2007,0))) | AZ21: =IF(OR($AS21="",$C$6=""),"",TRIM(INDEX($A:$AP,ROW(),$C$6)&"")) | BA21: =IF($AZ21="","",IF(COUNTIF($AZ$8:$AZ21,$AZ21)>1,1,0))
A22: 2026-08-10 | B22: 20260810-41008 | C22: 2026-08-10 | D22: 2026-08-10 | E22: 999-81-00001 | G22: (주)가온상사 | H22: 김가온 | I22: 가상 주소 | J22: 999-81-10001 | L22: (주)하늘정밀 | M22: 대표 | N22: 가상 주소 | O22: 3300000 | P22: 3000000 | Q22: 300000 | R22: 세금계산서 | S22: 일반 | T22: 직접발급 | AR22: =IF(OR($A$5="",$B$6="",ROW()<$A$5),"",IF(INDEX($A:$AP,ROW(),$B$6)="","",INDEX($A:$AP,ROW(),$B$6))) | AS22: =IF($AR22="","",IF(ISNUMBER($AR22),IF($AR22>=10000000,IFERROR(DATE(INT($AR22/10000),MOD(INT($AR22/100),100),MOD($AR22,100)),""),INT($AR22)),IFERROR(DATE(--LEFT(LEFT(SUBSTITUTE(SUBSTITUTE(SUBSTITUTE(SUBSTITUTE(TRIM($AR22),"-",""),".",""),"/","")," ",""),8),4),--MID(LEFT(SUBSTITUTE(SUBSTITUTE(SUBSTITUTE(SUBSTITUTE(TRIM($AR22),"-",""),".",""),"/","")," ",""),8),5,2),--MID(LEFT(SUBSTITUTE(SUBSTITUTE(SUBSTITUTE(SUBSTITUTE(TRIM($AR22),"-",""),".",""),"/","")," ",""),8),7,2)),""))) | AT22: =IF($AS22="","",IF($F$6="",0,IF(ISNUMBER(INDEX($A:$AP,ROW(),$F$6)),INDEX($A:$AP,ROW(),$F$6),IFERROR(--SUBSTITUTE(SUBSTITUTE(TRIM(INDEX($A:$AP,ROW(),$F$6)),",",""),"원",""),0)))) | AU22: =IF($AS22="","",IF($AX22<>"",SUBSTITUTE(SUBSTITUTE($AX22,"-","")," ",""),"N:"&$AV22)) | AV22: =IF(OR($AS22="",$E$6=""),"",TRIM(INDEX($A:$AP,ROW(),$E$6)&"")) | AW22: =IF($AU22="","",IF(MATCH($AU22,$AU$8:$AU$2007,0)=ROW()-7,MAX($AW$7:$AW21)+1,"")) | AX22: =IF(OR($AS22="",$D$6=""),"",TRIM(INDEX($A:$AP,ROW(),$D$6)&"")) | AY22: =IF($AU22="","",INDEX($AW$8:$AW$2007,MATCH($AU22,$AU$8:$AU$2007,0))) | AZ22: =IF(OR($AS22="",$C$6=""),"",TRIM(INDEX($A:$AP,ROW(),$C$6)&"")) | BA22: =IF($AZ22="","",IF(COUNTIF($AZ$8:$AZ22,$AZ22)>1,1,0))
A23: 2026-08-20 | B23: 20260820-41009 | C23: 2026-08-20 | D23: 2026-08-20 | E23: 999-81-00001 | G23: (주)가온상사 | H23: 김가온 | I23: 가상 주소 | J23: 999-81-10003 | L23: 새봄유통(주) | M23: 대표 | N23: 가상 주소 | O23: 4400000 | P23: 4000000 | Q23: 400000 | R23: 세금계산서 | S23: 일반 | T23: 직접발급 | AR23: =IF(OR($A$5="",$B$6="",ROW()<$A$5),"",IF(INDEX($A:$AP,ROW(),$B$6)="","",INDEX($A:$AP,ROW(),$B$6))) | AS23: =IF($AR23="","",IF(ISNUMBER($AR23),IF($AR23>=10000000,IFERROR(DATE(INT($AR23/10000),MOD(INT($AR23/100),100),MOD($AR23,100)),""),INT($AR23)),IFERROR(DATE(--LEFT(LEFT(SUBSTITUTE(SUBSTITUTE(SUBSTITUTE(SUBSTITUTE(TRIM($AR23),"-",""),".",""),"/","")," ",""),8),4),--MID(LEFT(SUBSTITUTE(SUBSTITUTE(SUBSTITUTE(SUBSTITUTE(TRIM($AR23),"-",""),".",""),"/","")," ",""),8),5,2),--MID(LEFT(SUBSTITUTE(SUBSTITUTE(SUBSTITUTE(SUBSTITUTE(TRIM($AR23),"-",""),".",""),"/","")," ",""),8),7,2)),""))) | AT23: =IF($AS23="","",IF($F$6="",0,IF(ISNUMBER(INDEX($A:$AP,ROW(),$F$6)),INDEX($A:$AP,ROW(),$F$6),IFERROR(--SUBSTITUTE(SUBSTITUTE(TRIM(INDEX($A:$AP,ROW(),$F$6)),",",""),"원",""),0)))) | AU23: =IF($AS23="","",IF($AX23<>"",SUBSTITUTE(SUBSTITUTE($AX23,"-","")," ",""),"N:"&$AV23)) | AV23: =IF(OR($AS23="",$E$6=""),"",TRIM(INDEX($A:$AP,ROW(),$E$6)&"")) | AW23: =IF($AU23="","",IF(MATCH($AU23,$AU$8:$AU$2007,0)=ROW()-7,MAX($AW$7:$AW22)+1,"")) | AX23: =IF(OR($AS23="",$D$6=""),"",TRIM(INDEX($A:$AP,ROW(),$D$6)&"")) | AY23: =IF($AU23="","",INDEX($AW$8:$AW$2007,MATCH($AU23,$AU$8:$AU$2007,0))) | AZ23: =IF(OR($AS23="",$C$6=""),"",TRIM(INDEX($A:$AP,ROW(),$C$6)&"")) | BA23: =IF($AZ23="","",IF(COUNTIF($AZ$8:$AZ23,$AZ23)>1,1,0))
A24: 2026-09-01 | B24: 20260901-41010 | C24: 2026-09-01 | D24: 2026-09-01 | E24: 999-81-00001 | G24: (주)가온상사 | H24: 김가온 | I24: 가상 주소 | J24: 999-81-10005 | L24: 해솔물산 | M24: 대표 | N24: 가상 주소 | O24: 1320000 | P24: 1200000 | Q24: 120000 | R24: 세금계산서 | S24: 일반 | T24: 직접발급 | AR24: =IF(OR($A$5="",$B$6="",ROW()<$A$5),"",IF(INDEX($A:$AP,ROW(),$B$6)="","",INDEX($A:$AP,ROW(),$B$6))) | AS24: =IF($AR24="","",IF(ISNUMBER($AR24),IF($AR24>=10000000,IFERROR(DATE(INT($AR24/10000),MOD(INT($AR24/100),100),MOD($AR24,100)),""),INT($AR24)),IFERROR(DATE(--LEFT(LEFT(SUBSTITUTE(SUBSTITUTE(SUBSTITUTE(SUBSTITUTE(TRIM($AR24),"-",""),".",""),"/","")," ",""),8),4),--MID(LEFT(SUBSTITUTE(SUBSTITUTE(SUBSTITUTE(SUBSTITUTE(TRIM($AR24),"-",""),".",""),"/","")," ",""),8),5,2),--MID(LEFT(SUBSTITUTE(SUBSTITUTE(SUBSTITUTE(SUBSTITUTE(TRIM($AR24),"-",""),".",""),"/","")," ",""),8),7,2)),""))) | AT24: =IF($AS24="","",IF($F$6="",0,IF(ISNUMBER(INDEX($A:$AP,ROW(),$F$6)),INDEX($A:$AP,ROW(),$F$6),IFERROR(--SUBSTITUTE(SUBSTITUTE(TRIM(INDEX($A:$AP,ROW(),$F$6)),",",""),"원",""),0)))) | AU24: =IF($AS24="","",IF($AX24<>"",SUBSTITUTE(SUBSTITUTE($AX24,"-","")," ",""),"N:"&$AV24)) | AV24: =IF(OR($AS24="",$E$6=""),"",TRIM(INDEX($A:$AP,ROW(),$E$6)&"")) | AW24: =IF($AU24="","",IF(MATCH($AU24,$AU$8:$AU$2007,0)=ROW()-7,MAX($AW$7:$AW23)+1,"")) | AX24: =IF(OR($AS24="",$D$6=""),"",TRIM(INDEX($A:$AP,ROW(),$D$6)&"")) | AY24: =IF($AU24="","",INDEX($AW$8:$AW$2007,MATCH($AU24,$AU$8:$AU$2007,0))) | AZ24: =IF(OR($AS24="",$C$6=""),"",TRIM(INDEX($A:$AP,ROW(),$C$6)&"")) | BA24: =IF($AZ24="","",IF(COUNTIF($AZ$8:$AZ24,$AZ24)>1,1,0))
A25: 2026-09-05 | B25: 20260905-41011 | C25: 2026-09-05 | D25: 2026-09-05 | E25: 999-81-00001 | G25: (주)가온상사 | H25: 김가온 | I25: 가상 주소 | J25: 999-81-10002 | L25: (주)바람테크 | M25: 대표 | N25: 가상 주소 | O25: 2750000 | P25: 2500000 | Q25: 250000 | R25: 세금계산서 | S25: 일반 | T25: 직접발급 | AR25: =IF(OR($A$5="",$B$6="",ROW()<$A$5),"",IF(INDEX($A:$AP,ROW(),$B$6)="","",INDEX($A:$AP,ROW(),$B$6))) | AS25: =IF($AR25="","",IF(ISNUMBER($AR25),IF($AR25>=10000000,IFERROR(DATE(INT($AR25/10000),MOD(INT($AR25/100),100),MOD($AR25,100)),""),INT($AR25)),IFERROR(DATE(--LEFT(LEFT(SUBSTITUTE(SUBSTITUTE(SUBSTITUTE(SUBSTITUTE(TRIM($AR25),"-",""),".",""),"/","")," ",""),8),4),--MID(LEFT(SUBSTITUTE(SUBSTITUTE(SUBSTITUTE(SUBSTITUTE(TRIM($AR25),"-",""),".",""),"/","")," ",""),8),5,2),--MID(LEFT(SUBSTITUTE(SUBSTITUTE(SUBSTITUTE(SUBSTITUTE(TRIM($AR25),"-",""),".",""),"/","")," ",""),8),7,2)),""))) | AT25: =IF($AS25="","",IF($F$6="",0,IF(ISNUMBER(INDEX($A:$AP,ROW(),$F$6)),INDEX($A:$AP,ROW(),$F$6),IFERROR(--SUBSTITUTE(SUBSTITUTE(TRIM(INDEX($A:$AP,ROW(),$F$6)),",",""),"원",""),0)))) | AU25: =IF($AS25="","",IF($AX25<>"",SUBSTITUTE(SUBSTITUTE($AX25,"-","")," ",""),"N:"&$AV25)) | AV25: =IF(OR($AS25="",$E$6=""),"",TRIM(INDEX($A:$AP,ROW(),$E$6)&"")) | AW25: =IF($AU25="","",IF(MATCH($AU25,$AU$8:$AU$2007,0)=ROW()-7,MAX($AW$7:$AW24)+1,"")) | AX25: =IF(OR($AS25="",$D$6=""),"",TRIM(INDEX($A:$AP,ROW(),$D$6)&"")) | AY25: =IF($AU25="","",INDEX($AW$8:$AW$2007,MATCH($AU25,$AU$8:$AU$2007,0))) | AZ25: =IF(OR($AS25="",$C$6=""),"",TRIM(INDEX($A:$AP,ROW(),$C$6)&"")) | BA25: =IF($AZ25="","",IF(COUNTIF($AZ$8:$AZ25,$AZ25)>1,1,0))
... A33: 2026-10-20 | B33: 20261020-41019 | C33: 2026-10-20 | D33: 2026-10-20 | E33: 999-81-00001 | G33: (주)가온상사 | H33: 김가온 | I33: 가상 주소 | J33: 999-81-10002 | L33: (주)바람테크 | M33: 대표 | N33: 가상 주소 | O33: 1100000 | P33: 1000000 | Q33: 100000 | R33: 세금계산서 | S33: 일반 | T33: 직접발급 | AR33: =IF(OR($A$5="",$B$6="",ROW()<$A$5),"",IF(INDEX($A:$AP,ROW(),$B$6)="","",INDEX($A:$AP,ROW(),$B$6))) | AS33: =IF($AR33="","",IF(ISNUMBER($AR33),IF($AR33>=10000000,IFERROR(DATE(INT($AR33/10000),MOD(INT($AR33/100),100),MOD($AR33,100)),""),INT($AR33)),IFERROR(DATE(--LEFT(LEFT(SUBSTITUTE(SUBSTITUTE(SUBSTITUTE(SUBSTITUTE(TRIM($AR33),"-",""),".",""),"/","")," ",""),8),4),--MID(LEFT(SUBSTITUTE(SUBSTITUTE(SUBSTITUTE(SUBSTITUTE(TRIM($AR33),"-",""),".",""),"/","")," ",""),8),5,2),--MID(LEFT(SUBSTITUTE(SUBSTITUTE(SUBSTITUTE(SUBSTITUTE(TRIM($AR33),"-",""),".",""),"/","")," ",""),8),7,2)),""))) | AT33: =IF($AS33="","",IF($F$6="",0,IF(ISNUMBER(INDEX($A:$AP,ROW(),$F$6)),INDEX($A:$AP,ROW(),$F$6),IFERROR(--SUBSTITUTE(SUBSTITUTE(TRIM(INDEX($A:$AP,ROW(),$F$6)),",",""),"원",""),0)))) | AU33: =IF($AS33="","",IF($AX33<>"",SUBSTITUTE(SUBSTITUTE($AX33,"-","")," ",""),"N:"&$AV33)) | AV33: =IF(OR($AS33="",$E$6=""),"",TRIM(INDEX($A:$AP,ROW(),$E$6)&"")) | AW33: =IF($AU33="","",IF(MATCH($AU33,$AU$8:$AU$2007,0)=ROW()-7,MAX($AW$7:$AW32)+1,"")) | AX33: =IF(OR($AS33="",$D$6=""),"",TRIM(INDEX($A:$AP,ROW(),$D$6)&"")) | AY33: =IF($AU33="","",INDEX($AW$8:$AW$2007,MATCH($AU33,$AU$8:$AU$2007,0))) | AZ33: =IF(OR($AS33="",$C$6=""),"",TRIM(INDEX($A:$AP,ROW(),$C$6)&"")) | BA33: =IF($AZ33="","",IF(COUNTIF($AZ$8:$AZ33,$AZ33)>1,1,0))
AR34: =IF(OR($A$5="",$B$6="",ROW()<$A$5),"",IF(INDEX($A:$AP,ROW(),$B$6)="","",INDEX($A:$AP,ROW(),$B$6))) | AS34: =IF($AR34="","",IF(ISNUMBER($AR34),IF($AR34>=10000000,IFERROR(DATE(INT($AR34/10000),MOD(INT($AR34/100),100),MOD($AR34,100)),""),INT($AR34)),IFERROR(DATE(--LEFT(LEFT(SUBSTITUTE(SUBSTITUTE(SUBSTITUTE(SUBSTITUTE(TRIM($AR34),"-",""),".",""),"/","")," ",""),8),4),--MID(LEFT(SUBSTITUTE(SUBSTITUTE(SUBSTITUTE(SUBSTITUTE(TRIM($AR34),"-",""),".",""),"/","")," ",""),8),5,2),--MID(LEFT(SUBSTITUTE(SUBSTITUTE(SUBSTITUTE(SUBSTITUTE(TRIM($AR34),"-",""),".",""),"/","")," ",""),8),7,2)),""))) | AT34: =IF($AS34="","",IF($F$6="",0,IF(ISNUMBER(INDEX($A:$AP,ROW(),$F$6)),INDEX($A:$AP,ROW(),$F$6),IFERROR(--SUBSTITUTE(SUBSTITUTE(TRIM(INDEX($A:$AP,ROW(),$F$6)),",",""),"원",""),0)))) | AU34: =IF($AS34="","",IF($AX34<>"",SUBSTITUTE(SUBSTITUTE($AX34,"-","")," ",""),"N:"&$AV34)) | AV34: =IF(OR($AS34="",$E$6=""),"",TRIM(INDEX($A:$AP,ROW(),$E$6)&"")) | AW34: =IF($AU34="","",IF(MATCH($AU34,$AU$8:$AU$2007,0)=ROW()-7,MAX($AW$7:$AW33)+1,"")) | AX34: =IF(OR($AS34="",$D$6=""),"",TRIM(INDEX($A:$AP,ROW(),$D$6)&"")) | AY34: =IF($AU34="","",INDEX($AW$8:$AW$2007,MATCH($AU34,$AU$8:$AU$2007,0))) | AZ34: =IF(OR($AS34="",$C$6=""),"",TRIM(INDEX($A:$AP,ROW(),$C$6)&"")) | BA34: =IF($AZ34="","",IF(COUNTIF($AZ$8:$AZ34,$AZ34)>1,1,0))
AR35: =IF(OR($A$5="",$B$6="",ROW()<$A$5),"",IF(INDEX($A:$AP,ROW(),$B$6)="","",INDEX($A:$AP,ROW(),$B$6))) | AS35: =IF($AR35="","",IF(ISNUMBER($AR35),IF($AR35>=10000000,IFERROR(DATE(INT($AR35/10000),MOD(INT($AR35/100),100),MOD($AR35,100)),""),INT($AR35)),IFERROR(DATE(--LEFT(LEFT(SUBSTITUTE(SUBSTITUTE(SUBSTITUTE(SUBSTITUTE(TRIM($AR35),"-",""),".",""),"/","")," ",""),8),4),--MID(LEFT(SUBSTITUTE(SUBSTITUTE(SUBSTITUTE(SUBSTITUTE(TRIM($AR35),"-",""),".",""),"/","")," ",""),8),5,2),--MID(LEFT(SUBSTITUTE(SUBSTITUTE(SUBSTITUTE(SUBSTITUTE(TRIM($AR35),"-",""),".",""),"/","")," ",""),8),7,2)),""))) | AT35: =IF($AS35="","",IF($F$6="",0,IF(ISNUMBER(INDEX($A:$AP,ROW(),$F$6)),INDEX($A:$AP,ROW(),$F$6),IFERROR(--SUBSTITUTE(SUBSTITUTE(TRIM(INDEX($A:$AP,ROW(),$F$6)),",",""),"원",""),0)))) | AU35: =IF($AS35="","",IF($AX35<>"",SUBSTITUTE(SUBSTITUTE($AX35,"-","")," ",""),"N:"&$AV35)) | AV35: =IF(OR($AS35="",$E$6=""),"",TRIM(INDEX($A:$AP,ROW(),$E$6)&"")) | AW35: =IF($AU35="","",IF(MATCH($AU35,$AU$8:$AU$2007,0)=ROW()-7,MAX($AW$7:$AW34)+1,"")) | AX35: =IF(OR($AS35="",$D$6=""),"",TRIM(INDEX($A:$AP,ROW(),$D$6)&"")) | AY35: =IF($AU35="","",INDEX($AW$8:$AW$2007,MATCH($AU35,$AU$8:$AU$2007,0))) | AZ35: =IF(OR($AS35="",$C$6=""),"",TRIM(INDEX($A:$AP,ROW(),$C$6)&"")) | BA35: =IF($AZ35="","",IF(COUNTIF($AZ$8:$AZ35,$AZ35)>1,1,0))
AR36: =IF(OR($A$5="",$B$6="",ROW()<$A$5),"",IF(INDEX($A:$AP,ROW(),$B$6)="","",INDEX($A:$AP,ROW(),$B$6))) | AS36: =IF($AR36="","",IF(ISNUMBER($AR36),IF($AR36>=10000000,IFERROR(DATE(INT($AR36/10000),MOD(INT($AR36/100),100),MOD($AR36,100)),""),INT($AR36)),IFERROR(DATE(--LEFT(LEFT(SUBSTITUTE(SUBSTITUTE(SUBSTITUTE(SUBSTITUTE(TRIM($AR36),"-",""),".",""),"/","")," ",""),8),4),--MID(LEFT(SUBSTITUTE(SUBSTITUTE(SUBSTITUTE(SUBSTITUTE(TRIM($AR36),"-",""),".",""),"/","")," ",""),8),5,2),--MID(LEFT(SUBSTITUTE(SUBSTITUTE(SUBSTITUTE(SUBSTITUTE(TRIM($AR36),"-",""),".",""),"/","")," ",""),8),7,2)),""))) | AT36: =IF($AS36="","",IF($F$6="",0,IF(ISNUMBER(INDEX($A:$AP,ROW(),$F$6)),INDEX($A:$AP,ROW(),$F$6),IFERROR(--SUBSTITUTE(SUBSTITUTE(TRIM(INDEX($A:$AP,ROW(),$F$6)),",",""),"원",""),0)))) | AU36: =IF($AS36="","",IF($AX36<>"",SUBSTITUTE(SUBSTITUTE($AX36,"-","")," ",""),"N:"&$AV36)) | AV36: =IF(OR($AS36="",$E$6=""),"",TRIM(INDEX($A:$AP,ROW(),$E$6)&"")) | AW36: =IF($AU36="","",IF(MATCH($AU36,$AU$8:$AU$2007,0)=ROW()-7,MAX($AW$7:$AW35)+1,"")) | AX36: =IF(OR($AS36="",$D$6=""),"",TRIM(INDEX($A:$AP,ROW(),$D$6)&"")) | AY36: =IF($AU36="","",INDEX($AW$8:$AW$2007,MATCH($AU36,$AU$8:$AU$2007,0))) | AZ36: =IF(OR($AS36="",$C$6=""),"",TRIM(INDEX($A:$AP,ROW(),$C$6)&"")) | BA36: =IF($AZ36="","",IF(COUNTIF($AZ$8:$AZ36,$AZ36)>1,1,0))
AR37: =IF(OR($A$5="",$B$6="",ROW()<$A$5),"",IF(INDEX($A:$AP,ROW(),$B$6)="","",INDEX($A:$AP,ROW(),$B$6))) | AS37: =IF($AR37="","",IF(ISNUMBER($AR37),IF($AR37>=10000000,IFERROR(DATE(INT($AR37/10000),MOD(INT($AR37/100),100),MOD($AR37,100)),""),INT($AR37)),IFERROR(DATE(--LEFT(LEFT(SUBSTITUTE(SUBSTITUTE(SUBSTITUTE(SUBSTITUTE(TRIM($AR37),"-",""),".",""),"/","")," ",""),8),4),--MID(LEFT(SUBSTITUTE(SUBSTITUTE(SUBSTITUTE(SUBSTITUTE(TRIM($AR37),"-",""),".",""),"/","")," ",""),8),5,2),--MID(LEFT(SUBSTITUTE(SUBSTITUTE(SUBSTITUTE(SUBSTITUTE(TRIM($AR37),"-",""),".",""),"/","")," ",""),8),7,2)),""))) | AT37: =IF($AS37="","",IF($F$6="",0,IF(ISNUMBER(INDEX($A:$AP,ROW(),$F$6)),INDEX($A:$AP,ROW(),$F$6),IFERROR(--SUBSTITUTE(SUBSTITUTE(TRIM(INDEX($A:$AP,ROW(),$F$6)),",",""),"원",""),0)))) | AU37: =IF($AS37="","",IF($AX37<>"",SUBSTITUTE(SUBSTITUTE($AX37,"-","")," ",""),"N:"&$AV37)) | AV37: =IF(OR($AS37="",$E$6=""),"",TRIM(INDEX($A:$AP,ROW(),$E$6)&"")) | AW37: =IF($AU37="","",IF(MATCH($AU37,$AU$8:$AU$2007,0)=ROW()-7,MAX($AW$7:$AW36)+1,"")) | AX37: =IF(OR($AS37="",$D$6=""),"",TRIM(INDEX($A:$AP,ROW(),$D$6)&"")) | AY37: =IF($AU37="","",INDEX($AW$8:$AW$2007,MATCH($AU37,$AU$8:$AU$2007,0))) | AZ37: =IF(OR($AS37="",$C$6=""),"",TRIM(INDEX($A:$AP,ROW(),$C$6)&"")) | BA37: =IF($AZ37="","",IF(COUNTIF($AZ$8:$AZ37,$AZ37)>1,1,0))
AR38: =IF(OR($A$5="",$B$6="",ROW()<$A$5),"",IF(INDEX($A:$AP,ROW(),$B$6)="","",INDEX($A:$AP,ROW(),$B$6))) | AS38: =IF($AR38="","",IF(ISNUMBER($AR38),IF($AR38>=10000000,IFERROR(DATE(INT($AR38/10000),MOD(INT($AR38/100),100),MOD($AR38,100)),""),INT($AR38)),IFERROR(DATE(--LEFT(LEFT(SUBSTITUTE(SUBSTITUTE(SUBSTITUTE(SUBSTITUTE(TRIM($AR38),"-",""),".",""),"/","")," ",""),8),4),--MID(LEFT(SUBSTITUTE(SUBSTITUTE(SUBSTITUTE(SUBSTITUTE(TRIM($AR38),"-",""),".",""),"/","")," ",""),8),5,2),--MID(LEFT(SUBSTITUTE(SUBSTITUTE(SUBSTITUTE(SUBSTITUTE(TRIM($AR38),"-",""),".",""),"/","")," ",""),8),7,2)),""))) | AT38: =IF($AS38="","",IF($F$6="",0,IF(ISNUMBER(INDEX($A:$AP,ROW(),$F$6)),INDEX($A:$AP,ROW(),$F$6),IFERROR(--SUBSTITUTE(SUBSTITUTE(TRIM(INDEX($A:$AP,ROW(),$F$6)),",",""),"원",""),0)))) | AU38: =IF($AS38="","",IF($AX38<>"",SUBSTITUTE(SUBSTITUTE($AX38,"-","")," ",""),"N:"&$AV38)) | AV38: =IF(OR($AS38="",$E$6=""),"",TRIM(INDEX($A:$AP,ROW(),$E$6)&"")) | AW38: =IF($AU38="","",IF(MATCH($AU38,$AU$8:$AU$2007,0)=ROW()-7,MAX($AW$7:$AW37)+1,"")) | AX38: =IF(OR($AS38="",$D$6=""),"",TRIM(INDEX($A:$AP,ROW(),$D$6)&"")) | AY38: =IF($AU38="","",INDEX($AW$8:$AW$2007,MATCH($AU38,$AU$8:$AU$2007,0))) | AZ38: =IF(OR($AS38="",$C$6=""),"",TRIM(INDEX($A:$AP,ROW(),$C$6)&"")) | BA38: =IF($AZ38="","",IF(COUNTIF($AZ$8:$AZ38,$AZ38)>1,1,0))
AR39: =IF(OR($A$5="",$B$6="",ROW()<$A$5),"",IF(INDEX($A:$AP,ROW(),$B$6)="","",INDEX($A:$AP,ROW(),$B$6))) | AS39: =IF($AR39="","",IF(ISNUMBER($AR39),IF($AR39>=10000000,IFERROR(DATE(INT($AR39/10000),MOD(INT($AR39/100),100),MOD($AR39,100)),""),INT($AR39)),IFERROR(DATE(--LEFT(LEFT(SUBSTITUTE(SUBSTITUTE(SUBSTITUTE(SUBSTITUTE(TRIM($AR39),"-",""),".",""),"/","")," ",""),8),4),--MID(LEFT(SUBSTITUTE(SUBSTITUTE(SUBSTITUTE(SUBSTITUTE(TRIM($AR39),"-",""),".",""),"/","")," ",""),8),5,2),--MID(LEFT(SUBSTITUTE(SUBSTITUTE(SUBSTITUTE(SUBSTITUTE(TRIM($AR39),"-",""),".",""),"/","")," ",""),8),7,2)),""))) | AT39: =IF($AS39="","",IF($F$6="",0,IF(ISNUMBER(INDEX($A:$AP,ROW(),$F$6)),INDEX($A:$AP,ROW(),$F$6),IFERROR(--SUBSTITUTE(SUBSTITUTE(TRIM(INDEX($A:$AP,ROW(),$F$6)),",",""),"원",""),0)))) | AU39: =IF($AS39="","",IF($AX39<>"",SUBSTITUTE(SUBSTITUTE($AX39,"-","")," ",""),"N:"&$AV39)) | AV39: =IF(OR($AS39="",$E$6=""),"",TRIM(INDEX($A:$AP,ROW(),$E$6)&"")) | AW39: =IF($AU39="","",IF(MATCH($AU39,$AU$8:$AU$2007,0)=ROW()-7,MAX($AW$7:$AW38)+1,"")) | AX39: =IF(OR($AS39="",$D$6=""),"",TRIM(INDEX($A:$AP,ROW(),$D$6)&"")) | AY39: =IF($AU39="","",INDEX($AW$8:$AW$2007,MATCH($AU39,$AU$8:$AU$2007,0))) | AZ39: =IF(OR($AS39="",$C$6=""),"",TRIM(INDEX($A:$AP,ROW(),$C$6)&"")) | BA39: =IF($AZ39="","",IF(COUNTIF($AZ$8:$AZ39,$AZ39)>1,1,0))
AR40: =IF(OR($A$5="",$B$6="",ROW()<$A$5),"",IF(INDEX($A:$AP,ROW(),$B$6)="","",INDEX($A:$AP,ROW(),$B$6))) | AS40: =IF($AR40="","",IF(ISNUMBER($AR40),IF($AR40>=10000000,IFERROR(DATE(INT($AR40/10000),MOD(INT($AR40/100),100),MOD($AR40,100)),""),INT($AR40)),IFERROR(DATE(--LEFT(LEFT(SUBSTITUTE(SUBSTITUTE(SUBSTITUTE(SUBSTITUTE(TRIM($AR40),"-",""),".",""),"/","")," ",""),8),4),--MID(LEFT(SUBSTITUTE(SUBSTITUTE(SUBSTITUTE(SUBSTITUTE(TRIM($AR40),"-",""),".",""),"/","")," ",""),8),5,2),--MID(LEFT(SUBSTITUTE(SUBSTITUTE(SUBSTITUTE(SUBSTITUTE(TRIM($AR40),"-",""),".",""),"/","")," ",""),8),7,2)),""))) | AT40: =IF($AS40="","",IF($F$6="",0,IF(ISNUMBER(INDEX($A:$AP,ROW(),$F$6)),INDEX($A:$AP,ROW(),$F$6),IFERROR(--SUBSTITUTE(SUBSTITUTE(TRIM(INDEX($A:$AP,ROW(),$F$6)),",",""),"원",""),0)))) | AU40: =IF($AS40="","",IF($AX40<>"",SUBSTITUTE(SUBSTITUTE($AX40,"-","")," ",""),"N:"&$AV40)) | AV40: =IF(OR($AS40="",$E$6=""),"",TRIM(INDEX($A:$AP,ROW(),$E$6)&"")) | AW40: =IF($AU40="","",IF(MATCH($AU40,$AU$8:$AU$2007,0)=ROW()-7,MAX($AW$7:$AW39)+1,"")) | AX40: =IF(OR($AS40="",$D$6=""),"",TRIM(INDEX($A:$AP,ROW(),$D$6)&"")) | AY40: =IF($AU40="","",INDEX($AW$8:$AW$2007,MATCH($AU40,$AU$8:$AU$2007,0))) | AZ40: =IF(OR($AS40="",$C$6=""),"",TRIM(INDEX($A:$AP,ROW(),$C$6)&"")) | BA40: =IF($AZ40="","",IF(COUNTIF($AZ$8:$AZ40,$AZ40)>1,1,0))
AR41: =IF(OR($A$5="",$B$6="",ROW()<$A$5),"",IF(INDEX($A:$AP,ROW(),$B$6)="","",INDEX($A:$AP,ROW(),$B$6))) | AS41: =IF($AR41="","",IF(ISNUMBER($AR41),IF($AR41>=10000000,IFERROR(DATE(INT($AR41/10000),MOD(INT($AR41/100),100),MOD($AR41,100)),""),INT($AR41)),IFERROR(DATE(--LEFT(LEFT(SUBSTITUTE(SUBSTITUTE(SUBSTITUTE(SUBSTITUTE(TRIM($AR41),"-",""),".",""),"/","")," ",""),8),4),--MID(LEFT(SUBSTITUTE(SUBSTITUTE(SUBSTITUTE(SUBSTITUTE(TRIM($AR41),"-",""),".",""),"/","")," ",""),8),5,2),--MID(LEFT(SUBSTITUTE(SUBSTITUTE(SUBSTITUTE(SUBSTITUTE(TRIM($AR41),"-",""),".",""),"/","")," ",""),8),7,2)),""))) | AT41: =IF($AS41="","",IF($F$6="",0,IF(ISNUMBER(INDEX($A:$AP,ROW(),$F$6)),INDEX($A:$AP,ROW(),$F$6),IFERROR(--SUBSTITUTE(SUBSTITUTE(TRIM(INDEX($A:$AP,ROW(),$F$6)),",",""),"원",""),0)))) | AU41: =IF($AS41="","",IF($AX41<>"",SUBSTITUTE(SUBSTITUTE($AX41,"-","")," ",""),"N:"&$AV41)) | AV41: =IF(OR($AS41="",$E$6=""),"",TRIM(INDEX($A:$AP,ROW(),$E$6)&"")) | AW41: =IF($AU41="","",IF(MATCH($AU41,$AU$8:$AU$2007,0)=ROW()-7,MAX($AW$7:$AW40)+1,"")) | AX41: =IF(OR($AS41="",$D$6=""),"",TRIM(INDEX($A:$AP,ROW(),$D$6)&"")) | AY41: =IF($AU41="","",INDEX($AW$8:$AW$2007,MATCH($AU41,$AU$8:$AU$2007,0))) | AZ41: =IF(OR($AS41="",$C$6=""),"",TRIM(INDEX($A:$AP,ROW(),$C$6)&"")) | BA41: =IF($AZ41="","",IF(COUNTIF($AZ$8:$AZ41,$AZ41)>1,1,0))
AR42: =IF(OR($A$5="",$B$6="",ROW()<$A$5),"",IF(INDEX($A:$AP,ROW(),$B$6)="","",INDEX($A:$AP,ROW(),$B$6))) | AS42: =IF($AR42="","",IF(ISNUMBER($AR42),IF($AR42>=10000000,IFERROR(DATE(INT($AR42/10000),MOD(INT($AR42/100),100),MOD($AR42,100)),""),INT($AR42)),IFERROR(DATE(--LEFT(LEFT(SUBSTITUTE(SUBSTITUTE(SUBSTITUTE(SUBSTITUTE(TRIM($AR42),"-",""),".",""),"/","")," ",""),8),4),--MID(LEFT(SUBSTITUTE(SUBSTITUTE(SUBSTITUTE(SUBSTITUTE(TRIM($AR42),"-",""),".",""),"/","")," ",""),8),5,2),--MID(LEFT(SUBSTITUTE(SUBSTITUTE(SUBSTITUTE(SUBSTITUTE(TRIM($AR42),"-",""),".",""),"/","")," ",""),8),7,2)),""))) | AT42: =IF($AS42="","",IF($F$6="",0,IF(ISNUMBER(INDEX($A:$AP,ROW(),$F$6)),INDEX($A:$AP,ROW(),$F$6),IFERROR(--SUBSTITUTE(SUBSTITUTE(TRIM(INDEX($A:$AP,ROW(),$F$6)),",",""),"원",""),0)))) | AU42: =IF($AS42="","",IF($AX42<>"",SUBSTITUTE(SUBSTITUTE($AX42,"-","")," ",""),"N:"&$AV42)) | AV42: =IF(OR($AS42="",$E$6=""),"",TRIM(INDEX($A:$AP,ROW(),$E$6)&"")) | AW42: =IF($AU42="","",IF(MATCH($AU42,$AU$8:$AU$2007,0)=ROW()-7,MAX($AW$7:$AW41)+1,"")) | AX42: =IF(OR($AS42="",$D$6=""),"",TRIM(INDEX($A:$AP,ROW(),$D$6)&"")) | AY42: =IF($AU42="","",INDEX($AW$8:$AW$2007,MATCH($AU42,$AU$8:$AU$2007,0))) | AZ42: =IF(OR($AS42="",$C$6=""),"",TRIM(INDEX($A:$AP,ROW(),$C$6)&"")) | BA42: =IF($AZ42="","",IF(COUNTIF($AZ$8:$AZ42,$AZ42)>1,1,0))
AR43: =IF(OR($A$5="",$B$6="",ROW()<$A$5),"",IF(INDEX($A:$AP,ROW(),$B$6)="","",INDEX($A:$AP,ROW(),$B$6))) | AS43: =IF($AR43="","",IF(ISNUMBER($AR43),IF($AR43>=10000000,IFERROR(DATE(INT($AR43/10000),MOD(INT($AR43/100),100),MOD($AR43,100)),""),INT($AR43)),IFERROR(DATE(--LEFT(LEFT(SUBSTITUTE(SUBSTITUTE(SUBSTITUTE(SUBSTITUTE(TRIM($AR43),"-",""),".",""),"/","")," ",""),8),4),--MID(LEFT(SUBSTITUTE(SUBSTITUTE(SUBSTITUTE(SUBSTITUTE(TRIM($AR43),"-",""),".",""),"/","")," ",""),8),5,2),--MID(LEFT(SUBSTITUTE(SUBSTITUTE(SUBSTITUTE(SUBSTITUTE(TRIM($AR43),"-",""),".",""),"/","")," ",""),8),7,2)),""))) | AT43: =IF($AS43="","",IF($F$6="",0,IF(ISNUMBER(INDEX($A:$AP,ROW(),$F$6)),INDEX($A:$AP,ROW(),$F$6),IFERROR(--SUBSTITUTE(SUBSTITUTE(TRIM(INDEX($A:$AP,ROW(),$F$6)),",",""),"원",""),0)))) | AU43: =IF($AS43="","",IF($AX43<>"",SUBSTITUTE(SUBSTITUTE($AX43,"-","")," ",""),"N:"&$AV43)) | AV43: =IF(OR($AS43="",$E$6=""),"",TRIM(INDEX($A:$AP,ROW(),$E$6)&"")) | AW43: =IF($AU43="","",IF(MATCH($AU43,$AU$8:$AU$2007,0)=ROW()-7,MAX($AW$7:$AW42)+1,"")) | AX43: =IF(OR($AS43="",$D$6=""),"",TRIM(INDEX($A:$AP,ROW(),$D$6)&"")) | AY43: =IF($AU43="","",INDEX($AW$8:$AW$2007,MATCH($AU43,$AU$8:$AU$2007,0))) | AZ43: =IF(OR($AS43="",$C$6=""),"",TRIM(INDEX($A:$AP,ROW(),$C$6)&"")) | BA43: =IF($AZ43="","",IF(COUNTIF($AZ$8:$AZ43,$AZ43)>1,1,0))
AR44: =IF(OR($A$5="",$B$6="",ROW()<$A$5),"",IF(INDEX($A:$AP,ROW(),$B$6)="","",INDEX($A:$AP,ROW(),$B$6))) | AS44: =IF($AR44="","",IF(ISNUMBER($AR44),IF($AR44>=10000000,IFERROR(DATE(INT($AR44/10000),MOD(INT($AR44/100),100),MOD($AR44,100)),""),INT($AR44)),IFERROR(DATE(--LEFT(LEFT(SUBSTITUTE(SUBSTITUTE(SUBSTITUTE(SUBSTITUTE(TRIM($AR44),"-",""),".",""),"/","")," ",""),8),4),--MID(LEFT(SUBSTITUTE(SUBSTITUTE(SUBSTITUTE(SUBSTITUTE(TRIM($AR44),"-",""),".",""),"/","")," ",""),8),5,2),--MID(LEFT(SUBSTITUTE(SUBSTITUTE(SUBSTITUTE(SUBSTITUTE(TRIM($AR44),"-",""),".",""),"/","")," ",""),8),7,2)),""))) | AT44: =IF($AS44="","",IF($F$6="",0,IF(ISNUMBER(INDEX($A:$AP,ROW(),$F$6)),INDEX($A:$AP,ROW(),$F$6),IFERROR(--SUBSTITUTE(SUBSTITUTE(TRIM(INDEX($A:$AP,ROW(),$F$6)),",",""),"원",""),0)))) | AU44: =IF($AS44="","",IF($AX44<>"",SUBSTITUTE(SUBSTITUTE($AX44,"-","")," ",""),"N:"&$AV44)) | AV44: =IF(OR($AS44="",$E$6=""),"",TRIM(INDEX($A:$AP,ROW(),$E$6)&"")) | AW44: =IF($AU44="","",IF(MATCH($AU44,$AU$8:$AU$2007,0)=ROW()-7,MAX($AW$7:$AW43)+1,"")) | AX44: =IF(OR($AS44="",$D$6=""),"",TRIM(INDEX($A:$AP,ROW(),$D$6)&"")) | AY44: =IF($AU44="","",INDEX($AW$8:$AW$2007,MATCH($AU44,$AU$8:$AU$2007,0))) | AZ44: =IF(OR($AS44="",$C$6=""),"",TRIM(INDEX($A:$AP,ROW(),$C$6)&"")) | BA44: =IF($AZ44="","",IF(COUNTIF($AZ$8:$AZ44,$AZ44)>1,1,0))
AR45: =IF(OR($A$5="",$B$6="",ROW()<$A$5),"",IF(INDEX($A:$AP,ROW(),$B$6)="","",INDEX($A:$AP,ROW(),$B$6))) | AS45: =IF($AR45="","",IF(ISNUMBER($AR45),IF($AR45>=10000000,IFERROR(DATE(INT($AR45/10000),MOD(INT($AR45/100),100),MOD($AR45,100)),""),INT($AR45)),IFERROR(DATE(--LEFT(LEFT(SUBSTITUTE(SUBSTITUTE(SUBSTITUTE(SUBSTITUTE(TRIM($AR45),"-",""),".",""),"/","")," ",""),8),4),--MID(LEFT(SUBSTITUTE(SUBSTITUTE(SUBSTITUTE(SUBSTITUTE(TRIM($AR45),"-",""),".",""),"/","")," ",""),8),5,2),--MID(LEFT(SUBSTITUTE(SUBSTITUTE(SUBSTITUTE(SUBSTITUTE(TRIM($AR45),"-",""),".",""),"/","")," ",""),8),7,2)),""))) | AT45: =IF($AS45="","",IF($F$6="",0,IF(ISNUMBER(INDEX($A:$AP,ROW(),$F$6)),INDEX($A:$AP,ROW(),$F$6),IFERROR(--SUBSTITUTE(SUBSTITUTE(TRIM(INDEX($A:$AP,ROW(),$F$6)),",",""),"원",""),0)))) | AU45: =IF($AS45="","",IF($AX45<>"",SUBSTITUTE(SUBSTITUTE($AX45,"-","")," ",""),"N:"&$AV45)) | AV45: =IF(OR($AS45="",$E$6=""),"",TRIM(INDEX($A:$AP,ROW(),$E$6)&"")) | AW45: =IF($AU45="","",IF(MATCH($AU45,$AU$8:$AU$2007,0)=ROW()-7,MAX($AW$7:$AW44)+1,"")) | AX45: =IF(OR($AS45="",$D$6=""),"",TRIM(INDEX($A:$AP,ROW(),$D$6)&"")) | AY45: =IF($AU45="","",INDEX($AW$8:$AW$2007,MATCH($AU45,$AU$8:$AU$2007,0))) | AZ45: =IF(OR($AS45="",$C$6=""),"",TRIM(INDEX($A:$AP,ROW(),$C$6)&"")) | BA45: =IF($AZ45="","",IF(COUNTIF($AZ$8:$AZ45,$AZ45)>1,1,0))
... AR2007: =IF(OR($A$5="",$B$6="",ROW()<$A$5),"",IF(INDEX($A:$AP,ROW(),$B$6)="","",INDEX($A:$AP,ROW(),$B$6))) | AS2007: =IF($AR2007="","",IF(ISNUMBER($AR2007),IF($AR2007>=10000000,IFERROR(DATE(INT($AR2007/10000),MOD(INT($AR2007/100),100),MOD($AR2007,100)),""),INT($AR2007)),IFERROR(DATE(--LEFT(LEFT(SUBSTITUTE(SUBSTITUTE(SUBSTITUTE(SUBSTITUTE(TRIM($AR2007),"-",""),".",""),"/","")," ",""),8),4),--MID(LEFT(SUBSTITUTE(SUBSTITUTE(SUBSTITUTE(SUBSTITUTE(TRIM($AR2007),"-",""),".",""),"/","")," ",""),8),5,2),--MID(LEFT(SUBSTITUTE(SUBSTITUTE(SUBSTITUTE(SUBSTITUTE(TRIM($AR2007),"-",""),".",""),"/","")," ",""),8),7,2)),""))) | AT2007: =IF($AS2007="","",IF($F$6="",0,IF(ISNUMBER(INDEX($A:$AP,ROW(),$F$6)),INDEX($A:$AP,ROW(),$F$6),IFERROR(--SUBSTITUTE(SUBSTITUTE(TRIM(INDEX($A:$AP,ROW(),$F$6)),",",""),"원",""),0)))) | AU2007: =IF($AS2007="","",IF($AX2007<>"",SUBSTITUTE(SUBSTITUTE($AX2007,"-","")," ",""),"N:"&$AV2007)) | AV2007: =IF(OR($AS2007="",$E$6=""),"",TRIM(INDEX($A:$AP,ROW(),$E$6)&"")) | AW2007: =IF($AU2007="","",IF(MATCH($AU2007,$AU$8:$AU$2007,0)=ROW()-7,MAX($AW$7:$AW2006)+1,"")) | AX2007: =IF(OR($AS2007="",$D$6=""),"",TRIM(INDEX($A:$AP,ROW(),$D$6)&"")) | AY2007: =IF($AU2007="","",INDEX($AW$8:$AW$2007,MATCH($AU2007,$AU$8:$AU$2007,0))) | AZ2007: =IF(OR($AS2007="",$C$6=""),"",TRIM(INDEX($A:$AP,ROW(),$C$6)&"")) | BA2007: =IF($AZ2007="","",IF(COUNTIF($AZ$8:$AZ2007,$AZ2007)>1,1,0))

Sheet 입금_은행1
A1: 입금_은행1 — 은행 입금내역 붙여넣기 (1번째 계좌)
A2: ✍ 직접 입력: 은행(인터넷뱅킹)에서 내려받은 거래내역 엑셀을 A8 셀부터 통째로 붙여넣고, 5행 노란 칸에 데이터 시작 행과 날짜·입금·보낸 분(내용) 열을 확인하세요. 입금·출금이 섞여 있어도 됩니다.
A3: ⚙ 자동 계산: W~AE열 회색 수식 — 수정 금지. 오른쪽 '인식 결과'가 ✔로 뜨면 성공. 처음 쓸 때: 8행 아래 예시를 전체 선택 → Delete 로 먼저 지우세요. 은행이 한 곳뿐이면 쓰지 않는 쪽은 비워 두세요.
A4: 은행·계좌 이름 | B4: 데이터 시작 행 | C4: 날짜 열 | D4: 입금 열 | E4: 보낸 분·내용 열 1 | F4: 내용 열 2 (선택) | H4: 인식 결과 (자동)
A5: 두리은행 결제계좌 (예시) | B5: 9 | C5: B | D5: E | E5: C | F5: G | H5: =IF(COUNT($Y$8:$Y$2007)=0,"비어 있음 (또는 아직 인식된 거래가 없습니다 — 붙여넣기와 열 설정을 확인하세요)","✔ 거래 "&COUNT($Y$8:$Y$2007)&"건 · 입금 "&COUNTIF($Z$8:$Z$2007,">0")&"건 "&TEXT(SUMIF($Z$8:$Z$2007,">0"),"#,##0")&"원 · 거래처로 매칭 "&COUNTIF($AC$8:$AC$2007,">0")&"건 / 미매칭 "&COUNT($AD$8:$AD$2007)&"건")
A6: ▼ 8행(A8 셀)부터 붙여넣기 | C6: =IF($C$5="","",IF(LEN(TRIM($C$5))=1,CODE(UPPER(TRIM($C$5)))-64,(CODE(UPPER(LEFT(TRIM($C$5),1)))-64)*26+CODE(UPPER(RIGHT(TRIM($C$5),1)))-64)) | D6: =IF($D$5="","",IF(LEN(TRIM($D$5))=1,CODE(UPPER(TRIM($D$5)))-64,(CODE(UPPER(LEFT(TRIM($D$5),1)))-64)*26+CODE(UPPER(RIGHT(TRIM($D$5),1)))-64)) | E6: =IF($E$5="","",IF(LEN(TRIM($E$5))=1,CODE(UPPER(TRIM($E$5)))-64,(CODE(UPPER(LEFT(TRIM($E$5),1)))-64)*26+CODE(UPPER(RIGHT(TRIM($E$5),1)))-64)) | F6: =IF($F$5="","",IF(LEN(TRIM($F$5))=1,CODE(UPPER(TRIM($F$5)))-64,(CODE(UPPER(LEFT(TRIM($F$5),1)))-64)*26+CODE(UPPER(RIGHT(TRIM($F$5),1)))-64)) | H6: =IF(COUNTIF($A$8:$U$2007,"*가상예시*")>0,"⚠ 예시 데이터 "&COUNTIF($A$8:$U$2007,"*가상예시*")&"줄이 남아 있습니다 — 지우고 쓰세요 (8행 아래 전체 선택 → Delete)","")
W7: 원본날짜(자동) | X7: 거래일(자동) | Y7: 날짜(자동) | Z7: 입금액(자동) | AA7: 내용 원문(자동) | AB7: 내용 정리(자동) | AC7: 거래처번호(자동) | AD7: 미매칭순번(자동) | AE7: 날짜수치(자동)
A8: 번호 | B8: 거래일자 | C8: 기재내용 | D8: 찾으신금액 | E8: 맡기신금액 | F8: 거래후잔액 | G8: 메모 | W8: =IF(OR($B$5="",$C$6="",ROW()<$B$5),"",IF(INDEX($A:$U,ROW(),$C$6)="","",INDEX($A:$U,ROW(),$C$6))) | X8: =IF($W8="","",IF(ISNUMBER($W8),IF($W8>=10000000,IFERROR(DATE(INT($W8/10000),MOD(INT($W8/100),100),MOD($W8,100)),""),INT($W8)),IFERROR(DATE(--LEFT(LEFT(SUBSTITUTE(SUBSTITUTE(SUBSTITUTE(SUBSTITUTE(TRIM($W8),"-",""),".",""),"/","")," ",""),8),4),--MID(LEFT(SUBSTITUTE(SUBSTITUTE(SUBSTITUTE(SUBSTITUTE(TRIM($W8),"-",""),".",""),"/","")," ",""),8),5,2),--MID(LEFT(SUBSTITUTE(SUBSTITUTE(SUBSTITUTE(SUBSTITUTE(TRIM($W8),"-",""),".",""),"/","")," ",""),8),7,2)),""))) | Y8: =IF($X8="","",INT($X8)) | Z8: =IF(OR($Y8="",$D$6=""),"",IF(INDEX($A:$U,ROW(),$D$6)="",0,IF(ISNUMBER(INDEX($A:$U,ROW(),$D$6)),INDEX($A:$U,ROW(),$D$6),IFERROR(--SUBSTITUTE(SUBSTITUTE(TRIM(INDEX($A:$U,ROW(),$D$6)),",",""),"원",""),0)))) | AA8: =IF($Y8="","",TRIM(INDEX($A:$U,ROW(),$E$6)&IF($F$6="",""," "&INDEX($A:$U,ROW(),$F$6)))) | AB8: =IF($AA8="","",SUBSTITUTE(SUBSTITUTE(SUBSTITUTE(SUBSTITUTE(SUBSTITUTE(SUBSTITUTE(SUBSTITUTE(SUBSTITUTE(SUBSTITUTE($AA8," ","")," ",""),"(주)",""),"（주）",""),"㈜",""),"주식회사",""),"(유)",""),"（유）",""),"유한회사","")) | AC8: =IF(OR($Y8="",N($Z8)<=0,$AB8=""),0,IFERROR(LOOKUP(2,1/((거래처별!$AC$8:$AC$307<>"")*ISNUMBER(SEARCH(거래처별!$AC$8:$AC$307,$AB8))),거래처별!$A$8:$A$307),IFERROR(LOOKUP(2,1/((거래처별!$AD$8:$AD$307<>"")*ISNUMBER(SEARCH(거래처별!$AD$8:$AD$307,$AB8))),거래처별!$A$8:$A$307),IFERROR(LOOKUP(2,1/((거래처별!$AE$8:$AE$307<>"")*ISNUMBER(SEARCH(거래처별!$AE$8:$AE$307,$AB8))),거래처별!$A$8:$A$307),0)))) | AD8: =IF(AND($Y8<>"",N($Z8)>0,$AC8=0),MAX($AD$7:$AD7)+1,"") | AE8: =IF($Y8="",0,$Y8)
A9: 1 | B9: 2026-07-02 00:00:00 | C9: 소나무상사 | E9: 400,000 | F9: 2,400,000 | G9: 가상예시 | W9: =IF(OR($B$5="",$C$6="",ROW()<$B$5),"",IF(INDEX($A:$U,ROW(),$C$6)="","",INDEX($A:$U,ROW(),$C$6))) | X9: =IF($W9="","",IF(ISNUMBER($W9),IF($W9>=10000000,IFERROR(DATE(INT($W9/10000),MOD(INT($W9/100),100),MOD($W9,100)),""),INT($W9)),IFERROR(DATE(--LEFT(LEFT(SUBSTITUTE(SUBSTITUTE(SUBSTITUTE(SUBSTITUTE(TRIM($W9),"-",""),".",""),"/","")," ",""),8),4),--MID(LEFT(SUBSTITUTE(SUBSTITUTE(SUBSTITUTE(SUBSTITUTE(TRIM($W9),"-",""),".",""),"/","")," ",""),8),5,2),--MID(LEFT(SUBSTITUTE(SUBSTITUTE(SUBSTITUTE(SUBSTITUTE(TRIM($W9),"-",""),".",""),"/","")," ",""),8),7,2)),""))) | Y9: =IF($X9="","",INT($X9)) | Z9: =IF(OR($Y9="",$D$6=""),"",IF(INDEX($A:$U,ROW(),$D$6)="",0,IF(ISNUMBER(INDEX($A:$U,ROW(),$D$6)),INDEX($A:$U,ROW(),$D$6),IFERROR(--SUBSTITUTE(SUBSTITUTE(TRIM(INDEX($A:$U,ROW(),$D$6)),",",""),"원",""),0)))) | AA9: =IF($Y9="","",TRIM(INDEX($A:$U,ROW(),$E$6)&IF($F$6="",""," "&INDEX($A:$U,ROW(),$F$6)))) | AB9: =IF($AA9="","",SUBSTITUTE(SUBSTITUTE(SUBSTITUTE(SUBSTITUTE(SUBSTITUTE(SUBSTITUTE(SUBSTITUTE(SUBSTITUTE(SUBSTITUTE($AA9," ","")," ",""),"(주)",""),"（주）",""),"㈜",""),"주식회사",""),"(유)",""),"（유）",""),"유한회사","")) | AC9: =IF(OR($Y9="",N($Z9)<=0,$AB9=""),0,IFERROR(LOOKUP(2,1/((거래처별!$AC$8:$AC$307<>"")*ISNUMBER(SEARCH(거래처별!$AC$8:$AC$307,$AB9))),거래처별!$A$8:$A$307),IFERROR(LOOKUP(2,1/((거래처별!$AD$8:$AD$307<>"")*ISNUMBER(SEARCH(거래처별!$AD$8:$AD$307,$AB9))),거래처별!$A$8:$A$307),IFERROR(LOOKUP(2,1/((거래처별!$AE$8:$AE$307<>"")*ISNUMBER(SEARCH(거래처별!$AE$8:$AE$307,$AB9))),거래처별!$A$8:$A$307),0)))) | AD9: =IF(AND($Y9<>"",N($Z9)>0,$AC9=0),MAX($AD$7:$AD8)+1,"") | AE9: =IF($Y9="",0,$Y9)
A10: 2 | B10: 2026-07-10 00:00:00 | C10: (주)하늘정밀 | E10: 4,620,000 | F10: 9,000,000 | G10: 가상예시 | W10: =IF(OR($B$5="",$C$6="",ROW()<$B$5),"",IF(INDEX($A:$U,ROW(),$C$6)="","",INDEX($A:$U,ROW(),$C$6))) | X10: =IF($W10="","",IF(ISNUMBER($W10),IF($W10>=10000000,IFERROR(DATE(INT($W10/10000),MOD(INT($W10/100),100),MOD($W10,100)),""),INT($W10)),IFERROR(DATE(--LEFT(LEFT(SUBSTITUTE(SUBSTITUTE(SUBSTITUTE(SUBSTITUTE(TRIM($W10),"-",""),".",""),"/","")," ",""),8),4),--MID(LEFT(SUBSTITUTE(SUBSTITUTE(SUBSTITUTE(SUBSTITUTE(TRIM($W10),"-",""),".",""),"/","")," ",""),8),5,2),--MID(LEFT(SUBSTITUTE(SUBSTITUTE(SUBSTITUTE(SUBSTITUTE(TRIM($W10),"-",""),".",""),"/","")," ",""),8),7,2)),""))) | Y10: =IF($X10="","",INT($X10)) | Z10: =IF(OR($Y10="",$D$6=""),"",IF(INDEX($A:$U,ROW(),$D$6)="",0,IF(ISNUMBER(INDEX($A:$U,ROW(),$D$6)),INDEX($A:$U,ROW(),$D$6),IFERROR(--SUBSTITUTE(SUBSTITUTE(TRIM(INDEX($A:$U,ROW(),$D$6)),",",""),"원",""),0)))) | AA10: =IF($Y10="","",TRIM(INDEX($A:$U,ROW(),$E$6)&IF($F$6="",""," "&INDEX($A:$U,ROW(),$F$6)))) | AB10: =IF($AA10="","",SUBSTITUTE(SUBSTITUTE(SUBSTITUTE(SUBSTITUTE(SUBSTITUTE(SUBSTITUTE(SUBSTITUTE(SUBSTITUTE(SUBSTITUTE($AA10," ","")," ",""),"(주)",""),"（주）",""),"㈜",""),"주식회사",""),"(유)",""),"（유）",""),"유한회사","")) | AC10: =IF(OR($Y10="",N($Z10)<=0,$AB10=""),0,IFERROR(LOOKUP(2,1/((거래처별!$AC$8:$AC$307<>"")*ISNUMBER(SEARCH(거래처별!$AC$8:$AC$307,$AB10))),거래처별!$A$8:$A$307),IFERROR(LOOKUP(2,1/((거래처별!$AD$8:$AD$307<>"")*ISNUMBER(SEARCH(거래처별!$AD$8:$AD$307,$AB10))),거래처별!$A$8:$A$307),IFERROR(LOOKUP(2,1/((거래처별!$AE$8:$AE$307<>"")*ISNUMBER(SEARCH(거래처별!$AE$8:$AE$307,$AB10))),거래처별!$A$8:$A$307),0)))) | AD10: =IF(AND($Y10<>"",N($Z10)>0,$AC10=0),MAX($AD$7:$AD9)+1,"") | AE10: =IF($Y10="",0,$Y10)
