Workbook

Sheet 사용법
B1: 급여명세서 자동 생성 양식
B2: 급여대장 엑셀을 붙여넣으면 직원별 임금명세서가 인쇄·PDF용 페이지로 자동 정리됩니다. 매크로 없는 순수 수식 · 노란 칸만 입력 · 하루보고 무료 양식
B4: ① 급여대장 내려받기 | C4: 쓰시는 급여프로그램에서 월 급여대장(직원별 지급·공제 항목이 한 줄에 있는 표)을 엑셀로 내려받습니다.
B5: ▼
B6: ② 붙여넣기 | C6: 내려받은 파일에서 Ctrl+A → Ctrl+C. 이 파일의 [급여대장_원본] 시트 A8 칸을 클릭하고 Ctrl+V. (파일이 '보호된 보기'면 노란 막대의 [편집 사용]을 먼저 누르세요.)
B7: ▼
B8: ③ 예시 지우기 | C8: 붙여넣기 전에 [급여대장_원본] 9행 아래를 모두 선택해 Delete. 예시가 남아 있으면 빨간 경고가 뜹니다.
B9: ▼
B10: ④ 설정 확인 | C10: [설정] 시트에서 회사명·귀속월·지급일(노란 칸)을 고칩니다. 아래쪽 머리글 이름이 모두 ✔면 더 건드릴 것이 없습니다. ✖ 줄은 파일 맨 윗줄에 적힌 글자와 똑같이 고치세요.
B11: ▼
B12: ⑤ 점검 | C12: [점검] 시트에서 합계가 급여프로그램 화면과 맞는지(✔), 확인 포인트에 ⚠가 뜬 줄이 있는지 봅니다.
B13: ▼
B14: ⑥ 확인·인쇄 | C14: [명세서_미리보기]에서 이름을 골라 한 명씩 확인하고, [명세서_전체]에서 1쪽 = 1명으로 인쇄하거나 PDF로 저장합니다. 인쇄할 쪽 수는 [점검] 시트에 나옵니다.
B16: 시트 안내
B17: 급여대장_원본 | C17: 내려받은 급여대장을 그대로 붙여넣는 곳
B18: 설정 | C18: 회사명·귀속월·지급일, 급여대장 머리글 이름 연결
B19: 점검 | C19: 합계 대조, 확인 후보 목록, 인쇄 쪽 수
B20: 명세서_미리보기 | C20: 이름을 골라 한 명씩 보기
B21: 명세서_전체 | C21: 직원 전원 명세서 (1쪽 1명, 최대 100명)
B22: 직원목록 | C22: 자동 정리용 계산 시트 (건드리지 마세요)
B24: 명세서에 들어가는 것
C25: 성명·사번·부서 / 임금 지급일 / 지급 항목별 금액과 합계 / 연장·야간·휴일 수당 옆 근로시간 / 공제 항목별 금액과 합계 / 실수령액
B27: 주의
C28: · 예시의 금액과 공제 수치는 모두 가상이며 실제 요율·세액과 무관합니다. 공제액은 급여프로그램에서 계산된 값을 그대로 가져옵니다.
C29: · 이 양식은 정리·인쇄 도구입니다. 명세서 기재 항목과 교부 방법은 근로기준법과 고용노동부 안내를 기준으로 담당자가 최종 확인하세요.
C30: · 주민등록번호·계좌번호 등은 명세서와 다른 시트로 옮기지 않습니다. 파일 보관·메일 전송 시 개인정보에 유의하세요.
C31: · 이름이 같은 직원이 있으면 미리보기는 첫 번째 사람만 보입니다 (전체 인쇄는 정상).

Sheet 급여대장_원본
A1: 급여대장 붙여넣기 시트
A2: 급여프로그램에서 내려받은 엑셀을 열어 Ctrl+A → Ctrl+C 한 뒤, 이 시트의 A8 칸을 클릭하고 Ctrl+V. 맨 윗줄(머리글)이 8행에 오면 됩니다.
A3: 예시 지우는 법: 9행 아래를 모두 선택 → Delete (머리글 8행은 새 파일 것으로 덮어써지니 그냥 붙여넣으면 됩니다).
A4: 내려받은 파일이 '보호된 보기'면 노란 막대의 [편집 사용]을 먼저 누른 뒤 복사하세요.
A5: ▶ 인식 결과 | B5: =IF('직원목록'!$D$3>0,"직원 "&'직원목록'!$D$3&"명 인식","⚠ 직원이 인식되지 않았습니다 — 8행 머리글과 설정 시트를 확인하세요") | E5: =IF('직원목록'!$D$4>0,"⚠ 예시 데이터 "&'직원목록'!$D$4&"줄이 남아 있습니다 — 지우고 쓰세요","")
A6: ▶ 머리글 | B6: =IF(COUNTIF(설정!$E$13:$E$37,"✖*")=0,"✔ 설정한 머리글을 모두 찾았습니다","✖ 못 찾은 머리글 "&COUNTIF(설정!$E$13:$E$37,"✖*")&"개 — 설정 시트의 ✖ 줄을 파일의 글자에 맞추세요")
A8: 사번 | B8: 성명 | C8: 부서 | D8: 입사일 | E8: 기본급 | F8: 연장근로시간 | G8: 연장근로수당 | H8: 야간근로시간 | I8: 야간근로수당 | J8: 휴일근로시간 | K8: 휴일근로수당 | L8: 식대 | M8: 직책수당 | N8: 상여금 | O8: 지급합계 | P8: 국민연금 | Q8: 건강보험 | R8: 장기요양보험 | S8: 고용보험 | T8: 소득세 | U8: 지방소득세 | V8: 공제합계 | W8: 실수령액
A9: EX-001 | B9: 가상직원01 | C9: 경영지원 | D9: 2019-03-04 | E9: 3200000 | F9: 0 | G9: 0 | H9: 0 | I9: 0 | J9: 0 | K9: 0 | L9: 200000 | M9: 300000 | N9: 0 | O9: 3700000 | P9: 164000 | Q9: 120000 | R9: 15000 | S9: 29000 | T9: 85000 | U9: 8500 | V9: 421500 | W9: 3278500
A10: EX-002 | B10: 가상직원02 | C10: 경영지원 | D10: 2021-07-12 | E10: 2700000 | F10: 10 | G10: 193780 | H10: 0 | I10: 0 | J10: 0 | K10: 0 | L10: 200000 | M10: 0 | N10: 0 | O10: 3093780 | P10: 133000 | Q10: 98000 | R10: 12000 | S10: 24000 | T10: 41000 | U10: 4100 | V10: 312100 | W10: 2781680
A11: EX-003 | B11: 가상직원03 | C11: 영업 | D11: 2022-01-03 | E11: 2800000 | F11: 18 | G11: 361720 | H11: 4 | I11: 26790 | J11: 0 | K11: 0 | L11: 200000 | M11: 0 | N11: 500000 | O11: 3888510 | P11: 139000 | Q11: 101000 | R11: 12000 | S11: 25000 | T11: 52000 | U11: 5200 | V11: 334200 | W11: 3554310
A12: EX-004 | B12: 가상직원04 | C12: 영업 | D12: 2023-05-22 | E12: 2500000 | F12: 6.5 | G12: 116630 | H12: 0 | I12: 0 | J12: 8 | K12: 143540 | L12: 200000 | M12: 0 | N12: 0 | O12: 2960170 | P12: 122000 | Q12: 90000 | R12: 11000 | S12: 22000 | T12: 33000 | U12: 3300 | V12: 281300 | W12: 2678870
A13: EX-005 | B13: 가상직원05 | C13: 생산 | D13: 2020-10-05 | E13: 2600000 | F13: 22 | G13: 410530 | H13: 12 | I13: 74640 | J13: 16 | K13: 298560 | L13: 200000 | M13: 100000 | N13: 0 | O13: 3683730 | P13: 140000 | Q13: 103000 | R13: 13000 | S13: 26000 | T13: 60000 | U13: 6000 | V13: 348000 | W13: 3335730
A14: EX-006 | B14: 가상직원06 | C14: 생산 | D14: 2024-02-19 | E14: 2400000 | F14: 0 | G14: 0 | H14: 0 | I14: 0 | J14: 0 | K14: 0 | L14: 200000 | M14: 0 | N14: 0 | O14: 2600000 | P14: 108000 | Q14: 80000 | R14: 10000 | S14: 20000 | T14: 25000 | U14: 2500 | V14: 245500 | W14: 2354500
A15: 합계 | E15: =SUM(E9:E14) | G15: =SUM(G9:G14) | I15: =SUM(I9:I14) | K15: =SUM(K9:K14) | L15: =SUM(L9:L14) | M15: =SUM(M9:M14) | N15: =SUM(N9:N14) | O15: =SUM(O9:O14) | P15: =SUM(P9:P14) | Q15: =SUM(Q9:Q14) | R15: =SUM(R9:R14) | ... W15: =SUM(W9:W14)

Sheet 설정
A1: 설정 — 평소에는 노란 칸 중 위쪽(회사명·귀속월·지급일)만 고치세요
A2: 아래 '머리글 이름'은 급여대장 파일 맨 윗줄에 적힌 글자와 똑같아야 합니다. 상태가 ✔ 이면 건드릴 것 없고, ✖ 가 뜨는 줄만 파일의 글자에 맞춰 고치세요.
A4: 회사명 | B4: 가상상사 주식회사
A5: 귀속월 (명세서 제목) | B5: 2026년 10월분
A6: 임금 지급일 | B6: 46320
A7: 명세서 하단 안내문 | B7: 문의: 경영지원팀 (내선 000)
A8: 머리글이 있는 행 번호 | B8: 8 | C8: ← 원본 시트 A8에 붙여넣으면 머리글이 8행에 옵니다 (기본값 그대로 두세요)
A9: 데이터 시작 행 | B9: =B8+1
A11: 항목 | B11: 급여대장 머리글 이름 | C11: 시간 열 머리글(선택) | D11: 찾은 열 | E11: 상태
A12: [인적사항]
A13: 사번 | B13: 사번 | D13: =IF(B13="","",IFERROR(MATCH(B13,INDEX(급여대장_원본!$A$1:$AZ$400,$B$8,0),0),"")) | E13: =IF(B13="","(사용 안 함)",IF(D13="","✖ 못 찾음 — 파일의 글자에 맞추세요","✔ "&SUBSTITUTE(ADDRESS(1,D13,4),"1",""))&"")
A14: 성명 | B14: 성명 | D14: =IF(B14="","",IFERROR(MATCH(B14,INDEX(급여대장_원본!$A$1:$AZ$400,$B$8,0),0),"")) | E14: =IF(B14="","(사용 안 함)",IF(D14="","✖ 못 찾음 — 파일의 글자에 맞추세요","✔ "&SUBSTITUTE(ADDRESS(1,D14,4),"1",""))&"")
A15: 부서 | B15: 부서 | D15: =IF(B15="","",IFERROR(MATCH(B15,INDEX(급여대장_원본!$A$1:$AZ$400,$B$8,0),0),"")) | E15: =IF(B15="","(사용 안 함)",IF(D15="","✖ 못 찾음 — 파일의 글자에 맞추세요","✔ "&SUBSTITUTE(ADDRESS(1,D15,4),"1",""))&"")
A16: [지급 항목] 8칸 · 비우면 사용 안 함
A17: 지급 1 | B17: 기본급 | D17: =IF(B17="","",IFERROR(MATCH(B17,INDEX(급여대장_원본!$A$1:$AZ$400,$B$8,0),0),"")) | E17: =IF(B17="","(사용 안 함)",IF(D17="","✖ 못 찾음 — 파일의 글자에 맞추세요","✔ "&SUBSTITUTE(ADDRESS(1,D17,4),"1",""))&IF(C17="","",IF(IFERROR(MATCH(C17,INDEX(급여대장_원본!$A$1:$AZ$400,$B$8,0),0),0)=0," / 시간열 ✖","")))
A18: 지급 2 | B18: 연장근로수당 | C18: 연장근로시간 | D18: =IF(B18="","",IFERROR(MATCH(B18,INDEX(급여대장_원본!$A$1:$AZ$400,$B$8,0),0),"")) | E18: =IF(B18="","(사용 안 함)",IF(D18="","✖ 못 찾음 — 파일의 글자에 맞추세요","✔ "&SUBSTITUTE(ADDRESS(1,D18,4),"1",""))&IF(C18="","",IF(IFERROR(MATCH(C18,INDEX(급여대장_원본!$A$1:$AZ$400,$B$8,0),0),0)=0," / 시간열 ✖","")))
A19: 지급 3 | B19: 야간근로수당 | C19: 야간근로시간 | D19: =IF(B19="","",IFERROR(MATCH(B19,INDEX(급여대장_원본!$A$1:$AZ$400,$B$8,0),0),"")) | E19: =IF(B19="","(사용 안 함)",IF(D19="","✖ 못 찾음 — 파일의 글자에 맞추세요","✔ "&SUBSTITUTE(ADDRESS(1,D19,4),"1",""))&IF(C19="","",IF(IFERROR(MATCH(C19,INDEX(급여대장_원본!$A$1:$AZ$400,$B$8,0),0),0)=0," / 시간열 ✖","")))
A20: 지급 4 | B20: 휴일근로수당 | C20: 휴일근로시간 | D20: =IF(B20="","",IFERROR(MATCH(B20,INDEX(급여대장_원본!$A$1:$AZ$400,$B$8,0),0),"")) | E20: =IF(B20="","(사용 안 함)",IF(D20="","✖ 못 찾음 — 파일의 글자에 맞추세요","✔ "&SUBSTITUTE(ADDRESS(1,D20,4),"1",""))&IF(C20="","",IF(IFERROR(MATCH(C20,INDEX(급여대장_원본!$A$1:$AZ$400,$B$8,0),0),0)=0," / 시간열 ✖","")))
A21: 지급 5 | B21: 식대 | D21: =IF(B21="","",IFERROR(MATCH(B21,INDEX(급여대장_원본!$A$1:$AZ$400,$B$8,0),0),"")) | E21: =IF(B21="","(사용 안 함)",IF(D21="","✖ 못 찾음 — 파일의 글자에 맞추세요","✔ "&SUBSTITUTE(ADDRESS(1,D21,4),"1",""))&IF(C21="","",IF(IFERROR(MATCH(C21,INDEX(급여대장_원본!$A$1:$AZ$400,$B$8,0),0),0)=0," / 시간열 ✖","")))
A22: 지급 6 | B22: 직책수당 | D22: =IF(B22="","",IFERROR(MATCH(B22,INDEX(급여대장_원본!$A$1:$AZ$400,$B$8,0),0),"")) | E22: =IF(B22="","(사용 안 함)",IF(D22="","✖ 못 찾음 — 파일의 글자에 맞추세요","✔ "&SUBSTITUTE(ADDRESS(1,D22,4),"1",""))&IF(C22="","",IF(IFERROR(MATCH(C22,INDEX(급여대장_원본!$A$1:$AZ$400,$B$8,0),0),0)=0," / 시간열 ✖","")))
A23: 지급 7 | B23: 상여금 | D23: =IF(B23="","",IFERROR(MATCH(B23,INDEX(급여대장_원본!$A$1:$AZ$400,$B$8,0),0),"")) | E23: =IF(B23="","(사용 안 함)",IF(D23="","✖ 못 찾음 — 파일의 글자에 맞추세요","✔ "&SUBSTITUTE(ADDRESS(1,D23,4),"1",""))&IF(C23="","",IF(IFERROR(MATCH(C23,INDEX(급여대장_원본!$A$1:$AZ$400,$B$8,0),0),0)=0," / 시간열 ✖","")))
A24: 지급 8 | D24: =IF(B24="","",IFERROR(MATCH(B24,INDEX(급여대장_원본!$A$1:$AZ$400,$B$8,0),0),"")) | E24: =IF(B24="","(사용 안 함)",IF(D24="","✖ 못 찾음 — 파일의 글자에 맞추세요","✔ "&SUBSTITUTE(ADDRESS(1,D24,4),"1",""))&IF(C24="","",IF(IFERROR(MATCH(C24,INDEX(급여대장_원본!$A$1:$AZ$400,$B$8,0),0),0)=0," / 시간열 ✖","")))
A25: [공제 항목] 8칸 · 비우면 사용 안 함
A26: 공제 1 | B26: 국민연금 | D26: =IF(B26="","",IFERROR(MATCH(B26,INDEX(급여대장_원본!$A$1:$AZ$400,$B$8,0),0),"")) | E26: =IF(B26="","(사용 안 함)",IF(D26="","✖ 못 찾음 — 파일의 글자에 맞추세요","✔ "&SUBSTITUTE(ADDRESS(1,D26,4),"1",""))&"")
A27: 공제 2 | B27: 건강보험 | D27: =IF(B27="","",IFERROR(MATCH(B27,INDEX(급여대장_원본!$A$1:$AZ$400,$B$8,0),0),"")) | E27: =IF(B27="","(사용 안 함)",IF(D27="","✖ 못 찾음 — 파일의 글자에 맞추세요","✔ "&SUBSTITUTE(ADDRESS(1,D27,4),"1",""))&"")
A28: 공제 3 | B28: 장기요양보험 | D28: =IF(B28="","",IFERROR(MATCH(B28,INDEX(급여대장_원본!$A$1:$AZ$400,$B$8,0),0),"")) | E28: =IF(B28="","(사용 안 함)",IF(D28="","✖ 못 찾음 — 파일의 글자에 맞추세요","✔ "&SUBSTITUTE(ADDRESS(1,D28,4),"1",""))&"")
A29: 공제 4 | B29: 고용보험 | D29: =IF(B29="","",IFERROR(MATCH(B29,INDEX(급여대장_원본!$A$1:$AZ$400,$B$8,0),0),"")) | E29: =IF(B29="","(사용 안 함)",IF(D29="","✖ 못 찾음 — 파일의 글자에 맞추세요","✔ "&SUBSTITUTE(ADDRESS(1,D29,4),"1",""))&"")
A30: 공제 5 | B30: 소득세 | D30: =IF(B30="","",IFERROR(MATCH(B30,INDEX(급여대장_원본!$A$1:$AZ$400,$B$8,0),0),"")) | E30: =IF(B30="","(사용 안 함)",IF(D30="","✖ 못 찾음 — 파일의 글자에 맞추세요","✔ "&SUBSTITUTE(ADDRESS(1,D30,4),"1",""))&"")
A31: 공제 6 | B31: 지방소득세 | D31: =IF(B31="","",IFERROR(MATCH(B31,INDEX(급여대장_원본!$A$1:$AZ$400,$B$8,0),0),"")) | E31: =IF(B31="","(사용 안 함)",IF(D31="","✖ 못 찾음 — 파일의 글자에 맞추세요","✔ "&SUBSTITUTE(ADDRESS(1,D31,4),"1",""))&"")
A32: 공제 7 | D32: =IF(B32="","",IFERROR(MATCH(B32,INDEX(급여대장_원본!$A$1:$AZ$400,$B$8,0),0),"")) | E32: =IF(B32="","(사용 안 함)",IF(D32="","✖ 못 찾음 — 파일의 글자에 맞추세요","✔ "&SUBSTITUTE(ADDRESS(1,D32,4),"1",""))&"")
A33: 공제 8 | D33: =IF(B33="","",IFERROR(MATCH(B33,INDEX(급여대장_원본!$A$1:$AZ$400,$B$8,0),0),"")) | E33: =IF(B33="","(사용 안 함)",IF(D33="","✖ 못 찾음 — 파일의 글자에 맞추세요","✔ "&SUBSTITUTE(ADDRESS(1,D33,4),"1",""))&"")
A34: [급여대장의 합계 열 · 선택] 있으면 점검 시트가 계산값과 맞춰 봅니다
A35: 총지급액 열 | B35: 지급합계 | D35: =IF(B35="","",IFERROR(MATCH(B35,INDEX(급여대장_원본!$A$1:$AZ$400,$B$8,0),0),"")) | E35: =IF(B35="","(사용 안 함)",IF(D35="","✖ 못 찾음 — 파일의 글자에 맞추세요","✔ "&SUBSTITUTE(ADDRESS(1,D35,4),"1",""))&"")
A36: 총공제액 열 | B36: 공제합계 | D36: =IF(B36="","",IFERROR(MATCH(B36,INDEX(급여대장_원본!$A$1:$AZ$400,$B$8,0),0),"")) | E36: =IF(B36="","(사용 안 함)",IF(D36="","✖ 못 찾음 — 파일의 글자에 맞추세요","✔ "&SUBSTITUTE(ADDRESS(1,D36,4),"1",""))&"")
A37: 실수령액 열 | B37: 실수령액 | D37: =IF(B37="","",IFERROR(MATCH(B37,INDEX(급여대장_원본!$A$1:$AZ$400,$B$8,0),0),"")) | E37: =IF(B37="","(사용 안 함)",IF(D37="","✖ 못 찾음 — 파일의 글자에 맞추세요","✔ "&SUBSTITUTE(ADDRESS(1,D37,4),"1",""))&"")
A39: ※ 급여대장에 있어도 위에 적지 않은 열(주민등록번호·계좌번호 등)은 명세서와 다른 시트로 옮기지 않습니다.
A40: ※ '시간 열 머리글'은 연장·야간·휴일 수당 줄 옆에 '○시간'을 찍기 위한 칸입니다. 고정 수당이면 비워 두세요.

Sheet 점검
A1: 점검 — 명세서를 나눠주기 전에 한 번 훑어보세요
A2: 아래는 '확인할 후보'만 알려줍니다. 맞고 틀림은 담당자가 급여대장과 근로계약 기준으로 판단하세요.
A4: 요약
B5: 인식 직원 수 | C5: =직원목록!$D$3 | F5: 급여프로그램 화면 합계 (노란 칸에 적으면 대조) | H5: 계산값
B6: 인쇄할 쪽 | C6: =IF(C5=0,"-","명세서_전체 1~"&C5&"쪽") | F6: 총지급액 | H6: =SUMIF(직원목록!$A$7:$A$306,1,직원목록!$V$7:$V$306) | I6: =IF(G6="","(화면 합계를 적으세요)",IF(G6=H6,"✔ 일치","✖ 차이 "&TEXT(H6-G6,"#,##0")&"원"))
B7: 확인 필요 줄 | C7: =COUNTIF($L$13:$L$312,"⚠*") | F7: 총공제액 | H7: =SUMIF(직원목록!$A$7:$A$306,1,직원목록!$AE$7:$AE$306) | I7: =IF(G7="","(화면 합계를 적으세요)",IF(G7=H7,"✔ 일치","✖ 차이 "&TEXT(H7-G7,"#,##0")&"원"))
F8: 실수령액 | H8: =SUMIF(직원목록!$A$7:$A$306,1,직원목록!$AF$7:$AF$306) | I8: =IF(G8="","(화면 합계를 적으세요)",IF(G8=H8,"✔ 일치","✖ 차이 "&TEXT(H8-G8,"#,##0")&"원"))
A10: ※ 명세서 하단 확인: 임금 지급일은 설정 시트에 적었는지, 연장·야간·휴일 수당 줄에 시간 열을 지정했는지 확인하세요.
A12: 순번 | B12: 성명 | C12: 사번 | D12: 계산 총지급 | E12: 대장 총지급 | F12: 차이 | G12: 계산 총공제 | H12: 대장 총공제 | I12: 차이 | J12: 계산 실수령 | K12: 대장 실수령 | L12: 확인 포인트
A13: =IF(IFERROR(MATCH(1,직원목록!$B$7:$B$306,0),0)=0,"",1) | B13: =IF($A13="","",IFERROR(INDEX(직원목록!$D$7:$D$306,MATCH(1,직원목록!$B$7:$B$306,0)),"")) | C13: =IF($A13="","",IFERROR(INDEX(직원목록!$C$7:$C$306,MATCH(1,직원목록!$B$7:$B$306,0)),"")) | D13: =IF($A13="","",IFERROR(INDEX(직원목록!$V$7:$V$306,MATCH(1,직원목록!$B$7:$B$306,0)),"")) | E13: =IF($A13="","",IFERROR(INDEX(직원목록!$AG$7:$AG$306,MATCH(1,직원목록!$B$7:$B$306,0)),"")) | F13: =IF(OR($A13="",E13=""),"",D13-E13) | G13: =IF($A13="","",IFERROR(INDEX(직원목록!$AE$7:$AE$306,MATCH(1,직원목록!$B$7:$B$306,0)),"")) | H13: =IF($A13="","",IFERROR(INDEX(직원목록!$AH$7:$AH$306,MATCH(1,직원목록!$B$7:$B$306,0)),"")) | I13: =IF(OR($A13="",H13=""),"",G13-H13) | J13: =IF($A13="","",IFERROR(INDEX(직원목록!$AF$7:$AF$306,MATCH(1,직원목록!$B$7:$B$306,0)),"")) | K13: =IF($A13="","",IFERROR(INDEX(직원목록!$AI$7:$AI$306,MATCH(1,직원목록!$B$7:$B$306,0)),"")) | L13: =IF($A13="","",IF(LEN(IF(AND(F13<>"",F13<>0),"계산 총지급과 대장 총지급이 다릅니다 / ","")&IF(AND(I13<>"",I13<>0),"계산 총공제와 대장 총공제가 다릅니다 / ","")&IF(J13<0,"실수령액이 음수입니다 / ","")&IF(COUNTIF(직원목록!$D$7:$D$306,B13)>1,"같은 이름이 둘 이상 — 미리보기는 첫 번째만 보입니다 / ","")&IF(AND(C13<>"",COUNTIF(직원목록!$C$7:$C$306,C13)>1),"사번 중복 / ","")&IF(D13=0,"총지급이 0원 — 머리글 매칭 확인 / ","")&IF(AND(설정!$B$17<>"",설정!$C$17="",OR(ISNUMBER(FIND("연장",설정!$B$17)),ISNUMBER(FIND("야간",설정!$B$17)),ISNUMBER(FIND("휴일",설정!$B$17))),INDEX(직원목록!$F$7:$F$306,MATCH(1,직원목록!$B$7:$B$306,0))>0),"연장·야간·휴일 수당은 시간 수도 명세서에 적어야 하니 시간 열 지정 필요 / ","")&IF(AND(설정!$B$18<>"",설정!$C$18="",OR(ISNUMBER(FIND("연장",설정!$B$18)),ISNUMBER(FIND("야간",설정!$B$18)),ISNUMBER(FIND("휴일",설정!$B$18))),INDEX(직원목록!$G$7:$G$306,MATCH(1,직원목록!$B$7:$B$306,0))>0),"연장·야간·휴일 수당은 시간 수도 명세서에 적어야 하니 시간 열 지정 필요 / ","")&IF(AND(설정!$B$19<>"",설정!$C$19="",OR(ISNUMBER(FIND("연장",설정!$B$19)),ISNUMBER(FIND("야간",설정!$B$19)),ISNUMBER(FIND("휴일",설정!$B$19))),INDEX(직원목록!$H$7:$H$306,MATCH(1,직원목록!$B$7:$B$306,0))>0),"연장·야간·휴일 수당은 시간 수도 명세서에 적어야 하니 시간 열 지정 필요 / ","")&IF(AND(설정!$B$20<>"",설정!$C$20="",OR(ISNUMBER(FIND("연장",설정!$B$20)),ISNUMBER(FIND("야간",설정!$B$20)),ISNUMBER(FIND("휴일",설정!$B$20))),INDEX(직원목록!$I$7:$I$306,MATCH(1,직원목록!$B$7:$B$306,0))>0),"연장·야간·휴일 수당은 시간 수도 명세서에 적어야 하니 시간 열 지정 필요 / ","")&IF(AND(설정!$B$21<>"",설정!$C$21="",OR(ISNUMBER(FIND("연장",설정!$B$21)),ISNUMBER(FIND("야간",설정!$B$21)),ISNUMBER(FIND("휴일",설정!$B$21))),INDEX(직원목록!$J$7:$J$306,MATCH(1,직원목록!$B$7:$B$306,0))>0),"연장·야간·휴일 수당은 시간 수도 명세서에 적어야 하니 시간 열 지정 필요 / ","")&IF(AND(설정!$B$22<>"",설정!$C$22="",OR(ISNUMBER(FIND("연장",설정!$B$22)),ISNUMBER(FIND("야간",설정!$B$22)),ISNUMBER(FIND("휴일",설정!$B$22))),INDEX(직원목록!$K$7:$K$306,MATCH(1,직원목록!$B$7:$B$306,0))>0),"연장·야간·휴일 수당은 시간 수도 명세서에 적어야 하니 시간 열 지정 필요 / ","")&IF(AND(설정!$B$23<>"",설정!$C$23="",OR(ISNUMBER(FIND("연장",설정!$B$23)),ISNUMBER(FIND("야간",설정!$B$23)),ISNUMBER(FIND("휴일",설정!$B$23))),INDEX(직원목록!$L$7:$L$306,MATCH(1,직원목록!$B$7:$B$306,0))>0),"연장·야간·휴일 수당은 시간 수도 명세서에 적어야 하니 시간 열 지정 필요 / ","")&IF(AND(설정!$B$24<>"",설정!$C$24="",OR(ISNUMBER(FIND("연장",설정!$B$24)),ISNUMBER(FIND("야간",설정!$B$24)),ISNUMBER(FIND("휴일",설정!$B$24))),INDEX(직원목록!$M$7:$M$306,MATCH(1,직원목록!$B$7:$B$306,0))>0),"연장·야간·휴일 수당은 시간 수도 명세서에 적어야 하니 시간 열 지정 필요 / ",""))=0,"✔",("⚠ "&IF(AND(F13<>"",F13<>0),"계산 총지급과 대장 총지급이 다릅니다 / ","")&IF(AND(I13<>"",I13<>0),"계산 총공제와 대장 총공제가 다릅니다 / ","")&IF(J13<0,"실수령액이 음수입니다 / ","")&IF(COUNTIF(직원목록!$D$7:$D$306,B13)>1,"같은 이름이 둘 이상 — 미리보기는 첫 번째만 보입니다 / ","")&IF(AND(C13<>"",COUNTIF(직원목록!$C$7:$C$306,C13)>1),"사번 중복 / ","")&IF(D13=0,"총지급이 0원 — 머리글 매칭 확인 / ","")&IF(AND(설정!$B$17<>"",설정!$C$17="",OR(ISNUMBER(FIND("연장",설정!$B$17)),ISNUMBER(FIND("야간",설정!$B$17)),ISNUMBER(FIND("휴일",설정!$B$17))),INDEX(직원목록!$F$7:$F$306,MATCH(1,직원목록!$B$7:$B$306,0))>0),"연장·야간·휴일 수당은 시간 수도 명세서에 적어야 하니 시간 열 지정 필요 / ","")&IF(AND(설정!$B$18<>"",설정!$C$18="",OR(ISNUMBER(FIND("연장",설정!$B$18)),ISNUMBER(FIND("야간",설정!$B$18)),ISNUMBER(FIND("휴일",설정!$B$18))),INDEX(직원목록!$G$7:$G$306,MATCH(1,직원목록!$B$7:$B$306,0))>0),"연장·야간·휴일 수당은 시간 수도 명세서에 적어야 하니 시간 열 지정 필요 / ","")&IF(AND(설정!$B$19<>"",설정!$C$19="",OR(ISNUMBER(FIND("연장",설정!$B$19)),ISNUMBER(FIND("야간",설정!$B$19)),ISNUMBER(FIND("휴일",설정!$B$19))),INDEX(직원목록!$H$7:$H$306,MATCH(1,직원목록!$B$7:$B$306,0))>0),"연장·야간·휴일 수당은 시간 수도 명세서에 적어야 하니 시간 열 지정 필요 / ","")&IF(AND(설정!$B$20<>"",설정!$C$20="",OR(ISNUMBER(FIND("연장",설정!$B$20)),ISNUMBER(FIND("야간",설정!$B$20)),ISNUMBER(FIND("휴일",설정!$B$20))),INDEX(직원목록!$I$7:$I$306,MATCH(1,직원목록!$B$7:$B$306,0))>0),"연장·야간·휴일 수당은 시간 수도 명세서에 적어야 하니 시간 열 지정 필요 / ","")&IF(AND(설정!$B$21<>"",설정!$C$21="",OR(ISNUMBER(FIND("연장",설정!$B$21)),ISNUMBER(FIND("야간",설정!$B$21)),ISNUMBER(FIND("휴일",설정!$B$21))),INDEX(직원목록!$J$7:$J$306,MATCH(1,직원목록!$B$7:$B$306,0))>0),"연장·야간·휴일 수당은 시간 수도 명세서에 적어야 하니 시간 열 지정 필요 / ","")&IF(AND(설정!$B$22<>"",설정!$C$22="",OR(ISNUMBER(FIND("연장",설정!$B$22)),ISNUMBER(FIND("야간",설정!$B$22)),ISNUMBER(FIND("휴일",설정!$B$22))),INDEX(직원목록!$K$7:$K$306,MATCH(1,직원목록!$B$7:$B$306,0))>0),"연장·야간·휴일 수당은 시간 수도 명세서에 적어야 하니 시간 열 지정 필요 / ","")&IF(AND(설정!$B$23<>"",설정!$C$23="",OR(ISNUMBER(FIND("연장",설정!$B$23)),ISNUMBER(FIND("야간",설정!$B$23)),ISNUMBER(FIND("휴일",설정!$B$23))),INDEX(직원목록!$L$7:$L$306,MATCH(1,직원목록!$B$7:$B$306,0))>0),"연장·야간·휴일 수당은 시간 수도 명세서에 적어야 하니 시간 열 지정 필요 / ","")&IF(AND(설정!$B$24<>"",설정!$C$24="",OR(ISNUMBER(FIND("연장",설정!$B$24)),ISNUMBER(FIND("야간",설정!$B$24)),ISNUMBER(FIND("휴일",설정!$B$24))),INDEX(직원목록!$M$7:$M$306,MATCH(1,직원목록!$B$7:$B$306,0))>0),"연장·야간·휴일 수당은 시간 수도 명세서에 적어야 하니 시간 열 지정 필요 / ",""))))
A14: =IF(IFERROR(MATCH(2,직원목록!$B$7:$B$306,0),0)=0,"",2) | B14: =IF($A14="","",IFERROR(INDEX(직원목록!$D$7:$D$306,MATCH(2,직원목록!$B$7:$B$306,0)),"")) | C14: =IF($A14="","",IFERROR(INDEX(직원목록!$C$7:$C$306,MATCH(2,직원목록!$B$7:$B$306,0)),"")) | D14: =IF($A14="","",IFERROR(INDEX(직원목록!$V$7:$V$306,MATCH(2,직원목록!$B$7:$B$306,0)),"")) | E14: =IF($A14="","",IFERROR(INDEX(직원목록!$AG$7:$AG$306,MATCH(2,직원목록!$B$7:$B$306,0)),"")) | F14: =IF(OR($A14="",E14=""),"",D14-E14) | G14: =IF($A14="","",IFERROR(INDEX(직원목록!$AE$7:$AE$306,MATCH(2,직원목록!$B$7:$B$306,0)),"")) | H14: =IF($A14="","",IFERROR(INDEX(직원목록!$AH$7:$AH$306,MATCH(2,직원목록!$B$7:$B$306,0)),"")) | I14: =IF(OR($A14="",H14=""),"",G14-H14) | J14: =IF($A14="","",IFERROR(INDEX(직원목록!$AF$7:$AF$306,MATCH(2,직원목록!$B$7:$B$306,0)),"")) | K14: =IF($A14="","",IFERROR(INDEX(직원목록!$AI$7:$AI$306,MATCH(2,직원목록!$B$7:$B$306,0)),"")) | L14: =IF($A14="","",IF(LEN(IF(AND(F14<>"",F14<>0),"계산 총지급과 대장 총지급이 다릅니다 / ","")&IF(AND(I14<>"",I14<>0),"계산 총공제와 대장 총공제가 다릅니다 / ","")&IF(J14<0,"실수령액이 음수입니다 / ","")&IF(COUNTIF(직원목록!$D$7:$D$306,B14)>1,"같은 이름이 둘 이상 — 미리보기는 첫 번째만 보입니다 / ","")&IF(AND(C14<>"",COUNTIF(직원목록!$C$7:$C$306,C14)>1),"사번 중복 / ","")&IF(D14=0,"총지급이 0원 — 머리글 매칭 확인 / ","")&IF(AND(설정!$B$17<>"",설정!$C$17="",OR(ISNUMBER(FIND("연장",설정!$B$17)),ISNUMBER(FIND("야간",설정!$B$17)),ISNUMBER(FIND("휴일",설정!$B$17))),INDEX(직원목록!$F$7:$F$306,MATCH(2,직원목록!$B$7:$B$306,0))>0),"연장·야간·휴일 수당은 시간 수도 명세서에 적어야 하니 시간 열 지정 필요 / ","")&IF(AND(설정!$B$18<>"",설정!$C$18="",OR(ISNUMBER(FIND("연장",설정!$B$18)),ISNUMBER(FIND("야간",설정!$B$18)),ISNUMBER(FIND("휴일",설정!$B$18))),INDEX(직원목록!$G$7:$G$306,MATCH(2,직원목록!$B$7:$B$306,0))>0),"연장·야간·휴일 수당은 시간 수도 명세서에 적어야 하니 시간 열 지정 필요 / ","")&IF(AND(설정!$B$19<>"",설정!$C$19="",OR(ISNUMBER(FIND("연장",설정!$B$19)),ISNUMBER(FIND("야간",설정!$B$19)),ISNUMBER(FIND("휴일",설정!$B$19))),INDEX(직원목록!$H$7:$H$306,MATCH(2,직원목록!$B$7:$B$306,0))>0),"연장·야간·휴일 수당은 시간 수도 명세서에 적어야 하니 시간 열 지정 필요 / ","")&IF(AND(설정!$B$20<>"",설정!$C$20="",OR(ISNUMBER(FIND("연장",설정!$B$20)),ISNUMBER(FIND("야간",설정!$B$20)),ISNUMBER(FIND("휴일",설정!$B$20))),INDEX(직원목록!$I$7:$I$306,MATCH(2,직원목록!$B$7:$B$306,0))>0),"연장·야간·휴일 수당은 시간 수도 명세서에 적어야 하니 시간 열 지정 필요 / ","")&IF(AND(설정!$B$21<>"",설정!$C$21="",OR(ISNUMBER(FIND("연장",설정!$B$21)),ISNUMBER(FIND("야간",설정!$B$21)),ISNUMBER(FIND("휴일",설정!$B$21))),INDEX(직원목록!$J$7:$J$306,MATCH(2,직원목록!$B$7:$B$306,0))>0),"연장·야간·휴일 수당은 시간 수도 명세서에 적어야 하니 시간 열 지정 필요 / ","")&IF(AND(설정!$B$22<>"",설정!$C$22="",OR(ISNUMBER(FIND("연장",설정!$B$22)),ISNUMBER(FIND("야간",설정!$B$22)),ISNUMBER(FIND("휴일",설정!$B$22))),INDEX(직원목록!$K$7:$K$306,MATCH(2,직원목록!$B$7:$B$306,0))>0),"연장·야간·휴일 수당은 시간 수도 명세서에 적어야 하니 시간 열 지정 필요 / ","")&IF(AND(설정!$B$23<>"",설정!$C$23="",OR(ISNUMBER(FIND("연장",설정!$B$23)),ISNUMBER(FIND("야간",설정!$B$23)),ISNUMBER(FIND("휴일",설정!$B$23))),INDEX(직원목록!$L$7:$L$306,MATCH(2,직원목록!$B$7:$B$306,0))>0),"연장·야간·휴일 수당은 시간 수도 명세서에 적어야 하니 시간 열 지정 필요 / ","")&IF(AND(설정!$B$24<>"",설정!$C$24="",OR(ISNUMBER(FIND("연장",설정!$B$24)),ISNUMBER(FIND("야간",설정!$B$24)),ISNUMBER(FIND("휴일",설정!$B$24))),INDEX(직원목록!$M$7:$M$306,MATCH(2,직원목록!$B$7:$B$306,0))>0),"연장·야간·휴일 수당은 시간 수도 명세서에 적어야 하니 시간 열 지정 필요 / ",""))=0,"✔",("⚠ "&IF(AND(F14<>"",F14<>0),"계산 총지급과 대장 총지급이 다릅니다 / ","")&IF(AND(I14<>"",I14<>0),"계산 총공제와 대장 총공제가 다릅니다 / ","")&IF(J14<0,"실수령액이 음수입니다 / ","")&IF(COUNTIF(직원목록!$D$7:$D$306,B14)>1,"같은 이름이 둘 이상 — 미리보기는 첫 번째만 보입니다 / ","")&IF(AND(C14<>"",COUNTIF(직원목록!$C$7:$C$306,C14)>1),"사번 중복 / ","")&IF(D14=0,"총지급이 0원 — 머리글 매칭 확인 / ","")&IF(AND(설정!$B$17<>"",설정!$C$17="",OR(ISNUMBER(FIND("연장",설정!$B$17)),ISNUMBER(FIND("야간",설정!$B$17)),ISNUMBER(FIND("휴일",설정!$B$17))),INDEX(직원목록!$F$7:$F$306,MATCH(2,직원목록!$B$7:$B$306,0))>0),"연장·야간·휴일 수당은 시간 수도 명세서에 적어야 하니 시간 열 지정 필요 / ","")&IF(AND(설정!$B$18<>"",설정!$C$18="",OR(ISNUMBER(FIND("연장",설정!$B$18)),ISNUMBER(FIND("야간",설정!$B$18)),ISNUMBER(FIND("휴일",설정!$B$18))),INDEX(직원목록!$G$7:$G$306,MATCH(2,직원목록!$B$7:$B$306,0))>0),"연장·야간·휴일 수당은 시간 수도 명세서에 적어야 하니 시간 열 지정 필요 / ","")&IF(AND(설정!$B$19<>"",설정!$C$19="",OR(ISNUMBER(FIND("연장",설정!$B$19)),ISNUMBER(FIND("야간",설정!$B$19)),ISNUMBER(FIND("휴일",설정!$B$19))),INDEX(직원목록!$H$7:$H$306,MATCH(2,직원목록!$B$7:$B$306,0))>0),"연장·야간·휴일 수당은 시간 수도 명세서에 적어야 하니 시간 열 지정 필요 / ","")&IF(AND(설정!$B$20<>"",설정!$C$20="",OR(ISNUMBER(FIND("연장",설정!$B$20)),ISNUMBER(FIND("야간",설정!$B$20)),ISNUMBER(FIND("휴일",설정!$B$20))),INDEX(직원목록!$I$7:$I$306,MATCH(2,직원목록!$B$7:$B$306,0))>0),"연장·야간·휴일 수당은 시간 수도 명세서에 적어야 하니 시간 열 지정 필요 / ","")&IF(AND(설정!$B$21<>"",설정!$C$21="",OR(ISNUMBER(FIND("연장",설정!$B$21)),ISNUMBER(FIND("야간",설정!$B$21)),ISNUMBER(FIND("휴일",설정!$B$21))),INDEX(직원목록!$J$7:$J$306,MATCH(2,직원목록!$B$7:$B$306,0))>0),"연장·야간·휴일 수당은 시간 수도 명세서에 적어야 하니 시간 열 지정 필요 / ","")&IF(AND(설정!$B$22<>"",설정!$C$22="",OR(ISNUMBER(FIND("연장",설정!$B$22)),ISNUMBER(FIND("야간",설정!$B$22)),ISNUMBER(FIND("휴일",설정!$B$22))),INDEX(직원목록!$K$7:$K$306,MATCH(2,직원목록!$B$7:$B$306,0))>0),"연장·야간·휴일 수당은 시간 수도 명세서에 적어야 하니 시간 열 지정 필요 / ","")&IF(AND(설정!$B$23<>"",설정!$C$23="",OR(ISNUMBER(FIND("연장",설정!$B$23)),ISNUMBER(FIND("야간",설정!$B$23)),ISNUMBER(FIND("휴일",설정!$B$23))),INDEX(직원목록!$L$7:$L$306,MATCH(2,직원목록!$B$7:$B$306,0))>0),"연장·야간·휴일 수당은 시간 수도 명세서에 적어야 하니 시간 열 지정 필요 / ","")&IF(AND(설정!$B$24<>"",설정!$C$24="",OR(ISNUMBER(FIND("연장",설정!$B$24)),ISNUMBER(FIND("야간",설정!$B$24)),ISNUMBER(FIND("휴일",설정!$B$24))),INDEX(직원목록!$M$7:$M$306,MATCH(2,직원목록!$B$7:$B$306,0))>0),"연장·야간·휴일 수당은 시간 수도 명세서에 적어야 하니 시간 열 지정 필요 / ",""))))
A15: =IF(IFERROR(MATCH(3,직원목록!$B$7:$B$306,0),0)=0,"",3) | B15: =IF($A15="","",IFERROR(INDEX(직원목록!$D$7:$D$306,MATCH(3,직원목록!$B$7:$B$306,0)),"")) | C15: =IF($A15="","",IFERROR(INDEX(직원목록!$C$7:$C$306,MATCH(3,직원목록!$B$7:$B$306,0)),"")) | D15: =IF($A15="","",IFERROR(INDEX(직원목록!$V$7:$V$306,MATCH(3,직원목록!$B$7:$B$306,0)),"")) | E15: =IF($A15="","",IFERROR(INDEX(직원목록!$AG$7:$AG$306,MATCH(3,직원목록!$B$7:$B$306,0)),"")) | F15: =IF(OR($A15="",E15=""),"",D15-E15) | G15: =IF($A15="","",IFERROR(INDEX(직원목록!$AE$7:$AE$306,MATCH(3,직원목록!$B$7:$B$306,0)),"")) | H15: =IF($A15="","",IFERROR(INDEX(직원목록!$AH$7:$AH$306,MATCH(3,직원목록!$B$7:$B$306,0)),"")) | I15: =IF(OR($A15="",H15=""),"",G15-H15) | J15: =IF($A15="","",IFERROR(INDEX(직원목록!$AF$7:$AF$306,MATCH(3,직원목록!$B$7:$B$306,0)),"")) | K15: =IF($A15="","",IFERROR(INDEX(직원목록!$AI$7:$AI$306,MATCH(3,직원목록!$B$7:$B$306,0)),"")) | L15: =IF($A15="","",IF(LEN(IF(AND(F15<>"",F15<>0),"계산 총지급과 대장 총지급이 다릅니다 / ","")&IF(AND(I15<>"",I15<>0),"계산 총공제와 대장 총공제가 다릅니다 / ","")&IF(J15<0,"실수령액이 음수입니다 / ","")&IF(COUNTIF(직원목록!$D$7:$D$306,B15)>1,"같은 이름이 둘 이상 — 미리보기는 첫 번째만 보입니다 / ","")&IF(AND(C15<>"",COUNTIF(직원목록!$C$7:$C$306,C15)>1),"사번 중복 / ","")&IF(D15=0,"총지급이 0원 — 머리글 매칭 확인 / ","")&IF(AND(설정!$B$17<>"",설정!$C$17="",OR(ISNUMBER(FIND("연장",설정!$B$17)),ISNUMBER(FIND("야간",설정!$B$17)),ISNUMBER(FIND("휴일",설정!$B$17))),INDEX(직원목록!$F$7:$F$306,MATCH(3,직원목록!$B$7:$B$306,0))>0),"연장·야간·휴일 수당은 시간 수도 명세서에 적어야 하니 시간 열 지정 필요 / ","")&IF(AND(설정!$B$18<>"",설정!$C$18="",OR(ISNUMBER(FIND("연장",설정!$B$18)),ISNUMBER(FIND("야간",설정!$B$18)),ISNUMBER(FIND("휴일",설정!$B$18))),INDEX(직원목록!$G$7:$G$306,MATCH(3,직원목록!$B$7:$B$306,0))>0),"연장·야간·휴일 수당은 시간 수도 명세서에 적어야 하니 시간 열 지정 필요 / ","")&IF(AND(설정!$B$19<>"",설정!$C$19="",OR(ISNUMBER(FIND("연장",설정!$B$19)),ISNUMBER(FIND("야간",설정!$B$19)),ISNUMBER(FIND("휴일",설정!$B$19))),INDEX(직원목록!$H$7:$H$306,MATCH(3,직원목록!$B$7:$B$306,0))>0),"연장·야간·휴일 수당은 시간 수도 명세서에 적어야 하니 시간 열 지정 필요 / ","")&IF(AND(설정!$B$20<>"",설정!$C$20="",OR(ISNUMBER(FIND("연장",설정!$B$20)),ISNUMBER(FIND("야간",설정!$B$20)),ISNUMBER(FIND("휴일",설정!$B$20))),INDEX(직원목록!$I$7:$I$306,MATCH(3,직원목록!$B$7:$B$306,0))>0),"연장·야간·휴일 수당은 시간 수도 명세서에 적어야 하니 시간 열 지정 필요 / ","")&IF(AND(설정!$B$21<>"",설정!$C$21="",OR(ISNUMBER(FIND("연장",설정!$B$21)),ISNUMBER(FIND("야간",설정!$B$21)),ISNUMBER(FIND("휴일",설정!$B$21))),INDEX(직원목록!$J$7:$J$306,MATCH(3,직원목록!$B$7:$B$306,0))>0),"연장·야간·휴일 수당은 시간 수도 명세서에 적어야 하니 시간 열 지정 필요 / ","")&IF(AND(설정!$B$22<>"",설정!$C$22="",OR(ISNUMBER(FIND("연장",설정!$B$22)),ISNUMBER(FIND("야간",설정!$B$22)),ISNUMBER(FIND("휴일",설정!$B$22))),INDEX(직원목록!$K$7:$K$306,MATCH(3,직원목록!$B$7:$B$306,0))>0),"연장·야간·휴일 수당은 시간 수도 명세서에 적어야 하니 시간 열 지정 필요 / ","")&IF(AND(설정!$B$23<>"",설정!$C$23="",OR(ISNUMBER(FIND("연장",설정!$B$23)),ISNUMBER(FIND("야간",설정!$B$23)),ISNUMBER(FIND("휴일",설정!$B$23))),INDEX(직원목록!$L$7:$L$306,MATCH(3,직원목록!$B$7:$B$306,0))>0),"연장·야간·휴일 수당은 시간 수도 명세서에 적어야 하니 시간 열 지정 필요 / ","")&IF(AND(설정!$B$24<>"",설정!$C$24="",OR(ISNUMBER(FIND("연장",설정!$B$24)),ISNUMBER(FIND("야간",설정!$B$24)),ISNUMBER(FIND("휴일",설정!$B$24))),INDEX(직원목록!$M$7:$M$306,MATCH(3,직원목록!$B$7:$B$306,0))>0),"연장·야간·휴일 수당은 시간 수도 명세서에 적어야 하니 시간 열 지정 필요 / ",""))=0,"✔",("⚠ "&IF(AND(F15<>"",F15<>0),"계산 총지급과 대장 총지급이 다릅니다 / ","")&IF(AND(I15<>"",I15<>0),"계산 총공제와 대장 총공제가 다릅니다 / ","")&IF(J15<0,"실수령액이 음수입니다 / ","")&IF(COUNTIF(직원목록!$D$7:$D$306,B15)>1,"같은 이름이 둘 이상 — 미리보기는 첫 번째만 보입니다 / ","")&IF(AND(C15<>"",COUNTIF(직원목록!$C$7:$C$306,C15)>1),"사번 중복 / ","")&IF(D15=0,"총지급이 0원 — 머리글 매칭 확인 / ","")&IF(AND(설정!$B$17<>"",설정!$C$17="",OR(ISNUMBER(FIND("연장",설정!$B$17)),ISNUMBER(FIND("야간",설정!$B$17)),ISNUMBER(FIND("휴일",설정!$B$17))),INDEX(직원목록!$F$7:$F$306,MATCH(3,직원목록!$B$7:$B$306,0))>0),"연장·야간·휴일 수당은 시간 수도 명세서에 적어야 하니 시간 열 지정 필요 / ","")&IF(AND(설정!$B$18<>"",설정!$C$18="",OR(ISNUMBER(FIND("연장",설정!$B$18)),ISNUMBER(FIND("야간",설정!$B$18)),ISNUMBER(FIND("휴일",설정!$B$18))),INDEX(직원목록!$G$7:$G$306,MATCH(3,직원목록!$B$7:$B$306,0))>0),"연장·야간·휴일 수당은 시간 수도 명세서에 적어야 하니 시간 열 지정 필요 / ","")&IF(AND(설정!$B$19<>"",설정!$C$19="",OR(ISNUMBER(FIND("연장",설정!$B$19)),ISNUMBER(FIND("야간",설정!$B$19)),ISNUMBER(FIND("휴일",설정!$B$19))),INDEX(직원목록!$H$7:$H$306,MATCH(3,직원목록!$B$7:$B$306,0))>0),"연장·야간·휴일 수당은 시간 수도 명세서에 적어야 하니 시간 열 지정 필요 / ","")&IF(AND(설정!$B$20<>"",설정!$C$20="",OR(ISNUMBER(FIND("연장",설정!$B$20)),ISNUMBER(FIND("야간",설정!$B$20)),ISNUMBER(FIND("휴일",설정!$B$20))),INDEX(직원목록!$I$7:$I$306,MATCH(3,직원목록!$B$7:$B$306,0))>0),"연장·야간·휴일 수당은 시간 수도 명세서에 적어야 하니 시간 열 지정 필요 / ","")&IF(AND(설정!$B$21<>"",설정!$C$21="",OR(ISNUMBER(FIND("연장",설정!$B$21)),ISNUMBER(FIND("야간",설정!$B$21)),ISNUMBER(FIND("휴일",설정!$B$21))),INDEX(직원목록!$J$7:$J$306,MATCH(3,직원목록!$B$7:$B$306,0))>0),"연장·야간·휴일 수당은 시간 수도 명세서에 적어야 하니 시간 열 지정 필요 / ","")&IF(AND(설정!$B$22<>"",설정!$C$22="",OR(ISNUMBER(FIND("연장",설정!$B$22)),ISNUMBER(FIND("야간",설정!$B$22)),ISNUMBER(FIND("휴일",설정!$B$22))),INDEX(직원목록!$K$7:$K$306,MATCH(3,직원목록!$B$7:$B$306,0))>0),"연장·야간·휴일 수당은 시간 수도 명세서에 적어야 하니 시간 열 지정 필요 / ","")&IF(AND(설정!$B$23<>"",설정!$C$23="",OR(ISNUMBER(FIND("연장",설정!$B$23)),ISNUMBER(FIND("야간",설정!$B$23)),ISNUMBER(FIND("휴일",설정!$B$23))),INDEX(직원목록!$L$7:$L$306,MATCH(3,직원목록!$B$7:$B$306,0))>0),"연장·야간·휴일 수당은 시간 수도 명세서에 적어야 하니 시간 열 지정 필요 / ","")&IF(AND(설정!$B$24<>"",설정!$C$24="",OR(ISNUMBER(FIND("연장",설정!$B$24)),ISNUMBER(FIND("야간",설정!$B$24)),ISNUMBER(FIND("휴일",설정!$B$24))),INDEX(직원목록!$M$7:$M$306,MATCH(3,직원목록!$B$7:$B$306,0))>0),"연장·야간·휴일 수당은 시간 수도 명세서에 적어야 하니 시간 열 지정 필요 / ",""))))
A16: =IF(IFERROR(MATCH(4,직원목록!$B$7:$B$306,0),0)=0,"",4) | B16: =IF($A16="","",IFERROR(INDEX(직원목록!$D$7:$D$306,MATCH(4,직원목록!$B$7:$B$306,0)),"")) | C16: =IF($A16="","",IFERROR(INDEX(직원목록!$C$7:$C$306,MATCH(4,직원목록!$B$7:$B$306,0)),"")) | D16: =IF($A16="","",IFERROR(INDEX(직원목록!$V$7:$V$306,MATCH(4,직원목록!$B$7:$B$306,0)),"")) | E16: =IF($A16="","",IFERROR(INDEX(직원목록!$AG$7:$AG$306,MATCH(4,직원목록!$B$7:$B$306,0)),"")) | F16: =IF(OR($A16="",E16=""),"",D16-E16) | G16: =IF($A16="","",IFERROR(INDEX(직원목록!$AE$7:$AE$306,MATCH(4,직원목록!$B$7:$B$306,0)),"")) | H16: =IF($A16="","",IFERROR(INDEX(직원목록!$AH$7:$AH$306,MATCH(4,직원목록!$B$7:$B$306,0)),"")) | I16: =IF(OR($A16="",H16=""),"",G16-H16) | J16: =IF($A16="","",IFERROR(INDEX(직원목록!$AF$7:$AF$306,MATCH(4,직원목록!$B$7:$B$306,0)),"")) | K16: =IF($A16="","",IFERROR(INDEX(직원목록!$AI$7:$AI$306,MATCH(4,직원목록!$B$7:$B$306,0)),"")) | L16: =IF($A16="","",IF(LEN(IF(AND(F16<>"",F16<>0),"계산 총지급과 대장 총지급이 다릅니다 / ","")&IF(AND(I16<>"",I16<>0),"계산 총공제와 대장 총공제가 다릅니다 / ","")&IF(J16<0,"실수령액이 음수입니다 / ","")&IF(COUNTIF(직원목록!$D$7:$D$306,B16)>1,"같은 이름이 둘 이상 — 미리보기는 첫 번째만 보입니다 / ","")&IF(AND(C16<>"",COUNTIF(직원목록!$C$7:$C$306,C16)>1),"사번 중복 / ","")&IF(D16=0,"총지급이 0원 — 머리글 매칭 확인 / ","")&IF(AND(설정!$B$17<>"",설정!$C$17="",OR(ISNUMBER(FIND("연장",설정!$B$17)),ISNUMBER(FIND("야간",설정!$B$17)),ISNUMBER(FIND("휴일",설정!$B$17))),INDEX(직원목록!$F$7:$F$306,MATCH(4,직원목록!$B$7:$B$306,0))>0),"연장·야간·휴일 수당은 시간 수도 명세서에 적어야 하니 시간 열 지정 필요 / ","")&IF(AND(설정!$B$18<>"",설정!$C$18="",OR(ISNUMBER(FIND("연장",설정!$B$18)),ISNUMBER(FIND("야간",설정!$B$18)),ISNUMBER(FIND("휴일",설정!$B$18))),INDEX(직원목록!$G$7:$G$306,MATCH(4,직원목록!$B$7:$B$306,0))>0),"연장·야간·휴일 수당은 시간 수도 명세서에 적어야 하니 시간 열 지정 필요 / ","")&IF(AND(설정!$B$19<>"",설정!$C$19="",OR(ISNUMBER(FIND("연장",설정!$B$19)),ISNUMBER(FIND("야간",설정!$B$19)),ISNUMBER(FIND("휴일",설정!$B$19))),INDEX(직원목록!$H$7:$H$306,MATCH(4,직원목록!$B$7:$B$306,0))>0),"연장·야간·휴일 수당은 시간 수도 명세서에 적어야 하니 시간 열 지정 필요 / ","")&IF(AND(설정!$B$20<>"",설정!$C$20="",OR(ISNUMBER(FIND("연장",설정!$B$20)),ISNUMBER(FIND("야간",설정!$B$20)),ISNUMBER(FIND("휴일",설정!$B$20))),INDEX(직원목록!$I$7:$I$306,MATCH(4,직원목록!$B$7:$B$306,0))>0),"연장·야간·휴일 수당은 시간 수도 명세서에 적어야 하니 시간 열 지정 필요 / ","")&IF(AND(설정!$B$21<>"",설정!$C$21="",OR(ISNUMBER(FIND("연장",설정!$B$21)),ISNUMBER(FIND("야간",설정!$B$21)),ISNUMBER(FIND("휴일",설정!$B$21))),INDEX(직원목록!$J$7:$J$306,MATCH(4,직원목록!$B$7:$B$306,0))>0),"연장·야간·휴일 수당은 시간 수도 명세서에 적어야 하니 시간 열 지정 필요 / ","")&IF(AND(설정!$B$22<>"",설정!$C$22="",OR(ISNUMBER(FIND("연장",설정!$B$22)),ISNUMBER(FIND("야간",설정!$B$22)),ISNUMBER(FIND("휴일",설정!$B$22))),INDEX(직원목록!$K$7:$K$306,MATCH(4,직원목록!$B$7:$B$306,0))>0),"연장·야간·휴일 수당은 시간 수도 명세서에 적어야 하니 시간 열 지정 필요 / ","")&IF(AND(설정!$B$23<>"",설정!$C$23="",OR(ISNUMBER(FIND("연장",설정!$B$23)),ISNUMBER(FIND("야간",설정!$B$23)),ISNUMBER(FIND("휴일",설정!$B$23))),INDEX(직원목록!$L$7:$L$306,MATCH(4,직원목록!$B$7:$B$306,0))>0),"연장·야간·휴일 수당은 시간 수도 명세서에 적어야 하니 시간 열 지정 필요 / ","")&IF(AND(설정!$B$24<>"",설정!$C$24="",OR(ISNUMBER(FIND("연장",설정!$B$24)),ISNUMBER(FIND("야간",설정!$B$24)),ISNUMBER(FIND("휴일",설정!$B$24))),INDEX(직원목록!$M$7:$M$306,MATCH(4,직원목록!$B$7:$B$306,0))>0),"연장·야간·휴일 수당은 시간 수도 명세서에 적어야 하니 시간 열 지정 필요 / ",""))=0,"✔",("⚠ "&IF(AND(F16<>"",F16<>0),"계산 총지급과 대장 총지급이 다릅니다 / ","")&IF(AND(I16<>"",I16<>0),"계산 총공제와 대장 총공제가 다릅니다 / ","")&IF(J16<0,"실수령액이 음수입니다 / ","")&IF(COUNTIF(직원목록!$D$7:$D$306,B16)>1,"같은 이름이 둘 이상 — 미리보기는 첫 번째만 보입니다 / ","")&IF(AND(C16<>"",COUNTIF(직원목록!$C$7:$C$306,C16)>1),"사번 중복 / ","")&IF(D16=0,"총지급이 0원 — 머리글 매칭 확인 / ","")&IF(AND(설정!$B$17<>"",설정!$C$17="",OR(ISNUMBER(FIND("연장",설정!$B$17)),ISNUMBER(FIND("야간",설정!$B$17)),ISNUMBER(FIND("휴일",설정!$B$17))),INDEX(직원목록!$F$7:$F$306,MATCH(4,직원목록!$B$7:$B$306,0))>0),"연장·야간·휴일 수당은 시간 수도 명세서에 적어야 하니 시간 열 지정 필요 / ","")&IF(AND(설정!$B$18<>"",설정!$C$18="",OR(ISNUMBER(FIND("연장",설정!$B$18)),ISNUMBER(FIND("야간",설정!$B$18)),ISNUMBER(FIND("휴일",설정!$B$18))),INDEX(직원목록!$G$7:$G$306,MATCH(4,직원목록!$B$7:$B$306,0))>0),"연장·야간·휴일 수당은 시간 수도 명세서에 적어야 하니 시간 열 지정 필요 / ","")&IF(AND(설정!$B$19<>"",설정!$C$19="",OR(ISNUMBER(FIND("연장",설정!$B$19)),ISNUMBER(FIND("야간",설정!$B$19)),ISNUMBER(FIND("휴일",설정!$B$19))),INDEX(직원목록!$H$7:$H$306,MATCH(4,직원목록!$B$7:$B$306,0))>0),"연장·야간·휴일 수당은 시간 수도 명세서에 적어야 하니 시간 열 지정 필요 / ","")&IF(AND(설정!$B$20<>"",설정!$C$20="",OR(ISNUMBER(FIND("연장",설정!$B$20)),ISNUMBER(FIND("야간",설정!$B$20)),ISNUMBER(FIND("휴일",설정!$B$20))),INDEX(직원목록!$I$7:$I$306,MATCH(4,직원목록!$B$7:$B$306,0))>0),"연장·야간·휴일 수당은 시간 수도 명세서에 적어야 하니 시간 열 지정 필요 / ","")&IF(AND(설정!$B$21<>"",설정!$C$21="",OR(ISNUMBER(FIND("연장",설정!$B$21)),ISNUMBER(FIND("야간",설정!$B$21)),ISNUMBER(FIND("휴일",설정!$B$21))),INDEX(직원목록!$J$7:$J$306,MATCH(4,직원목록!$B$7:$B$306,0))>0),"연장·야간·휴일 수당은 시간 수도 명세서에 적어야 하니 시간 열 지정 필요 / ","")&IF(AND(설정!$B$22<>"",설정!$C$22="",OR(ISNUMBER(FIND("연장",설정!$B$22)),ISNUMBER(FIND("야간",설정!$B$22)),ISNUMBER(FIND("휴일",설정!$B$22))),INDEX(직원목록!$K$7:$K$306,MATCH(4,직원목록!$B$7:$B$306,0))>0),"연장·야간·휴일 수당은 시간 수도 명세서에 적어야 하니 시간 열 지정 필요 / ","")&IF(AND(설정!$B$23<>"",설정!$C$23="",OR(ISNUMBER(FIND("연장",설정!$B$23)),ISNUMBER(FIND("야간",설정!$B$23)),ISNUMBER(FIND("휴일",설정!$B$23))),INDEX(직원목록!$L$7:$L$306,MATCH(4,직원목록!$B$7:$B$306,0))>0),"연장·야간·휴일 수당은 시간 수도 명세서에 적어야 하니 시간 열 지정 필요 / ","")&IF(AND(설정!$B$24<>"",설정!$C$24="",OR(ISNUMBER(FIND("연장",설정!$B$24)),ISNUMBER(FIND("야간",설정!$B$24)),ISNUMBER(FIND("휴일",설정!$B$24))),INDEX(직원목록!$M$7:$M$306,MATCH(4,직원목록!$B$7:$B$306,0))>0),"연장·야간·휴일 수당은 시간 수도 명세서에 적어야 하니 시간 열 지정 필요 / ",""))))
A17: =IF(IFERROR(MATCH(5,직원목록!$B$7:$B$306,0),0)=0,"",5) | B17: =IF($A17="","",IFERROR(INDEX(직원목록!$D$7:$D$306,MATCH(5,직원목록!$B$7:$B$306,0)),"")) | C17: =IF($A17="","",IFERROR(INDEX(직원목록!$C$7:$C$306,MATCH(5,직원목록!$B$7:$B$306,0)),"")) | D17: =IF($A17="","",IFERROR(INDEX(직원목록!$V$7:$V$306,MATCH(5,직원목록!$B$7:$B$306,0)),"")) | E17: =IF($A17="","",IFERROR(INDEX(직원목록!$AG$7:$AG$306,MATCH(5,직원목록!$B$7:$B$306,0)),"")) | F17: =IF(OR($A17="",E17=""),"",D17-E17) | G17: =IF($A17="","",IFERROR(INDEX(직원목록!$AE$7:$AE$306,MATCH(5,직원목록!$B$7:$B$306,0)),"")) | H17: =IF($A17="","",IFERROR(INDEX(직원목록!$AH$7:$AH$306,MATCH(5,직원목록!$B$7:$B$306,0)),"")) | I17: =IF(OR($A17="",H17=""),"",G17-H17) | J17: =IF($A17="","",IFERROR(INDEX(직원목록!$AF$7:$AF$306,MATCH(5,직원목록!$B$7:$B$306,0)),"")) | K17: =IF($A17="","",IFERROR(INDEX(직원목록!$AI$7:$AI$306,MATCH(5,직원목록!$B$7:$B$306,0)),"")) | L17: =IF($A17="","",IF(LEN(IF(AND(F17<>"",F17<>0),"계산 총지급과 대장 총지급이 다릅니다 / ","")&IF(AND(I17<>"",I17<>0),"계산 총공제와 대장 총공제가 다릅니다 / ","")&IF(J17<0,"실수령액이 음수입니다 / ","")&IF(COUNTIF(직원목록!$D$7:$D$306,B17)>1,"같은 이름이 둘 이상 — 미리보기는 첫 번째만 보입니다 / ","")&IF(AND(C17<>"",COUNTIF(직원목록!$C$7:$C$306,C17)>1),"사번 중복 / ","")&IF(D17=0,"총지급이 0원 — 머리글 매칭 확인 / ","")&IF(AND(설정!$B$17<>"",설정!$C$17="",OR(ISNUMBER(FIND("연장",설정!$B$17)),ISNUMBER(FIND("야간",설정!$B$17)),ISNUMBER(FIND("휴일",설정!$B$17))),INDEX(직원목록!$F$7:$F$306,MATCH(5,직원목록!$B$7:$B$306,0))>0),"연장·야간·휴일 수당은 시간 수도 명세서에 적어야 하니 시간 열 지정 필요 / ","")&IF(AND(설정!$B$18<>"",설정!$C$18="",OR(ISNUMBER(FIND("연장",설정!$B$18)),ISNUMBER(FIND("야간",설정!$B$18)),ISNUMBER(FIND("휴일",설정!$B$18))),INDEX(직원목록!$G$7:$G$306,MATCH(5,직원목록!$B$7:$B$306,0))>0),"연장·야간·휴일 수당은 시간 수도 명세서에 적어야 하니 시간 열 지정 필요 / ","")&IF(AND(설정!$B$19<>"",설정!$C$19="",OR(ISNUMBER(FIND("연장",설정!$B$19)),ISNUMBER(FIND("야간",설정!$B$19)),ISNUMBER(FIND("휴일",설정!$B$19))),INDEX(직원목록!$H$7:$H$306,MATCH(5,직원목록!$B$7:$B$306,0))>0),"연장·야간·휴일 수당은 시간 수도 명세서에 적어야 하니 시간 열 지정 필요 / ","")&IF(AND(설정!$B$20<>"",설정!$C$20="",OR(ISNUMBER(FIND("연장",설정!$B$20)),ISNUMBER(FIND("야간",설정!$B$20)),ISNUMBER(FIND("휴일",설정!$B$20))),INDEX(직원목록!$I$7:$I$306,MATCH(5,직원목록!$B$7:$B$306,0))>0),"연장·야간·휴일 수당은 시간 수도 명세서에 적어야 하니 시간 열 지정 필요 / ","")&IF(AND(설정!$B$21<>"",설정!$C$21="",OR(ISNUMBER(FIND("연장",설정!$B$21)),ISNUMBER(FIND("야간",설정!$B$21)),ISNUMBER(FIND("휴일",설정!$B$21))),INDEX(직원목록!$J$7:$J$306,MATCH(5,직원목록!$B$7:$B$306,0))>0),"연장·야간·휴일 수당은 시간 수도 명세서에 적어야 하니 시간 열 지정 필요 / ","")&IF(AND(설정!$B$22<>"",설정!$C$22="",OR(ISNUMBER(FIND("연장",설정!$B$22)),ISNUMBER(FIND("야간",설정!$B$22)),ISNUMBER(FIND("휴일",설정!$B$22))),INDEX(직원목록!$K$7:$K$306,MATCH(5,직원목록!$B$7:$B$306,0))>0),"연장·야간·휴일 수당은 시간 수도 명세서에 적어야 하니 시간 열 지정 필요 / ","")&IF(AND(설정!$B$23<>"",설정!$C$23="",OR(ISNUMBER(FIND("연장",설정!$B$23)),ISNUMBER(FIND("야간",설정!$B$23)),ISNUMBER(FIND("휴일",설정!$B$23))),INDEX(직원목록!$L$7:$L$306,MATCH(5,직원목록!$B$7:$B$306,0))>0),"연장·야간·휴일 수당은 시간 수도 명세서에 적어야 하니 시간 열 지정 필요 / ","")&IF(AND(설정!$B$24<>"",설정!$C$24="",OR(ISNUMBER(FIND("연장",설정!$B$24)),ISNUMBER(FIND("야간",설정!$B$24)),ISNUMBER(FIND("휴일",설정!$B$24))),INDEX(직원목록!$M$7:$M$306,MATCH(5,직원목록!$B$7:$B$306,0))>0),"연장·야간·휴일 수당은 시간 수도 명세서에 적어야 하니 시간 열 지정 필요 / ",""))=0,"✔",("⚠ "&IF(AND(F17<>"",F17<>0),"계산 총지급과 대장 총지급이 다릅니다 / ","")&IF(AND(I17<>"",I17<>0),"계산 총공제와 대장 총공제가 다릅니다 / ","")&IF(J17<0,"실수령액이 음수입니다 / ","")&IF(COUNTIF(직원목록!$D$7:$D$306,B17)>1,"같은 이름이 둘 이상 — 미리보기는 첫 번째만 보입니다 / ","")&IF(AND(C17<>"",COUNTIF(직원목록!$C$7:$C$306,C17)>1),"사번 중복 / ","")&IF(D17=0,"총지급이 0원 — 머리글 매칭 확인 / ","")&IF(AND(설정!$B$17<>"",설정!$C$17="",OR(ISNUMBER(FIND("연장",설정!$B$17)),ISNUMBER(FIND("야간",설정!$B$17)),ISNUMBER(FIND("휴일",설정!$B$17))),INDEX(직원목록!$F$7:$F$306,MATCH(5,직원목록!$B$7:$B$306,0))>0),"연장·야간·휴일 수당은 시간 수도 명세서에 적어야 하니 시간 열 지정 필요 / ","")&IF(AND(설정!$B$18<>"",설정!$C$18="",OR(ISNUMBER(FIND("연장",설정!$B$18)),ISNUMBER(FIND("야간",설정!$B$18)),ISNUMBER(FIND("휴일",설정!$B$18))),INDEX(직원목록!$G$7:$G$306,MATCH(5,직원목록!$B$7:$B$306,0))>0),"연장·야간·휴일 수당은 시간 수도 명세서에 적어야 하니 시간 열 지정 필요 / ","")&IF(AND(설정!$B$19<>"",설정!$C$19="",OR(ISNUMBER(FIND("연장",설정!$B$19)),ISNUMBER(FIND("야간",설정!$B$19)),ISNUMBER(FIND("휴일",설정!$B$19))),INDEX(직원목록!$H$7:$H$306,MATCH(5,직원목록!$B$7:$B$306,0))>0),"연장·야간·휴일 수당은 시간 수도 명세서에 적어야 하니 시간 열 지정 필요 / ","")&IF(AND(설정!$B$20<>"",설정!$C$20="",OR(ISNUMBER(FIND("연장",설정!$B$20)),ISNUMBER(FIND("야간",설정!$B$20)),ISNUMBER(FIND("휴일",설정!$B$20))),INDEX(직원목록!$I$7:$I$306,MATCH(5,직원목록!$B$7:$B$306,0))>0),"연장·야간·휴일 수당은 시간 수도 명세서에 적어야 하니 시간 열 지정 필요 / ","")&IF(AND(설정!$B$21<>"",설정!$C$21="",OR(ISNUMBER(FIND("연장",설정!$B$21)),ISNUMBER(FIND("야간",설정!$B$21)),ISNUMBER(FIND("휴일",설정!$B$21))),INDEX(직원목록!$J$7:$J$306,MATCH(5,직원목록!$B$7:$B$306,0))>0),"연장·야간·휴일 수당은 시간 수도 명세서에 적어야 하니 시간 열 지정 필요 / ","")&IF(AND(설정!$B$22<>"",설정!$C$22="",OR(ISNUMBER(FIND("연장",설정!$B$22)),ISNUMBER(FIND("야간",설정!$B$22)),ISNUMBER(FIND("휴일",설정!$B$22))),INDEX(직원목록!$K$7:$K$306,MATCH(5,직원목록!$B$7:$B$306,0))>0),"연장·야간·휴일 수당은 시간 수도 명세서에 적어야 하니 시간 열 지정 필요 / ","")&IF(AND(설정!$B$23<>"",설정!$C$23="",OR(ISNUMBER(FIND("연장",설정!$B$23)),ISNUMBER(FIND("야간",설정!$B$23)),ISNUMBER(FIND("휴일",설정!$B$23))),INDEX(직원목록!$L$7:$L$306,MATCH(5,직원목록!$B$7:$B$306,0))>0),"연장·야간·휴일 수당은 시간 수도 명세서에 적어야 하니 시간 열 지정 필요 / ","")&IF(AND(설정!$B$24<>"",설정!$C$24="",OR(ISNUMBER(FIND("연장",설정!$B$24)),ISNUMBER(FIND("야간",설정!$B$24)),ISNUMBER(FIND("휴일",설정!$B$24))),INDEX(직원목록!$M$7:$M$306,MATCH(5,직원목록!$B$7:$B$306,0))>0),"연장·야간·휴일 수당은 시간 수도 명세서에 적어야 하니 시간 열 지정 필요 / ",""))))
A18: =IF(IFERROR(MATCH(6,직원목록!$B$7:$B$306,0),0)=0,"",6) | B18: =IF($A18="","",IFERROR(INDEX(직원목록!$D$7:$D$306,MATCH(6,직원목록!$B$7:$B$306,0)),"")) | C18: =IF($A18="","",IFERROR(INDEX(직원목록!$C$7:$C$306,MATCH(6,직원목록!$B$7:$B$306,0)),"")) | D18: =IF($A18="","",IFERROR(INDEX(직원목록!$V$7:$V$306,MATCH(6,직원목록!$B$7:$B$306,0)),"")) | E18: =IF($A18="","",IFERROR(INDEX(직원목록!$AG$7:$AG$306,MATCH(6,직원목록!$B$7:$B$306,0)),"")) | F18: =IF(OR($A18="",E18=""),"",D18-E18) | G18: =IF($A18="","",IFERROR(INDEX(직원목록!$AE$7:$AE$306,MATCH(6,직원목록!$B$7:$B$306,0)),"")) | H18: =IF($A18="","",IFERROR(INDEX(직원목록!$AH$7:$AH$306,MATCH(6,직원목록!$B$7:$B$306,0)),"")) | I18: =IF(OR($A18="",H18=""),"",G18-H18) | J18: =IF($A18="","",IFERROR(INDEX(직원목록!$AF$7:$AF$306,MATCH(6,직원목록!$B$7:$B$306,0)),"")) | K18: =IF($A18="","",IFERROR(INDEX(직원목록!$AI$7:$AI$306,MATCH(6,직원목록!$B$7:$B$306,0)),"")) | L18: =IF($A18="","",IF(LEN(IF(AND(F18<>"",F18<>0),"계산 총지급과 대장 총지급이 다릅니다 / ","")&IF(AND(I18<>"",I18<>0),"계산 총공제와 대장 총공제가 다릅니다 / ","")&IF(J18<0,"실수령액이 음수입니다 / ","")&IF(COUNTIF(직원목록!$D$7:$D$306,B18)>1,"같은 이름이 둘 이상 — 미리보기는 첫 번째만 보입니다 / ","")&IF(AND(C18<>"",COUNTIF(직원목록!$C$7:$C$306,C18)>1),"사번 중복 / ","")&IF(D18=0,"총지급이 0원 — 머리글 매칭 확인 / ","")&IF(AND(설정!$B$17<>"",설정!$C$17="",OR(ISNUMBER(FIND("연장",설정!$B$17)),ISNUMBER(FIND("야간",설정!$B$17)),ISNUMBER(FIND("휴일",설정!$B$17))),INDEX(직원목록!$F$7:$F$306,MATCH(6,직원목록!$B$7:$B$306,0))>0),"연장·야간·휴일 수당은 시간 수도 명세서에 적어야 하니 시간 열 지정 필요 / ","")&IF(AND(설정!$B$18<>"",설정!$C$18="",OR(ISNUMBER(FIND("연장",설정!$B$18)),ISNUMBER(FIND("야간",설정!$B$18)),ISNUMBER(FIND("휴일",설정!$B$18))),INDEX(직원목록!$G$7:$G$306,MATCH(6,직원목록!$B$7:$B$306,0))>0),"연장·야간·휴일 수당은 시간 수도 명세서에 적어야 하니 시간 열 지정 필요 / ","")&IF(AND(설정!$B$19<>"",설정!$C$19="",OR(ISNUMBER(FIND("연장",설정!$B$19)),ISNUMBER(FIND("야간",설정!$B$19)),ISNUMBER(FIND("휴일",설정!$B$19))),INDEX(직원목록!$H$7:$H$306,MATCH(6,직원목록!$B$7:$B$306,0))>0),"연장·야간·휴일 수당은 시간 수도 명세서에 적어야 하니 시간 열 지정 필요 / ","")&IF(AND(설정!$B$20<>"",설정!$C$20="",OR(ISNUMBER(FIND("연장",설정!$B$20)),ISNUMBER(FIND("야간",설정!$B$20)),ISNUMBER(FIND("휴일",설정!$B$20))),INDEX(직원목록!$I$7:$I$306,MATCH(6,직원목록!$B$7:$B$306,0))>0),"연장·야간·휴일 수당은 시간 수도 명세서에 적어야 하니 시간 열 지정 필요 / ","")&IF(AND(설정!$B$21<>"",설정!$C$21="",OR(ISNUMBER(FIND("연장",설정!$B$21)),ISNUMBER(FIND("야간",설정!$B$21)),ISNUMBER(FIND("휴일",설정!$B$21))),INDEX(직원목록!$J$7:$J$306,MATCH(6,직원목록!$B$7:$B$306,0))>0),"연장·야간·휴일 수당은 시간 수도 명세서에 적어야 하니 시간 열 지정 필요 / ","")&IF(AND(설정!$B$22<>"",설정!$C$22="",OR(ISNUMBER(FIND("연장",설정!$B$22)),ISNUMBER(FIND("야간",설정!$B$22)),ISNUMBER(FIND("휴일",설정!$B$22))),INDEX(직원목록!$K$7:$K$306,MATCH(6,직원목록!$B$7:$B$306,0))>0),"연장·야간·휴일 수당은 시간 수도 명세서에 적어야 하니 시간 열 지정 필요 / ","")&IF(AND(설정!$B$23<>"",설정!$C$23="",OR(ISNUMBER(FIND("연장",설정!$B$23)),ISNUMBER(FIND("야간",설정!$B$23)),ISNUMBER(FIND("휴일",설정!$B$23))),INDEX(직원목록!$L$7:$L$306,MATCH(6,직원목록!$B$7:$B$306,0))>0),"연장·야간·휴일 수당은 시간 수도 명세서에 적어야 하니 시간 열 지정 필요 / ","")&IF(AND(설정!$B$24<>"",설정!$C$24="",OR(ISNUMBER(FIND("연장",설정!$B$24)),ISNUMBER(FIND("야간",설정!$B$24)),ISNUMBER(FIND("휴일",설정!$B$24))),INDEX(직원목록!$M$7:$M$306,MATCH(6,직원목록!$B$7:$B$306,0))>0),"연장·야간·휴일 수당은 시간 수도 명세서에 적어야 하니 시간 열 지정 필요 / ",""))=0,"✔",("⚠ "&IF(AND(F18<>"",F18<>0),"계산 총지급과 대장 총지급이 다릅니다 / ","")&IF(AND(I18<>"",I18<>0),"계산 총공제와 대장 총공제가 다릅니다 / ","")&IF(J18<0,"실수령액이 음수입니다 / ","")&IF(COUNTIF(직원목록!$D$7:$D$306,B18)>1,"같은 이름이 둘 이상 — 미리보기는 첫 번째만 보입니다 / ","")&IF(AND(C18<>"",COUNTIF(직원목록!$C$7:$C$306,C18)>1),"사번 중복 / ","")&IF(D18=0,"총지급이 0원 — 머리글 매칭 확인 / ","")&IF(AND(설정!$B$17<>"",설정!$C$17="",OR(ISNUMBER(FIND("연장",설정!$B$17)),ISNUMBER(FIND("야간",설정!$B$17)),ISNUMBER(FIND("휴일",설정!$B$17))),INDEX(직원목록!$F$7:$F$306,MATCH(6,직원목록!$B$7:$B$306,0))>0),"연장·야간·휴일 수당은 시간 수도 명세서에 적어야 하니 시간 열 지정 필요 / ","")&IF(AND(설정!$B$18<>"",설정!$C$18="",OR(ISNUMBER(FIND("연장",설정!$B$18)),ISNUMBER(FIND("야간",설정!$B$18)),ISNUMBER(FIND("휴일",설정!$B$18))),INDEX(직원목록!$G$7:$G$306,MATCH(6,직원목록!$B$7:$B$306,0))>0),"연장·야간·휴일 수당은 시간 수도 명세서에 적어야 하니 시간 열 지정 필요 / ","")&IF(AND(설정!$B$19<>"",설정!$C$19="",OR(ISNUMBER(FIND("연장",설정!$B$19)),ISNUMBER(FIND("야간",설정!$B$19)),ISNUMBER(FIND("휴일",설정!$B$19))),INDEX(직원목록!$H$7:$H$306,MATCH(6,직원목록!$B$7:$B$306,0))>0),"연장·야간·휴일 수당은 시간 수도 명세서에 적어야 하니 시간 열 지정 필요 / ","")&IF(AND(설정!$B$20<>"",설정!$C$20="",OR(ISNUMBER(FIND("연장",설정!$B$20)),ISNUMBER(FIND("야간",설정!$B$20)),ISNUMBER(FIND("휴일",설정!$B$20))),INDEX(직원목록!$I$7:$I$306,MATCH(6,직원목록!$B$7:$B$306,0))>0),"연장·야간·휴일 수당은 시간 수도 명세서에 적어야 하니 시간 열 지정 필요 / ","")&IF(AND(설정!$B$21<>"",설정!$C$21="",OR(ISNUMBER(FIND("연장",설정!$B$21)),ISNUMBER(FIND("야간",설정!$B$21)),ISNUMBER(FIND("휴일",설정!$B$21))),INDEX(직원목록!$J$7:$J$306,MATCH(6,직원목록!$B$7:$B$306,0))>0),"연장·야간·휴일 수당은 시간 수도 명세서에 적어야 하니 시간 열 지정 필요 / ","")&IF(AND(설정!$B$22<>"",설정!$C$22="",OR(ISNUMBER(FIND("연장",설정!$B$22)),ISNUMBER(FIND("야간",설정!$B$22)),ISNUMBER(FIND("휴일",설정!$B$22))),INDEX(직원목록!$K$7:$K$306,MATCH(6,직원목록!$B$7:$B$306,0))>0),"연장·야간·휴일 수당은 시간 수도 명세서에 적어야 하니 시간 열 지정 필요 / ","")&IF(AND(설정!$B$23<>"",설정!$C$23="",OR(ISNUMBER(FIND("연장",설정!$B$23)),ISNUMBER(FIND("야간",설정!$B$23)),ISNUMBER(FIND("휴일",설정!$B$23))),INDEX(직원목록!$L$7:$L$306,MATCH(6,직원목록!$B$7:$B$306,0))>0),"연장·야간·휴일 수당은 시간 수도 명세서에 적어야 하니 시간 열 지정 필요 / ","")&IF(AND(설정!$B$24<>"",설정!$C$24="",OR(ISNUMBER(FIND("연장",설정!$B$24)),ISNUMBER(FIND("야간",설정!$B$24)),ISNUMBER(FIND("휴일",설정!$B$24))),INDEX(직원목록!$M$7:$M$306,MATCH(6,직원목록!$B$7:$B$306,0))>0),"연장·야간·휴일 수당은 시간 수도 명세서에 적어야 하니 시간 열 지정 필요 / ",""))))
A19: =IF(IFERROR(MATCH(7,직원목록!$B$7:$B$306,0),0)=0,"",7) | B19: =IF($A19="","",IFERROR(INDEX(직원목록!$D$7:$D$306,MATCH(7,직원목록!$B$7:$B$306,0)),"")) | C19: =IF($A19="","",IFERROR(INDEX(직원목록!$C$7:$C$306,MATCH(7,직원목록!$B$7:$B$306,0)),"")) | D19: =IF($A19="","",IFERROR(INDEX(직원목록!$V$7:$V$306,MATCH(7,직원목록!$B$7:$B$306,0)),"")) | E19: =IF($A19="","",IFERROR(INDEX(직원목록!$AG$7:$AG$306,MATCH(7,직원목록!$B$7:$B$306,0)),"")) | F19: =IF(OR($A19="",E19=""),"",D19-E19) | G19: =IF($A19="","",IFERROR(INDEX(직원목록!$AE$7:$AE$306,MATCH(7,직원목록!$B$7:$B$306,0)),"")) | H19: =IF($A19="","",IFERROR(INDEX(직원목록!$AH$7:$AH$306,MATCH(7,직원목록!$B$7:$B$306,0)),"")) | I19: =IF(OR($A19="",H19=""),"",G19-H19) | J19: =IF($A19="","",IFERROR(INDEX(직원목록!$AF$7:$AF$306,MATCH(7,직원목록!$B$7:$B$306,0)),"")) | K19: =IF($A19="","",IFERROR(INDEX(직원목록!$AI$7:$AI$306,MATCH(7,직원목록!$B$7:$B$306,0)),"")) | L19: =IF($A19="","",IF(LEN(IF(AND(F19<>"",F19<>0),"계산 총지급과 대장 총지급이 다릅니다 / ","")&IF(AND(I19<>"",I19<>0),"계산 총공제와 대장 총공제가 다릅니다 / ","")&IF(J19<0,"실수령액이 음수입니다 / ","")&IF(COUNTIF(직원목록!$D$7:$D$306,B19)>1,"같은 이름이 둘 이상 — 미리보기는 첫 번째만 보입니다 / ","")&IF(AND(C19<>"",COUNTIF(직원목록!$C$7:$C$306,C19)>1),"사번 중복 / ","")&IF(D19=0,"총지급이 0원 — 머리글 매칭 확인 / ","")&IF(AND(설정!$B$17<>"",설정!$C$17="",OR(ISNUMBER(FIND("연장",설정!$B$17)),ISNUMBER(FIND("야간",설정!$B$17)),ISNUMBER(FIND("휴일",설정!$B$17))),INDEX(직원목록!$F$7:$F$306,MATCH(7,직원목록!$B$7:$B$306,0))>0),"연장·야간·휴일 수당은 시간 수도 명세서에 적어야 하니 시간 열 지정 필요 / ","")&IF(AND(설정!$B$18<>"",설정!$C$18="",OR(ISNUMBER(FIND("연장",설정!$B$18)),ISNUMBER(FIND("야간",설정!$B$18)),ISNUMBER(FIND("휴일",설정!$B$18))),INDEX(직원목록!$G$7:$G$306,MATCH(7,직원목록!$B$7:$B$306,0))>0),"연장·야간·휴일 수당은 시간 수도 명세서에 적어야 하니 시간 열 지정 필요 / ","")&IF(AND(설정!$B$19<>"",설정!$C$19="",OR(ISNUMBER(FIND("연장",설정!$B$19)),ISNUMBER(FIND("야간",설정!$B$19)),ISNUMBER(FIND("휴일",설정!$B$19))),INDEX(직원목록!$H$7:$H$306,MATCH(7,직원목록!$B$7:$B$306,0))>0),"연장·야간·휴일 수당은 시간 수도 명세서에 적어야 하니 시간 열 지정 필요 / ","")&IF(AND(설정!$B$20<>"",설정!$C$20="",OR(ISNUMBER(FIND("연장",설정!$B$20)),ISNUMBER(FIND("야간",설정!$B$20)),ISNUMBER(FIND("휴일",설정!$B$20))),INDEX(직원목록!$I$7:$I$306,MATCH(7,직원목록!$B$7:$B$306,0))>0),"연장·야간·휴일 수당은 시간 수도 명세서에 적어야 하니 시간 열 지정 필요 / ","")&IF(AND(설정!$B$21<>"",설정!$C$21="",OR(ISNUMBER(FIND("연장",설정!$B$21)),ISNUMBER(FIND("야간",설정!$B$21)),ISNUMBER(FIND("휴일",설정!$B$21))),INDEX(직원목록!$J$7:$J$306,MATCH(7,직원목록!$B$7:$B$306,0))>0),"연장·야간·휴일 수당은 시간 수도 명세서에 적어야 하니 시간 열 지정 필요 / ","")&IF(AND(설정!$B$22<>"",설정!$C$22="",OR(ISNUMBER(FIND("연장",설정!$B$22)),ISNUMBER(FIND("야간",설정!$B$22)),ISNUMBER(FIND("휴일",설정!$B$22))),INDEX(직원목록!$K$7:$K$306,MATCH(7,직원목록!$B$7:$B$306,0))>0),"연장·야간·휴일 수당은 시간 수도 명세서에 적어야 하니 시간 열 지정 필요 / ","")&IF(AND(설정!$B$23<>"",설정!$C$23="",OR(ISNUMBER(FIND("연장",설정!$B$23)),ISNUMBER(FIND("야간",설정!$B$23)),ISNUMBER(FIND("휴일",설정!$B$23))),INDEX(직원목록!$L$7:$L$306,MATCH(7,직원목록!$B$7:$B$306,0))>0),"연장·야간·휴일 수당은 시간 수도 명세서에 적어야 하니 시간 열 지정 필요 / ","")&IF(AND(설정!$B$24<>"",설정!$C$24="",OR(ISNUMBER(FIND("연장",설정!$B$24)),ISNUMBER(FIND("야간",설정!$B$24)),ISNUMBER(FIND("휴일",설정!$B$24))),INDEX(직원목록!$M$7:$M$306,MATCH(7,직원목록!$B$7:$B$306,0))>0),"연장·야간·휴일 수당은 시간 수도 명세서에 적어야 하니 시간 열 지정 필요 / ",""))=0,"✔",("⚠ "&IF(AND(F19<>"",F19<>0),"계산 총지급과 대장 총지급이 다릅니다 / ","")&IF(AND(I19<>"",I19<>0),"계산 총공제와 대장 총공제가 다릅니다 / ","")&IF(J19<0,"실수령액이 음수입니다 / ","")&IF(COUNTIF(직원목록!$D$7:$D$306,B19)>1,"같은 이름이 둘 이상 — 미리보기는 첫 번째만 보입니다 / ","")&IF(AND(C19<>"",COUNTIF(직원목록!$C$7:$C$306,C19)>1),"사번 중복 / ","")&IF(D19=0,"총지급이 0원 — 머리글 매칭 확인 / ","")&IF(AND(설정!$B$17<>"",설정!$C$17="",OR(ISNUMBER(FIND("연장",설정!$B$17)),ISNUMBER(FIND("야간",설정!$B$17)),ISNUMBER(FIND("휴일",설정!$B$17))),INDEX(직원목록!$F$7:$F$306,MATCH(7,직원목록!$B$7:$B$306,0))>0),"연장·야간·휴일 수당은 시간 수도 명세서에 적어야 하니 시간 열 지정 필요 / ","")&IF(AND(설정!$B$18<>"",설정!$C$18="",OR(ISNUMBER(FIND("연장",설정!$B$18)),ISNUMBER(FIND("야간",설정!$B$18)),ISNUMBER(FIND("휴일",설정!$B$18))),INDEX(직원목록!$G$7:$G$306,MATCH(7,직원목록!$B$7:$B$306,0))>0),"연장·야간·휴일 수당은 시간 수도 명세서에 적어야 하니 시간 열 지정 필요 / ","")&IF(AND(설정!$B$19<>"",설정!$C$19="",OR(ISNUMBER(FIND("연장",설정!$B$19)),ISNUMBER(FIND("야간",설정!$B$19)),ISNUMBER(FIND("휴일",설정!$B$19))),INDEX(직원목록!$H$7:$H$306,MATCH(7,직원목록!$B$7:$B$306,0))>0),"연장·야간·휴일 수당은 시간 수도 명세서에 적어야 하니 시간 열 지정 필요 / ","")&IF(AND(설정!$B$20<>"",설정!$C$20="",OR(ISNUMBER(FIND("연장",설정!$B$20)),ISNUMBER(FIND("야간",설정!$B$20)),ISNUMBER(FIND("휴일",설정!$B$20))),INDEX(직원목록!$I$7:$I$306,MATCH(7,직원목록!$B$7:$B$306,0))>0),"연장·야간·휴일 수당은 시간 수도 명세서에 적어야 하니 시간 열 지정 필요 / ","")&IF(AND(설정!$B$21<>"",설정!$C$21="",OR(ISNUMBER(FIND("연장",설정!$B$21)),ISNUMBER(FIND("야간",설정!$B$21)),ISNUMBER(FIND("휴일",설정!$B$21))),INDEX(직원목록!$J$7:$J$306,MATCH(7,직원목록!$B$7:$B$306,0))>0),"연장·야간·휴일 수당은 시간 수도 명세서에 적어야 하니 시간 열 지정 필요 / ","")&IF(AND(설정!$B$22<>"",설정!$C$22="",OR(ISNUMBER(FIND("연장",설정!$B$22)),ISNUMBER(FIND("야간",설정!$B$22)),ISNUMBER(FIND("휴일",설정!$B$22))),INDEX(직원목록!$K$7:$K$306,MATCH(7,직원목록!$B$7:$B$306,0))>0),"연장·야간·휴일 수당은 시간 수도 명세서에 적어야 하니 시간 열 지정 필요 / ","")&IF(AND(설정!$B$23<>"",설정!$C$23="",OR(ISNUMBER(FIND("연장",설정!$B$23)),ISNUMBER(FIND("야간",설정!$B$23)),ISNUMBER(FIND("휴일",설정!$B$23))),INDEX(직원목록!$L$7:$L$306,MATCH(7,직원목록!$B$7:$B$306,0))>0),"연장·야간·휴일 수당은 시간 수도 명세서에 적어야 하니 시간 열 지정 필요 / ","")&IF(AND(설정!$B$24<>"",설정!$C$24="",OR(ISNUMBER(FIND("연장",설정!$B$24)),ISNUMBER(FIND("야간",설정!$B$24)),ISNUMBER(FIND("휴일",설정!$B$24))),INDEX(직원목록!$M$7:$M$306,MATCH(7,직원목록!$B$7:$B$306,0))>0),"연장·야간·휴일 수당은 시간 수도 명세서에 적어야 하니 시간 열 지정 필요 / ",""))))
A20: =IF(IFERROR(MATCH(8,직원목록!$B$7:$B$306,0),0)=0,"",8) | B20: =IF($A20="","",IFERROR(INDEX(직원목록!$D$7:$D$306,MATCH(8,직원목록!$B$7:$B$306,0)),"")) | C20: =IF($A20="","",IFERROR(INDEX(직원목록!$C$7:$C$306,MATCH(8,직원목록!$B$7:$B$306,0)),"")) | D20: =IF($A20="","",IFERROR(INDEX(직원목록!$V$7:$V$306,MATCH(8,직원목록!$B$7:$B$306,0)),"")) | E20: =IF($A20="","",IFERROR(INDEX(직원목록!$AG$7:$AG$306,MATCH(8,직원목록!$B$7:$B$306,0)),"")) | F20: =IF(OR($A20="",E20=""),"",D20-E20) | G20: =IF($A20="","",IFERROR(INDEX(직원목록!$AE$7:$AE$306,MATCH(8,직원목록!$B$7:$B$306,0)),"")) | H20: =IF($A20="","",IFERROR(INDEX(직원목록!$AH$7:$AH$306,MATCH(8,직원목록!$B$7:$B$306,0)),"")) | I20: =IF(OR($A20="",H20=""),"",G20-H20) | J20: =IF($A20="","",IFERROR(INDEX(직원목록!$AF$7:$AF$306,MATCH(8,직원목록!$B$7:$B$306,0)),"")) | K20: =IF($A20="","",IFERROR(INDEX(직원목록!$AI$7:$AI$306,MATCH(8,직원목록!$B$7:$B$306,0)),"")) | L20: =IF($A20="","",IF(LEN(IF(AND(F20<>"",F20<>0),"계산 총지급과 대장 총지급이 다릅니다 / ","")&IF(AND(I20<>"",I20<>0),"계산 총공제와 대장 총공제가 다릅니다 / ","")&IF(J20<0,"실수령액이 음수입니다 / ","")&IF(COUNTIF(직원목록!$D$7:$D$306,B20)>1,"같은 이름이 둘 이상 — 미리보기는 첫 번째만 보입니다 / ","")&IF(AND(C20<>"",COUNTIF(직원목록!$C$7:$C$306,C20)>1),"사번 중복 / ","")&IF(D20=0,"총지급이 0원 — 머리글 매칭 확인 / ","")&IF(AND(설정!$B$17<>"",설정!$C$17="",OR(ISNUMBER(FIND("연장",설정!$B$17)),ISNUMBER(FIND("야간",설정!$B$17)),ISNUMBER(FIND("휴일",설정!$B$17))),INDEX(직원목록!$F$7:$F$306,MATCH(8,직원목록!$B$7:$B$306,0))>0),"연장·야간·휴일 수당은 시간 수도 명세서에 적어야 하니 시간 열 지정 필요 / ","")&IF(AND(설정!$B$18<>"",설정!$C$18="",OR(ISNUMBER(FIND("연장",설정!$B$18)),ISNUMBER(FIND("야간",설정!$B$18)),ISNUMBER(FIND("휴일",설정!$B$18))),INDEX(직원목록!$G$7:$G$306,MATCH(8,직원목록!$B$7:$B$306,0))>0),"연장·야간·휴일 수당은 시간 수도 명세서에 적어야 하니 시간 열 지정 필요 / ","")&IF(AND(설정!$B$19<>"",설정!$C$19="",OR(ISNUMBER(FIND("연장",설정!$B$19)),ISNUMBER(FIND("야간",설정!$B$19)),ISNUMBER(FIND("휴일",설정!$B$19))),INDEX(직원목록!$H$7:$H$306,MATCH(8,직원목록!$B$7:$B$306,0))>0),"연장·야간·휴일 수당은 시간 수도 명세서에 적어야 하니 시간 열 지정 필요 / ","")&IF(AND(설정!$B$20<>"",설정!$C$20="",OR(ISNUMBER(FIND("연장",설정!$B$20)),ISNUMBER(FIND("야간",설정!$B$20)),ISNUMBER(FIND("휴일",설정!$B$20))),INDEX(직원목록!$I$7:$I$306,MATCH(8,직원목록!$B$7:$B$306,0))>0),"연장·야간·휴일 수당은 시간 수도 명세서에 적어야 하니 시간 열 지정 필요 / ","")&IF(AND(설정!$B$21<>"",설정!$C$21="",OR(ISNUMBER(FIND("연장",설정!$B$21)),ISNUMBER(FIND("야간",설정!$B$21)),ISNUMBER(FIND("휴일",설정!$B$21))),INDEX(직원목록!$J$7:$J$306,MATCH(8,직원목록!$B$7:$B$306,0))>0),"연장·야간·휴일 수당은 시간 수도 명세서에 적어야 하니 시간 열 지정 필요 / ","")&IF(AND(설정!$B$22<>"",설정!$C$22="",OR(ISNUMBER(FIND("연장",설정!$B$22)),ISNUMBER(FIND("야간",설정!$B$22)),ISNUMBER(FIND("휴일",설정!$B$22))),INDEX(직원목록!$K$7:$K$306,MATCH(8,직원목록!$B$7:$B$306,0))>0),"연장·야간·휴일 수당은 시간 수도 명세서에 적어야 하니 시간 열 지정 필요 / ","")&IF(AND(설정!$B$23<>"",설정!$C$23="",OR(ISNUMBER(FIND("연장",설정!$B$23)),ISNUMBER(FIND("야간",설정!$B$23)),ISNUMBER(FIND("휴일",설정!$B$23))),INDEX(직원목록!$L$7:$L$306,MATCH(8,직원목록!$B$7:$B$306,0))>0),"연장·야간·휴일 수당은 시간 수도 명세서에 적어야 하니 시간 열 지정 필요 / ","")&IF(AND(설정!$B$24<>"",설정!$C$24="",OR(ISNUMBER(FIND("연장",설정!$B$24)),ISNUMBER(FIND("야간",설정!$B$24)),ISNUMBER(FIND("휴일",설정!$B$24))),INDEX(직원목록!$M$7:$M$306,MATCH(8,직원목록!$B$7:$B$306,0))>0),"연장·야간·휴일 수당은 시간 수도 명세서에 적어야 하니 시간 열 지정 필요 / ",""))=0,"✔",("⚠ "&IF(AND(F20<>"",F20<>0),"계산 총지급과 대장 총지급이 다릅니다 / ","")&IF(AND(I20<>"",I20<>0),"계산 총공제와 대장 총공제가 다릅니다 / ","")&IF(J20<0,"실수령액이 음수입니다 / ","")&IF(COUNTIF(직원목록!$D$7:$D$306,B20)>1,"같은 이름이 둘 이상 — 미리보기는 첫 번째만 보입니다 / ","")&IF(AND(C20<>"",COUNTIF(직원목록!$C$7:$C$306,C20)>1),"사번 중복 / ","")&IF(D20=0,"총지급이 0원 — 머리글 매칭 확인 / ","")&IF(AND(설정!$B$17<>"",설정!$C$17="",OR(ISNUMBER(FIND("연장",설정!$B$17)),ISNUMBER(FIND("야간",설정!$B$17)),ISNUMBER(FIND("휴일",설정!$B$17))),INDEX(직원목록!$F$7:$F$306,MATCH(8,직원목록!$B$7:$B$306,0))>0),"연장·야간·휴일 수당은 시간 수도 명세서에 적어야 하니 시간 열 지정 필요 / ","")&IF(AND(설정!$B$18<>"",설정!$C$18="",OR(ISNUMBER(FIND("연장",설정!$B$18)),ISNUMBER(FIND("야간",설정!$B$18)),ISNUMBER(FIND("휴일",설정!$B$18))),INDEX(직원목록!$G$7:$G$306,MATCH(8,직원목록!$B$7:$B$306,0))>0),"연장·야간·휴일 수당은 시간 수도 명세서에 적어야 하니 시간 열 지정 필요 / ","")&IF(AND(설정!$B$19<>"",설정!$C$19="",OR(ISNUMBER(FIND("연장",설정!$B$19)),ISNUMBER(FIND("야간",설정!$B$19)),ISNUMBER(FIND("휴일",설정!$B$19))),INDEX(직원목록!$H$7:$H$306,MATCH(8,직원목록!$B$7:$B$306,0))>0),"연장·야간·휴일 수당은 시간 수도 명세서에 적어야 하니 시간 열 지정 필요 / ","")&IF(AND(설정!$B$20<>"",설정!$C$20="",OR(ISNUMBER(FIND("연장",설정!$B$20)),ISNUMBER(FIND("야간",설정!$B$20)),ISNUMBER(FIND("휴일",설정!$B$20))),INDEX(직원목록!$I$7:$I$306,MATCH(8,직원목록!$B$7:$B$306,0))>0),"연장·야간·휴일 수당은 시간 수도 명세서에 적어야 하니 시간 열 지정 필요 / ","")&IF(AND(설정!$B$21<>"",설정!$C$21="",OR(ISNUMBER(FIND("연장",설정!$B$21)),ISNUMBER(FIND("야간",설정!$B$21)),ISNUMBER(FIND("휴일",설정!$B$21))),INDEX(직원목록!$J$7:$J$306,MATCH(8,직원목록!$B$7:$B$306,0))>0),"연장·야간·휴일 수당은 시간 수도 명세서에 적어야 하니 시간 열 지정 필요 / ","")&IF(AND(설정!$B$22<>"",설정!$C$22="",OR(ISNUMBER(FIND("연장",설정!$B$22)),ISNUMBER(FIND("야간",설정!$B$22)),ISNUMBER(FIND("휴일",설정!$B$22))),INDEX(직원목록!$K$7:$K$306,MATCH(8,직원목록!$B$7:$B$306,0))>0),"연장·야간·휴일 수당은 시간 수도 명세서에 적어야 하니 시간 열 지정 필요 / ","")&IF(AND(설정!$B$23<>"",설정!$C$23="",OR(ISNUMBER(FIND("연장",설정!$B$23)),ISNUMBER(FIND("야간",설정!$B$23)),ISNUMBER(FIND("휴일",설정!$B$23))),INDEX(직원목록!$L$7:$L$306,MATCH(8,직원목록!$B$7:$B$306,0))>0),"연장·야간·휴일 수당은 시간 수도 명세서에 적어야 하니 시간 열 지정 필요 / ","")&IF(AND(설정!$B$24<>"",설정!$C$24="",OR(ISNUMBER(FIND("연장",설정!$B$24)),ISNUMBER(FIND("야간",설정!$B$24)),ISNUMBER(FIND("휴일",설정!$B$24))),INDEX(직원목록!$M$7:$M$306,MATCH(8,직원목록!$B$7:$B$306,0))>0),"연장·야간·휴일 수당은 시간 수도 명세서에 적어야 하니 시간 열 지정 필요 / ",""))))
A21: =IF(IFERROR(MATCH(9,직원목록!$B$7:$B$306,0),0)=0,"",9) | B21: =IF($A21="","",IFERROR(INDEX(직원목록!$D$7:$D$306,MATCH(9,직원목록!$B$7:$B$306,0)),"")) | C21: =IF($A21="","",IFERROR(INDEX(직원목록!$C$7:$C$306,MATCH(9,직원목록!$B$7:$B$306,0)),"")) | D21: =IF($A21="","",IFERROR(INDEX(직원목록!$V$7:$V$306,MATCH(9,직원목록!$B$7:$B$306,0)),"")) | E21: =IF($A21="","",IFERROR(INDEX(직원목록!$AG$7:$AG$306,MATCH(9,직원목록!$B$7:$B$306,0)),"")) | F21: =IF(OR($A21="",E21=""),"",D21-E21) | G21: =IF($A21="","",IFERROR(INDEX(직원목록!$AE$7:$AE$306,MATCH(9,직원목록!$B$7:$B$306,0)),"")) | H21: =IF($A21="","",IFERROR(INDEX(직원목록!$AH$7:$AH$306,MATCH(9,직원목록!$B$7:$B$306,0)),"")) | I21: =IF(OR($A21="",H21=""),"",G21-H21) | J21: =IF($A21="","",IFERROR(INDEX(직원목록!$AF$7:$AF$306,MATCH(9,직원목록!$B$7:$B$306,0)),"")) | K21: =IF($A21="","",IFERROR(INDEX(직원목록!$AI$7:$AI$306,MATCH(9,직원목록!$B$7:$B$306,0)),"")) | L21: =IF($A21="","",IF(LEN(IF(AND(F21<>"",F21<>0),"계산 총지급과 대장 총지급이 다릅니다 / ","")&IF(AND(I21<>"",I21<>0),"계산 총공제와 대장 총공제가 다릅니다 / ","")&IF(J21<0,"실수령액이 음수입니다 / ","")&IF(COUNTIF(직원목록!$D$7:$D$306,B21)>1,"같은 이름이 둘 이상 — 미리보기는 첫 번째만 보입니다 / ","")&IF(AND(C21<>"",COUNTIF(직원목록!$C$7:$C$306,C21)>1),"사번 중복 / ","")&IF(D21=0,"총지급이 0원 — 머리글 매칭 확인 / ","")&IF(AND(설정!$B$17<>"",설정!$C$17="",OR(ISNUMBER(FIND("연장",설정!$B$17)),ISNUMBER(FIND("야간",설정!$B$17)),ISNUMBER(FIND("휴일",설정!$B$17))),INDEX(직원목록!$F$7:$F$306,MATCH(9,직원목록!$B$7:$B$306,0))>0),"연장·야간·휴일 수당은 시간 수도 명세서에 적어야 하니 시간 열 지정 필요 / ","")&IF(AND(설정!$B$18<>"",설정!$C$18="",OR(ISNUMBER(FIND("연장",설정!$B$18)),ISNUMBER(FIND("야간",설정!$B$18)),ISNUMBER(FIND("휴일",설정!$B$18))),INDEX(직원목록!$G$7:$G$306,MATCH(9,직원목록!$B$7:$B$306,0))>0),"연장·야간·휴일 수당은 시간 수도 명세서에 적어야 하니 시간 열 지정 필요 / ","")&IF(AND(설정!$B$19<>"",설정!$C$19="",OR(ISNUMBER(FIND("연장",설정!$B$19)),ISNUMBER(FIND("야간",설정!$B$19)),ISNUMBER(FIND("휴일",설정!$B$19))),INDEX(직원목록!$H$7:$H$306,MATCH(9,직원목록!$B$7:$B$306,0))>0),"연장·야간·휴일 수당은 시간 수도 명세서에 적어야 하니 시간 열 지정 필요 / ","")&IF(AND(설정!$B$20<>"",설정!$C$20="",OR(ISNUMBER(FIND("연장",설정!$B$20)),ISNUMBER(FIND("야간",설정!$B$20)),ISNUMBER(FIND("휴일",설정!$B$20))),INDEX(직원목록!$I$7:$I$306,MATCH(9,직원목록!$B$7:$B$306,0))>0),"연장·야간·휴일 수당은 시간 수도 명세서에 적어야 하니 시간 열 지정 필요 / ","")&IF(AND(설정!$B$21<>"",설정!$C$21="",OR(ISNUMBER(FIND("연장",설정!$B$21)),ISNUMBER(FIND("야간",설정!$B$21)),ISNUMBER(FIND("휴일",설정!$B$21))),INDEX(직원목록!$J$7:$J$306,MATCH(9,직원목록!$B$7:$B$306,0))>0),"연장·야간·휴일 수당은 시간 수도 명세서에 적어야 하니 시간 열 지정 필요 / ","")&IF(AND(설정!$B$22<>"",설정!$C$22="",OR(ISNUMBER(FIND("연장",설정!$B$22)),ISNUMBER(FIND("야간",설정!$B$22)),ISNUMBER(FIND("휴일",설정!$B$22))),INDEX(직원목록!$K$7:$K$306,MATCH(9,직원목록!$B$7:$B$306,0))>0),"연장·야간·휴일 수당은 시간 수도 명세서에 적어야 하니 시간 열 지정 필요 / ","")&IF(AND(설정!$B$23<>"",설정!$C$23="",OR(ISNUMBER(FIND("연장",설정!$B$23)),ISNUMBER(FIND("야간",설정!$B$23)),ISNUMBER(FIND("휴일",설정!$B$23))),INDEX(직원목록!$L$7:$L$306,MATCH(9,직원목록!$B$7:$B$306,0))>0),"연장·야간·휴일 수당은 시간 수도 명세서에 적어야 하니 시간 열 지정 필요 / ","")&IF(AND(설정!$B$24<>"",설정!$C$24="",OR(ISNUMBER(FIND("연장",설정!$B$24)),ISNUMBER(FIND("야간",설정!$B$24)),ISNUMBER(FIND("휴일",설정!$B$24))),INDEX(직원목록!$M$7:$M$306,MATCH(9,직원목록!$B$7:$B$306,0))>0),"연장·야간·휴일 수당은 시간 수도 명세서에 적어야 하니 시간 열 지정 필요 / ",""))=0,"✔",("⚠ "&IF(AND(F21<>"",F21<>0),"계산 총지급과 대장 총지급이 다릅니다 / ","")&IF(AND(I21<>"",I21<>0),"계산 총공제와 대장 총공제가 다릅니다 / ","")&IF(J21<0,"실수령액이 음수입니다 / ","")&IF(COUNTIF(직원목록!$D$7:$D$306,B21)>1,"같은 이름이 둘 이상 — 미리보기는 첫 번째만 보입니다 / ","")&IF(AND(C21<>"",COUNTIF(직원목록!$C$7:$C$306,C21)>1),"사번 중복 / ","")&IF(D21=0,"총지급이 0원 — 머리글 매칭 확인 / ","")&IF(AND(설정!$B$17<>"",설정!$C$17="",OR(ISNUMBER(FIND("연장",설정!$B$17)),ISNUMBER(FIND("야간",설정!$B$17)),ISNUMBER(FIND("휴일",설정!$B$17))),INDEX(직원목록!$F$7:$F$306,MATCH(9,직원목록!$B$7:$B$306,0))>0),"연장·야간·휴일 수당은 시간 수도 명세서에 적어야 하니 시간 열 지정 필요 / ","")&IF(AND(설정!$B$18<>"",설정!$C$18="",OR(ISNUMBER(FIND("연장",설정!$B$18)),ISNUMBER(FIND("야간",설정!$B$18)),ISNUMBER(FIND("휴일",설정!$B$18))),INDEX(직원목록!$G$7:$G$306,MATCH(9,직원목록!$B$7:$B$306,0))>0),"연장·야간·휴일 수당은 시간 수도 명세서에 적어야 하니 시간 열 지정 필요 / ","")&IF(AND(설정!$B$19<>"",설정!$C$19="",OR(ISNUMBER(FIND("연장",설정!$B$19)),ISNUMBER(FIND("야간",설정!$B$19)),ISNUMBER(FIND("휴일",설정!$B$19))),INDEX(직원목록!$H$7:$H$306,MATCH(9,직원목록!$B$7:$B$306,0))>0),"연장·야간·휴일 수당은 시간 수도 명세서에 적어야 하니 시간 열 지정 필요 / ","")&IF(AND(설정!$B$20<>"",설정!$C$20="",OR(ISNUMBER(FIND("연장",설정!$B$20)),ISNUMBER(FIND("야간",설정!$B$20)),ISNUMBER(FIND("휴일",설정!$B$20))),INDEX(직원목록!$I$7:$I$306,MATCH(9,직원목록!$B$7:$B$306,0))>0),"연장·야간·휴일 수당은 시간 수도 명세서에 적어야 하니 시간 열 지정 필요 / ","")&IF(AND(설정!$B$21<>"",설정!$C$21="",OR(ISNUMBER(FIND("연장",설정!$B$21)),ISNUMBER(FIND("야간",설정!$B$21)),ISNUMBER(FIND("휴일",설정!$B$21))),INDEX(직원목록!$J$7:$J$306,MATCH(9,직원목록!$B$7:$B$306,0))>0),"연장·야간·휴일 수당은 시간 수도 명세서에 적어야 하니 시간 열 지정 필요 / ","")&IF(AND(설정!$B$22<>"",설정!$C$22="",OR(ISNUMBER(FIND("연장",설정!$B$22)),ISNUMBER(FIND("야간",설정!$B$22)),ISNUMBER(FIND("휴일",설정!$B$22))),INDEX(직원목록!$K$7:$K$306,MATCH(9,직원목록!$B$7:$B$306,0))>0),"연장·야간·휴일 수당은 시간 수도 명세서에 적어야 하니 시간 열 지정 필요 / ","")&IF(AND(설정!$B$23<>"",설정!$C$23="",OR(ISNUMBER(FIND("연장",설정!$B$23)),ISNUMBER(FIND("야간",설정!$B$23)),ISNUMBER(FIND("휴일",설정!$B$23))),INDEX(직원목록!$L$7:$L$306,MATCH(9,직원목록!$B$7:$B$306,0))>0),"연장·야간·휴일 수당은 시간 수도 명세서에 적어야 하니 시간 열 지정 필요 / ","")&IF(AND(설정!$B$24<>"",설정!$C$24="",OR(ISNUMBER(FIND("연장",설정!$B$24)),ISNUMBER(FIND("야간",설정!$B$24)),ISNUMBER(FIND("휴일",설정!$B$24))),INDEX(직원목록!$M$7:$M$306,MATCH(9,직원목록!$B$7:$B$306,0))>0),"연장·야간·휴일 수당은 시간 수도 명세서에 적어야 하니 시간 열 지정 필요 / ",""))))
